Workbook

Sheet Read me
A1: Mock R1 roster, Build 1 (TRAINER ONLY)
A2: Seats and groups, never names. Durations only: every time is a minute inside a 180-minute block.
A4: Which cells do you edit?
A5: Yellow cells with blue text are the inputs: the slot, changeover, huddle and close minutes on Settings; each group's sub-problem on Groups, chosen from its list after Monday's allocation; and each seat's present flag on Seats. Every other cell is a formula.
A7: How does the default work?
A8: 35 seats in nine groups, eight of four and G9 of three, as data/programme/facts.yaml states the cohort. The Programme Head changes the group sizes on Seats if Monday's allocation differs.
A9: The call order on Seats takes seat 1 of every group, then seat 2 of every group, and so on, and each slot fills the three assessors in call order, so the three learners out at once come from three different groups and every group keeps building while one member is out.
A10: The Programme Head and the Academic TA take 12 learners each in person, and the Principal Advisor takes 11 online and holds the spare slot at the end of the day. Each assessor meets every member of the same three groups: the Programme Head G1, G4 and G7, the Academic TA G2, G5 and G8, and the Principal Advisor G3, G6 and G9, so work carried for a group-mate shows against the others' answers.
A11: Each seat's set letter picks its three technical questions from the Sets sheet, consecutive letters within a group, so no two group-mates meet the same set. Its seat number picks its viva probe: seat 1 takes P1. Where a set's question sits close to the group's own sub-problem, the Sets sheet's swap table puts the reserve in its place, and the Seats, Roster and Grid sheets print the swapped question.
A12: Print the Grid sheet for the huddle: one row per slot, one column per assessor.
A14: What moves when a learner is absent?
A15: Known before the day: set that seat's present flag to no. The queue closes up and the day ends one slot sooner for one assessor. Then read the clash count on Settings: above zero means two group-mates now share a slot, so swap two rows' call order on Seats until it reads zero.
... A19: The grid assumes three assessors. If one is out for part of the day, their learners move first to the other two assessors' free and spare slots, then to the open build time after the second block. The day sheet carries this plan.

Sheet Settings
A1: Settings and the day's verdict
A3: Mock slot, minutes | B3: 20 | C3: The row: roughly 20 minutes each.
A4: Changeover, minutes | B4: 5 | C4: The assessor finishes the evidence note and enters the marks.
A5: Block length, minutes | B5: 180 | C5: data/programme/facts.yaml: two blocks of 180 minutes.
A6: Assessors' huddle at the start of block 1, minutes | B6: 10 | C6: Calibration before the first mock.
A7: Close at the end of block 2, minutes | B7: 15 | C7: The row: the close-out, 15 minutes.
A8: One slot and its changeover, minutes | B8: =B3+B4
A9: Slots per assessor in block 1 | B9: =INT((B5-B6)/B8)
A10: Slots per assessor in block 2 | B10: =INT((B5-B7)/B8)
A11: Slots per assessor in the day | B11: =B9+B10
A12: Assessors | B12: 3
A13: Mock places in the day | B13: =B11*B12
A14: Learners present | B14: =COUNTIF(Seats!G2:G36,"yes")
A15: Spare places | B15: =B13-B14
A16: Verdict | B16: =IF(B14<=B13,"fits: "&B13&" slots for "&B14&" learners","does not fit: "&(B14-B13)&" learners without a slot")
A17: Last mock of the day ends at | B17: =IF(B14>B13,"after the day",IF(ROUNDUP(B14/B12,0)<=B9,"block 1, minute "&(B6+ROUNDUP(B14/B12,0)*B8-B4),"block 2, minute "&((ROUNDUP(B14/B12,0)-B9)*B8-B4)))
A18: Close starts at | B18: ="block 2, minute "&(B5-B7)
A19: Slots where two group-mates are out at once | B19: =COUNTIF(Roster!L2:L43,"yes") | C19: Zero by default. Above zero after an absence: swap call orders on Seats.
A20: Assessor minutes in mocks | B20: =B14*B3
A22: Load per assessor
A23: Assessor | B23: Mode | C23: Learners | D23: Minutes in mocks | E23: Last mock ends at
A24: Programme Head | B24: in person | C24: =COUNTIFS(Roster!B2:B43,A24,Roster!H2:H43,"G*") | D24: =C24*$B$3 | E24: =IF(C24=0,"no mocks",IF(_xlfn.MAXIFS(Roster!M2:M43,Roster!B2:B43,A24,Roster!H2:H43,"G*")>$B$5,"block 2, minute "&(_xlfn.MAXIFS(Roster!M2:M43,Roster!B2:B43,A24,Roster!H2:H43,"G*")-$B$5),"block 1, minute "&_xlfn.MAXIFS(Roster!M2:M43,Roster!B2:B43,A24,Roster!H2:H43,"G*")))
A25: Academic TA | B25: in person | C25: =COUNTIFS(Roster!B2:B43,A25,Roster!H2:H43,"G*") | D25: =C25*$B$3 | E25: =IF(C25=0,"no mocks",IF(_xlfn.MAXIFS(Roster!M2:M43,Roster!B2:B43,A25,Roster!H2:H43,"G*")>$B$5,"block 2, minute "&(_xlfn.MAXIFS(Roster!M2:M43,Roster!B2:B43,A25,Roster!H2:H43,"G*")-$B$5),"block 1, minute "&_xlfn.MAXIFS(Roster!M2:M43,Roster!B2:B43,A25,Roster!H2:H43,"G*")))
A26: Principal Advisor | B26: online | C26: =COUNTIFS(Roster!B2:B43,A26,Roster!H2:H43,"G*") | D26: =C26*$B$3 | E26: =IF(C26=0,"no mocks",IF(_xlfn.MAXIFS(Roster!M2:M43,Roster!B2:B43,A26,Roster!H2:H43,"G*")>$B$5,"block 2, minute "&(_xlfn.MAXIFS(Roster!M2:M43,Roster!B2:B43,A26,Roster!H2:H43,"G*")-$B$5),"block 1, minute "&_xlfn.MAXIFS(Roster!M2:M43,Roster!B2:B43,A26,Roster!H2:H43,"G*")))
A27: Total | C27: =SUM(C24:C26) | D27: =SUM(D24:D26)

Sheet Sets
A1: Set | B1: L1, the move | C1: L2, the number | D1: L3, the judgement | F1: Swap key | G1: Ask instead | I1: What the two tables do
A2: A | B2: T01-L1 | C2: T04-L2 | D2: T07-L3 | F2: T04-L2|4 | G2: T02-L2 | I2: A swap key is a question and the first digit of a group's sub-problem. When a seat's set holds that question and its group took that sub-problem, the seat is asked the reserve beside it, so the technical half never rehearses the learner's own viva.
A3: B | B3: T02-L1 | C3: T05-L2 | D3: T08-L3 | F3: T07-L2|3 | G3: T02-L2 | I3: The reserves are T09-L1, T10-L1, T02-L2, T03-L2, T05-L3 and T06-L3.
A4: C | B4: T03-L1 | C4: T06-L2 | D4: T09-L3 | F4: T09-L2|3 | G4: T02-L2 | I4: T03-L2 is never asked of a learner whose group took sub-problem 2.
A5: D | B5: T04-L1 | C5: T07-L2 | D5: T10-L3 | F5: T04-L3|5 | G5: T05-L3
A6: E | B6: T05-L1 | C6: T08-L2 | D6: T01-L3
A7: F | B7: T06-L1 | C7: T09-L2 | D7: T02-L3
A8: G | B8: T07-L1 | C8: T10-L2 | D8: T03-L3
A9: H | B9: T08-L1 | C9: T01-L2 | D9: T04-L3

Sheet Groups
A1: Group | B1: Sub-problem (choose after Monday) | C1: Seats | D1: Present | E1: Mocks placed | F1: Assessor
A2: G1 | C2: =COUNTIF(Seats!B$2:B$36,A2) | D2: =COUNTIFS(Seats!B$2:B$36,A2,Seats!G$2:G$36,"yes") | E2: =COUNTIF(Roster!I$2:I$43,A2) | F2: Programme Head
A3: G2 | C3: =COUNTIF(Seats!B$2:B$36,A3) | D3: =COUNTIFS(Seats!B$2:B$36,A3,Seats!G$2:G$36,"yes") | E3: =COUNTIF(Roster!I$2:I$43,A3) | F3: Academic TA
A4: G3 | C4: =COUNTIF(Seats!B$2:B$36,A4) | D4: =COUNTIFS(Seats!B$2:B$36,A4,Seats!G$2:G$36,"yes") | E4: =COUNTIF(Roster!I$2:I$43,A4) | F4: Principal Advisor
A5: G4 | C5: =COUNTIF(Seats!B$2:B$36,A5) | D5: =COUNTIFS(Seats!B$2:B$36,A5,Seats!G$2:G$36,"yes") | E5: =COUNTIF(Roster!I$2:I$43,A5) | F5: Programme Head
A6: G5 | C6: =COUNTIF(Seats!B$2:B$36,A6) | D6: =COUNTIFS(Seats!B$2:B$36,A6,Seats!G$2:G$36,"yes") | E6: =COUNTIF(Roster!I$2:I$43,A6) | F6: Academic TA
A7: G6 | C7: =COUNTIF(Seats!B$2:B$36,A7) | D7: =COUNTIFS(Seats!B$2:B$36,A7,Seats!G$2:G$36,"yes") | E7: =COUNTIF(Roster!I$2:I$43,A7) | F7: Principal Advisor
A8: G7 | C8: =COUNTIF(Seats!B$2:B$36,A8) | D8: =COUNTIFS(Seats!B$2:B$36,A8,Seats!G$2:G$36,"yes") | E8: =COUNTIF(Roster!I$2:I$43,A8) | F8: Programme Head
A9: G8 | C9: =COUNTIF(Seats!B$2:B$36,A9) | D9: =COUNTIFS(Seats!B$2:B$36,A9,Seats!G$2:G$36,"yes") | E9: =COUNTIF(Roster!I$2:I$43,A9) | F9: Academic TA
A10: G9 | C10: =COUNTIF(Seats!B$2:B$36,A10) | D10: =COUNTIFS(Seats!B$2:B$36,A10,Seats!G$2:G$36,"yes") | E10: =COUNTIF(Roster!I$2:I$43,A10) | F10: Principal Advisor
A11: Total | C11: =SUM(C2:C10) | D11: =SUM(D2:D10) | E11: =SUM(E2:E10)

Sheet Seats
A1: Call order | B1: Group | C1: Seat | D1: Seat label | E1: Set | F1: Sub-problem | G1: Present | H1: Queue position | I1: Viva probe | J1: L1 | K1: L2 | L1: L3
A2: 1 | B2: G1 | C2: 1 | D2: =B2&"-S"&C2 | E2: =MID("ABCDEFGH",MOD(VALUE(MID(B2,2,2))+C2-2,8)+1,1) | F2: =IF(INDEX(Groups!B$2:B$10,VALUE(MID(B2,2,2)))="","allocate on Monday",INDEX(Groups!B$2:B$10,VALUE(MID(B2,2,2)))) | G2: yes | H2: =IF(G2="yes",COUNTIFS(G$2:G$36,"yes",A$2:A$36,"<="&A2),"") | I2: ="P"&C2 | J2: =IFERROR(INDEX(Sets!G$2:G$5,MATCH(INDEX(Sets!B$2:B$9,MATCH(E2,Sets!A$2:A$9,0))&"|"&LEFT(F2,1),Sets!F$2:F$5,0)),INDEX(Sets!B$2:B$9,MATCH(E2,Sets!A$2:A$9,0))) | K2: =IFERROR(INDEX(Sets!G$2:G$5,MATCH(INDEX(Sets!C$2:C$9,MATCH(E2,Sets!A$2:A$9,0))&"|"&LEFT(F2,1),Sets!F$2:F$5,0)),INDEX(Sets!C$2:C$9,MATCH(E2,Sets!A$2:A$9,0))) | L2: =IFERROR(INDEX(Sets!G$2:G$5,MATCH(INDEX(Sets!D$2:D$9,MATCH(E2,Sets!A$2:A$9,0))&"|"&LEFT(F2,1),Sets!F$2:F$5,0)),INDEX(Sets!D$2:D$9,MATCH(E2,Sets!A$2:A$9,0)))
A3: 2 | B3: G2 | C3: 1 | D3: =B3&"-S"&C3 | E3: =MID("ABCDEFGH",MOD(VALUE(MID(B3,2,2))+C3-2,8)+1,1) | F3: =IF(INDEX(Groups!B$2:B$10,VALUE(MID(B3,2,2)))="","allocate on Monday",INDEX(Groups!B$2:B$10,VALUE(MID(B3,2,2)))) | G3: yes | H3: =IF(G3="yes",COUNTIFS(G$2:G$36,"yes",A$2:A$36,"<="&A3),"") | I3: ="P"&C3 | J3: =IFERROR(INDEX(Sets!G$2:G$5,MATCH(INDEX(Sets!B$2:B$9,MATCH(E3,Sets!A$2:A$9,0))&"|"&LEFT(F3,1),Sets!F$2:F$5,0)),INDEX(Sets!B$2:B$9,MATCH(E3,Sets!A$2:A$9,0))) | K3: =IFERROR(INDEX(Sets!G$2:G$5,MATCH(INDEX(Sets!C$2:C$9,MATCH(E3,Sets!A$2:A$9,0))&"|"&LEFT(F3,1),Sets!F$2:F$5,0)),INDEX(Sets!C$2:C$9,MATCH(E3,Sets!A$2:A$9,0))) | L3: =IFERROR(INDEX(Sets!G$2:G$5,MATCH(INDEX(Sets!D$2:D$9,MATCH(E3,Sets!A$2:A$9,0))&"|"&LEFT(F3,1),Sets!F$2:F$5,0)),INDEX(Sets!D$2:D$9,MATCH(E3,Sets!A$2:A$9,0)))
A4: 3 | B4: G3 | C4: 1 | D4: =B4&"-S"&C4 | E4: =MID("ABCDEFGH",MOD(VALUE(MID(B4,2,2))+C4-2,8)+1,1) | F4: =IF(INDEX(Groups!B$2:B$10,VALUE(MID(B4,2,2)))="","allocate on Monday",INDEX(Groups!B$2:B$10,VALUE(MID(B4,2,2)))) | G4: yes | H4: =IF(G4="yes",COUNTIFS(G$2:G$36,"yes",A$2:A$36,"<="&A4),"") | I4: ="P"&C4 | J4: =IFERROR(INDEX(Sets!G$2:G$5,MATCH(INDEX(Sets!B$2:B$9,MATCH(E4,Sets!A$2:A$9,0))&"|"&LEFT(F4,1),Sets!F$2:F$5,0)),INDEX(Sets!B$2:B$9,MATCH(E4,Sets!A$2:A$9,0))) | K4: =IFERROR(INDEX(Sets!G$2:G$5,MATCH(INDEX(Sets!C$2:C$9,MATCH(E4,Sets!A$2:A$9,0))&"|"&LEFT(F4,1),Sets!F$2:F$5,0)),INDEX(Sets!C$2:C$9,MATCH(E4,Sets!A$2:A$9,0))) | L4: =IFERROR(INDEX(Sets!G$2:G$5,MATCH(INDEX(Sets!D$2:D$9,MATCH(E4,Sets!A$2:A$9,0))&"|"&LEFT(F4,1),Sets!F$2:F$5,0)),INDEX(Sets!D$2:D$9,MATCH(E4,Sets!A$2:A$9,0)))
A5: 4 | B5: G4 | C5: 1 | D5: =B5&"-S"&C5 | E5: =MID("ABCDEFGH",MOD(VALUE(MID(B5,2,2))+C5-2,8)+1,1) | F5: =IF(INDEX(Groups!B$2:B$10,VALUE(MID(B5,2,2)))="","allocate on Monday",INDEX(Groups!B$2:B$10,VALUE(MID(B5,2,2)))) | G5: yes | H5: =IF(G5="yes",COUNTIFS(G$2:G$36,"yes",A$2:A$36,"<="&A5),"") | I5: ="P"&C5 | J5: =IFERROR(INDEX(Sets!G$2:G$5,MATCH(INDEX(Sets!B$2:B$9,MATCH(E5,Sets!A$2:A$9,0))&"|"&LEFT(F5,1),Sets!F$2:F$5,0)),INDEX(Sets!B$2:B$9,MATCH(E5,Sets!A$2:A$9,0))) | K5: =IFERROR(INDEX(Sets!G$2:G$5,MATCH(INDEX(Sets!C$2:C$9,MATCH(E5,Sets!A$2:A$9,0))&"|"&LEFT(F5,1),Sets!F$2:F$5,0)),INDEX(Sets!C$2:C$9,MATCH(E5,Sets!A$2:A$9,0))) | L5: =IFERROR(INDEX(Sets!G$2:G$5,MATCH(INDEX(Sets!D$2:D$9,MATCH(E5,Sets!A$2:A$9,0))&"|"&LEFT(F5,1),Sets!F$2:F$5,0)),INDEX(Sets!D$2:D$9,MATCH(E5,Sets!A$2:A$9,0)))
A6: 5 | B6: G5 | C6: 1 | D6: =B6&"-S"&C6 | E6: =MID("ABCDEFGH",MOD(VALUE(MID(B6,2,2))+C6-2,8)+1,1) | F6: =IF(INDEX(Groups!B$2:B$10,VALUE(MID(B6,2,2)))="","allocate on Monday",INDEX(Groups!B$2:B$10,VALUE(MID(B6,2,2)))) | G6: yes | H6: =IF(G6="yes",COUNTIFS(G$2:G$36,"yes",A$2:A$36,"<="&A6),"") | I6: ="P"&C6 | J6: =IFERROR(INDEX(Sets!G$2:G$5,MATCH(INDEX(Sets!B$2:B$9,MATCH(E6,Sets!A$2:A$9,0))&"|"&LEFT(F6,1),Sets!F$2:F$5,0)),INDEX(Sets!B$2:B$9,MATCH(E6,Sets!A$2:A$9,0))) | K6: =IFERROR(INDEX(Sets!G$2:G$5,MATCH(INDEX(Sets!C$2:C$9,MATCH(E6,Sets!A$2:A$9,0))&"|"&LEFT(F6,1),Sets!F$2:F$5,0)),INDEX(Sets!C$2:C$9,MATCH(E6,Sets!A$2:A$9,0))) | L6: =IFERROR(INDEX(Sets!G$2:G$5,MATCH(INDEX(Sets!D$2:D$9,MATCH(E6,Sets!A$2:A$9,0))&"|"&LEFT(F6,1),Sets!F$2:F$5,0)),INDEX(Sets!D$2:D$9,MATCH(E6,Sets!A$2:A$9,0)))
A7: 6 | B7: G6 | C7: 1 | D7: =B7&"-S"&C7 | E7: =MID("ABCDEFGH",MOD(VALUE(MID(B7,2,2))+C7-2,8)+1,1) | F7: =IF(INDEX(Groups!B$2:B$10,VALUE(MID(B7,2,2)))="","allocate on Monday",INDEX(Groups!B$2:B$10,VALUE(MID(B7,2,2)))) | G7: yes | H7: =IF(G7="yes",COUNTIFS(G$2:G$36,"yes",A$2:A$36,"<="&A7),"") | I7: ="P"&C7 | J7: =IFERROR(INDEX(Sets!G$2:G$5,MATCH(INDEX(Sets!B$2:B$9,MATCH(E7,Sets!A$2:A$9,0))&"|"&LEFT(F7,1),Sets!F$2:F$5,0)),INDEX(Sets!B$2:B$9,MATCH(E7,Sets!A$2:A$9,0))) | K7: =IFERROR(INDEX(Sets!G$2:G$5,MATCH(INDEX(Sets!C$2:C$9,MATCH(E7,Sets!A$2:A$9,0))&"|"&LEFT(F7,1),Sets!F$2:F$5,0)),INDEX(Sets!C$2:C$9,MATCH(E7,Sets!A$2:A$9,0))) | L7: =IFERROR(INDEX(Sets!G$2:G$5,MATCH(INDEX(Sets!D$2:D$9,MATCH(E7,Sets!A$2:A$9,0))&"|"&LEFT(F7,1),Sets!F$2:F$5,0)),INDEX(Sets!D$2:D$9,MATCH(E7,Sets!A$2:A$9,0)))
A8: 7 | B8: G7 | C8: 1 | D8: =B8&"-S"&C8 | E8: =MID("ABCDEFGH",MOD(VALUE(MID(B8,2,2))+C8-2,8)+1,1) | F8: =IF(INDEX(Groups!B$2:B$10,VALUE(MID(B8,2,2)))="","allocate on Monday",INDEX(Groups!B$2:B$10,VALUE(MID(B8,2,2)))) | G8: yes | H8: =IF(G8="yes",COUNTIFS(G$2:G$36,"yes",A$2:A$36,"<="&A8),"") | I8: ="P"&C8 | J8: =IFERROR(INDEX(Sets!G$2:G$5,MATCH(INDEX(Sets!B$2:B$9,MATCH(E8,Sets!A$2:A$9,0))&"|"&LEFT(F8,1),Sets!F$2:F$5,0)),INDEX(Sets!B$2:B$9,MATCH(E8,Sets!A$2:A$9,0))) | K8: =IFERROR(INDEX(Sets!G$2:G$5,MATCH(INDEX(Sets!C$2:C$9,MATCH(E8,Sets!A$2:A$9,0))&"|"&LEFT(F8,1),Sets!F$2:F$5,0)),INDEX(Sets!C$2:C$9,MATCH(E8,Sets!A$2:A$9,0))) | L8: =IFERROR(INDEX(Sets!G$2:G$5,MATCH(INDEX(Sets!D$2:D$9,MATCH(E8,Sets!A$2:A$9,0))&"|"&LEFT(F8,1),Sets!F$2:F$5,0)),INDEX(Sets!D$2:D$9,MATCH(E8,Sets!A$2:A$9,0)))
A9: 8 | B9: G8 | C9: 1 | D9: =B9&"-S"&C9 | E9: =MID("ABCDEFGH",MOD(VALUE(MID(B9,2,2))+C9-2,8)+1,1) | F9: =IF(INDEX(Groups!B$2:B$10,VALUE(MID(B9,2,2)))="","allocate on Monday",INDEX(Groups!B$2:B$10,VALUE(MID(B9,2,2)))) | G9: yes | H9: =IF(G9="yes",COUNTIFS(G$2:G$36,"yes",A$2:A$36,"<="&A9),"") | I9: ="P"&C9 | J9: =IFERROR(INDEX(Sets!G$2:G$5,MATCH(INDEX(Sets!B$2:B$9,MATCH(E9,Sets!A$2:A$9,0))&"|"&LEFT(F9,1),Sets!F$2:F$5,0)),INDEX(Sets!B$2:B$9,MATCH(E9,Sets!A$2:A$9,0))) | K9: =IFERROR(INDEX(Sets!G$2:G$5,MATCH(INDEX(Sets!C$2:C$9,MATCH(E9,Sets!A$2:A$9,0))&"|"&LEFT(F9,1),Sets!F$2:F$5,0)),INDEX(Sets!C$2:C$9,MATCH(E9,Sets!A$2:A$9,0))) | L9: =IFERROR(INDEX(Sets!G$2:G$5,MATCH(INDEX(Sets!D$2:D$9,MATCH(E9,Sets!A$2:A$9,0))&"|"&LEFT(F9,1),Sets!F$2:F$5,0)),INDEX(Sets!D$2:D$9,MATCH(E9,Sets!A$2:A$9,0)))
A10: 9 | B10: G9 | C10: 1 | D10: =B10&"-S"&C10 | E10: =MID("ABCDEFGH",MOD(VALUE(MID(B10,2,2))+C10-2,8)+1,1) | F10: =IF(INDEX(Groups!B$2:B$10,VALUE(MID(B10,2,2)))="","allocate on Monday",INDEX(Groups!B$2:B$10,VALUE(MID(B10,2,2)))) | G10: yes | H10: =IF(G10="yes",COUNTIFS(G$2:G$36,"yes",A$2:A$36,"<="&A10),"") | I10: ="P"&C10 | J10: =IFERROR(INDEX(Sets!G$2:G$5,MATCH(INDEX(Sets!B$2:B$9,MATCH(E10,Sets!A$2:A$9,0))&"|"&LEFT(F10,1),Sets!F$2:F$5,0)),INDEX(Sets!B$2:B$9,MATCH(E10,Sets!A$2:A$9,0))) | K10: =IFERROR(INDEX(Sets!G$2:G$5,MATCH(INDEX(Sets!C$2:C$9,MATCH(E10,Sets!A$2:A$9,0))&"|"&LEFT(F10,1),Sets!F$2:F$5,0)),INDEX(Sets!C$2:C$9,MATCH(E10,Sets!A$2:A$9,0))) | L10: =IFERROR(INDEX(Sets!G$2:G$5,MATCH(INDEX(Sets!D$2:D$9,MATCH(E10,Sets!A$2:A$9,0))&"|"&LEFT(F10,1),Sets!F$2:F$5,0)),INDEX(Sets!D$2:D$9,MATCH(E10,Sets!A$2:A$9,0)))
A11: 10 | B11: G1 | C11: 2 | D11: =B11&"-S"&C11 | E11: =MID("ABCDEFGH",MOD(VALUE(MID(B11,2,2))+C11-2,8)+1,1) | F11: =IF(INDEX(Groups!B$2:B$10,VALUE(MID(B11,2,2)))="","allocate on Monday",INDEX(Groups!B$2:B$10,VALUE(MID(B11,2,2)))) | G11: yes | H11: =IF(G11="yes",COUNTIFS(G$2:G$36,"yes",A$2:A$36,"<="&A11),"") | I11: ="P"&C11 | J11: =IFERROR(INDEX(Sets!G$2:G$5,MATCH(INDEX(Sets!B$2:B$9,MATCH(E11,Sets!A$2:A$9,0))&"|"&LEFT(F11,1),Sets!F$2:F$5,0)),INDEX(Sets!B$2:B$9,MATCH(E11,Sets!A$2:A$9,0))) | K11: =IFERROR(INDEX(Sets!G$2:G$5,MATCH(INDEX(Sets!C$2:C$9,MATCH(E11,Sets!A$2:A$9,0))&"|"&LEFT(F11,1),Sets!F$2:F$5,0)),INDEX(Sets!C$2:C$9,MATCH(E11,Sets!A$2:A$9,0))) | L11: =IFERROR(INDEX(Sets!G$2:G$5,MATCH(INDEX(Sets!D$2:D$9,MATCH(E11,Sets!A$2:A$9,0))&"|"&LEFT(F11,1),Sets!F$2:F$5,0)),INDEX(Sets!D$2:D$9,MATCH(E11,Sets!A$2:A$9,0)))
A12: 11 | B12: G2 | C12: 2 | D12: =B12&"-S"&C12 | E12: =MID("ABCDEFGH",MOD(VALUE(MID(B12,2,2))+C12-2,8)+1,1) | F12: =IF(INDEX(Groups!B$2:B$10,VALUE(MID(B12,2,2)))="","allocate on Monday",INDEX(Groups!B$2:B$10,VALUE(MID(B12,2,2)))) | G12: yes | H12: =IF(G12="yes",COUNTIFS(G$2:G$36,"yes",A$2:A$36,"<="&A12),"") | I12: ="P"&C12 | J12: =IFERROR(INDEX(Sets!G$2:G$5,MATCH(INDEX(Sets!B$2:B$9,MATCH(E12,Sets!A$2:A$9,0))&"|"&LEFT(F12,1),Sets!F$2:F$5,0)),INDEX(Sets!B$2:B$9,MATCH(E12,Sets!A$2:A$9,0))) | K12: =IFERROR(INDEX(Sets!G$2:G$5,MATCH(INDEX(Sets!C$2:C$9,MATCH(E12,Sets!A$2:A$9,0))&"|"&LEFT(F12,1),Sets!F$2:F$5,0)),INDEX(Sets!C$2:C$9,MATCH(E12,Sets!A$2:A$9,0))) | L12: =IFERROR(INDEX(Sets!G$2:G$5,MATCH(INDEX(Sets!D$2:D$9,MATCH(E12,Sets!A$2:A$9,0))&"|"&LEFT(F12,1),Sets!F$2:F$5,0)),INDEX(Sets!D$2:D$9,MATCH(E12,Sets!A$2:A$9,0)))
A13: 12 | B13: G3 | C13: 2 | D13: =B13&"-S"&C13 | E13: =MID("ABCDEFGH",MOD(VALUE(MID(B13,2,2))+C13-2,8)+1,1) | F13: =IF(INDEX(Groups!B$2:B$10,VALUE(MID(B13,2,2)))="","allocate on Monday",INDEX(Groups!B$2:B$10,VALUE(MID(B13,2,2)))) | G13: yes | H13: =IF(G13="yes",COUNTIFS(G$2:G$36,"yes",A$2:A$36,"<="&A13),"") | I13: ="P"&C13 | J13: =IFERROR(INDEX(Sets!G$2:G$5,MATCH(INDEX(Sets!B$2:B$9,MATCH(E13,Sets!A$2:A$9,0))&"|"&LEFT(F13,1),Sets!F$2:F$5,0)),INDEX(Sets!B$2:B$9,MATCH(E13,Sets!A$2:A$9,0))) | K13: =IFERROR(INDEX(Sets!G$2:G$5,MATCH(INDEX(Sets!C$2:C$9,MATCH(E13,Sets!A$2:A$9,0))&"|"&LEFT(F13,1),Sets!F$2:F$5,0)),INDEX(Sets!C$2:C$9,MATCH(E13,Sets!A$2:A$9,0))) | L13: =IFERROR(INDEX(Sets!G$2:G$5,MATCH(INDEX(Sets!D$2:D$9,MATCH(E13,Sets!A$2:A$9,0))&"|"&LEFT(F13,1),Sets!F$2:F$5,0)),INDEX(Sets!D$2:D$9,MATCH(E13,Sets!A$2:A$9,0)))
... A36: 35 | B36: G8 | C36: 4 | D36: =B36&"-S"&C36 | E36: =MID("ABCDEFGH",MOD(VALUE(MID(B36,2,2))+C36-2,8)+1,1) | F36: =IF(INDEX(Groups!B$2:B$10,VALUE(MID(B36,2,2)))="","allocate on Monday",INDEX(Groups!B$2:B$10,VALUE(MID(B36,2,2)))) | G36: yes | H36: =IF(G36="yes",COUNTIFS(G$2:G$36,"yes",A$2:A$36,"<="&A36),"") | I36: ="P"&C36 | J36: =IFERROR(INDEX(Sets!G$2:G$5,MATCH(INDEX(Sets!B$2:B$9,MATCH(E36,Sets!A$2:A$9,0))&"|"&LEFT(F36,1),Sets!F$2:F$5,0)),INDEX(Sets!B$2:B$9,MATCH(E36,Sets!A$2:A$9,0))) | K36: =IFERROR(INDEX(Sets!G$2:G$5,MATCH(INDEX(Sets!C$2:C$9,MATCH(E36,Sets!A$2:A$9,0))&"|"&LEFT(F36,1),Sets!F$2:F$5,0)),INDEX(Sets!C$2:C$9,MATCH(E36,Sets!A$2:A$9,0))) | L36: =IFERROR(INDEX(Sets!G$2:G$5,MATCH(INDEX(Sets!D$2:D$9,MATCH(E36,Sets!A$2:A$9,0))&"|"&LEFT(F36,1),Sets!F$2:F$5,0)),INDEX(Sets!D$2:D$9,MATCH(E36,Sets!A$2:A$9,0)))

Sheet Roster
A1: Slot | B1: Assessor | C1: Mode | D1: Block | E1: Starts, minute of block | F1: Ends, minute of block | G1: Queue position | H1: Seat | I1: Group | J1: Set | K1: Sub-problem | L1: Group-mate in same slot | M1: Ends, minute of day | N1: Viva probe | O1: L1 | P1: L2 | Q1: L3 | R1: Grid text
A2: 1 | B2: Programme Head | C2: in person | D2: =IF(A2<=Settings!$B$9,1,IF(A2<=Settings!$B$11,2,"none")) | E2: =IF(D2=1,Settings!$B$6+(A2-1)*Settings!$B$8,IF(D2=2,(A2-Settings!$B$9-1)*Settings!$B$8,"")) | F2: =IF(E2="","",E2+Settings!$B$3) | G2: =(A2-1)*Settings!$B$12+1 | H2: =IF(D2="none","outside the day",IF(ISNUMBER(MATCH(G2,Seats!$H$2:$H$36,0)),INDEX(Seats!$D$2:$D$36,MATCH(G2,Seats!$H$2:$H$36,0)),"spare")) | I2: =IF(LEFT(H2,1)="G",INDEX(Seats!$B$2:$B$36,MATCH(G2,Seats!$H$2:$H$36,0)),"") | J2: =IF(I2="","",INDEX(Seats!$E$2:$E$36,MATCH(G2,Seats!$H$2:$H$36,0))) | K2: =IF(I2="","",INDEX(Seats!$F$2:$F$36,MATCH(G2,Seats!$H$2:$H$36,0))) | L2: =IF(I2="","",IF(COUNTIFS($A$2:$A$43,A2,$I$2:$I$43,I2)>1,"yes","no")) | M2: =IF(D2=1,F2,IF(D2=2,Settings!$B$5+F2,"")) | N2: =IF(I2="","",INDEX(Seats!$I$2:$I$36,MATCH(G2,Seats!$H$2:$H$36,0))) | O2: =IF(I2="","",INDEX(Seats!$J$2:$J$36,MATCH(G2,Seats!$H$2:$H$36,0))) | P2: =IF(I2="","",INDEX(Seats!$K$2:$K$36,MATCH(G2,Seats!$H$2:$H$36,0))) | Q2: =IF(I2="","",INDEX(Seats!$L$2:$L$36,MATCH(G2,Seats!$H$2:$H$36,0))) | R2: =IF(I2="",H2,H2&", set "&J2&", "&N2&": "&O2&", "&P2&", "&Q2)
A3: 1 | B3: Academic TA | C3: in person | D3: =IF(A3<=Settings!$B$9,1,IF(A3<=Settings!$B$11,2,"none")) | E3: =IF(D3=1,Settings!$B$6+(A3-1)*Settings!$B$8,IF(D3=2,(A3-Settings!$B$9-1)*Settings!$B$8,"")) | F3: =IF(E3="","",E3+Settings!$B$3) | G3: =(A3-1)*Settings!$B$12+2 | H3: =IF(D3="none","outside the day",IF(ISNUMBER(MATCH(G3,Seats!$H$2:$H$36,0)),INDEX(Seats!$D$2:$D$36,MATCH(G3,Seats!$H$2:$H$36,0)),"spare")) | I3: =IF(LEFT(H3,1)="G",INDEX(Seats!$B$2:$B$36,MATCH(G3,Seats!$H$2:$H$36,0)),"") | J3: =IF(I3="","",INDEX(Seats!$E$2:$E$36,MATCH(G3,Seats!$H$2:$H$36,0))) | K3: =IF(I3="","",INDEX(Seats!$F$2:$F$36,MATCH(G3,Seats!$H$2:$H$36,0))) | L3: =IF(I3="","",IF(COUNTIFS($A$2:$A$43,A3,$I$2:$I$43,I3)>1,"yes","no")) | M3: =IF(D3=1,F3,IF(D3=2,Settings!$B$5+F3,"")) | N3: =IF(I3="","",INDEX(Seats!$I$2:$I$36,MATCH(G3,Seats!$H$2:$H$36,0))) | O3: =IF(I3="","",INDEX(Seats!$J$2:$J$36,MATCH(G3,Seats!$H$2:$H$36,0))) | P3: =IF(I3="","",INDEX(Seats!$K$2:$K$36,MATCH(G3,Seats!$H$2:$H$36,0))) | Q3: =IF(I3="","",INDEX(Seats!$L$2:$L$36,MATCH(G3,Seats!$H$2:$H$36,0))) | R3: =IF(I3="",H3,H3&", set "&J3&", "&N3&": "&O3&", "&P3&", "&Q3)
A4: 1 | B4: Principal Advisor | C4: online | D4: =IF(A4<=Settings!$B$9,1,IF(A4<=Settings!$B$11,2,"none")) | E4: =IF(D4=1,Settings!$B$6+(A4-1)*Settings!$B$8,IF(D4=2,(A4-Settings!$B$9-1)*Settings!$B$8,"")) | F4: =IF(E4="","",E4+Settings!$B$3) | G4: =(A4-1)*Settings!$B$12+3 | H4: =IF(D4="none","outside the day",IF(ISNUMBER(MATCH(G4,Seats!$H$2:$H$36,0)),INDEX(Seats!$D$2:$D$36,MATCH(G4,Seats!$H$2:$H$36,0)),"spare")) | I4: =IF(LEFT(H4,1)="G",INDEX(Seats!$B$2:$B$36,MATCH(G4,Seats!$H$2:$H$36,0)),"") | J4: =IF(I4="","",INDEX(Seats!$E$2:$E$36,MATCH(G4,Seats!$H$2:$H$36,0))) | K4: =IF(I4="","",INDEX(Seats!$F$2:$F$36,MATCH(G4,Seats!$H$2:$H$36,0))) | L4: =IF(I4="","",IF(COUNTIFS($A$2:$A$43,A4,$I$2:$I$43,I4)>1,"yes","no")) | M4: =IF(D4=1,F4,IF(D4=2,Settings!$B$5+F4,"")) | N4: =IF(I4="","",INDEX(Seats!$I$2:$I$36,MATCH(G4,Seats!$H$2:$H$36,0))) | O4: =IF(I4="","",INDEX(Seats!$J$2:$J$36,MATCH(G4,Seats!$H$2:$H$36,0))) | P4: =IF(I4="","",INDEX(Seats!$K$2:$K$36,MATCH(G4,Seats!$H$2:$H$36,0))) | Q4: =IF(I4="","",INDEX(Seats!$L$2:$L$36,MATCH(G4,Seats!$H$2:$H$36,0))) | R4: =IF(I4="",H4,H4&", set "&J4&", "&N4&": "&O4&", "&P4&", "&Q4)
A5: 2 | B5: Programme Head | C5: in person | D5: =IF(A5<=Settings!$B$9,1,IF(A5<=Settings!$B$11,2,"none")) | E5: =IF(D5=1,Settings!$B$6+(A5-1)*Settings!$B$8,IF(D5=2,(A5-Settings!$B$9-1)*Settings!$B$8,"")) | F5: =IF(E5="","",E5+Settings!$B$3) | G5: =(A5-1)*Settings!$B$12+1 | H5: =IF(D5="none","outside the day",IF(ISNUMBER(MATCH(G5,Seats!$H$2:$H$36,0)),INDEX(Seats!$D$2:$D$36,MATCH(G5,Seats!$H$2:$H$36,0)),"spare")) | I5: =IF(LEFT(H5,1)="G",INDEX(Seats!$B$2:$B$36,MATCH(G5,Seats!$H$2:$H$36,0)),"") | J5: =IF(I5="","",INDEX(Seats!$E$2:$E$36,MATCH(G5,Seats!$H$2:$H$36,0))) | K5: =IF(I5="","",INDEX(Seats!$F$2:$F$36,MATCH(G5,Seats!$H$2:$H$36,0))) | L5: =IF(I5="","",IF(COUNTIFS($A$2:$A$43,A5,$I$2:$I$43,I5)>1,"yes","no")) | M5: =IF(D5=1,F5,IF(D5=2,Settings!$B$5+F5,"")) | N5: =IF(I5="","",INDEX(Seats!$I$2:$I$36,MATCH(G5,Seats!$H$2:$H$36,0))) | O5: =IF(I5="","",INDEX(Seats!$J$2:$J$36,MATCH(G5,Seats!$H$2:$H$36,0))) | P5: =IF(I5="","",INDEX(Seats!$K$2:$K$36,MATCH(G5,Seats!$H$2:$H$36,0))) | Q5: =IF(I5="","",INDEX(Seats!$L$2:$L$36,MATCH(G5,Seats!$H$2:$H$36,0))) | R5: =IF(I5="",H5,H5&", set "&J5&", "&N5&": "&O5&", "&P5&", "&Q5)
A6: 2 | B6: Academic TA | C6: in person | D6: =IF(A6<=Settings!$B$9,1,IF(A6<=Settings!$B$11,2,"none")) | E6: =IF(D6=1,Settings!$B$6+(A6-1)*Settings!$B$8,IF(D6=2,(A6-Settings!$B$9-1)*Settings!$B$8,"")) | F6: =IF(E6="","",E6+Settings!$B$3) | G6: =(A6-1)*Settings!$B$12+2 | H6: =IF(D6="none","outside the day",IF(ISNUMBER(MATCH(G6,Seats!$H$2:$H$36,0)),INDEX(Seats!$D$2:$D$36,MATCH(G6,Seats!$H$2:$H$36,0)),"spare")) | I6: =IF(LEFT(H6,1)="G",INDEX(Seats!$B$2:$B$36,MATCH(G6,Seats!$H$2:$H$36,0)),"") | J6: =IF(I6="","",INDEX(Seats!$E$2:$E$36,MATCH(G6,Seats!$H$2:$H$36,0))) | K6: =IF(I6="","",INDEX(Seats!$F$2:$F$36,MATCH(G6,Seats!$H$2:$H$36,0))) | L6: =IF(I6="","",IF(COUNTIFS($A$2:$A$43,A6,$I$2:$I$43,I6)>1,"yes","no")) | M6: =IF(D6=1,F6,IF(D6=2,Settings!$B$5+F6,"")) | N6: =IF(I6="","",INDEX(Seats!$I$2:$I$36,MATCH(G6,Seats!$H$2:$H$36,0))) | O6: =IF(I6="","",INDEX(Seats!$J$2:$J$36,MATCH(G6,Seats!$H$2:$H$36,0))) | P6: =IF(I6="","",INDEX(Seats!$K$2:$K$36,MATCH(G6,Seats!$H$2:$H$36,0))) | Q6: =IF(I6="","",INDEX(Seats!$L$2:$L$36,MATCH(G6,Seats!$H$2:$H$36,0))) | R6: =IF(I6="",H6,H6&", set "&J6&", "&N6&": "&O6&", "&P6&", "&Q6)
A7: 2 | B7: Principal Advisor | C7: online | D7: =IF(A7<=Settings!$B$9,1,IF(A7<=Settings!$B$11,2,"none")) | E7: =IF(D7=1,Settings!$B$6+(A7-1)*Settings!$B$8,IF(D7=2,(A7-Settings!$B$9-1)*Settings!$B$8,"")) | F7: =IF(E7="","",E7+Settings!$B$3) | G7: =(A7-1)*Settings!$B$12+3 | H7: =IF(D7="none","outside the day",IF(ISNUMBER(MATCH(G7,Seats!$H$2:$H$36,0)),INDEX(Seats!$D$2:$D$36,MATCH(G7,Seats!$H$2:$H$36,0)),"spare")) | I7: =IF(LEFT(H7,1)="G",INDEX(Seats!$B$2:$B$36,MATCH(G7,Seats!$H$2:$H$36,0)),"") | J7: =IF(I7="","",INDEX(Seats!$E$2:$E$36,MATCH(G7,Seats!$H$2:$H$36,0))) | K7: =IF(I7="","",INDEX(Seats!$F$2:$F$36,MATCH(G7,Seats!$H$2:$H$36,0))) | L7: =IF(I7="","",IF(COUNTIFS($A$2:$A$43,A7,$I$2:$I$43,I7)>1,"yes","no")) | M7: =IF(D7=1,F7,IF(D7=2,Settings!$B$5+F7,"")) | N7: =IF(I7="","",INDEX(Seats!$I$2:$I$36,MATCH(G7,Seats!$H$2:$H$36,0))) | O7: =IF(I7="","",INDEX(Seats!$J$2:$J$36,MATCH(G7,Seats!$H$2:$H$36,0))) | P7: =IF(I7="","",INDEX(Seats!$K$2:$K$36,MATCH(G7,Seats!$H$2:$H$36,0))) | Q7: =IF(I7="","",INDEX(Seats!$L$2:$L$36,MATCH(G7,Seats!$H$2:$H$36,0))) | R7: =IF(I7="",H7,H7&", set "&J7&", "&N7&": "&O7&", "&P7&", "&Q7)
A8: 3 | B8: Programme Head | C8: in person | D8: =IF(A8<=Settings!$B$9,1,IF(A8<=Settings!$B$11,2,"none")) | E8: =IF(D8=1,Settings!$B$6+(A8-1)*Settings!$B$8,IF(D8=2,(A8-Settings!$B$9-1)*Settings!$B$8,"")) | F8: =IF(E8="","",E8+Settings!$B$3) | G8: =(A8-1)*Settings!$B$12+1 | H8: =IF(D8="none","outside the day",IF(ISNUMBER(MATCH(G8,Seats!$H$2:$H$36,0)),INDEX(Seats!$D$2:$D$36,MATCH(G8,Seats!$H$2:$H$36,0)),"spare")) | I8: =IF(LEFT(H8,1)="G",INDEX(Seats!$B$2:$B$36,MATCH(G8,Seats!$H$2:$H$36,0)),"") | J8: =IF(I8="","",INDEX(Seats!$E$2:$E$36,MATCH(G8,Seats!$H$2:$H$36,0))) | K8: =IF(I8="","",INDEX(Seats!$F$2:$F$36,MATCH(G8,Seats!$H$2:$H$36,0))) | L8: =IF(I8="","",IF(COUNTIFS($A$2:$A$43,A8,$I$2:$I$43,I8)>1,"yes","no")) | M8: =IF(D8=1,F8,IF(D8=2,Settings!$B$5+F8,"")) | N8: =IF(I8="","",INDEX(Seats!$I$2:$I$36,MATCH(G8,Seats!$H$2:$H$36,0))) | O8: =IF(I8="","",INDEX(Seats!$J$2:$J$36,MATCH(G8,Seats!$H$2:$H$36,0))) | P8: =IF(I8="","",INDEX(Seats!$K$2:$K$36,MATCH(G8,Seats!$H$2:$H$36,0))) | Q8: =IF(I8="","",INDEX(Seats!$L$2:$L$36,MATCH(G8,Seats!$H$2:$H$36,0))) | R8: =IF(I8="",H8,H8&", set "&J8&", "&N8&": "&O8&", "&P8&", "&Q8)
A9: 3 | B9: Academic TA | C9: in person | D9: =IF(A9<=Settings!$B$9,1,IF(A9<=Settings!$B$11,2,"none")) | E9: =IF(D9=1,Settings!$B$6+(A9-1)*Settings!$B$8,IF(D9=2,(A9-Settings!$B$9-1)*Settings!$B$8,"")) | F9: =IF(E9="","",E9+Settings!$B$3) | G9: =(A9-1)*Settings!$B$12+2 | H9: =IF(D9="none","outside the day",IF(ISNUMBER(MATCH(G9,Seats!$H$2:$H$36,0)),INDEX(Seats!$D$2:$D$36,MATCH(G9,Seats!$H$2:$H$36,0)),"spare")) | I9: =IF(LEFT(H9,1)="G",INDEX(Seats!$B$2:$B$36,MATCH(G9,Seats!$H$2:$H$36,0)),"") | J9: =IF(I9="","",INDEX(Seats!$E$2:$E$36,MATCH(G9,Seats!$H$2:$H$36,0))) | K9: =IF(I9="","",INDEX(Seats!$F$2:$F$36,MATCH(G9,Seats!$H$2:$H$36,0))) | L9: =IF(I9="","",IF(COUNTIFS($A$2:$A$43,A9,$I$2:$I$43,I9)>1,"yes","no")) | M9: =IF(D9=1,F9,IF(D9=2,Settings!$B$5+F9,"")) | N9: =IF(I9="","",INDEX(Seats!$I$2:$I$36,MATCH(G9,Seats!$H$2:$H$36,0))) | O9: =IF(I9="","",INDEX(Seats!$J$2:$J$36,MATCH(G9,Seats!$H$2:$H$36,0))) | P9: =IF(I9="","",INDEX(Seats!$K$2:$K$36,MATCH(G9,Seats!$H$2:$H$36,0))) | Q9: =IF(I9="","",INDEX(Seats!$L$2:$L$36,MATCH(G9,Seats!$H$2:$H$36,0))) | R9: =IF(I9="",H9,H9&", set "&J9&", "&N9&": "&O9&", "&P9&", "&Q9)
A10: 3 | B10: Principal Advisor | C10: online | D10: =IF(A10<=Settings!$B$9,1,IF(A10<=Settings!$B$11,2,"none")) | E10: =IF(D10=1,Settings!$B$6+(A10-1)*Settings!$B$8,IF(D10=2,(A10-Settings!$B$9-1)*Settings!$B$8,"")) | F10: =IF(E10="","",E10+Settings!$B$3) | G10: =(A10-1)*Settings!$B$12+3 | H10: =IF(D10="none","outside the day",IF(ISNUMBER(MATCH(G10,Seats!$H$2:$H$36,0)),INDEX(Seats!$D$2:$D$36,MATCH(G10,Seats!$H$2:$H$36,0)),"spare")) | I10: =IF(LEFT(H10,1)="G",INDEX(Seats!$B$2:$B$36,MATCH(G10,Seats!$H$2:$H$36,0)),"") | J10: =IF(I10="","",INDEX(Seats!$E$2:$E$36,MATCH(G10,Seats!$H$2:$H$36,0))) | K10: =IF(I10="","",INDEX(Seats!$F$2:$F$36,MATCH(G10,Seats!$H$2:$H$36,0))) | L10: =IF(I10="","",IF(COUNTIFS($A$2:$A$43,A10,$I$2:$I$43,I10)>1,"yes","no")) | M10: =IF(D10=1,F10,IF(D10=2,Settings!$B$5+F10,"")) | N10: =IF(I10="","",INDEX(Seats!$I$2:$I$36,MATCH(G10,Seats!$H$2:$H$36,0))) | O10: =IF(I10="","",INDEX(Seats!$J$2:$J$36,MATCH(G10,Seats!$H$2:$H$36,0))) | P10: =IF(I10="","",INDEX(Seats!$K$2:$K$36,MATCH(G10,Seats!$H$2:$H$36,0))) | Q10: =IF(I10="","",INDEX(Seats!$L$2:$L$36,MATCH(G10,Seats!$H$2:$H$36,0))) | R10: =IF(I10="",H10,H10&", set "&J10&", "&N10&": "&O10&", "&P10&", "&Q10)
A11: 4 | B11: Programme Head | C11: in person | D11: =IF(A11<=Settings!$B$9,1,IF(A11<=Settings!$B$11,2,"none")) | E11: =IF(D11=1,Settings!$B$6+(A11-1)*Settings!$B$8,IF(D11=2,(A11-Settings!$B$9-1)*Settings!$B$8,"")) | F11: =IF(E11="","",E11+Settings!$B$3) | G11: =(A11-1)*Settings!$B$12+1 | H11: =IF(D11="none","outside the day",IF(ISNUMBER(MATCH(G11,Seats!$H$2:$H$36,0)),INDEX(Seats!$D$2:$D$36,MATCH(G11,Seats!$H$2:$H$36,0)),"spare")) | I11: =IF(LEFT(H11,1)="G",INDEX(Seats!$B$2:$B$36,MATCH(G11,Seats!$H$2:$H$36,0)),"") | J11: =IF(I11="","",INDEX(Seats!$E$2:$E$36,MATCH(G11,Seats!$H$2:$H$36,0))) | K11: =IF(I11="","",INDEX(Seats!$F$2:$F$36,MATCH(G11,Seats!$H$2:$H$36,0))) | L11: =IF(I11="","",IF(COUNTIFS($A$2:$A$43,A11,$I$2:$I$43,I11)>1,"yes","no")) | M11: =IF(D11=1,F11,IF(D11=2,Settings!$B$5+F11,"")) | N11: =IF(I11="","",INDEX(Seats!$I$2:$I$36,MATCH(G11,Seats!$H$2:$H$36,0))) | O11: =IF(I11="","",INDEX(Seats!$J$2:$J$36,MATCH(G11,Seats!$H$2:$H$36,0))) | P11: =IF(I11="","",INDEX(Seats!$K$2:$K$36,MATCH(G11,Seats!$H$2:$H$36,0))) | Q11: =IF(I11="","",INDEX(Seats!$L$2:$L$36,MATCH(G11,Seats!$H$2:$H$36,0))) | R11: =IF(I11="",H11,H11&", set "&J11&", "&N11&": "&O11&", "&P11&", "&Q11)
A12: 4 | B12: Academic TA | C12: in person | D12: =IF(A12<=Settings!$B$9,1,IF(A12<=Settings!$B$11,2,"none")) | E12: =IF(D12=1,Settings!$B$6+(A12-1)*Settings!$B$8,IF(D12=2,(A12-Settings!$B$9-1)*Settings!$B$8,"")) | F12: =IF(E12="","",E12+Settings!$B$3) | G12: =(A12-1)*Settings!$B$12+2 | H12: =IF(D12="none","outside the day",IF(ISNUMBER(MATCH(G12,Seats!$H$2:$H$36,0)),INDEX(Seats!$D$2:$D$36,MATCH(G12,Seats!$H$2:$H$36,0)),"spare")) | I12: =IF(LEFT(H12,1)="G",INDEX(Seats!$B$2:$B$36,MATCH(G12,Seats!$H$2:$H$36,0)),"") | J12: =IF(I12="","",INDEX(Seats!$E$2:$E$36,MATCH(G12,Seats!$H$2:$H$36,0))) | K12: =IF(I12="","",INDEX(Seats!$F$2:$F$36,MATCH(G12,Seats!$H$2:$H$36,0))) | L12: =IF(I12="","",IF(COUNTIFS($A$2:$A$43,A12,$I$2:$I$43,I12)>1,"yes","no")) | M12: =IF(D12=1,F12,IF(D12=2,Settings!$B$5+F12,"")) | N12: =IF(I12="","",INDEX(Seats!$I$2:$I$36,MATCH(G12,Seats!$H$2:$H$36,0))) | O12: =IF(I12="","",INDEX(Seats!$J$2:$J$36,MATCH(G12,Seats!$H$2:$H$36,0))) | P12: =IF(I12="","",INDEX(Seats!$K$2:$K$36,MATCH(G12,Seats!$H$2:$H$36,0))) | Q12: =IF(I12="","",INDEX(Seats!$L$2:$L$36,MATCH(G12,Seats!$H$2:$H$36,0))) | R12: =IF(I12="",H12,H12&", set "&J12&", "&N12&": "&O12&", "&P12&", "&Q12)
A13: 4 | B13: Principal Advisor | C13: online | D13: =IF(A13<=Settings!$B$9,1,IF(A13<=Settings!$B$11,2,"none")) | E13: =IF(D13=1,Settings!$B$6+(A13-1)*Settings!$B$8,IF(D13=2,(A13-Settings!$B$9-1)*Settings!$B$8,"")) | F13: =IF(E13="","",E13+Settings!$B$3) | G13: =(A13-1)*Settings!$B$12+3 | H13: =IF(D13="none","outside the day",IF(ISNUMBER(MATCH(G13,Seats!$H$2:$H$36,0)),INDEX(Seats!$D$2:$D$36,MATCH(G13,Seats!$H$2:$H$36,0)),"spare")) | I13: =IF(LEFT(H13,1)="G",INDEX(Seats!$B$2:$B$36,MATCH(G13,Seats!$H$2:$H$36,0)),"") | J13: =IF(I13="","",INDEX(Seats!$E$2:$E$36,MATCH(G13,Seats!$H$2:$H$36,0))) | K13: =IF(I13="","",INDEX(Seats!$F$2:$F$36,MATCH(G13,Seats!$H$2:$H$36,0))) | L13: =IF(I13="","",IF(COUNTIFS($A$2:$A$43,A13,$I$2:$I$43,I13)>1,"yes","no")) | M13: =IF(D13=1,F13,IF(D13=2,Settings!$B$5+F13,"")) | N13: =IF(I13="","",INDEX(Seats!$I$2:$I$36,MATCH(G13,Seats!$H$2:$H$36,0))) | O13: =IF(I13="","",INDEX(Seats!$J$2:$J$36,MATCH(G13,Seats!$H$2:$H$36,0))) | P13: =IF(I13="","",INDEX(Seats!$K$2:$K$36,MATCH(G13,Seats!$H$2:$H$36,0))) | Q13: =IF(I13="","",INDEX(Seats!$L$2:$L$36,MATCH(G13,Seats!$H$2:$H$36,0))) | R13: =IF(I13="",H13,H13&", set "&J13&", "&N13&": "&O13&", "&P13&", "&Q13)
A14: 5 | B14: Programme Head | C14: in person | D14: =IF(A14<=Settings!$B$9,1,IF(A14<=Settings!$B$11,2,"none")) | E14: =IF(D14=1,Settings!$B$6+(A14-1)*Settings!$B$8,IF(D14=2,(A14-Settings!$B$9-1)*Settings!$B$8,"")) | F14: =IF(E14="","",E14+Settings!$B$3) | G14: =(A14-1)*Settings!$B$12+1 | H14: =IF(D14="none","outside the day",IF(ISNUMBER(MATCH(G14,Seats!$H$2:$H$36,0)),INDEX(Seats!$D$2:$D$36,MATCH(G14,Seats!$H$2:$H$36,0)),"spare")) | I14: =IF(LEFT(H14,1)="G",INDEX(Seats!$B$2:$B$36,MATCH(G14,Seats!$H$2:$H$36,0)),"") | J14: =IF(I14="","",INDEX(Seats!$E$2:$E$36,MATCH(G14,Seats!$H$2:$H$36,0))) | K14: =IF(I14="","",INDEX(Seats!$F$2:$F$36,MATCH(G14,Seats!$H$2:$H$36,0))) | L14: =IF(I14="","",IF(COUNTIFS($A$2:$A$43,A14,$I$2:$I$43,I14)>1,"yes","no")) | M14: =IF(D14=1,F14,IF(D14=2,Settings!$B$5+F14,"")) | N14: =IF(I14="","",INDEX(Seats!$I$2:$I$36,MATCH(G14,Seats!$H$2:$H$36,0))) | O14: =IF(I14="","",INDEX(Seats!$J$2:$J$36,MATCH(G14,Seats!$H$2:$H$36,0))) | P14: =IF(I14="","",INDEX(Seats!$K$2:$K$36,MATCH(G14,Seats!$H$2:$H$36,0))) | Q14: =IF(I14="","",INDEX(Seats!$L$2:$L$36,MATCH(G14,Seats!$H$2:$H$36,0))) | R14: =IF(I14="",H14,H14&", set "&J14&", "&N14&": "&O14&", "&P14&", "&Q14)
A15: 5 | B15: Academic TA | C15: in person | D15: =IF(A15<=Settings!$B$9,1,IF(A15<=Settings!$B$11,2,"none")) | E15: =IF(D15=1,Settings!$B$6+(A15-1)*Settings!$B$8,IF(D15=2,(A15-Settings!$B$9-1)*Settings!$B$8,"")) | F15: =IF(E15="","",E15+Settings!$B$3) | G15: =(A15-1)*Settings!$B$12+2 | H15: =IF(D15="none","outside the day",IF(ISNUMBER(MATCH(G15,Seats!$H$2:$H$36,0)),INDEX(Seats!$D$2:$D$36,MATCH(G15,Seats!$H$2:$H$36,0)),"spare")) | I15: =IF(LEFT(H15,1)="G",INDEX(Seats!$B$2:$B$36,MATCH(G15,Seats!$H$2:$H$36,0)),"") | J15: =IF(I15="","",INDEX(Seats!$E$2:$E$36,MATCH(G15,Seats!$H$2:$H$36,0))) | K15: =IF(I15="","",INDEX(Seats!$F$2:$F$36,MATCH(G15,Seats!$H$2:$H$36,0))) | L15: =IF(I15="","",IF(COUNTIFS($A$2:$A$43,A15,$I$2:$I$43,I15)>1,"yes","no")) | M15: =IF(D15=1,F15,IF(D15=2,Settings!$B$5+F15,"")) | N15: =IF(I15="","",INDEX(Seats!$I$2:$I$36,MATCH(G15,Seats!$H$2:$H$36,0))) | O15: =IF(I15="","",INDEX(Seats!$J$2:$J$36,MATCH(G15,Seats!$H$2:$H$36,0))) | P15: =IF(I15="","",INDEX(Seats!$K$2:$K$36,MATCH(G15,Seats!$H$2:$H$36,0))) | Q15: =IF(I15="","",INDEX(Seats!$L$2:$L$36,MATCH(G15,Seats!$H$2:$H$36,0))) | R15: =IF(I15="",H15,H15&", set "&J15&", "&N15&": "&O15&", "&P15&", "&Q15)
A16: 5 | B16: Principal Advisor | C16: online | D16: =IF(A16<=Settings!$B$9,1,IF(A16<=Settings!$B$11,2,"none")) | E16: =IF(D16=1,Settings!$B$6+(A16-1)*Settings!$B$8,IF(D16=2,(A16-Settings!$B$9-1)*Settings!$B$8,"")) | F16: =IF(E16="","",E16+Settings!$B$3) | G16: =(A16-1)*Settings!$B$12+3 | H16: =IF(D16="none","outside the day",IF(ISNUMBER(MATCH(G16,Seats!$H$2:$H$36,0)),INDEX(Seats!$D$2:$D$36,MATCH(G16,Seats!$H$2:$H$36,0)),"spare")) | I16: =IF(LEFT(H16,1)="G",INDEX(Seats!$B$2:$B$36,MATCH(G16,Seats!$H$2:$H$36,0)),"") | J16: =IF(I16="","",INDEX(Seats!$E$2:$E$36,MATCH(G16,Seats!$H$2:$H$36,0))) | K16: =IF(I16="","",INDEX(Seats!$F$2:$F$36,MATCH(G16,Seats!$H$2:$H$36,0))) | L16: =IF(I16="","",IF(COUNTIFS($A$2:$A$43,A16,$I$2:$I$43,I16)>1,"yes","no")) | M16: =IF(D16=1,F16,IF(D16=2,Settings!$B$5+F16,"")) | N16: =IF(I16="","",INDEX(Seats!$I$2:$I$36,MATCH(G16,Seats!$H$2:$H$36,0))) | O16: =IF(I16="","",INDEX(Seats!$J$2:$J$36,MATCH(G16,Seats!$H$2:$H$36,0))) | P16: =IF(I16="","",INDEX(Seats!$K$2:$K$36,MATCH(G16,Seats!$H$2:$H$36,0))) | Q16: =IF(I16="","",INDEX(Seats!$L$2:$L$36,MATCH(G16,Seats!$H$2:$H$36,0))) | R16: =IF(I16="",H16,H16&", set "&J16&", "&N16&": "&O16&", "&P16&", "&Q16)
A17: 6 | B17: Programme Head | C17: in person | D17: =IF(A17<=Settings!$B$9,1,IF(A17<=Settings!$B$11,2,"none")) | E17: =IF(D17=1,Settings!$B$6+(A17-1)*Settings!$B$8,IF(D17=2,(A17-Settings!$B$9-1)*Settings!$B$8,"")) | F17: =IF(E17="","",E17+Settings!$B$3) | G17: =(A17-1)*Settings!$B$12+1 | H17: =IF(D17="none","outside the day",IF(ISNUMBER(MATCH(G17,Seats!$H$2:$H$36,0)),INDEX(Seats!$D$2:$D$36,MATCH(G17,Seats!$H$2:$H$36,0)),"spare")) | I17: =IF(LEFT(H17,1)="G",INDEX(Seats!$B$2:$B$36,MATCH(G17,Seats!$H$2:$H$36,0)),"") | J17: =IF(I17="","",INDEX(Seats!$E$2:$E$36,MATCH(G17,Seats!$H$2:$H$36,0))) | K17: =IF(I17="","",INDEX(Seats!$F$2:$F$36,MATCH(G17,Seats!$H$2:$H$36,0))) | L17: =IF(I17="","",IF(COUNTIFS($A$2:$A$43,A17,$I$2:$I$43,I17)>1,"yes","no")) | M17: =IF(D17=1,F17,IF(D17=2,Settings!$B$5+F17,"")) | N17: =IF(I17="","",INDEX(Seats!$I$2:$I$36,MATCH(G17,Seats!$H$2:$H$36,0))) | O17: =IF(I17="","",INDEX(Seats!$J$2:$J$36,MATCH(G17,Seats!$H$2:$H$36,0))) | P17: =IF(I17="","",INDEX(Seats!$K$2:$K$36,MATCH(G17,Seats!$H$2:$H$36,0))) | Q17: =IF(I17="","",INDEX(Seats!$L$2:$L$36,MATCH(G17,Seats!$H$2:$H$36,0))) | R17: =IF(I17="",H17,H17&", set "&J17&", "&N17&": "&O17&", "&P17&", "&Q17)
A18: 6 | B18: Academic TA | C18: in person | D18: =IF(A18<=Settings!$B$9,1,IF(A18<=Settings!$B$11,2,"none")) | E18: =IF(D18=1,Settings!$B$6+(A18-1)*Settings!$B$8,IF(D18=2,(A18-Settings!$B$9-1)*Settings!$B$8,"")) | F18: =IF(E18="","",E18+Settings!$B$3) | G18: =(A18-1)*Settings!$B$12+2 | H18: =IF(D18="none","outside the day",IF(ISNUMBER(MATCH(G18,Seats!$H$2:$H$36,0)),INDEX(Seats!$D$2:$D$36,MATCH(G18,Seats!$H$2:$H$36,0)),"spare")) | I18: =IF(LEFT(H18,1)="G",INDEX(Seats!$B$2:$B$36,MATCH(G18,Seats!$H$2:$H$36,0)),"") | J18: =IF(I18="","",INDEX(Seats!$E$2:$E$36,MATCH(G18,Seats!$H$2:$H$36,0))) | K18: =IF(I18="","",INDEX(Seats!$F$2:$F$36,MATCH(G18,Seats!$H$2:$H$36,0))) | L18: =IF(I18="","",IF(COUNTIFS($A$2:$A$43,A18,$I$2:$I$43,I18)>1,"yes","no")) | M18: =IF(D18=1,F18,IF(D18=2,Settings!$B$5+F18,"")) | N18: =IF(I18="","",INDEX(Seats!$I$2:$I$36,MATCH(G18,Seats!$H$2:$H$36,0))) | O18: =IF(I18="","",INDEX(Seats!$J$2:$J$36,MATCH(G18,Seats!$H$2:$H$36,0))) | P18: =IF(I18="","",INDEX(Seats!$K$2:$K$36,MATCH(G18,Seats!$H$2:$H$36,0))) | Q18: =IF(I18="","",INDEX(Seats!$L$2:$L$36,MATCH(G18,Seats!$H$2:$H$36,0))) | R18: =IF(I18="",H18,H18&", set "&J18&", "&N18&": "&O18&", "&P18&", "&Q18)
A19: 6 | B19: Principal Advisor | C19: online | D19: =IF(A19<=Settings!$B$9,1,IF(A19<=Settings!$B$11,2,"none")) | E19: =IF(D19=1,Settings!$B$6+(A19-1)*Settings!$B$8,IF(D19=2,(A19-Settings!$B$9-1)*Settings!$B$8,"")) | F19: =IF(E19="","",E19+Settings!$B$3) | G19: =(A19-1)*Settings!$B$12+3 | H19: =IF(D19="none","outside the day",IF(ISNUMBER(MATCH(G19,Seats!$H$2:$H$36,0)),INDEX(Seats!$D$2:$D$36,MATCH(G19,Seats!$H$2:$H$36,0)),"spare")) | I19: =IF(LEFT(H19,1)="G",INDEX(Seats!$B$2:$B$36,MATCH(G19,Seats!$H$2:$H$36,0)),"") | J19: =IF(I19="","",INDEX(Seats!$E$2:$E$36,MATCH(G19,Seats!$H$2:$H$36,0))) | K19: =IF(I19="","",INDEX(Seats!$F$2:$F$36,MATCH(G19,Seats!$H$2:$H$36,0))) | L19: =IF(I19="","",IF(COUNTIFS($A$2:$A$43,A19,$I$2:$I$43,I19)>1,"yes","no")) | M19: =IF(D19=1,F19,IF(D19=2,Settings!$B$5+F19,"")) | N19: =IF(I19="","",INDEX(Seats!$I$2:$I$36,MATCH(G19,Seats!$H$2:$H$36,0))) | O19: =IF(I19="","",INDEX(Seats!$J$2:$J$36,MATCH(G19,Seats!$H$2:$H$36,0))) | P19: =IF(I19="","",INDEX(Seats!$K$2:$K$36,MATCH(G19,Seats!$H$2:$H$36,0))) | Q19: =IF(I19="","",INDEX(Seats!$L$2:$L$36,MATCH(G19,Seats!$H$2:$H$36,0))) | R19: =IF(I19="",H19,H19&", set "&J19&", "&N19&": "&O19&", "&P19&", "&Q19)
A20: 7 | B20: Programme Head | C20: in person | D20: =IF(A20<=Settings!$B$9,1,IF(A20<=Settings!$B$11,2,"none")) | E20: =IF(D20=1,Settings!$B$6+(A20-1)*Settings!$B$8,IF(D20=2,(A20-Settings!$B$9-1)*Settings!$B$8,"")) | F20: =IF(E20="","",E20+Settings!$B$3) | G20: =(A20-1)*Settings!$B$12+1 | H20: =IF(D20="none","outside the day",IF(ISNUMBER(MATCH(G20,Seats!$H$2:$H$36,0)),INDEX(Seats!$D$2:$D$36,MATCH(G20,Seats!$H$2:$H$36,0)),"spare")) | I20: =IF(LEFT(H20,1)="G",INDEX(Seats!$B$2:$B$36,MATCH(G20,Seats!$H$2:$H$36,0)),"") | J20: =IF(I20="","",INDEX(Seats!$E$2:$E$36,MATCH(G20,Seats!$H$2:$H$36,0))) | K20: =IF(I20="","",INDEX(Seats!$F$2:$F$36,MATCH(G20,Seats!$H$2:$H$36,0))) | L20: =IF(I20="","",IF(COUNTIFS($A$2:$A$43,A20,$I$2:$I$43,I20)>1,"yes","no")) | M20: =IF(D20=1,F20,IF(D20=2,Settings!$B$5+F20,"")) | N20: =IF(I20="","",INDEX(Seats!$I$2:$I$36,MATCH(G20,Seats!$H$2:$H$36,0))) | O20: =IF(I20="","",INDEX(Seats!$J$2:$J$36,MATCH(G20,Seats!$H$2:$H$36,0))) | P20: =IF(I20="","",INDEX(Seats!$K$2:$K$36,MATCH(G20,Seats!$H$2:$H$36,0))) | Q20: =IF(I20="","",INDEX(Seats!$L$2:$L$36,MATCH(G20,Seats!$H$2:$H$36,0))) | R20: =IF(I20="",H20,H20&", set "&J20&", "&N20&": "&O20&", "&P20&", "&Q20)
A21: 7 | B21: Academic TA | C21: in person | D21: =IF(A21<=Settings!$B$9,1,IF(A21<=Settings!$B$11,2,"none")) | E21: =IF(D21=1,Settings!$B$6+(A21-1)*Settings!$B$8,IF(D21=2,(A21-Settings!$B$9-1)*Settings!$B$8,"")) | F21: =IF(E21="","",E21+Settings!$B$3) | G21: =(A21-1)*Settings!$B$12+2 | H21: =IF(D21="none","outside the day",IF(ISNUMBER(MATCH(G21,Seats!$H$2:$H$36,0)),INDEX(Seats!$D$2:$D$36,MATCH(G21,Seats!$H$2:$H$36,0)),"spare")) | I21: =IF(LEFT(H21,1)="G",INDEX(Seats!$B$2:$B$36,MATCH(G21,Seats!$H$2:$H$36,0)),"") | J21: =IF(I21="","",INDEX(Seats!$E$2:$E$36,MATCH(G21,Seats!$H$2:$H$36,0))) | K21: =IF(I21="","",INDEX(Seats!$F$2:$F$36,MATCH(G21,Seats!$H$2:$H$36,0))) | L21: =IF(I21="","",IF(COUNTIFS($A$2:$A$43,A21,$I$2:$I$43,I21)>1,"yes","no")) | M21: =IF(D21=1,F21,IF(D21=2,Settings!$B$5+F21,"")) | N21: =IF(I21="","",INDEX(Seats!$I$2:$I$36,MATCH(G21,Seats!$H$2:$H$36,0))) | O21: =IF(I21="","",INDEX(Seats!$J$2:$J$36,MATCH(G21,Seats!$H$2:$H$36,0))) | P21: =IF(I21="","",INDEX(Seats!$K$2:$K$36,MATCH(G21,Seats!$H$2:$H$36,0))) | Q21: =IF(I21="","",INDEX(Seats!$L$2:$L$36,MATCH(G21,Seats!$H$2:$H$36,0))) | R21: =IF(I21="",H21,H21&", set "&J21&", "&N21&": "&O21&", "&P21&", "&Q21)
A22: 7 | B22: Principal Advisor | C22: online | D22: =IF(A22<=Settings!$B$9,1,IF(A22<=Settings!$B$11,2,"none")) | E22: =IF(D22=1,Settings!$B$6+(A22-1)*Settings!$B$8,IF(D22=2,(A22-Settings!$B$9-1)*Settings!$B$8,"")) | F22: =IF(E22="","",E22+Settings!$B$3) | G22: =(A22-1)*Settings!$B$12+3 | H22: =IF(D22="none","outside the day",IF(ISNUMBER(MATCH(G22,Seats!$H$2:$H$36,0)),INDEX(Seats!$D$2:$D$36,MATCH(G22,Seats!$H$2:$H$36,0)),"spare")) | I22: =IF(LEFT(H22,1)="G",INDEX(Seats!$B$2:$B$36,MATCH(G22,Seats!$H$2:$H$36,0)),"") | J22: =IF(I22="","",INDEX(Seats!$E$2:$E$36,MATCH(G22,Seats!$H$2:$H$36,0))) | K22: =IF(I22="","",INDEX(Seats!$F$2:$F$36,MATCH(G22,Seats!$H$2:$H$36,0))) | L22: =IF(I22="","",IF(COUNTIFS($A$2:$A$43,A22,$I$2:$I$43,I22)>1,"yes","no")) | M22: =IF(D22=1,F22,IF(D22=2,Settings!$B$5+F22,"")) | N22: =IF(I22="","",INDEX(Seats!$I$2:$I$36,MATCH(G22,Seats!$H$2:$H$36,0))) | O22: =IF(I22="","",INDEX(Seats!$J$2:$J$36,MATCH(G22,Seats!$H$2:$H$36,0))) | P22: =IF(I22="","",INDEX(Seats!$K$2:$K$36,MATCH(G22,Seats!$H$2:$H$36,0))) | Q22: =IF(I22="","",INDEX(Seats!$L$2:$L$36,MATCH(G22,Seats!$H$2:$H$36,0))) | R22: =IF(I22="",H22,H22&", set "&J22&", "&N22&": "&O22&", "&P22&", "&Q22)
A23: 8 | B23: Programme Head | C23: in person | D23: =IF(A23<=Settings!$B$9,1,IF(A23<=Settings!$B$11,2,"none")) | E23: =IF(D23=1,Settings!$B$6+(A23-1)*Settings!$B$8,IF(D23=2,(A23-Settings!$B$9-1)*Settings!$B$8,"")) | F23: =IF(E23="","",E23+Settings!$B$3) | G23: =(A23-1)*Settings!$B$12+1 | H23: =IF(D23="none","outside the day",IF(ISNUMBER(MATCH(G23,Seats!$H$2:$H$36,0)),INDEX(Seats!$D$2:$D$36,MATCH(G23,Seats!$H$2:$H$36,0)),"spare")) | I23: =IF(LEFT(H23,1)="G",INDEX(Seats!$B$2:$B$36,MATCH(G23,Seats!$H$2:$H$36,0)),"") | J23: =IF(I23="","",INDEX(Seats!$E$2:$E$36,MATCH(G23,Seats!$H$2:$H$36,0))) | K23: =IF(I23="","",INDEX(Seats!$F$2:$F$36,MATCH(G23,Seats!$H$2:$H$36,0))) | L23: =IF(I23="","",IF(COUNTIFS($A$2:$A$43,A23,$I$2:$I$43,I23)>1,"yes","no")) | M23: =IF(D23=1,F23,IF(D23=2,Settings!$B$5+F23,"")) | N23: =IF(I23="","",INDEX(Seats!$I$2:$I$36,MATCH(G23,Seats!$H$2:$H$36,0))) | O23: =IF(I23="","",INDEX(Seats!$J$2:$J$36,MATCH(G23,Seats!$H$2:$H$36,0))) | P23: =IF(I23="","",INDEX(Seats!$K$2:$K$36,MATCH(G23,Seats!$H$2:$H$36,0))) | Q23: =IF(I23="","",INDEX(Seats!$L$2:$L$36,MATCH(G23,Seats!$H$2:$H$36,0))) | R23: =IF(I23="",H23,H23&", set "&J23&", "&N23&": "&O23&", "&P23&", "&Q23)
A24: 8 | B24: Academic TA | C24: in person | D24: =IF(A24<=Settings!$B$9,1,IF(A24<=Settings!$B$11,2,"none")) | E24: =IF(D24=1,Settings!$B$6+(A24-1)*Settings!$B$8,IF(D24=2,(A24-Settings!$B$9-1)*Settings!$B$8,"")) | F24: =IF(E24="","",E24+Settings!$B$3) | G24: =(A24-1)*Settings!$B$12+2 | H24: =IF(D24="none","outside the day",IF(ISNUMBER(MATCH(G24,Seats!$H$2:$H$36,0)),INDEX(Seats!$D$2:$D$36,MATCH(G24,Seats!$H$2:$H$36,0)),"spare")) | I24: =IF(LEFT(H24,1)="G",INDEX(Seats!$B$2:$B$36,MATCH(G24,Seats!$H$2:$H$36,0)),"") | J24: =IF(I24="","",INDEX(Seats!$E$2:$E$36,MATCH(G24,Seats!$H$2:$H$36,0))) | K24: =IF(I24="","",INDEX(Seats!$F$2:$F$36,MATCH(G24,Seats!$H$2:$H$36,0))) | L24: =IF(I24="","",IF(COUNTIFS($A$2:$A$43,A24,$I$2:$I$43,I24)>1,"yes","no")) | M24: =IF(D24=1,F24,IF(D24=2,Settings!$B$5+F24,"")) | N24: =IF(I24="","",INDEX(Seats!$I$2:$I$36,MATCH(G24,Seats!$H$2:$H$36,0))) | O24: =IF(I24="","",INDEX(Seats!$J$2:$J$36,MATCH(G24,Seats!$H$2:$H$36,0))) | P24: =IF(I24="","",INDEX(Seats!$K$2:$K$36,MATCH(G24,Seats!$H$2:$H$36,0))) | Q24: =IF(I24="","",INDEX(Seats!$L$2:$L$36,MATCH(G24,Seats!$H$2:$H$36,0))) | R24: =IF(I24="",H24,H24&", set "&J24&", "&N24&": "&O24&", "&P24&", "&Q24)
A25: 8 | B25: Principal Advisor | C25: online | D25: =IF(A25<=Settings!$B$9,1,IF(A25<=Settings!$B$11,2,"none")) | E25: =IF(D25=1,Settings!$B$6+(A25-1)*Settings!$B$8,IF(D25=2,(A25-Settings!$B$9-1)*Settings!$B$8,"")) | F25: =IF(E25="","",E25+Settings!$B$3) | G25: =(A25-1)*Settings!$B$12+3 | H25: =IF(D25="none","outside the day",IF(ISNUMBER(MATCH(G25,Seats!$H$2:$H$36,0)),INDEX(Seats!$D$2:$D$36,MATCH(G25,Seats!$H$2:$H$36,0)),"spare")) | I25: =IF(LEFT(H25,1)="G",INDEX(Seats!$B$2:$B$36,MATCH(G25,Seats!$H$2:$H$36,0)),"") | J25: =IF(I25="","",INDEX(Seats!$E$2:$E$36,MATCH(G25,Seats!$H$2:$H$36,0))) | K25: =IF(I25="","",INDEX(Seats!$F$2:$F$36,MATCH(G25,Seats!$H$2:$H$36,0))) | L25: =IF(I25="","",IF(COUNTIFS($A$2:$A$43,A25,$I$2:$I$43,I25)>1,"yes","no")) | M25: =IF(D25=1,F25,IF(D25=2,Settings!$B$5+F25,"")) | N25: =IF(I25="","",INDEX(Seats!$I$2:$I$36,MATCH(G25,Seats!$H$2:$H$36,0))) | O25: =IF(I25="","",INDEX(Seats!$J$2:$J$36,MATCH(G25,Seats!$H$2:$H$36,0))) | P25: =IF(I25="","",INDEX(Seats!$K$2:$K$36,MATCH(G25,Seats!$H$2:$H$36,0))) | Q25: =IF(I25="","",INDEX(Seats!$L$2:$L$36,MATCH(G25,Seats!$H$2:$H$36,0))) | R25: =IF(I25="",H25,H25&", set "&J25&", "&N25&": "&O25&", "&P25&", "&Q25)
A26: 9 | B26: Programme Head | C26: in person | D26: =IF(A26<=Settings!$B$9,1,IF(A26<=Settings!$B$11,2,"none")) | E26: =IF(D26=1,Settings!$B$6+(A26-1)*Settings!$B$8,IF(D26=2,(A26-Settings!$B$9-1)*Settings!$B$8,"")) | F26: =IF(E26="","",E26+Settings!$B$3) | G26: =(A26-1)*Settings!$B$12+1 | H26: =IF(D26="none","outside the day",IF(ISNUMBER(MATCH(G26,Seats!$H$2:$H$36,0)),INDEX(Seats!$D$2:$D$36,MATCH(G26,Seats!$H$2:$H$36,0)),"spare")) | I26: =IF(LEFT(H26,1)="G",INDEX(Seats!$B$2:$B$36,MATCH(G26,Seats!$H$2:$H$36,0)),"") | J26: =IF(I26="","",INDEX(Seats!$E$2:$E$36,MATCH(G26,Seats!$H$2:$H$36,0))) | K26: =IF(I26="","",INDEX(Seats!$F$2:$F$36,MATCH(G26,Seats!$H$2:$H$36,0))) | L26: =IF(I26="","",IF(COUNTIFS($A$2:$A$43,A26,$I$2:$I$43,I26)>1,"yes","no")) | M26: =IF(D26=1,F26,IF(D26=2,Settings!$B$5+F26,"")) | N26: =IF(I26="","",INDEX(Seats!$I$2:$I$36,MATCH(G26,Seats!$H$2:$H$36,0))) | O26: =IF(I26="","",INDEX(Seats!$J$2:$J$36,MATCH(G26,Seats!$H$2:$H$36,0))) | P26: =IF(I26="","",INDEX(Seats!$K$2:$K$36,MATCH(G26,Seats!$H$2:$H$36,0))) | Q26: =IF(I26="","",INDEX(Seats!$L$2:$L$36,MATCH(G26,Seats!$H$2:$H$36,0))) | R26: =IF(I26="",H26,H26&", set "&J26&", "&N26&": "&O26&", "&P26&", "&Q26)
A27: 9 | B27: Academic TA | C27: in person | D27: =IF(A27<=Settings!$B$9,1,IF(A27<=Settings!$B$11,2,"none")) | E27: =IF(D27=1,Settings!$B$6+(A27-1)*Settings!$B$8,IF(D27=2,(A27-Settings!$B$9-1)*Settings!$B$8,"")) | F27: =IF(E27="","",E27+Settings!$B$3) | G27: =(A27-1)*Settings!$B$12+2 | H27: =IF(D27="none","outside the day",IF(ISNUMBER(MATCH(G27,Seats!$H$2:$H$36,0)),INDEX(Seats!$D$2:$D$36,MATCH(G27,Seats!$H$2:$H$36,0)),"spare")) | I27: =IF(LEFT(H27,1)="G",INDEX(Seats!$B$2:$B$36,MATCH(G27,Seats!$H$2:$H$36,0)),"") | J27: =IF(I27="","",INDEX(Seats!$E$2:$E$36,MATCH(G27,Seats!$H$2:$H$36,0))) | K27: =IF(I27="","",INDEX(Seats!$F$2:$F$36,MATCH(G27,Seats!$H$2:$H$36,0))) | L27: =IF(I27="","",IF(COUNTIFS($A$2:$A$43,A27,$I$2:$I$43,I27)>1,"yes","no")) | M27: =IF(D27=1,F27,IF(D27=2,Settings!$B$5+F27,"")) | N27: =IF(I27="","",INDEX(Seats!$I$2:$I$36,MATCH(G27,Seats!$H$2:$H$36,0))) | O27: =IF(I27="","",INDEX(Seats!$J$2:$J$36,MATCH(G27,Seats!$H$2:$H$36,0))) | P27: =IF(I27="","",INDEX(Seats!$K$2:$K$36,MATCH(G27,Seats!$H$2:$H$36,0))) | Q27: =IF(I27="","",INDEX(Seats!$L$2:$L$36,MATCH(G27,Seats!$H$2:$H$36,0))) | R27: =IF(I27="",H27,H27&", set "&J27&", "&N27&": "&O27&", "&P27&", "&Q27)
A28: 9 | B28: Principal Advisor | C28: online | D28: =IF(A28<=Settings!$B$9,1,IF(A28<=Settings!$B$11,2,"none")) | E28: =IF(D28=1,Settings!$B$6+(A28-1)*Settings!$B$8,IF(D28=2,(A28-Settings!$B$9-1)*Settings!$B$8,"")) | F28: =IF(E28="","",E28+Settings!$B$3) | G28: =(A28-1)*Settings!$B$12+3 | H28: =IF(D28="none","outside the day",IF(ISNUMBER(MATCH(G28,Seats!$H$2:$H$36,0)),INDEX(Seats!$D$2:$D$36,MATCH(G28,Seats!$H$2:$H$36,0)),"spare")) | I28: =IF(LEFT(H28,1)="G",INDEX(Seats!$B$2:$B$36,MATCH(G28,Seats!$H$2:$H$36,0)),"") | J28: =IF(I28="","",INDEX(Seats!$E$2:$E$36,MATCH(G28,Seats!$H$2:$H$36,0))) | K28: =IF(I28="","",INDEX(Seats!$F$2:$F$36,MATCH(G28,Seats!$H$2:$H$36,0))) | L28: =IF(I28="","",IF(COUNTIFS($A$2:$A$43,A28,$I$2:$I$43,I28)>1,"yes","no")) | M28: =IF(D28=1,F28,IF(D28=2,Settings!$B$5+F28,"")) | N28: =IF(I28="","",INDEX(Seats!$I$2:$I$36,MATCH(G28,Seats!$H$2:$H$36,0))) | O28: =IF(I28="","",INDEX(Seats!$J$2:$J$36,MATCH(G28,Seats!$H$2:$H$36,0))) | P28: =IF(I28="","",INDEX(Seats!$K$2:$K$36,MATCH(G28,Seats!$H$2:$H$36,0))) | Q28: =IF(I28="","",INDEX(Seats!$L$2:$L$36,MATCH(G28,Seats!$H$2:$H$36,0))) | R28: =IF(I28="",H28,H28&", set "&J28&", "&N28&": "&O28&", "&P28&", "&Q28)
A29: 10 | B29: Programme Head | C29: in person | D29: =IF(A29<=Settings!$B$9,1,IF(A29<=Settings!$B$11,2,"none")) | E29: =IF(D29=1,Settings!$B$6+(A29-1)*Settings!$B$8,IF(D29=2,(A29-Settings!$B$9-1)*Settings!$B$8,"")) | F29: =IF(E29="","",E29+Settings!$B$3) | G29: =(A29-1)*Settings!$B$12+1 | H29: =IF(D29="none","outside the day",IF(ISNUMBER(MATCH(G29,Seats!$H$2:$H$36,0)),INDEX(Seats!$D$2:$D$36,MATCH(G29,Seats!$H$2:$H$36,0)),"spare")) | I29: =IF(LEFT(H29,1)="G",INDEX(Seats!$B$2:$B$36,MATCH(G29,Seats!$H$2:$H$36,0)),"") | J29: =IF(I29="","",INDEX(Seats!$E$2:$E$36,MATCH(G29,Seats!$H$2:$H$36,0))) | K29: =IF(I29="","",INDEX(Seats!$F$2:$F$36,MATCH(G29,Seats!$H$2:$H$36,0))) | L29: =IF(I29="","",IF(COUNTIFS($A$2:$A$43,A29,$I$2:$I$43,I29)>1,"yes","no")) | M29: =IF(D29=1,F29,IF(D29=2,Settings!$B$5+F29,"")) | N29: =IF(I29="","",INDEX(Seats!$I$2:$I$36,MATCH(G29,Seats!$H$2:$H$36,0))) | O29: =IF(I29="","",INDEX(Seats!$J$2:$J$36,MATCH(G29,Seats!$H$2:$H$36,0))) | P29: =IF(I29="","",INDEX(Seats!$K$2:$K$36,MATCH(G29,Seats!$H$2:$H$36,0))) | Q29: =IF(I29="","",INDEX(Seats!$L$2:$L$36,MATCH(G29,Seats!$H$2:$H$36,0))) | R29: =IF(I29="",H29,H29&", set "&J29&", "&N29&": "&O29&", "&P29&", "&Q29)
A30: 10 | B30: Academic TA | C30: in person | D30: =IF(A30<=Settings!$B$9,1,IF(A30<=Settings!$B$11,2,"none")) | E30: =IF(D30=1,Settings!$B$6+(A30-1)*Settings!$B$8,IF(D30=2,(A30-Settings!$B$9-1)*Settings!$B$8,"")) | F30: =IF(E30="","",E30+Settings!$B$3) | G30: =(A30-1)*Settings!$B$12+2 | H30: =IF(D30="none","outside the day",IF(ISNUMBER(MATCH(G30,Seats!$H$2:$H$36,0)),INDEX(Seats!$D$2:$D$36,MATCH(G30,Seats!$H$2:$H$36,0)),"spare")) | I30: =IF(LEFT(H30,1)="G",INDEX(Seats!$B$2:$B$36,MATCH(G30,Seats!$H$2:$H$36,0)),"") | J30: =IF(I30="","",INDEX(Seats!$E$2:$E$36,MATCH(G30,Seats!$H$2:$H$36,0))) | K30: =IF(I30="","",INDEX(Seats!$F$2:$F$36,MATCH(G30,Seats!$H$2:$H$36,0))) | L30: =IF(I30="","",IF(COUNTIFS($A$2:$A$43,A30,$I$2:$I$43,I30)>1,"yes","no")) | M30: =IF(D30=1,F30,IF(D30=2,Settings!$B$5+F30,"")) | N30: =IF(I30="","",INDEX(Seats!$I$2:$I$36,MATCH(G30,Seats!$H$2:$H$36,0))) | O30: =IF(I30="","",INDEX(Seats!$J$2:$J$36,MATCH(G30,Seats!$H$2:$H$36,0))) | P30: =IF(I30="","",INDEX(Seats!$K$2:$K$36,MATCH(G30,Seats!$H$2:$H$36,0))) | Q30: =IF(I30="","",INDEX(Seats!$L$2:$L$36,MATCH(G30,Seats!$H$2:$H$36,0))) | R30: =IF(I30="",H30,H30&", set "&J30&", "&N30&": "&O30&", "&P30&", "&Q30)
A31: 10 | B31: Principal Advisor | C31: online | D31: =IF(A31<=Settings!$B$9,1,IF(A31<=Settings!$B$11,2,"none")) | E31: =IF(D31=1,Settings!$B$6+(A31-1)*Settings!$B$8,IF(D31=2,(A31-Settings!$B$9-1)*Settings!$B$8,"")) | F31: =IF(E31="","",E31+Settings!$B$3) | G31: =(A31-1)*Settings!$B$12+3 | H31: =IF(D31="none","outside the day",IF(ISNUMBER(MATCH(G31,Seats!$H$2:$H$36,0)),INDEX(Seats!$D$2:$D$36,MATCH(G31,Seats!$H$2:$H$36,0)),"spare")) | I31: =IF(LEFT(H31,1)="G",INDEX(Seats!$B$2:$B$36,MATCH(G31,Seats!$H$2:$H$36,0)),"") | J31: =IF(I31="","",INDEX(Seats!$E$2:$E$36,MATCH(G31,Seats!$H$2:$H$36,0))) | K31: =IF(I31="","",INDEX(Seats!$F$2:$F$36,MATCH(G31,Seats!$H$2:$H$36,0))) | L31: =IF(I31="","",IF(COUNTIFS($A$2:$A$43,A31,$I$2:$I$43,I31)>1,"yes","no")) | M31: =IF(D31=1,F31,IF(D31=2,Settings!$B$5+F31,"")) | N31: =IF(I31="","",INDEX(Seats!$I$2:$I$36,MATCH(G31,Seats!$H$2:$H$36,0))) | O31: =IF(I31="","",INDEX(Seats!$J$2:$J$36,MATCH(G31,Seats!$H$2:$H$36,0))) | P31: =IF(I31="","",INDEX(Seats!$K$2:$K$36,MATCH(G31,Seats!$H$2:$H$36,0))) | Q31: =IF(I31="","",INDEX(Seats!$L$2:$L$36,MATCH(G31,Seats!$H$2:$H$36,0))) | R31: =IF(I31="",H31,H31&", set "&J31&", "&N31&": "&O31&", "&P31&", "&Q31)
A32: 11 | B32: Programme Head | C32: in person | D32: =IF(A32<=Settings!$B$9,1,IF(A32<=Settings!$B$11,2,"none")) | E32: =IF(D32=1,Settings!$B$6+(A32-1)*Settings!$B$8,IF(D32=2,(A32-Settings!$B$9-1)*Settings!$B$8,"")) | F32: =IF(E32="","",E32+Settings!$B$3) | G32: =(A32-1)*Settings!$B$12+1 | H32: =IF(D32="none","outside the day",IF(ISNUMBER(MATCH(G32,Seats!$H$2:$H$36,0)),INDEX(Seats!$D$2:$D$36,MATCH(G32,Seats!$H$2:$H$36,0)),"spare")) | I32: =IF(LEFT(H32,1)="G",INDEX(Seats!$B$2:$B$36,MATCH(G32,Seats!$H$2:$H$36,0)),"") | J32: =IF(I32="","",INDEX(Seats!$E$2:$E$36,MATCH(G32,Seats!$H$2:$H$36,0))) | K32: =IF(I32="","",INDEX(Seats!$F$2:$F$36,MATCH(G32,Seats!$H$2:$H$36,0))) | L32: =IF(I32="","",IF(COUNTIFS($A$2:$A$43,A32,$I$2:$I$43,I32)>1,"yes","no")) | M32: =IF(D32=1,F32,IF(D32=2,Settings!$B$5+F32,"")) | N32: =IF(I32="","",INDEX(Seats!$I$2:$I$36,MATCH(G32,Seats!$H$2:$H$36,0))) | O32: =IF(I32="","",INDEX(Seats!$J$2:$J$36,MATCH(G32,Seats!$H$2:$H$36,0))) | P32: =IF(I32="","",INDEX(Seats!$K$2:$K$36,MATCH(G32,Seats!$H$2:$H$36,0))) | Q32: =IF(I32="","",INDEX(Seats!$L$2:$L$36,MATCH(G32,Seats!$H$2:$H$36,0))) | R32: =IF(I32="",H32,H32&", set "&J32&", "&N32&": "&O32&", "&P32&", "&Q32)
A33: 11 | B33: Academic TA | C33: in person | D33: =IF(A33<=Settings!$B$9,1,IF(A33<=Settings!$B$11,2,"none")) | E33: =IF(D33=1,Settings!$B$6+(A33-1)*Settings!$B$8,IF(D33=2,(A33-Settings!$B$9-1)*Settings!$B$8,"")) | F33: =IF(E33="","",E33+Settings!$B$3) | G33: =(A33-1)*Settings!$B$12+2 | H33: =IF(D33="none","outside the day",IF(ISNUMBER(MATCH(G33,Seats!$H$2:$H$36,0)),INDEX(Seats!$D$2:$D$36,MATCH(G33,Seats!$H$2:$H$36,0)),"spare")) | I33: =IF(LEFT(H33,1)="G",INDEX(Seats!$B$2:$B$36,MATCH(G33,Seats!$H$2:$H$36,0)),"") | J33: =IF(I33="","",INDEX(Seats!$E$2:$E$36,MATCH(G33,Seats!$H$2:$H$36,0))) | K33: =IF(I33="","",INDEX(Seats!$F$2:$F$36,MATCH(G33,Seats!$H$2:$H$36,0))) | L33: =IF(I33="","",IF(COUNTIFS($A$2:$A$43,A33,$I$2:$I$43,I33)>1,"yes","no")) | M33: =IF(D33=1,F33,IF(D33=2,Settings!$B$5+F33,"")) | N33: =IF(I33="","",INDEX(Seats!$I$2:$I$36,MATCH(G33,Seats!$H$2:$H$36,0))) | O33: =IF(I33="","",INDEX(Seats!$J$2:$J$36,MATCH(G33,Seats!$H$2:$H$36,0))) | P33: =IF(I33="","",INDEX(Seats!$K$2:$K$36,MATCH(G33,Seats!$H$2:$H$36,0))) | Q33: =IF(I33="","",INDEX(Seats!$L$2:$L$36,MATCH(G33,Seats!$H$2:$H$36,0))) | R33: =IF(I33="",H33,H33&", set "&J33&", "&N33&": "&O33&", "&P33&", "&Q33)
A34: 11 | B34: Principal Advisor | C34: online | D34: =IF(A34<=Settings!$B$9,1,IF(A34<=Settings!$B$11,2,"none")) | E34: =IF(D34=1,Settings!$B$6+(A34-1)*Settings!$B$8,IF(D34=2,(A34-Settings!$B$9-1)*Settings!$B$8,"")) | F34: =IF(E34="","",E34+Settings!$B$3) | G34: =(A34-1)*Settings!$B$12+3 | H34: =IF(D34="none","outside the day",IF(ISNUMBER(MATCH(G34,Seats!$H$2:$H$36,0)),INDEX(Seats!$D$2:$D$36,MATCH(G34,Seats!$H$2:$H$36,0)),"spare")) | I34: =IF(LEFT(H34,1)="G",INDEX(Seats!$B$2:$B$36,MATCH(G34,Seats!$H$2:$H$36,0)),"") | J34: =IF(I34="","",INDEX(Seats!$E$2:$E$36,MATCH(G34,Seats!$H$2:$H$36,0))) | K34: =IF(I34="","",INDEX(Seats!$F$2:$F$36,MATCH(G34,Seats!$H$2:$H$36,0))) | L34: =IF(I34="","",IF(COUNTIFS($A$2:$A$43,A34,$I$2:$I$43,I34)>1,"yes","no")) | M34: =IF(D34=1,F34,IF(D34=2,Settings!$B$5+F34,"")) | N34: =IF(I34="","",INDEX(Seats!$I$2:$I$36,MATCH(G34,Seats!$H$2:$H$36,0))) | O34: =IF(I34="","",INDEX(Seats!$J$2:$J$36,MATCH(G34,Seats!$H$2:$H$36,0))) | P34: =IF(I34="","",INDEX(Seats!$K$2:$K$36,MATCH(G34,Seats!$H$2:$H$36,0))) | Q34: =IF(I34="","",INDEX(Seats!$L$2:$L$36,MATCH(G34,Seats!$H$2:$H$36,0))) | R34: =IF(I34="",H34,H34&", set "&J34&", "&N34&": "&O34&", "&P34&", "&Q34)
A35: 12 | B35: Programme Head | C35: in person | D35: =IF(A35<=Settings!$B$9,1,IF(A35<=Settings!$B$11,2,"none")) | E35: =IF(D35=1,Settings!$B$6+(A35-1)*Settings!$B$8,IF(D35=2,(A35-Settings!$B$9-1)*Settings!$B$8,"")) | F35: =IF(E35="","",E35+Settings!$B$3) | G35: =(A35-1)*Settings!$B$12+1 | H35: =IF(D35="none","outside the day",IF(ISNUMBER(MATCH(G35,Seats!$H$2:$H$36,0)),INDEX(Seats!$D$2:$D$36,MATCH(G35,Seats!$H$2:$H$36,0)),"spare")) | I35: =IF(LEFT(H35,1)="G",INDEX(Seats!$B$2:$B$36,MATCH(G35,Seats!$H$2:$H$36,0)),"") | J35: =IF(I35="","",INDEX(Seats!$E$2:$E$36,MATCH(G35,Seats!$H$2:$H$36,0))) | K35: =IF(I35="","",INDEX(Seats!$F$2:$F$36,MATCH(G35,Seats!$H$2:$H$36,0))) | L35: =IF(I35="","",IF(COUNTIFS($A$2:$A$43,A35,$I$2:$I$43,I35)>1,"yes","no")) | M35: =IF(D35=1,F35,IF(D35=2,Settings!$B$5+F35,"")) | N35: =IF(I35="","",INDEX(Seats!$I$2:$I$36,MATCH(G35,Seats!$H$2:$H$36,0))) | O35: =IF(I35="","",INDEX(Seats!$J$2:$J$36,MATCH(G35,Seats!$H$2:$H$36,0))) | P35: =IF(I35="","",INDEX(Seats!$K$2:$K$36,MATCH(G35,Seats!$H$2:$H$36,0))) | Q35: =IF(I35="","",INDEX(Seats!$L$2:$L$36,MATCH(G35,Seats!$H$2:$H$36,0))) | R35: =IF(I35="",H35,H35&", set "&J35&", "&N35&": "&O35&", "&P35&", "&Q35)
A36: 12 | B36: Academic TA | C36: in person | D36: =IF(A36<=Settings!$B$9,1,IF(A36<=Settings!$B$11,2,"none")) | E36: =IF(D36=1,Settings!$B$6+(A36-1)*Settings!$B$8,IF(D36=2,(A36-Settings!$B$9-1)*Settings!$B$8,"")) | F36: =IF(E36="","",E36+Settings!$B$3) | G36: =(A36-1)*Settings!$B$12+2 | H36: =IF(D36="none","outside the day",IF(ISNUMBER(MATCH(G36,Seats!$H$2:$H$36,0)),INDEX(Seats!$D$2:$D$36,MATCH(G36,Seats!$H$2:$H$36,0)),"spare")) | I36: =IF(LEFT(H36,1)="G",INDEX(Seats!$B$2:$B$36,MATCH(G36,Seats!$H$2:$H$36,0)),"") | J36: =IF(I36="","",INDEX(Seats!$E$2:$E$36,MATCH(G36,Seats!$H$2:$H$36,0))) | K36: =IF(I36="","",INDEX(Seats!$F$2:$F$36,MATCH(G36,Seats!$H$2:$H$36,0))) | L36: =IF(I36="","",IF(COUNTIFS($A$2:$A$43,A36,$I$2:$I$43,I36)>1,"yes","no")) | M36: =IF(D36=1,F36,IF(D36=2,Settings!$B$5+F36,"")) | N36: =IF(I36="","",INDEX(Seats!$I$2:$I$36,MATCH(G36,Seats!$H$2:$H$36,0))) | O36: =IF(I36="","",INDEX(Seats!$J$2:$J$36,MATCH(G36,Seats!$H$2:$H$36,0))) | P36: =IF(I36="","",INDEX(Seats!$K$2:$K$36,MATCH(G36,Seats!$H$2:$H$36,0))) | Q36: =IF(I36="","",INDEX(Seats!$L$2:$L$36,MATCH(G36,Seats!$H$2:$H$36,0))) | R36: =IF(I36="",H36,H36&", set "&J36&", "&N36&": "&O36&", "&P36&", "&Q36)
