Workbook

Sheet Dashboard
B2: Baseline Diagnostic: key and cohort profile
B3: Cohort 2 | Week 0 | INTERNAL | built 28 Sep 2026 | every number below is a formula over the Entry tab
B5: Students entered | C5: Cohort mean, all 46 marks | D5: Python mean | E5: SQL mean | F5: Need full Python brush-up | G5: Need full SQL brush-up | I5: Mean over-claim (bands)
B6: =SUM(Scoring!BL7:BL41) -> 0 | C6: =IFERROR(AVERAGE(Profile!J7:J41),"Pending") -> Pending | D6: =IFERROR(AVERAGE(Profile!D7:D41),"Pending") -> Pending | E6: =IFERROR(AVERAGE(Profile!E7:E41),"Pending") -> Pending | F6: =COUNTIF(Profile!Y7:Y41,"Full") -> 0 | G6: =COUNTIF(Profile!Z7:Z41,"Full") -> 0 | I6: =IFERROR(AVERAGE(Profile!X7:X41),"Pending") -> Pending
B9: Inputs
B10: Blue cells are the only ones to edit on this tab. Every profile and chart recalculates from them.
B11: Input | C11: Value | D11: What it drives
B12: Band 2 starts at (score %) | C12: 0.35 | D12: Scored band 1 below this
B13: Band 3 starts at (score %) | C13: 0.6 | D13: Scored band 2 up to this
B14: Band 4 starts at (score %) | C14: 0.8 | D14: Scored band 3 up to this, band 4 from here
B15: Python full brush-up below (%) | C15: 0.5 | D15: Profile column Python brush-up
B16: SQL full brush-up below (%) | C16: 0.5 | D16: Profile column SQL brush-up
B17: Proposed defaults, this course's own construction; the one-to-one owner may move them before results are read.
B19: Cohort accuracy by section and tier
B20: Share of entered students answering correctly, averaged over the items in each cell. Tiers: L1 entry, L2 interview screen, L3 differentiator.
B21: Section | C21: L1 | D21: L2 | E21: L3 | F21: All items | G21: Items
B22: A. Python | C22: =IFERROR(AVERAGEIFS(Scoring!$H$43:$BA$43,Scoring!$H$2:$BA$2,"A",Scoring!$H$4:$BA$4,"L1"),"n/a") -> n/a | D22: =IFERROR(AVERAGEIFS(Scoring!$H$43:$BA$43,Scoring!$H$2:$BA$2,"A",Scoring!$H$4:$BA$4,"L2"),"n/a") -> n/a | E22: =IFERROR(AVERAGEIFS(Scoring!$H$43:$BA$43,Scoring!$H$2:$BA$2,"A",Scoring!$H$4:$BA$4,"L3"),"n/a") -> n/a | F22: =IFERROR(AVERAGEIFS(Scoring!$H$43:$BA$43,Scoring!$H$2:$BA$2,"A"),"Pending") -> Pending | G22: =COUNTIF(Scoring!$H$2:$BA$2,"A") -> 12
B23: B. SQL | C23: =IFERROR(AVERAGEIFS(Scoring!$H$43:$BA$43,Scoring!$H$2:$BA$2,"B",Scoring!$H$4:$BA$4,"L1"),"n/a") -> n/a | D23: =IFERROR(AVERAGEIFS(Scoring!$H$43:$BA$43,Scoring!$H$2:$BA$2,"B",Scoring!$H$4:$BA$4,"L2"),"n/a") -> n/a | E23: =IFERROR(AVERAGEIFS(Scoring!$H$43:$BA$43,Scoring!$H$2:$BA$2,"B",Scoring!$H$4:$BA$4,"L3"),"n/a") -> n/a | F23: =IFERROR(AVERAGEIFS(Scoring!$H$43:$BA$43,Scoring!$H$2:$BA$2,"B"),"Pending") -> Pending | G23: =COUNTIF(Scoring!$H$2:$BA$2,"B") -> 8
B24: C. Numbers | C24: =IFERROR(AVERAGEIFS(Scoring!$H$43:$BA$43,Scoring!$H$2:$BA$2,"C",Scoring!$H$4:$BA$4,"L1"),"n/a") -> n/a | D24: =IFERROR(AVERAGEIFS(Scoring!$H$43:$BA$43,Scoring!$H$2:$BA$2,"C",Scoring!$H$4:$BA$4,"L2"),"n/a") -> n/a | E24: =IFERROR(AVERAGEIFS(Scoring!$H$43:$BA$43,Scoring!$H$2:$BA$2,"C",Scoring!$H$4:$BA$4,"L3"),"n/a") -> n/a | F24: =IFERROR(AVERAGEIFS(Scoring!$H$43:$BA$43,Scoring!$H$2:$BA$2,"C"),"Pending") -> Pending | G24: =COUNTIF(Scoring!$H$2:$BA$2,"C") -> 8
B25: D. Case and scenarios | C25: =IFERROR(AVERAGEIFS(Scoring!$H$43:$BA$43,Scoring!$H$2:$BA$2,"D",Scoring!$H$4:$BA$4,"L1"),"n/a") -> n/a | D25: =IFERROR(AVERAGEIFS(Scoring!$H$43:$BA$43,Scoring!$H$2:$BA$2,"D",Scoring!$H$4:$BA$4,"L2"),"n/a") -> n/a | E25: =IFERROR(AVERAGEIFS(Scoring!$H$43:$BA$43,Scoring!$H$2:$BA$2,"D",Scoring!$H$4:$BA$4,"L3"),"n/a") -> n/a | F25: =IFERROR(AVERAGEIFS(Scoring!$H$43:$BA$43,Scoring!$H$2:$BA$2,"D"),"Pending") -> Pending | G25: =COUNTIF(Scoring!$H$2:$BA$2,"D") -> 6
B26: E. Judgment | C26: =IFERROR(AVERAGEIFS(Scoring!$H$43:$BA$43,Scoring!$H$2:$BA$2,"E",Scoring!$H$4:$BA$4,"L1"),"n/a") -> n/a | D26: =IFERROR(AVERAGEIFS(Scoring!$H$43:$BA$43,Scoring!$H$2:$BA$2,"E",Scoring!$H$4:$BA$4,"L2"),"n/a") -> n/a | E26: =IFERROR(AVERAGEIFS(Scoring!$H$43:$BA$43,Scoring!$H$2:$BA$2,"E",Scoring!$H$4:$BA$4,"L3"),"n/a") -> n/a | F26: =IFERROR(AVERAGEIFS(Scoring!$H$43:$BA$43,Scoring!$H$2:$BA$2,"E"),"Pending") -> Pending | G26: =COUNTIF(Scoring!$H$2:$BA$2,"E") -> 12
B27: GenAI-flavoured subset | C27: =IFERROR(AVERAGEIFS(Scoring!$H$43:$BA$43,Scoring!$H$5:$BA$5,1,Scoring!$H$4:$BA$4,"L1"),"n/a") -> n/a | D27: =IFERROR(AVERAGEIFS(Scoring!$H$43:$BA$43,Scoring!$H$5:$BA$5,1,Scoring!$H$4:$BA$4,"L2"),"n/a") -> n/a | E27: =IFERROR(AVERAGEIFS(Scoring!$H$43:$BA$43,Scoring!$H$5:$BA$5,1,Scoring!$H$4:$BA$4,"L3"),"n/a") -> n/a | F27: =IFERROR(AVERAGEIFS(Scoring!$H$43:$BA$43,Scoring!$H$5:$BA$5,1),"Pending") -> Pending | G27: =COUNTIF(Scoring!$H$5:$BA$5,1) -> 8
B29: Claimed against scored
B30: Claimed is the self-rating on page one of the paper (1 to 4). Scored band maps each area's score to 1 to 4 using the inputs above. Gap above zero means the room rates itself higher than it scored.
B31: Area | C31: Mean claimed | D31: Mean scored band | E31: Gap | F31: Share over-claiming | G31: Share under-claiming
B32: Python | C32: =IFERROR(AVERAGE(Profile!N7:N41),"Pending") -> Pending | D32: =IFERROR(C32-E32,"Pending") -> Pending | E32: =IFERROR(AVERAGE(Profile!O7:O41),"Pending") -> Pending | F32: =IFERROR(COUNTIF(Profile!O7:O41,">0")/COUNT(Profile!O7:O41),"Pending") -> Pending | G32: =IFERROR(COUNTIF(Profile!O7:O41,"<0")/COUNT(Profile!O7:O41),"Pending") -> Pending
B33: SQL | C33: =IFERROR(AVERAGE(Profile!P7:P41),"Pending") -> Pending | D33: =IFERROR(C33-E33,"Pending") -> Pending | E33: =IFERROR(AVERAGE(Profile!Q7:Q41),"Pending") -> Pending | F33: =IFERROR(COUNTIF(Profile!Q7:Q41,">0")/COUNT(Profile!Q7:Q41),"Pending") -> Pending | G33: =IFERROR(COUNTIF(Profile!Q7:Q41,"<0")/COUNT(Profile!Q7:Q41),"Pending") -> Pending
B34: Numbers and reasoning | C34: =IFERROR(AVERAGE(Profile!R7:R41),"Pending") -> Pending | D34: =IFERROR(C34-E34,"Pending") -> Pending | E34: =IFERROR(AVERAGE(Profile!S7:S41),"Pending") -> Pending | F34: =IFERROR(COUNTIF(Profile!S7:S41,">0")/COUNT(Profile!S7:S41),"Pending") -> Pending | G34: =IFERROR(COUNTIF(Profile!S7:S41,"<0")/COUNT(Profile!S7:S41),"Pending") -> Pending
B35: Business problem | C35: =IFERROR(AVERAGE(Profile!T7:T41),"Pending") -> Pending | D35: =IFERROR(C35-E35,"Pending") -> Pending | E35: =IFERROR(AVERAGE(Profile!U7:U41),"Pending") -> Pending | F35: =IFERROR(COUNTIF(Profile!U7:U41,">0")/COUNT(Profile!U7:U41),"Pending") -> Pending | G35: =IFERROR(COUNTIF(Profile!U7:U41,"<0")/COUNT(Profile!U7:U41),"Pending") -> Pending
B36: LLM tools | C36: =IFERROR(AVERAGE(Profile!V7:V41),"Pending") -> Pending | D36: =IFERROR(C36-E36,"Pending") -> Pending | E36: =IFERROR(AVERAGE(Profile!W7:W41),"Pending") -> Pending | F36: =IFERROR(COUNTIF(Profile!W7:W41,">0")/COUNT(Profile!W7:W41),"Pending") -> Pending | G36: =IFERROR(COUNTIF(Profile!W7:W41,"<0")/COUNT(Profile!W7:W41),"Pending") -> Pending
B38: Where the room sits
B39: Students by total score band, all 46 marks.
B40: Band | C40: Students
B41: Below 40% | C41: =COUNTIFS(Profile!$J$7:$J$41,"<0.4") -> 0
B42: 40% to 60% | C42: =COUNTIFS(Profile!$J$7:$J$41,">=0.4",Profile!$J$7:$J$41,"<0.6") -> 0
B43: 60% to 80% | C43: =COUNTIFS(Profile!$J$7:$J$41,">=0.6",Profile!$J$7:$J$41,"<0.8") -> 0
B44: 80% and above | C44: =COUNTIFS(Profile!$J$7:$J$41,">=0.8") -> 0
B46: Hardest eight items
B47: Lowest cohort accuracy first. An L1 item in this list is a prerequisite gap for the brush-up; an L3 item here is expected.
B48: Item | C48: Concept | D48: Section | E48: Tier | F48: Accuracy
...

Sheet Key
B2: Answer key, tiers and misconception map
B3: Cohort 2 | Week 0 | INTERNAL | never printed for students | Accuracy columns read from the Scoring tab
A5: Item | B5: Section | C5: Section title | D5: Format shown to student | E5: Tier | F5: GenAI flavour | G5: Interview tag | H5: Concept tested | I5: Key | J5: Best | K5: Worst | L5: What A catches | M5: What B catches | N5: What C catches | O5: What D catches | P5: Marks | Q5: Entered | R5: Cohort accuracy | S5: Sort helper
A6: Q1 | B6: A | C6: Python for data and GenAI | D6: Predict the output | E6: L1 | F6: No | G6: [S] | H6: Types do not convert on their own | I6: C | J6: n/a | K6: n/a | L6: Assumes strings become numbers on their own | M6: Assumes + on an int and a str concatenates | N6: Correct: total starts as int 0 and o is a str | O6: Thinks the loop does not execute | P6: 1 | Q6: =SUM(Scoring!$BL$7:$BL$41) -> 0 | R6: =IF(Scoring!H43="","",Scoring!H43) | S6: =IF(R6="","",R6+ROW()/100000)
A7: Q2 | B7: A | C7: Python for data and GenAI | D7: Spot the bug, if there is one | E7: L1 | F7: No | G7: [S] | H7: Two names, one list | I7: B | J7: n/a | K7: n/a | L7: Believes assignment copies | M7: Correct: the expectation was wrong, the code was not | N7: Believes a method call binds to the name, not the object | O7: Confuses sorted() with .sort() and with append | P7: 1 | Q7: =SUM(Scoring!$BL$7:$BL$41) -> 0 | R7: =IF(Scoring!I43="","",Scoring!I43) | S7: =IF(R7="","",R7+ROW()/100000)
A8: Q3 | B8: A | C8: Python for data and GenAI | D8: Trace the flow (pseudocode) | E8: L1 | F8: No | G8: [S] | H8: Accumulator and running best, strict comparison on a tie | I8: D | J8: n/a | K8: n/a | L8: Gives the tie to the later day; the comparison is strict | M8: Stops accumulating once the best is found | N8: Prints best_revenue instead of the running total | O8: Correct: strict > keeps Wed on the tie; the total is 40+25+55+55 | P8: 1 | Q8: =SUM(Scoring!$BL$7:$BL$41) -> 0 | R8: =IF(Scoring!J43="","",Scoring!J43) | S8: =IF(R8="","",R8+ROW()/100000)
A9: Q4 | B9: A | C9: Python for data and GenAI | D9: Predict the output | E9: L1 | F9: Yes | G9: [S] | H9: Counting labels with dict.get | I9: A | J9: n/a | K9: n/a | L9: Correct: three refund labels, three distinct keys | M9: Thinks len(count) counts the labels, not the keys | N9: Swaps the two values | O9: Thinks .get raises on a missing key | P9: 1 | Q9: =SUM(Scoring!$BL$7:$BL$41) -> 0 | R9: =IF(Scoring!K43="","",Scoring!K43) | S9: =IF(R9="","",R9+ROW()/100000)
A10: Q5 | B10: A | C10: Python for data and GenAI | D10: Fix the code | E10: L1 | F10: Yes | G10: [F] | H10: Reading a nested JSON response | I10: B | J10: n/a | K10: n/a | L10: Puts the list index at the wrong level | M10: Correct: choices is a list, so index it first | N10: Treats a dict like an object with attributes | O10: Indexes the string, and still fails on the list | P10: 1 | Q10: =SUM(Scoring!$BL$7:$BL$41) -> 0 | R10: =IF(Scoring!L43="","",Scoring!L43) | S10: =IF(R10="","",R10+ROW()/100000)
A11: Q6 | B11: A | C11: Python for data and GenAI | D11: Predict the output | E11: L2 | F11: No | G11: [F] | H11: Truthiness drops zero as well as None | I11: D | J11: n/a | K11: n/a | L11: Thinks only None is removed; the zero is removed too | M11: Thinks / on ints gives an int | N11: Missed that the comprehension filters | O11: Correct: 0 and None are both false, so two values are dropped | P11: 1 | Q11: =SUM(Scoring!$BL$7:$BL$41) -> 0 | R11: =IF(Scoring!M43="","",Scoring!M43) | S11: =IF(R11="","",R11+ROW()/100000)
A12: Q7 | B12: A | C12: Python for data and GenAI | D12: Which line | E12: L2 | F12: No | G12: [F] | H12: Integer division hides the fraction | I12: A | J12: n/a | K12: n/a | L12: Correct | M12: The two forms are equivalent | N12: Would double count | O12: Blames the tool rather than the code | P12: 1 | Q12: =SUM(Scoring!$BL$7:$BL$41) -> 0 | R12: =IF(Scoring!N43="","",Scoring!N43) | S12: =IF(R12="","",R12+ROW()/100000)
A13: Q8 | B13: A | C13: Python for data and GenAI | D13: Predict the output | E13: L2 | F13: No | G13: [F] | H13: A default argument is created once | I13: C | J13: n/a | K13: n/a | L13: Believes the default list is made fresh on every call | M13: Believes return hands back a snapshot copy | N13: Correct: one default object, shared by both names | O13: Hedging when unsure; it does not | P13: 1 | Q13: =SUM(Scoring!$BL$7:$BL$41) -> 0 | R13: =IF(Scoring!O43="","",Scoring!O43) | S13: =IF(R13="","",R13+ROW()/100000)
A14: Q9 | B14: A | C14: Python for data and GenAI | D14: Fix the code | E14: L2 | F14: No | G14: [F] | H14: Defensive conversion: skip and count the bad rows | I14: A | J14: n/a | K14: n/a | L14: Correct: every failure is caught and kept | M14: Skips a fixed list of bad strings; the next new one still crashes and nothing is counted | N14: Stops at the first bad row and drops every row after it | O14: Filters empty strings only; 'n/a' still crashes | P14: 1 | Q14: =SUM(Scoring!$BL$7:$BL$41) -> 0 | R14: =IF(Scoring!P43="","",Scoring!P43) | S14: =IF(R14="","",R14+ROW()/100000)
A15: Q10 | B15: A | C15: Python for data and GenAI | D15: Spot the bug | E15: L2 | F15: No | G15: [F] | H15: sorted() on tuples orders by the first element | I15: D | J15: n/a | K15: n/a | L15: Reverses the meaning of the last element | M15: Tuples sort fine | N15: Invents a string comparison that is not happening | O15: Correct | P15: 1 | Q15: =SUM(Scoring!$BL$7:$BL$41) -> 0 | R15: =IF(Scoring!Q43="","",Scoring!Q43) | S15: =IF(R15="","",R15+ROW()/100000)
A16: Q11 | B16: A | C16: Python for data and GenAI | D16: Predict the output | E16: L3 | F16: Yes | G16: [D] | H16: Braces inside a format template are placeholders | I16: B | J16: n/a | K16: n/a | L16: Missed that the JSON braces are also parsed | M16: Correct: format() treats every {...} as a field | N16: Single quotes outside, double inside is valid | O16: Invents a partial fill; format() is all or nothing | P16: 1 | Q16: =SUM(Scoring!$BL$7:$BL$41) -> 0 | R16: =IF(Scoring!R43="","",Scoring!R43) | S16: =IF(R16="","",R16+ROW()/100000)
A17: Q12 | B17: A | C17: Python for data and GenAI | D17: Fix the code | E17: L3 | F17: No | G17: [D] | H17: A repeated inner list is one object | I17: C | J17: n/a | K17: n/a | L17: Same trap: one inner list repeated | M17: list() copies the outer list only | N17: Correct: the comprehension builds a new inner list each time | O17: copy() is shallow; the inner list is still shared | P17: 1 | Q17: =SUM(Scoring!$BL$7:$BL$41) -> 0 | R17: =IF(Scoring!S43="","",Scoring!S43) | S17: =IF(R17="","",R17+ROW()/100000)
A18: Q13 | B18: B | C18: SQL for data and GenAI | D18: Predict the result | E18: L1 | F18: No | G18: [S] | H18: COUNT(*) against COUNT(column) with NULL | I18: B | J18: n/a | K18: n/a | L18: Thinks COUNT(column) counts NULL rows | M18: Correct: COUNT(amount) skips the NULL; SUM ignores it | N18: Ignores the WHERE clause | O18: Thinks one NULL makes the SUM NULL | P18: 1 | Q18: =SUM(Scoring!$BL$7:$BL$41) -> 0 | R18: =IF(Scoring!T43="","",Scoring!T43) | S18: =IF(R18="","",R18+ROW()/100000)
A19: Q14 | B19: B | C19: SQL for data and GenAI | D19: Fix the query | E19: L1 | F19: No | G19: [S] | H19: Integer division in SQL | I19: A | J19: n/a | K19: n/a | L19: Correct: one decimal operand stops the integer division | M19: Rounds a value that is already 0 | N19: COUNT of an expression counts every non-null row, so 5/5 | O19: Postgres has no AVG over a boolean; it errors | P19: 1 | Q19: =SUM(Scoring!$BL$7:$BL$41) -> 0 | R19: =IF(Scoring!U43="","",Scoring!U43) | S19: =IF(R19="","",R19+ROW()/100000)
A20: Q15 | B20: B | C20: SQL for data and GenAI | D20: Predict the result | E20: L1 | F20: No | G20: [S] | H20: WHERE before grouping, HAVING after | I20: D | J20: n/a | K20: n/a | L20: Counts the cancelled Plus order | M20: Ignores HAVING | N20: Alias belief; HAVING can repeat the aggregate | O20: Correct | P20: 1 | Q20: =SUM(Scoring!$BL$7:$BL$41) -> 0 | R20: =IF(Scoring!V43="","",Scoring!V43) | S20: =IF(R20="","",R20+ROW()/100000)
A21: Q16 | B21: B | C21: SQL for data and GenAI | D21: Spot the bug | E21: L2 | F21: No | G21: [F] | H21: NULL in a comparison | I21: C | J21: n/a | K21: n/a | L21: Both operators are valid | M21: COUNT(*) counts every row it receives | N21: Correct: three-valued logic | O21: Invents a filter that is not in the query | P21: 1 | Q21: =SUM(Scoring!$BL$7:$BL$41) -> 0 | R21: =IF(Scoring!W43="","",Scoring!W43) | S21: =IF(R21="","",R21+ROW()/100000)
A22: Q17 | B22: B | C22: SQL for data and GenAI | D22: Spot the bug and fix it | E22: L2 | F22: No | G22: [F] | H22: A WHERE on the right table turns a LEFT JOIN into an inner join | I22: A | J22: n/a | K22: n/a | L22: Correct: WHERE discards the NULL rows the left join created | M22: Confuses the count bug with the row-loss bug | N22: Guesses at join direction | O22: Believes HAVING can bring back filtered rows | P22: 1 | Q22: =SUM(Scoring!$BL$7:$BL$41) -> 0 | R22: =IF(Scoring!X43="","",Scoring!X43) | S22: =IF(R22="","",R22+ROW()/100000)
A23: Q18 | B23: B | C23: SQL for data and GenAI | D23: Predict the result | E23: L2 | F23: No | G23: [F] | H23: Aggregates cannot sit in WHERE | I23: B | J23: n/a | K23: n/a | L23: Assumes WHERE can see the aggregate | M23: Correct | N23: Invents a silent skip | O23: Invents a NULL evaluation | P23: 1 | Q23: =SUM(Scoring!$BL$7:$BL$41) -> 0 | R23: =IF(Scoring!Y43="","",Scoring!Y43) | S23: =IF(R23="","",R23+ROW()/100000)
A24: Q19 | B24: B | C24: SQL for data and GenAI | D24: Predict the result | E24: L2 | F24: Yes | G24: [F] | H24: Latest row per group with ROW_NUMBER | I24: D | J24: n/a | K24: n/a | L24: Reads DESC as ascending | M24: Missed the outer WHERE rn = 1 | N24: Over-applies a true rule; the filter is in the outer query | O24: Correct: highest call_id per ticket | P24: 1 | Q24: =SUM(Scoring!$BL$7:$BL$41) -> 0 | R24: =IF(Scoring!Z43="","",Scoring!Z43) | S24: =IF(R24="","",R24+ROW()/100000)
A25: Q20 | B25: B | C25: SQL for data and GenAI | D25: Fix the query | E25: L3 | F25: Yes | G25: [D] | H25: Join fan-out inflates a SUM | I25: C | J25: n/a | K25: n/a | L25: Drops the two genuine 0.30 costs down to one; wrong for a different reason | M25: DISTINCT applies to the output rows, after the SUM | N25: Correct: fan-out from a one-to-many join | O25: No ticket is lost; the problem is duplication | P25: 1 | Q25: =SUM(Scoring!$BL$7:$BL$41) -> 0 | R25: =IF(Scoring!AA43="","",Scoring!AA43) | S25: =IF(R25="","",R25+ROW()/100000)
A26: Q21 | B26: C | C26: Numbers and reasoning | D26: Reason with numbers | E26: L1 | F26: No | G26: [S] | H26: Ratios of percentage changes | I26: D | J26: n/a | K26: n/a | L26: Subtracts the percentages | M26: Ignores the order-count change | N26: Reaches for data the question does not need | O26: Correct: 0.88 / 1.05 is about 0.84 | P26: 1 | Q26: =SUM(Scoring!$BL$7:$BL$41) -> 0 | R26: =IF(Scoring!AB43="","",Scoring!AB43) | S26: =IF(R26="","",R26+ROW()/100000)
A27: Q22 | B27: C | C27: Numbers and reasoning | D27: Reason with numbers | E27: L1 | F27: No | G27: [S] | H27: Median against mean under one extreme value | I27: A | J27: n/a | K27: n/a | L27: Correct | M27: Uses the mean where one value dominates | N27: Avoids the decision the slide needs | O27: Invents a compromise statistic | P27: 1 | Q27: =SUM(Scoring!$BL$7:$BL$41) -> 0 | R27: =IF(Scoring!AC43="","",Scoring!AC43) | S27: =IF(R27="","",R27+ROW()/100000)
A28: Q23 | B28: C | C28: Numbers and reasoning | D28: Reason with numbers | E28: L1 | F28: No | G28: [S] | H28: Compare rates, not counts | I28: B | J28: n/a | K28: n/a | L28: Compares counts with different denominators | M28: Correct: 150/5000 against 400/20000 | N28: Assumes the sizes cancel | O28: Reaches for extra data; the question is about response | P28: 1 | Q28: =SUM(Scoring!$BL$7:$BL$41) -> 0 | R28: =IF(Scoring!AD43="","",Scoring!AD43) | S28: =IF(R28="","",R28+ROW()/100000)
A29: Q24 | B29: C | C29: Numbers and reasoning | D29: Two statements | E29: L2 | F29: No | G29: [F] | H29: Percentage changes do not add | I29: C | J29: n/a | K29: n/a | L29: 1.1 x 0.9 is 0.99, so I is false | M29: I is false | N29: Correct: 0.5 x 2 is 1 | O29: II is true | P29: 1 | Q29: =SUM(Scoring!$BL$7:$BL$41) -> 0 | R29: =IF(Scoring!AE43="","",Scoring!AE43) | S29: =IF(R29="","",R29+ROW()/100000)
A30: Q25 | B30: C | C30: Numbers and reasoning | D30: Reason with numbers | E30: L2 | F30: No | G30: [F] | H30: Small counts move for no reason | I30: A | J30: n/a | K30: n/a | L30: Correct: 5 became 7 | M30: Reads a relative change on a tiny base as a signal | N30: Arithmetic slip: 7/50 is 14 percent | O30: Refuses the judgment the numbers already allow | P30: 1 | Q30: =SUM(Scoring!$BL$7:$BL$41) -> 0 | R30: =IF(Scoring!AF43="","",Scoring!AF43) | S30: =IF(R30="","",R30+ROW()/100000)
A31: Q26 | B31: C | C31: Numbers and reasoning | D31: Reason with numbers | E31: L2 | F31: No | G31: [F] | H31: Base rates: precision from recall and prevalence | I31: D | J31: n/a | K31: n/a | L31: Confuses recall with precision | M31: Picks a given number | N31: Picks the base rate | O31: Correct: 0.9 x 1 = 0.9 caught, out of 5 flagged | P31: 1 | Q31: =SUM(Scoring!$BL$7:$BL$41) -> 0 | R31: =IF(Scoring!AG43="","",Scoring!AG43) | S31: =IF(R31="","",R31+ROW()/100000)
A32: Q27 | B32: C | C32: Numbers and reasoning | D32: Reason with numbers | E32: L3 | F32: No | G32: [D] | H32: Mix shift can reverse a total | I32: B | J32: n/a | K32: n/a | L32: Denies the mix effect | M32: Correct | N32: Rounding cannot flip a direction in every city | O32: The total is made of the cities | P32: 1 | Q32: =SUM(Scoring!$BL$7:$BL$41) -> 0 | R32: =IF(Scoring!AH43="","",Scoring!AH43) | S32: =IF(R32="","",R32+ROW()/100000)
A33: Q28 | B33: C | C33: Numbers and reasoning | D33: Estimate | E33: L3 | F33: Yes | G33: [D] | H33: Token economics, multi-step estimate | I33: C | J33: n/a | K33: n/a | L33: Counts input tokens only | M33: Applies the output price to every token | N33: Correct: 36M x 40/M plus 6M x 160/M | O33: Decimal slip | P33: 1 | Q33: =SUM(Scoring!$BL$7:$BL$41) -> 0 | R33: =IF(Scoring!AI43="","",Scoring!AI43) | S33: =IF(R33="","",R33+ROW()/100000)
A34: Q29 | B34: D | C34: Case and scenarios | D34: Case: Kalpa Retail, Q1 against Q2 | E34: L1 | F34: No | G34: [S] | H34: Which branch moved | I34: A | J34: n/a | K34: n/a | L34: Correct: Plus lost 36 of a net 44 | M34: Real but smaller: Basic lost 20 | N34: Invents a link the table does not show | O34: Customers rose from 55,000 to 62,000 | P34: 1 | Q34: =SUM(Scoring!$BL$7:$BL$41) -> 0 | R34: =IF(Scoring!AJ43="","",Scoring!AJ43) | S34: =IF(R34="","",R34+ROW()/100000)
A35: Q30 | B35: D | C35: Case and scenarios | D35: Case: Kalpa Retail, Q1 against Q2 | E35: L2 | F35: No | G35: [F] | H35: Test a hypothesis against the table | I35: C | J35: n/a | K35: n/a | L35: Reads the Basic rise as proof of the source | M35: Unrelated evidence | N35: Correct: 10,000 in both quarters | O35: The table already carries the test | P35: 1 | Q35: =SUM(Scoring!$BL$7:$BL$41) -> 0 | R35: =IF(Scoring!AK43="","",Scoring!AK43) | S35: =IF(R35="","",R35+ROW()/100000)
A36: Q31 | B36: D | C36: Case and scenarios | D36: Case: Kalpa Retail, Q1 against Q2 | E36: L2 | F36: No | G36: [F] | H36: The fair comparison | I36: B | J36: n/a | K36: n/a | L36: Before-and-after mixes the discount with everything else that changed | M36: Correct: like with like, same window | N36: Different tier, different behaviour | O36: Plan is a target, not a comparison group | P36: 1 | Q36: =SUM(Scoring!$BL$7:$BL$41) -> 0 | R36: =IF(Scoring!AL43="","",Scoring!AL43) | S36: =IF(R36="","",R36+ROW()/100000)
A37: Q32 | B37: D | C37: Case and scenarios | D37: Case: Kalpa Retail, Q1 against Q2 | E37: L3 | F37: No | G37: [D] | H37: Like-with-like windows before presenting | I37: D | J37: n/a | K37: n/a | L37: Explains, but does not test, the finding | M37: Checks arithmetic, not the claim | N37: Describes the same numbers differently | O37: Correct: the window can create the whole fall | P37: 1 | Q37: =SUM(Scoring!$BL$7:$BL$41) -> 0 | R37: =IF(Scoring!AM43="","",Scoring!AM43) | S37: =IF(R37="","",R37+ROW()/100000)
A38: Q33 | B38: D | C38: Case and scenarios | D38: Scenario: LLM intuition | E38: L2 | F38: Yes | G38: [F] | H38: Sampling variance and an under-specified prompt | I38: A | J38: n/a | K38: n/a | L38: Correct | M38: Calls carry no memory unless the history is sent | N38: Blames the data for a sampling effect | O38: Reaches for scale before fixing the prompt | P38: 1 | Q38: =SUM(Scoring!$BL$7:$BL$41) -> 0 | R38: =IF(Scoring!AN43="","",Scoring!AN43) | S38: =IF(R38="","",R38+ROW()/100000)
A39: Q34 | B39: D | C39: Case and scenarios | D39: Scenario: LLM intuition | E39: L3 | F39: Yes | G39: [D] | H39: A small hand-labelled set is the fastest trust check | I39: B | J39: n/a | K39: n/a | L39: Self-reported confidence is not a check | M39: Correct: a small golden set | N39: Agreement between models is not accuracy | O39: Changes the input without measuring the output | P39: 1 | Q39: =SUM(Scoring!$BL$7:$BL$41) -> 0 | R39: =IF(Scoring!AO43="","",Scoring!AO43) | S39: =IF(R39="","",R39+ROW()/100000)
A40: Q35 | B40: E | C40: Judgment calls | D40: Best and worst | E40: J | F40: No | G40: [SV] | H40: Disclosing an error you found yourself | I40: n/a | J40: C | K40: A | L40: Worst: conceals a known error in a board figure | M40: Delays a correction you already have | N40: Best | O40: Passes the decision upward | P40: 2 | Q40: =SUM(Scoring!$BL$7:$BL$41) -> 0 | R40: =IF(Scoring!AP43="","",AVERAGE(Scoring!AP43,Scoring!AQ43)) | S40: =IF(R40="","",R40+ROW()/100000)
A41: Q36 | B41: E | C41: Judgment calls | D41: Best and worst | E41: J | F41: Yes | G41: [SV] | H41: Owning what you do not yet understand | I41: n/a | J41: B | K41: D | L41: Delays, but stays honest | M41: Best | N41: Avoids the question | O41: Worst: misrepresents and compounds the gap | P41: 2 | Q41: =SUM(Scoring!$BL$7:$BL$41) -> 0 | R41: =IF(Scoring!AR43="","",AVERAGE(Scoring!AR43,Scoring!AS43)) | S41: =IF(R41="","",R41+ROW()/100000)
A42: Q37 | B42: E | C42: Judgment calls | D42: Best and worst | E42: J | F42: No | G42: [SV] | H42: Taking criticism in front of others | I42: n/a | J42: D | K42: B | L42: Leaves the panel with the doubt | M42: Worst: retaliation in front of the panel | N42: Defends before hearing the point | O42: Best | P42: 2 | Q42: =SUM(Scoring!$BL$7:$BL$41) -> 0 | R42: =IF(Scoring!AT43="","",AVERAGE(Scoring!AT43,Scoring!AU43)) | S42: =IF(R42="","",R42+ROW()/100000)
...

Sheet Entry
B2: Answer sheet entry
B3: Cohort 2 | Week 0 | INTERNAL | type into the blue cells only; letters A to D, a dash for a question left blank, self-ratings 1 to 4, statements 1 to 5
C5: Self-rating, page one | H5: Sections A to D, one letter each | AP5: Section E, best and worst | BB5: Ten statements, 1 to 5
A6: Student ID | B6: Name | C6: Claimed: Python | D6: Claimed: SQL | E6: Claimed: Numbers and reasoning | F6: Claimed: Working an unfamiliar business problem | G6: Claimed: Using LLM tools for work | H6: Q1 | I6: Q2 | J6: Q3 | K6: Q4 | L6: Q5 | M6: Q6 | N6: Q7 | O6: Q8 | P6: Q9 | Q6: Q10 | R6: Q11 | S6: Q12 | T6: Q13 | U6: Q14 | V6: Q15 | W6: Q16 | X6: Q17 | Y6: Q18 | Z6: Q19 | AA6: Q20 | AB6: Q21 | AC6: Q22 | AD6: Q23 | AE6: Q24 | AF6: Q25 | AG6: Q26 | AH6: Q27 | AI6: Q28 | AJ6: Q29 | AK6: Q30 | AL6: Q31 | AM6: Q32 | AN6: Q33 | AO6: Q34 | AP6: Q35 best | AQ6: Q35 worst | AR6: Q36 best | AS6: Q36 worst | AT6: Q37 best | AU6: Q37 worst | AV6: Q38 best | AW6: Q38 worst | AX6: Q39 best | AY6: Q39 worst | AZ6: Q40 best | BA6: Q40 worst | BB6: R1 | BC6: R2 | BD6: R3 | BE6: R4 | BF6: R5 | BG6: R6 | BH6: R7 | BI6: R8 | BJ6: R9 | BK6: R10 | BL6: Entered
A7: S01 | B7: TBD | BL7: =IF(COUNTBLANK(C7:BK7)=0,"Yes","Pending") -> Pending
A8: S02 | B8: TBD | BL8: =IF(COUNTBLANK(C8:BK8)=0,"Yes","Pending") -> Pending
A9: S03 | B9: TBD | BL9: =IF(COUNTBLANK(C9:BK9)=0,"Yes","Pending") -> Pending
A10: S04 | B10: TBD | BL10: =IF(COUNTBLANK(C10:BK10)=0,"Yes","Pending") -> Pending
A11: S05 | B11: TBD | BL11: =IF(COUNTBLANK(C11:BK11)=0,"Yes","Pending") -> Pending
A12: S06 | B12: TBD | BL12: =IF(COUNTBLANK(C12:BK12)=0,"Yes","Pending") -> Pending
A13: S07 | B13: TBD | BL13: =IF(COUNTBLANK(C13:BK13)=0,"Yes","Pending") -> Pending
A14: S08 | B14: TBD | BL14: =IF(COUNTBLANK(C14:BK14)=0,"Yes","Pending") -> Pending
A15: S09 | B15: TBD | BL15: =IF(COUNTBLANK(C15:BK15)=0,"Yes","Pending") -> Pending
A16: S10 | B16: TBD | BL16: =IF(COUNTBLANK(C16:BK16)=0,"Yes","Pending") -> Pending
A17: S11 | B17: TBD | BL17: =IF(COUNTBLANK(C17:BK17)=0,"Yes","Pending") -> Pending
A18: S12 | B18: TBD | BL18: =IF(COUNTBLANK(C18:BK18)=0,"Yes","Pending") -> Pending
... A41: S35 | B41: TBD | BL41: =IF(COUNTBLANK(C41:BK41)=0,"Yes","Pending") -> Pending
A43: Example row, not counted anywhere: this is the format the entry expects.
A44: S00 | B44: Example Student | C44: 3 | D44: 2 | E44: 3 | F44: 2 | G44: 4 | H44: C | I44: B | J44: D | K44: A | L44: B | M44: D | N44: A | O44: C | P44: A | Q44: - | R44: B | S44: C | T44: B | U44: A | V44: D | W44: C | X44: A | Y44: B | Z44: D | AA44: C | AB44: D | AC44: A | AD44: B | AE44: C | AF44: A | AG44: D | AH44: B | AI44: C | AJ44: A | AK44: C | AL44: B | AM44: D | AN44: A | AO44: B | AP44: C | AQ44: A | AR44: B | AS44: D | AT44: D | AU44: B | AV44: A | AW44: C | AX44: C | AY44: D | AZ44: B | BA44: A | BB44: 4 | BC44: 3 | BD44: 5 | BE44: 4 | BF44: 3 | BG44: 2 | BH44: 5 | BI44: 3 | BJ44: 2 | BK44: 5

Sheet Scoring
B2: Section | H2: A | I2: A | J2: A | K2: A | L2: A | M2: A | N2: A | O2: A | P2: A | Q2: A | R2: A | S2: A | T2: B | U2: B | V2: B | W2: B | X2: B | Y2: B | Z2: B | AA2: B | AB2: C | AC2: C | AD2: C | AE2: C | AF2: C | AG2: C | AH2: C | AI2: C | AJ2: D | AK2: D | AL2: D | AM2: D | AN2: D | AO2: D | AP2: E | AQ2: E | AR2: E | AS2: E | AT2: E | AU2: E | AV2: E | AW2: E | AX2: E | AY2: E | AZ2: E | BA2: E
B3: Key | H3: C | I3: B | J3: D | K3: A | L3: B | M3: D | N3: A | O3: C | P3: A | Q3: D | R3: B | S3: C | T3: B | U3: A | V3: D | W3: C | X3: A | Y3: B | Z3: D | AA3: C | AB3: D | AC3: A | AD3: B | AE3: C | AF3: A | AG3: D | AH3: B | AI3: C | AJ3: A | AK3: C | AL3: B | AM3: D | AN3: A | AO3: B | AP3: C | AQ3: A | AR3: B | AS3: D | AT3: D | AU3: B | AV3: A | AW3: C | AX3: C | AY3: D | AZ3: B | BA3: A
B4: Tier | H4: L1 | I4: L1 | J4: L1 | K4: L1 | L4: L1 | M4: L2 | N4: L2 | O4: L2 | P4: L2 | Q4: L2 | R4: L3 | S4: L3 | T4: L1 | U4: L1 | V4: L1 | W4: L2 | X4: L2 | Y4: L2 | Z4: L2 | AA4: L3 | AB4: L1 | AC4: L1 | AD4: L1 | AE4: L2 | AF4: L2 | AG4: L2 | AH4: L3 | AI4: L3 | AJ4: L1 | AK4: L2 | AL4: L2 | AM4: L3 | AN4: L2 | AO4: L3 | AP4: J | AQ4: J | AR4: J | AS4: J | AT4: J | AU4: J | AV4: J | AW4: J | AX4: J | AY4: J | AZ4: J | BA4: J
B5: GenAI | H5: 0 | I5: 0 | J5: 0 | K5: 1 | L5: 1 | M5: 0 | N5: 0 | O5: 0 | P5: 0 | Q5: 0 | R5: 1 | S5: 0 | T5: 0 | U5: 0 | V5: 0 | W5: 0 | X5: 0 | Y5: 0 | Z5: 1 | AA5: 1 | AB5: 0 | AC5: 0 | AD5: 0 | AE5: 0 | AF5: 0 | AG5: 0 | AH5: 0 | AI5: 1 | AJ5: 0 | AK5: 0 | AL5: 0 | AM5: 0 | AN5: 1 | AO5: 1 | AP5: 0 | AQ5: 0 | AR5: 0 | AS5: 0 | AT5: 0 | AU5: 0 | AV5: 0 | AW5: 0 | AX5: 0 | AY5: 0 | AZ5: 0 | BA5: 0
A6: Student ID | B6: Name | H6: Q1 | I6: Q2 | J6: Q3 | K6: Q4 | L6: Q5 | M6: Q6 | N6: Q7 | O6: Q8 | P6: Q9 | Q6: Q10 | R6: Q11 | S6: Q12 | T6: Q13 | U6: Q14 | V6: Q15 | W6: Q16 | X6: Q17 | Y6: Q18 | Z6: Q19 | AA6: Q20 | AB6: Q21 | AC6: Q22 | AD6: Q23 | AE6: Q24 | AF6: Q25 | AG6: Q26 | AH6: Q27 | AI6: Q28 | AJ6: Q29 | AK6: Q30 | AL6: Q31 | AM6: Q32 | AN6: Q33 | AO6: Q34 | AP6: Q35b | AQ6: Q35w | AR6: Q36b | AS6: Q36w | AT6: Q37b | AU6: Q37w | AV6: Q38b | AW6: Q38w | AX6: Q39b | AY6: Q39w | AZ6: Q40b | BA6: Q40w | BL6: Entered
A7: =Entry!A7 -> S01 | B7: =Entry!B7 -> TBD | H7: =IF(Entry!H7="",0,IF(Entry!H7=H$3,1,0)) -> 0 | I7: =IF(Entry!I7="",0,IF(Entry!I7=I$3,1,0)) -> 0 | J7: =IF(Entry!J7="",0,IF(Entry!J7=J$3,1,0)) -> 0 | K7: =IF(Entry!K7="",0,IF(Entry!K7=K$3,1,0)) -> 0 | L7: =IF(Entry!L7="",0,IF(Entry!L7=L$3,1,0)) -> 0 | M7: =IF(Entry!M7="",0,IF(Entry!M7=M$3,1,0)) -> 0 | N7: =IF(Entry!N7="",0,IF(Entry!N7=N$3,1,0)) -> 0 | O7: =IF(Entry!O7="",0,IF(Entry!O7=O$3,1,0)) -> 0 | ... BA7: =IF(Entry!BA7="",0,IF(Entry!BA7=BA$3,1,0)) -> 0 | BL7: =IF(Entry!BL7="Yes",1,0) -> 0
A8: =Entry!A8 -> S02 | B8: =Entry!B8 -> TBD | H8: =IF(Entry!H8="",0,IF(Entry!H8=H$3,1,0)) -> 0 | I8: =IF(Entry!I8="",0,IF(Entry!I8=I$3,1,0)) -> 0 | J8: =IF(Entry!J8="",0,IF(Entry!J8=J$3,1,0)) -> 0 | K8: =IF(Entry!K8="",0,IF(Entry!K8=K$3,1,0)) -> 0 | L8: =IF(Entry!L8="",0,IF(Entry!L8=L$3,1,0)) -> 0 | M8: =IF(Entry!M8="",0,IF(Entry!M8=M$3,1,0)) -> 0 | N8: =IF(Entry!N8="",0,IF(Entry!N8=N$3,1,0)) -> 0 | O8: =IF(Entry!O8="",0,IF(Entry!O8=O$3,1,0)) -> 0 | ... BA8: =IF(Entry!BA8="",0,IF(Entry!BA8=BA$3,1,0)) -> 0 | BL8: =IF(Entry!BL8="Yes",1,0) -> 0
A9: =Entry!A9 -> S03 | B9: =Entry!B9 -> TBD | H9: =IF(Entry!H9="",0,IF(Entry!H9=H$3,1,0)) -> 0 | I9: =IF(Entry!I9="",0,IF(Entry!I9=I$3,1,0)) -> 0 | J9: =IF(Entry!J9="",0,IF(Entry!J9=J$3,1,0)) -> 0 | K9: =IF(Entry!K9="",0,IF(Entry!K9=K$3,1,0)) -> 0 | L9: =IF(Entry!L9="",0,IF(Entry!L9=L$3,1,0)) -> 0 | M9: =IF(Entry!M9="",0,IF(Entry!M9=M$3,1,0)) -> 0 | N9: =IF(Entry!N9="",0,IF(Entry!N9=N$3,1,0)) -> 0 | O9: =IF(Entry!O9="",0,IF(Entry!O9=O$3,1,0)) -> 0 | ... BA9: =IF(Entry!BA9="",0,IF(Entry!BA9=BA$3,1,0)) -> 0 | BL9: =IF(Entry!BL9="Yes",1,0) -> 0
A10: =Entry!A10 -> S04 | B10: =Entry!B10 -> TBD | H10: =IF(Entry!H10="",0,IF(Entry!H10=H$3,1,0)) -> 0 | I10: =IF(Entry!I10="",0,IF(Entry!I10=I$3,1,0)) -> 0 | J10: =IF(Entry!J10="",0,IF(Entry!J10=J$3,1,0)) -> 0 | K10: =IF(Entry!K10="",0,IF(Entry!K10=K$3,1,0)) -> 0 | L10: =IF(Entry!L10="",0,IF(Entry!L10=L$3,1,0)) -> 0 | M10: =IF(Entry!M10="",0,IF(Entry!M10=M$3,1,0)) -> 0 | N10: =IF(Entry!N10="",0,IF(Entry!N10=N$3,1,0)) -> 0 | O10: =IF(Entry!O10="",0,IF(Entry!O10=O$3,1,0)) -> 0 | ... BA10: =IF(Entry!BA10="",0,IF(Entry!BA10=BA$3,1,0)) -> 0 | BL10: =IF(Entry!BL10="Yes",1,0) -> 0
A11: =Entry!A11 -> S05 | B11: =Entry!B11 -> TBD | H11: =IF(Entry!H11="",0,IF(Entry!H11=H$3,1,0)) -> 0 | I11: =IF(Entry!I11="",0,IF(Entry!I11=I$3,1,0)) -> 0 | J11: =IF(Entry!J11="",0,IF(Entry!J11=J$3,1,0)) -> 0 | K11: =IF(Entry!K11="",0,IF(Entry!K11=K$3,1,0)) -> 0 | L11: =IF(Entry!L11="",0,IF(Entry!L11=L$3,1,0)) -> 0 | M11: =IF(Entry!M11="",0,IF(Entry!M11=M$3,1,0)) -> 0 | N11: =IF(Entry!N11="",0,IF(Entry!N11=N$3,1,0)) -> 0 | O11: =IF(Entry!O11="",0,IF(Entry!O11=O$3,1,0)) -> 0 | ... BA11: =IF(Entry!BA11="",0,IF(Entry!BA11=BA$3,1,0)) -> 0 | BL11: =IF(Entry!BL11="Yes",1,0) -> 0
A12: =Entry!A12 -> S06 | B12: =Entry!B12 -> TBD | H12: =IF(Entry!H12="",0,IF(Entry!H12=H$3,1,0)) -> 0 | I12: =IF(Entry!I12="",0,IF(Entry!I12=I$3,1,0)) -> 0 | J12: =IF(Entry!J12="",0,IF(Entry!J12=J$3,1,0)) -> 0 | K12: =IF(Entry!K12="",0,IF(Entry!K12=K$3,1,0)) -> 0 | L12: =IF(Entry!L12="",0,IF(Entry!L12=L$3,1,0)) -> 0 | M12: =IF(Entry!M12="",0,IF(Entry!M12=M$3,1,0)) -> 0 | N12: =IF(Entry!N12="",0,IF(Entry!N12=N$3,1,0)) -> 0 | O12: =IF(Entry!O12="",0,IF(Entry!O12=O$3,1,0)) -> 0 | ... BA12: =IF(Entry!BA12="",0,IF(Entry!BA12=BA$3,1,0)) -> 0 | BL12: =IF(Entry!BL12="Yes",1,0) -> 0
A13: =Entry!A13 -> S07 | B13: =Entry!B13 -> TBD | H13: =IF(Entry!H13="",0,IF(Entry!H13=H$3,1,0)) -> 0 | I13: =IF(Entry!I13="",0,IF(Entry!I13=I$3,1,0)) -> 0 | J13: =IF(Entry!J13="",0,IF(Entry!J13=J$3,1,0)) -> 0 | K13: =IF(Entry!K13="",0,IF(Entry!K13=K$3,1,0)) -> 0 | L13: =IF(Entry!L13="",0,IF(Entry!L13=L$3,1,0)) -> 0 | M13: =IF(Entry!M13="",0,IF(Entry!M13=M$3,1,0)) -> 0 | N13: =IF(Entry!N13="",0,IF(Entry!N13=N$3,1,0)) -> 0 | O13: =IF(Entry!O13="",0,IF(Entry!O13=O$3,1,0)) -> 0 | ... BA13: =IF(Entry!BA13="",0,IF(Entry!BA13=BA$3,1,0)) -> 0 | BL13: =IF(Entry!BL13="Yes",1,0) -> 0
A14: =Entry!A14 -> S08 | B14: =Entry!B14 -> TBD | H14: =IF(Entry!H14="",0,IF(Entry!H14=H$3,1,0)) -> 0 | I14: =IF(Entry!I14="",0,IF(Entry!I14=I$3,1,0)) -> 0 | J14: =IF(Entry!J14="",0,IF(Entry!J14=J$3,1,0)) -> 0 | K14: =IF(Entry!K14="",0,IF(Entry!K14=K$3,1,0)) -> 0 | L14: =IF(Entry!L14="",0,IF(Entry!L14=L$3,1,0)) -> 0 | M14: =IF(Entry!M14="",0,IF(Entry!M14=M$3,1,0)) -> 0 | N14: =IF(Entry!N14="",0,IF(Entry!N14=N$3,1,0)) -> 0 | O14: =IF(Entry!O14="",0,IF(Entry!O14=O$3,1,0)) -> 0 | ... BA14: =IF(Entry!BA14="",0,IF(Entry!BA14=BA$3,1,0)) -> 0 | BL14: =IF(Entry!BL14="Yes",1,0) -> 0
A15: =Entry!A15 -> S09 | B15: =Entry!B15 -> TBD | H15: =IF(Entry!H15="",0,IF(Entry!H15=H$3,1,0)) -> 0 | I15: =IF(Entry!I15="",0,IF(Entry!I15=I$3,1,0)) -> 0 | J15: =IF(Entry!J15="",0,IF(Entry!J15=J$3,1,0)) -> 0 | K15: =IF(Entry!K15="",0,IF(Entry!K15=K$3,1,0)) -> 0 | L15: =IF(Entry!L15="",0,IF(Entry!L15=L$3,1,0)) -> 0 | M15: =IF(Entry!M15="",0,IF(Entry!M15=M$3,1,0)) -> 0 | N15: =IF(Entry!N15="",0,IF(Entry!N15=N$3,1,0)) -> 0 | O15: =IF(Entry!O15="",0,IF(Entry!O15=O$3,1,0)) -> 0 | ... BA15: =IF(Entry!BA15="",0,IF(Entry!BA15=BA$3,1,0)) -> 0 | BL15: =IF(Entry!BL15="Yes",1,0) -> 0
A16: =Entry!A16 -> S10 | B16: =Entry!B16 -> TBD | H16: =IF(Entry!H16="",0,IF(Entry!H16=H$3,1,0)) -> 0 | I16: =IF(Entry!I16="",0,IF(Entry!I16=I$3,1,0)) -> 0 | J16: =IF(Entry!J16="",0,IF(Entry!J16=J$3,1,0)) -> 0 | K16: =IF(Entry!K16="",0,IF(Entry!K16=K$3,1,0)) -> 0 | L16: =IF(Entry!L16="",0,IF(Entry!L16=L$3,1,0)) -> 0 | M16: =IF(Entry!M16="",0,IF(Entry!M16=M$3,1,0)) -> 0 | N16: =IF(Entry!N16="",0,IF(Entry!N16=N$3,1,0)) -> 0 | O16: =IF(Entry!O16="",0,IF(Entry!O16=O$3,1,0)) -> 0 | ... BA16: =IF(Entry!BA16="",0,IF(Entry!BA16=BA$3,1,0)) -> 0 | BL16: =IF(Entry!BL16="Yes",1,0) -> 0
A17: =Entry!A17 -> S11 | B17: =Entry!B17 -> TBD | H17: =IF(Entry!H17="",0,IF(Entry!H17=H$3,1,0)) -> 0 | I17: =IF(Entry!I17="",0,IF(Entry!I17=I$3,1,0)) -> 0 | J17: =IF(Entry!J17="",0,IF(Entry!J17=J$3,1,0)) -> 0 | K17: =IF(Entry!K17="",0,IF(Entry!K17=K$3,1,0)) -> 0 | L17: =IF(Entry!L17="",0,IF(Entry!L17=L$3,1,0)) -> 0 | M17: =IF(Entry!M17="",0,IF(Entry!M17=M$3,1,0)) -> 0 | N17: =IF(Entry!N17="",0,IF(Entry!N17=N$3,1,0)) -> 0 | O17: =IF(Entry!O17="",0,IF(Entry!O17=O$3,1,0)) -> 0 | ... BA17: =IF(Entry!BA17="",0,IF(Entry!BA17=BA$3,1,0)) -> 0 | BL17: =IF(Entry!BL17="Yes",1,0) -> 0
A18: =Entry!A18 -> S12 | B18: =Entry!B18 -> TBD | H18: =IF(Entry!H18="",0,IF(Entry!H18=H$3,1,0)) -> 0 | I18: =IF(Entry!I18="",0,IF(Entry!I18=I$3,1,0)) -> 0 | J18: =IF(Entry!J18="",0,IF(Entry!J18=J$3,1,0)) -> 0 | K18: =IF(Entry!K18="",0,IF(Entry!K18=K$3,1,0)) -> 0 | L18: =IF(Entry!L18="",0,IF(Entry!L18=L$3,1,0)) -> 0 | M18: =IF(Entry!M18="",0,IF(Entry!M18=M$3,1,0)) -> 0 | N18: =IF(Entry!N18="",0,IF(Entry!N18=N$3,1,0)) -> 0 | O18: =IF(Entry!O18="",0,IF(Entry!O18=O$3,1,0)) -> 0 | ... BA18: =IF(Entry!BA18="",0,IF(Entry!BA18=BA$3,1,0)) -> 0 | BL18: =IF(Entry!BL18="Yes",1,0) -> 0
... A41: =Entry!A41 -> S35 | B41: =Entry!B41 -> TBD | H41: =IF(Entry!H41="",0,IF(Entry!H41=H$3,1,0)) -> 0 | I41: =IF(Entry!I41="",0,IF(Entry!I41=I$3,1,0)) -> 0 | J41: =IF(Entry!J41="",0,IF(Entry!J41=J$3,1,0)) -> 0 | K41: =IF(Entry!K41="",0,IF(Entry!K41=K$3,1,0)) -> 0 | L41: =IF(Entry!L41="",0,IF(Entry!L41=L$3,1,0)) -> 0 | M41: =IF(Entry!M41="",0,IF(Entry!M41=M$3,1,0)) -> 0 | N41: =IF(Entry!N41="",0,IF(Entry!N41=N$3,1,0)) -> 0 | O41: =IF(Entry!O41="",0,IF(Entry!O41=O$3,1,0)) -> 0 | ... BA41: =IF(Entry!BA41="",0,IF(Entry!BA41=BA$3,1,0)) -> 0 | BL41: =IF(Entry!BL41="Yes",1,0) -> 0
B43: Cohort accuracy, entered rows only | H43: =IF(SUM($BL$7:$BL$41)=0,"",SUMPRODUCT(H7:H41,$BL$7:$BL$41)/SUM($BL$7:$BL$41)) | I43: =IF(SUM($BL$7:$BL$41)=0,"",SUMPRODUCT(I7:I41,$BL$7:$BL$41)/SUM($BL$7:$BL$41)) | J43: =IF(SUM($BL$7:$BL$41)=0,"",SUMPRODUCT(J7:J41,$BL$7:$BL$41)/SUM($BL$7:$BL$41)) | K43: =IF(SUM($BL$7:$BL$41)=0,"",SUMPRODUCT(K7:K41,$BL$7:$BL$41)/SUM($BL$7:$BL$41)) | L43: =IF(SUM($BL$7:$BL$41)=0,"",SUMPRODUCT(L7:L41,$BL$7:$BL$41)/SUM($BL$7:$BL$41)) | M43: =IF(SUM($BL$7:$BL$41)=0,"",SUMPRODUCT(M7:M41,$BL$7:$BL$41)/SUM($BL$7:$BL$41)) | N43: =IF(SUM($BL$7:$BL$41)=0,"",SUMPRODUCT(N7:N41,$BL$7:$BL$41)/SUM($BL$7:$BL$41)) | O43: =IF(SUM($BL$7:$BL$41)=0,"",SUMPRODUCT(O7:O41,$BL$7:$BL$41)/SUM($BL$7:$BL$41)) | ... BA43: =IF(SUM($BL$7:$BL$41)=0,"",SUMPRODUCT(BA7:BA41,$BL$7:$BL$41)/SUM($BL$7:$BL$41))

Sheet Profile
B2: Student profiles for the one-to-one
B3: Cohort 2 | Week 0 | INTERNAL | one row per student, every value a formula; Pending until the Entry row is complete
D5: Section scores | K5: By tier | N5: Claimed band against scored band (gap = claimed minus scored) | X5: Calls
A6: Student ID | B6: Name | C6: Entered | D6: Python % | E6: SQL % | F6: Numbers % | G6: Case and scenario % | H6: Judgment % | I6: GenAI subset % | J6: Total % | K6: L1 % | L6: L2 % | M6: L3 % | N6: Python: claimed | O6: Python: gap | P6: SQL: claimed | Q6: SQL: gap | R6: Numbers: claimed | S6: Numbers: gap | T6: Business: claimed | U6: Business: gap | V6: LLM: claimed | W6: LLM: gap | X6: Mean gap | Y6: Python brush-up | Z6: SQL brush-up | AA6: Calibration | AB6: Note for the one-to-one
A7: =Entry!A7 -> S01 | B7: =Entry!B7 -> TBD | C7: =Entry!BL7 -> Pending | D7: =IF($C7<>"Yes","Pending",SUM(Scoring!H7:S7)/12) -> Pending | E7: =IF($C7<>"Yes","Pending",SUM(Scoring!T7:AA7)/8) -> Pending | F7: =IF($C7<>"Yes","Pending",SUM(Scoring!AB7:AI7)/8) -> Pending | G7: =IF($C7<>"Yes","Pending",SUM(Scoring!AJ7:AO7)/6) -> Pending | H7: =IF($C7<>"Yes","Pending",SUM(Scoring!AP7:BA7)/12) -> Pending | I7: =IF($C7<>"Yes","Pending",SUMPRODUCT((Scoring!$H$5:$AO$5=1)*Scoring!H7:AO7)/8) -> Pending | J7: =IF($C7<>"Yes","Pending",SUM(Scoring!H7:BA7)/46) -> Pending | K7: =IF($C7<>"Yes","Pending",SUMPRODUCT((Scoring!$H$4:$AO$4="L1")*Scoring!H7:AO7)/12) -> Pending | L7: =IF($C7<>"Yes","Pending",SUMPRODUCT((Scoring!$H$4:$AO$4="L2")*Scoring!H7:AO7)/15) -> Pending | M7: =IF($C7<>"Yes","Pending",SUMPRODUCT((Scoring!$H$4:$AO$4="L3")*Scoring!H7:AO7)/7) -> Pending | N7: =IF($C7<>"Yes","Pending",VALUE(Entry!C7)) -> Pending | O7: =IF($C7<>"Yes","Pending",N7-IF(D7>=Band4,4,IF(D7>=Band3,3,IF(D7>=Band2,2,1)))) -> Pending | P7: =IF($C7<>"Yes","Pending",VALUE(Entry!D7)) -> Pending | Q7: =IF($C7<>"Yes","Pending",P7-IF(E7>=Band4,4,IF(E7>=Band3,3,IF(E7>=Band2,2,1)))) -> Pending | R7: =IF($C7<>"Yes","Pending",VALUE(Entry!E7)) -> Pending | S7: =IF($C7<>"Yes","Pending",R7-IF(F7>=Band4,4,IF(F7>=Band3,3,IF(F7>=Band2,2,1)))) -> Pending | T7: =IF($C7<>"Yes","Pending",VALUE(Entry!F7)) -> Pending | U7: =IF($C7<>"Yes","Pending",T7-IF(G7>=Band4,4,IF(G7>=Band3,3,IF(G7>=Band2,2,1)))) -> Pending | V7: =IF($C7<>"Yes","Pending",VALUE(Entry!G7)) -> Pending | W7: =IF($C7<>"Yes","Pending",V7-IF(I7>=Band4,4,IF(I7>=Band3,3,IF(I7>=Band2,2,1)))) -> Pending | X7: =IF($C7<>"Yes","Pending",AVERAGE(O7,Q7,S7,U7,W7)) -> Pending | Y7: =IF($C7<>"Yes","Pending",IF(D7<PyCut,"Full","Light")) -> Pending | Z7: =IF($C7<>"Yes","Pending",IF(E7<SqlCut,"Full","Light")) -> Pending | AA7: =IF($C7<>"Yes","Pending",IF(X7>=1,"Over-claims",IF(X7<=-1,"Under-claims","Calibrated"))) -> Pending | AB7: =IF($C7<>"Yes","Pending","Python "&TEXT(D7,"0%")&", SQL "&TEXT(E7,"0%")&", numbers "&TEXT(F7,"0%")&"; L3 "&TEXT(M7,"0%")&"; "&AA7&"; "&IF(MIN(D7,E7,F7,G7,I7)>=Band4,"no weak area","weakest area: "&INDEX({"Python","SQL","numbers","case","LLM"},MATCH(MIN(D7,E7,F7,G7,I7),CHOOSE({1,2,3,4,5},D7,E7,F7,G7,I7),0)))) -> Pending
A8: =Entry!A8 -> S02 | B8: =Entry!B8 -> TBD | C8: =Entry!BL8 -> Pending | D8: =IF($C8<>"Yes","Pending",SUM(Scoring!H8:S8)/12) -> Pending | E8: =IF($C8<>"Yes","Pending",SUM(Scoring!T8:AA8)/8) -> Pending | F8: =IF($C8<>"Yes","Pending",SUM(Scoring!AB8:AI8)/8) -> Pending | G8: =IF($C8<>"Yes","Pending",SUM(Scoring!AJ8:AO8)/6) -> Pending | H8: =IF($C8<>"Yes","Pending",SUM(Scoring!AP8:BA8)/12) -> Pending | I8: =IF($C8<>"Yes","Pending",SUMPRODUCT((Scoring!$H$5:$AO$5=1)*Scoring!H8:AO8)/8) -> Pending | J8: =IF($C8<>"Yes","Pending",SUM(Scoring!H8:BA8)/46) -> Pending | K8: =IF($C8<>"Yes","Pending",SUMPRODUCT((Scoring!$H$4:$AO$4="L1")*Scoring!H8:AO8)/12) -> Pending | L8: =IF($C8<>"Yes","Pending",SUMPRODUCT((Scoring!$H$4:$AO$4="L2")*Scoring!H8:AO8)/15) -> Pending | M8: =IF($C8<>"Yes","Pending",SUMPRODUCT((Scoring!$H$4:$AO$4="L3")*Scoring!H8:AO8)/7) -> Pending | N8: =IF($C8<>"Yes","Pending",VALUE(Entry!C8)) -> Pending | O8: =IF($C8<>"Yes","Pending",N8-IF(D8>=Band4,4,IF(D8>=Band3,3,IF(D8>=Band2,2,1)))) -> Pending | P8: =IF($C8<>"Yes","Pending",VALUE(Entry!D8)) -> Pending | Q8: =IF($C8<>"Yes","Pending",P8-IF(E8>=Band4,4,IF(E8>=Band3,3,IF(E8>=Band2,2,1)))) -> Pending | R8: =IF($C8<>"Yes","Pending",VALUE(Entry!E8)) -> Pending | S8: =IF($C8<>"Yes","Pending",R8-IF(F8>=Band4,4,IF(F8>=Band3,3,IF(F8>=Band2,2,1)))) -> Pending | T8: =IF($C8<>"Yes","Pending",VALUE(Entry!F8)) -> Pending | U8: =IF($C8<>"Yes","Pending",T8-IF(G8>=Band4,4,IF(G8>=Band3,3,IF(G8>=Band2,2,1)))) -> Pending | V8: =IF($C8<>"Yes","Pending",VALUE(Entry!G8)) -> Pending | W8: =IF($C8<>"Yes","Pending",V8-IF(I8>=Band4,4,IF(I8>=Band3,3,IF(I8>=Band2,2,1)))) -> Pending | X8: =IF($C8<>"Yes","Pending",AVERAGE(O8,Q8,S8,U8,W8)) -> Pending | Y8: =IF($C8<>"Yes","Pending",IF(D8<PyCut,"Full","Light")) -> Pending | Z8: =IF($C8<>"Yes","Pending",IF(E8<SqlCut,"Full","Light")) -> Pending | AA8: =IF($C8<>"Yes","Pending",IF(X8>=1,"Over-claims",IF(X8<=-1,"Under-claims","Calibrated"))) -> Pending | AB8: =IF($C8<>"Yes","Pending","Python "&TEXT(D8,"0%")&", SQL "&TEXT(E8,"0%")&", numbers "&TEXT(F8,"0%")&"; L3 "&TEXT(M8,"0%")&"; "&AA8&"; "&IF(MIN(D8,E8,F8,G8,I8)>=Band4,"no weak area","weakest area: "&INDEX({"Python","SQL","numbers","case","LLM"},MATCH(MIN(D8,E8,F8,G8,I8),CHOOSE({1,2,3,4,5},D8,E8,F8,G8,I8),0)))) -> Pending
A9: =Entry!A9 -> S03 | B9: =Entry!B9 -> TBD | C9: =Entry!BL9 -> Pending | D9: =IF($C9<>"Yes","Pending",SUM(Scoring!H9:S9)/12) -> Pending | E9: =IF($C9<>"Yes","Pending",SUM(Scoring!T9:AA9)/8) -> Pending | F9: =IF($C9<>"Yes","Pending",SUM(Scoring!AB9:AI9)/8) -> Pending | G9: =IF($C9<>"Yes","Pending",SUM(Scoring!AJ9:AO9)/6) -> Pending | H9: =IF($C9<>"Yes","Pending",SUM(Scoring!AP9:BA9)/12) -> Pending | I9: =IF($C9<>"Yes","Pending",SUMPRODUCT((Scoring!$H$5:$AO$5=1)*Scoring!H9:AO9)/8) -> Pending | J9: =IF($C9<>"Yes","Pending",SUM(Scoring!H9:BA9)/46) -> Pending | K9: =IF($C9<>"Yes","Pending",SUMPRODUCT((Scoring!$H$4:$AO$4="L1")*Scoring!H9:AO9)/12) -> Pending | L9: =IF($C9<>"Yes","Pending",SUMPRODUCT((Scoring!$H$4:$AO$4="L2")*Scoring!H9:AO9)/15) -> Pending | M9: =IF($C9<>"Yes","Pending",SUMPRODUCT((Scoring!$H$4:$AO$4="L3")*Scoring!H9:AO9)/7) -> Pending | N9: =IF($C9<>"Yes","Pending",VALUE(Entry!C9)) -> Pending | O9: =IF($C9<>"Yes","Pending",N9-IF(D9>=Band4,4,IF(D9>=Band3,3,IF(D9>=Band2,2,1)))) -> Pending | P9: =IF($C9<>"Yes","Pending",VALUE(Entry!D9)) -> Pending | Q9: =IF($C9<>"Yes","Pending",P9-IF(E9>=Band4,4,IF(E9>=Band3,3,IF(E9>=Band2,2,1)))) -> Pending | R9: =IF($C9<>"Yes","Pending",VALUE(Entry!E9)) -> Pending | S9: =IF($C9<>"Yes","Pending",R9-IF(F9>=Band4,4,IF(F9>=Band3,3,IF(F9>=Band2,2,1)))) -> Pending | T9: =IF($C9<>"Yes","Pending",VALUE(Entry!F9)) -> Pending | U9: =IF($C9<>"Yes","Pending",T9-IF(G9>=Band4,4,IF(G9>=Band3,3,IF(G9>=Band2,2,1)))) -> Pending | V9: =IF($C9<>"Yes","Pending",VALUE(Entry!G9)) -> Pending | W9: =IF($C9<>"Yes","Pending",V9-IF(I9>=Band4,4,IF(I9>=Band3,3,IF(I9>=Band2,2,1)))) -> Pending | X9: =IF($C9<>"Yes","Pending",AVERAGE(O9,Q9,S9,U9,W9)) -> Pending | Y9: =IF($C9<>"Yes","Pending",IF(D9<PyCut,"Full","Light")) -> Pending | Z9: =IF($C9<>"Yes","Pending",IF(E9<SqlCut,"Full","Light")) -> Pending | AA9: =IF($C9<>"Yes","Pending",IF(X9>=1,"Over-claims",IF(X9<=-1,"Under-claims","Calibrated"))) -> Pending | AB9: =IF($C9<>"Yes","Pending","Python "&TEXT(D9,"0%")&", SQL "&TEXT(E9,"0%")&", numbers "&TEXT(F9,"0%")&"; L3 "&TEXT(M9,"0%")&"; "&AA9&"; "&IF(MIN(D9,E9,F9,G9,I9)>=Band4,"no weak area","weakest area: "&INDEX({"Python","SQL","numbers","case","LLM"},MATCH(MIN(D9,E9,F9,G9,I9),CHOOSE({1,2,3,4,5},D9,E9,F9,G9,I9),0)))) -> Pending
A10: =Entry!A10 -> S04 | B10: =Entry!B10 -> TBD | C10: =Entry!BL10 -> Pending | D10: =IF($C10<>"Yes","Pending",SUM(Scoring!H10:S10)/12) -> Pending | E10: =IF($C10<>"Yes","Pending",SUM(Scoring!T10:AA10)/8) -> Pending | F10: =IF($C10<>"Yes","Pending",SUM(Scoring!AB10:AI10)/8) -> Pending | G10: =IF($C10<>"Yes","Pending",SUM(Scoring!AJ10:AO10)/6) -> Pending | H10: =IF($C10<>"Yes","Pending",SUM(Scoring!AP10:BA10)/12) -> Pending | I10: =IF($C10<>"Yes","Pending",SUMPRODUCT((Scoring!$H$5:$AO$5=1)*Scoring!H10:AO10)/8) -> Pending | J10: =IF($C10<>"Yes","Pending",SUM(Scoring!H10:BA10)/46) -> Pending | K10: =IF($C10<>"Yes","Pending",SUMPRODUCT((Scoring!$H$4:$AO$4="L1")*Scoring!H10:AO10)/12) -> Pending | L10: =IF($C10<>"Yes","Pending",SUMPRODUCT((Scoring!$H$4:$AO$4="L2")*Scoring!H10:AO10)/15) -> Pending | M10: =IF($C10<>"Yes","Pending",SUMPRODUCT((Scoring!$H$4:$AO$4="L3")*Scoring!H10:AO10)/7) -> Pending | N10: =IF($C10<>"Yes","Pending",VALUE(Entry!C10)) -> Pending | O10: =IF($C10<>"Yes","Pending",N10-IF(D10>=Band4,4,IF(D10>=Band3,3,IF(D10>=Band2,2,1)))) -> Pending | P10: =IF($C10<>"Yes","Pending",VALUE(Entry!D10)) -> Pending | Q10: =IF($C10<>"Yes","Pending",P10-IF(E10>=Band4,4,IF(E10>=Band3,3,IF(E10>=Band2,2,1)))) -> Pending | R10: =IF($C10<>"Yes","Pending",VALUE(Entry!E10)) -> Pending | S10: =IF($C10<>"Yes","Pending",R10-IF(F10>=Band4,4,IF(F10>=Band3,3,IF(F10>=Band2,2,1)))) -> Pending | T10: =IF($C10<>"Yes","Pending",VALUE(Entry!F10)) -> Pending | U10: =IF($C10<>"Yes","Pending",T10-IF(G10>=Band4,4,IF(G10>=Band3,3,IF(G10>=Band2,2,1)))) -> Pending | V10: =IF($C10<>"Yes","Pending",VALUE(Entry!G10)) -> Pending | W10: =IF($C10<>"Yes","Pending",V10-IF(I10>=Band4,4,IF(I10>=Band3,3,IF(I10>=Band2,2,1)))) -> Pending | X10: =IF($C10<>"Yes","Pending",AVERAGE(O10,Q10,S10,U10,W10)) -> Pending | Y10: =IF($C10<>"Yes","Pending",IF(D10<PyCut,"Full","Light")) -> Pending | Z10: =IF($C10<>"Yes","Pending",IF(E10<SqlCut,"Full","Light")) -> Pending | AA10: =IF($C10<>"Yes","Pending",IF(X10>=1,"Over-claims",IF(X10<=-1,"Under-claims","Calibrated"))) -> Pending | AB10: =IF($C10<>"Yes","Pending","Python "&TEXT(D10,"0%")&", SQL "&TEXT(E10,"0%")&", numbers "&TEXT(F10,"0%")&"; L3 "&TEXT(M10,"0%")&"; "&AA10&"; "&IF(MIN(D10,E10,F10,G10,I10)>=Band4,"no weak area","weakest area: "&INDEX({"Python","SQL","numbers","case","LLM"},MATCH(MIN(D10,E10,F10,G10,I10),CHOOSE({1,2,3,4,5},D10,E10,F10,G10,I10),0)))) -> Pending
A11: =Entry!A11 -> S05 | B11: =Entry!B11 -> TBD | C11: =Entry!BL11 -> Pending | D11: =IF($C11<>"Yes","Pending",SUM(Scoring!H11:S11)/12) -> Pending | E11: =IF($C11<>"Yes","Pending",SUM(Scoring!T11:AA11)/8) -> Pending | F11: =IF($C11<>"Yes","Pending",SUM(Scoring!AB11:AI11)/8) -> Pending | G11: =IF($C11<>"Yes","Pending",SUM(Scoring!AJ11:AO11)/6) -> Pending | H11: =IF($C11<>"Yes","Pending",SUM(Scoring!AP11:BA11)/12) -> Pending | I11: =IF($C11<>"Yes","Pending",SUMPRODUCT((Scoring!$H$5:$AO$5=1)*Scoring!H11:AO11)/8) -> Pending | J11: =IF($C11<>"Yes","Pending",SUM(Scoring!H11:BA11)/46) -> Pending | K11: =IF($C11<>"Yes","Pending",SUMPRODUCT((Scoring!$H$4:$AO$4="L1")*Scoring!H11:AO11)/12) -> Pending | L11: =IF($C11<>"Yes","Pending",SUMPRODUCT((Scoring!$H$4:$AO$4="L2")*Scoring!H11:AO11)/15) -> Pending | M11: =IF($C11<>"Yes","Pending",SUMPRODUCT((Scoring!$H$4:$AO$4="L3")*Scoring!H11:AO11)/7) -> Pending | N11: =IF($C11<>"Yes","Pending",VALUE(Entry!C11)) -> Pending | O11: =IF($C11<>"Yes","Pending",N11-IF(D11>=Band4,4,IF(D11>=Band3,3,IF(D11>=Band2,2,1)))) -> Pending | P11: =IF($C11<>"Yes","Pending",VALUE(Entry!D11)) -> Pending | Q11: =IF($C11<>"Yes","Pending",P11-IF(E11>=Band4,4,IF(E11>=Band3,3,IF(E11>=Band2,2,1)))) -> Pending | R11: =IF($C11<>"Yes","Pending",VALUE(Entry!E11)) -> Pending | S11: =IF($C11<>"Yes","Pending",R11-IF(F11>=Band4,4,IF(F11>=Band3,3,IF(F11>=Band2,2,1)))) -> Pending | T11: =IF($C11<>"Yes","Pending",VALUE(Entry!F11)) -> Pending | U11: =IF($C11<>"Yes","Pending",T11-IF(G11>=Band4,4,IF(G11>=Band3,3,IF(G11>=Band2,2,1)))) -> Pending | V11: =IF($C11<>"Yes","Pending",VALUE(Entry!G11)) -> Pending | W11: =IF($C11<>"Yes","Pending",V11-IF(I11>=Band4,4,IF(I11>=Band3,3,IF(I11>=Band2,2,1)))) -> Pending | X11: =IF($C11<>"Yes","Pending",AVERAGE(O11,Q11,S11,U11,W11)) -> Pending | Y11: =IF($C11<>"Yes","Pending",IF(D11<PyCut,"Full","Light")) -> Pending | Z11: =IF($C11<>"Yes","Pending",IF(E11<SqlCut,"Full","Light")) -> Pending | AA11: =IF($C11<>"Yes","Pending",IF(X11>=1,"Over-claims",IF(X11<=-1,"Under-claims","Calibrated"))) -> Pending | AB11: =IF($C11<>"Yes","Pending","Python "&TEXT(D11,"0%")&", SQL "&TEXT(E11,"0%")&", numbers "&TEXT(F11,"0%")&"; L3 "&TEXT(M11,"0%")&"; "&AA11&"; "&IF(MIN(D11,E11,F11,G11,I11)>=Band4,"no weak area","weakest area: "&INDEX({"Python","SQL","numbers","case","LLM"},MATCH(MIN(D11,E11,F11,G11,I11),CHOOSE({1,2,3,4,5},D11,E11,F11,G11,I11),0)))) -> Pending
A12: =Entry!A12 -> S06 | B12: =Entry!B12 -> TBD | C12: =Entry!BL12 -> Pending | D12: =IF($C12<>"Yes","Pending",SUM(Scoring!H12:S12)/12) -> Pending | E12: =IF($C12<>"Yes","Pending",SUM(Scoring!T12:AA12)/8) -> Pending | F12: =IF($C12<>"Yes","Pending",SUM(Scoring!AB12:AI12)/8) -> Pending | G12: =IF($C12<>"Yes","Pending",SUM(Scoring!AJ12:AO12)/6) -> Pending | H12: =IF($C12<>"Yes","Pending",SUM(Scoring!AP12:BA12)/12) -> Pending | I12: =IF($C12<>"Yes","Pending",SUMPRODUCT((Scoring!$H$5:$AO$5=1)*Scoring!H12:AO12)/8) -> Pending | J12: =IF($C12<>"Yes","Pending",SUM(Scoring!H12:BA12)/46) -> Pending | K12: =IF($C12<>"Yes","Pending",SUMPRODUCT((Scoring!$H$4:$AO$4="L1")*Scoring!H12:AO12)/12) -> Pending | L12: =IF($C12<>"Yes","Pending",SUMPRODUCT((Scoring!$H$4:$AO$4="L2")*Scoring!H12:AO12)/15) -> Pending | M12: =IF($C12<>"Yes","Pending",SUMPRODUCT((Scoring!$H$4:$AO$4="L3")*Scoring!H12:AO12)/7) -> Pending | N12: =IF($C12<>"Yes","Pending",VALUE(Entry!C12)) -> Pending | O12: =IF($C12<>"Yes","Pending",N12-IF(D12>=Band4,4,IF(D12>=Band3,3,IF(D12>=Band2,2,1)))) -> Pending | P12: =IF($C12<>"Yes","Pending",VALUE(Entry!D12)) -> Pending | Q12: =IF($C12<>"Yes","Pending",P12-IF(E12>=Band4,4,IF(E12>=Band3,3,IF(E12>=Band2,2,1)))) -> Pending | R12: =IF($C12<>"Yes","Pending",VALUE(Entry!E12)) -> Pending | S12: =IF($C12<>"Yes","Pending",R12-IF(F12>=Band4,4,IF(F12>=Band3,3,IF(F12>=Band2,2,1)))) -> Pending | T12: =IF($C12<>"Yes","Pending",VALUE(Entry!F12)) -> Pending | U12: =IF($C12<>"Yes","Pending",T12-IF(G12>=Band4,4,IF(G12>=Band3,3,IF(G12>=Band2,2,1)))) -> Pending | V12: =IF($C12<>"Yes","Pending",VALUE(Entry!G12)) -> Pending | W12: =IF($C12<>"Yes","Pending",V12-IF(I12>=Band4,4,IF(I12>=Band3,3,IF(I12>=Band2,2,1)))) -> Pending | X12: =IF($C12<>"Yes","Pending",AVERAGE(O12,Q12,S12,U12,W12)) -> Pending | Y12: =IF($C12<>"Yes","Pending",IF(D12<PyCut,"Full","Light")) -> Pending | Z12: =IF($C12<>"Yes","Pending",IF(E12<SqlCut,"Full","Light")) -> Pending | AA12: =IF($C12<>"Yes","Pending",IF(X12>=1,"Over-claims",IF(X12<=-1,"Under-claims","Calibrated"))) -> Pending | AB12: =IF($C12<>"Yes","Pending","Python "&TEXT(D12,"0%")&", SQL "&TEXT(E12,"0%")&", numbers "&TEXT(F12,"0%")&"; L3 "&TEXT(M12,"0%")&"; "&AA12&"; "&IF(MIN(D12,E12,F12,G12,I12)>=Band4,"no weak area","weakest area: "&INDEX({"Python","SQL","numbers","case","LLM"},MATCH(MIN(D12,E12,F12,G12,I12),CHOOSE({1,2,3,4,5},D12,E12,F12,G12,I12),0)))) -> Pending
A13: =Entry!A13 -> S07 | B13: =Entry!B13 -> TBD | C13: =Entry!BL13 -> Pending | D13: =IF($C13<>"Yes","Pending",SUM(Scoring!H13:S13)/12) -> Pending | E13: =IF($C13<>"Yes","Pending",SUM(Scoring!T13:AA13)/8) -> Pending | F13: =IF($C13<>"Yes","Pending",SUM(Scoring!AB13:AI13)/8) -> Pending | G13: =IF($C13<>"Yes","Pending",SUM(Scoring!AJ13:AO13)/6) -> Pending | H13: =IF($C13<>"Yes","Pending",SUM(Scoring!AP13:BA13)/12) -> Pending | I13: =IF($C13<>"Yes","Pending",SUMPRODUCT((Scoring!$H$5:$AO$5=1)*Scoring!H13:AO13)/8) -> Pending | J13: =IF($C13<>"Yes","Pending",SUM(Scoring!H13:BA13)/46) -> Pending | K13: =IF($C13<>"Yes","Pending",SUMPRODUCT((Scoring!$H$4:$AO$4="L1")*Scoring!H13:AO13)/12) -> Pending | L13: =IF($C13<>"Yes","Pending",SUMPRODUCT((Scoring!$H$4:$AO$4="L2")*Scoring!H13:AO13)/15) -> Pending | M13: =IF($C13<>"Yes","Pending",SUMPRODUCT((Scoring!$H$4:$AO$4="L3")*Scoring!H13:AO13)/7) -> Pending | N13: =IF($C13<>"Yes","Pending",VALUE(Entry!C13)) -> Pending | O13: =IF($C13<>"Yes","Pending",N13-IF(D13>=Band4,4,IF(D13>=Band3,3,IF(D13>=Band2,2,1)))) -> Pending | P13: =IF($C13<>"Yes","Pending",VALUE(Entry!D13)) -> Pending | Q13: =IF($C13<>"Yes","Pending",P13-IF(E13>=Band4,4,IF(E13>=Band3,3,IF(E13>=Band2,2,1)))) -> Pending | R13: =IF($C13<>"Yes","Pending",VALUE(Entry!E13)) -> Pending | S13: =IF($C13<>"Yes","Pending",R13-IF(F13>=Band4,4,IF(F13>=Band3,3,IF(F13>=Band2,2,1)))) -> Pending | T13: =IF($C13<>"Yes","Pending",VALUE(Entry!F13)) -> Pending | U13: =IF($C13<>"Yes","Pending",T13-IF(G13>=Band4,4,IF(G13>=Band3,3,IF(G13>=Band2,2,1)))) -> Pending | V13: =IF($C13<>"Yes","Pending",VALUE(Entry!G13)) -> Pending | W13: =IF($C13<>"Yes","Pending",V13-IF(I13>=Band4,4,IF(I13>=Band3,3,IF(I13>=Band2,2,1)))) -> Pending | X13: =IF($C13<>"Yes","Pending",AVERAGE(O13,Q13,S13,U13,W13)) -> Pending | Y13: =IF($C13<>"Yes","Pending",IF(D13<PyCut,"Full","Light")) -> Pending | Z13: =IF($C13<>"Yes","Pending",IF(E13<SqlCut,"Full","Light")) -> Pending | AA13: =IF($C13<>"Yes","Pending",IF(X13>=1,"Over-claims",IF(X13<=-1,"Under-claims","Calibrated"))) -> Pending | AB13: =IF($C13<>"Yes","Pending","Python "&TEXT(D13,"0%")&", SQL "&TEXT(E13,"0%")&", numbers "&TEXT(F13,"0%")&"; L3 "&TEXT(M13,"0%")&"; "&AA13&"; "&IF(MIN(D13,E13,F13,G13,I13)>=Band4,"no weak area","weakest area: "&INDEX({"Python","SQL","numbers","case","LLM"},MATCH(MIN(D13,E13,F13,G13,I13),CHOOSE({1,2,3,4,5},D13,E13,F13,G13,I13),0)))) -> Pending
A14: =Entry!A14 -> S08 | B14: =Entry!B14 -> TBD | C14: =Entry!BL14 -> Pending | D14: =IF($C14<>"Yes","Pending",SUM(Scoring!H14:S14)/12) -> Pending | E14: =IF($C14<>"Yes","Pending",SUM(Scoring!T14:AA14)/8) -> Pending | F14: =IF($C14<>"Yes","Pending",SUM(Scoring!AB14:AI14)/8) -> Pending | G14: =IF($C14<>"Yes","Pending",SUM(Scoring!AJ14:AO14)/6) -> Pending | H14: =IF($C14<>"Yes","Pending",SUM(Scoring!AP14:BA14)/12) -> Pending | I14: =IF($C14<>"Yes","Pending",SUMPRODUCT((Scoring!$H$5:$AO$5=1)*Scoring!H14:AO14)/8) -> Pending | J14: =IF($C14<>"Yes","Pending",SUM(Scoring!H14:BA14)/46) -> Pending | K14: =IF($C14<>"Yes","Pending",SUMPRODUCT((Scoring!$H$4:$AO$4="L1")*Scoring!H14:AO14)/12) -> Pending | L14: =IF($C14<>"Yes","Pending",SUMPRODUCT((Scoring!$H$4:$AO$4="L2")*Scoring!H14:AO14)/15) -> Pending | M14: =IF($C14<>"Yes","Pending",SUMPRODUCT((Scoring!$H$4:$AO$4="L3")*Scoring!H14:AO14)/7) -> Pending | N14: =IF($C14<>"Yes","Pending",VALUE(Entry!C14)) -> Pending | O14: =IF($C14<>"Yes","Pending",N14-IF(D14>=Band4,4,IF(D14>=Band3,3,IF(D14>=Band2,2,1)))) -> Pending | P14: =IF($C14<>"Yes","Pending",VALUE(Entry!D14)) -> Pending | Q14: =IF($C14<>"Yes","Pending",P14-IF(E14>=Band4,4,IF(E14>=Band3,3,IF(E14>=Band2,2,1)))) -> Pending | R14: =IF($C14<>"Yes","Pending",VALUE(Entry!E14)) -> Pending | S14: =IF($C14<>"Yes","Pending",R14-IF(F14>=Band4,4,IF(F14>=Band3,3,IF(F14>=Band2,2,1)))) -> Pending | T14: =IF($C14<>"Yes","Pending",VALUE(Entry!F14)) -> Pending | U14: =IF($C14<>"Yes","Pending",T14-IF(G14>=Band4,4,IF(G14>=Band3,3,IF(G14>=Band2,2,1)))) -> Pending | V14: =IF($C14<>"Yes","Pending",VALUE(Entry!G14)) -> Pending | W14: =IF($C14<>"Yes","Pending",V14-IF(I14>=Band4,4,IF(I14>=Band3,3,IF(I14>=Band2,2,1)))) -> Pending | X14: =IF($C14<>"Yes","Pending",AVERAGE(O14,Q14,S14,U14,W14)) -> Pending | Y14: =IF($C14<>"Yes","Pending",IF(D14<PyCut,"Full","Light")) -> Pending | Z14: =IF($C14<>"Yes","Pending",IF(E14<SqlCut,"Full","Light")) -> Pending | AA14: =IF($C14<>"Yes","Pending",IF(X14>=1,"Over-claims",IF(X14<=-1,"Under-claims","Calibrated"))) -> Pending | AB14: =IF($C14<>"Yes","Pending","Python "&TEXT(D14,"0%")&", SQL "&TEXT(E14,"0%")&", numbers "&TEXT(F14,"0%")&"; L3 "&TEXT(M14,"0%")&"; "&AA14&"; "&IF(MIN(D14,E14,F14,G14,I14)>=Band4,"no weak area","weakest area: "&INDEX({"Python","SQL","numbers","case","LLM"},MATCH(MIN(D14,E14,F14,G14,I14),CHOOSE({1,2,3,4,5},D14,E14,F14,G14,I14),0)))) -> Pending
