Workbook

Sheet Overview
A2: IIT Gandhinagar faculty sessions · PG Diploma in AI-ML and Agentic AI Engineering · Cohort 2
A3: A proposal for the faculty's teaching hours in Cohort 2: what each session covers, when it runs, where it sits in the curriculum and what the learners will already know. Every session is tentative until IIT Gandhinagar confirms the faculty member and the date. Version 2, 21 September 2026.
A5: =COUNTIF(Sessions!$D$6:$D$49,">0") -> 30 | C5: =SUM(Sessions!$D$6:$D$49)/60 -> 60 | D5: =$C$10-7 -> 46293 | E5: =$C$10 -> 46300 | F5: =MIN(Sessions!$C$6:$C$49) -> 46307 | G5: =MAX(Sessions!$C$6:$C$49) -> 46374 | I5: =COUNTIF(Sessions!$N$6:$N$49,"Confirmed") -> 0
A6: Faculty sessions | C6: Faculty hours | D6: Week 0 begins (orientation and baseline week) | E6: Teaching begins (Week 1) | F6: First faculty session (Week 2) | G6: Last faculty session | I6: Sessions confirmed so far
A8: Calendar inputs, and what we request from IIT Gandhinagar
A10: Input | B10: Teaching Week 1 begins on | C10: 46300 | D10: Request 1. Please name a faculty lead for each of the seven weeks in the yellow column of the table below. One faculty member for a whole week is the ideal, so that the week reads as one short course.
A11: Input | B11: Session length (minutes) | C11: 120 | D11: Request 2. On the Sessions tab, please mark each session as Confirmed or Change requested, and add a remark where a date, a topic or a reference should change.
A12: Input | B12: Faculty hours committed | C12: 60 | D12: =IF($H$28=$C$12,"Check: the plan below reconciles to the "&$C$12&" committed faculty hours.","Check: the plan below differs by "&TEXT($H$28-$C$12,"0")&" hours from the "&$C$12&" committed.") -> Check: the plan below reconciles to the 60 committed faculty hours.
A14: Design of the faculty sessions
A15: 1. | B15: Each session runs for 120 minutes and follows that day's applied session, which an industry trainer teaches on the same topic through a running business case.
A16: 2. | B16: The faculty session then carries the theory beneath the method the learners have just used: the derivation, the mathematics and the conditions under which the method holds. Theory therefore arrives once the learners have a reason to want it.
A17: 3. | B17: Sessions run on consecutive teaching days within a week, in seven weeks between Week 2 and Week 11. From Week 13 the programme moves to agentic systems, deployment and the capstone, which are taught by industry practitioners.
A19: The seven weeks, each as one short course
A20: Week | B20: Dates (Mon to Sat) | C20: Module (credits) | D20: Industry-led applied track that week | E20: Faculty short course and its sessions | F20: Suggested faculty expertise | G20: Sessions | H20: Hours | I20: Faculty lead (IIT Gandhinagar to complete)
A21: 2 | B21: =TEXT(Overview!$C$10+7*(A21-1),"DD MMM")&" to "&TEXT(Overview!$C$10+7*(A21-1)+5,"DD MMM YYYY") -> 12 Oct to 17 Oct 2026 | C21: Module 1: Foundations of AI and Data (3 credits). | D21: Data manipulation: SQL joins and window functions, pandas, Excel for analysts | E21: Statistical inference 1. Sampling distributions and the central limit theorem 2. Confidence intervals and the t-test family 3. Errors, power and sample size; multiple comparisons | F21: Statistics | G21: =COUNTIF(Sessions!$B$6:$B$49,A21) -> 3 | H21: =SUMIF(Sessions!$B$6:$B$49,A21,Sessions!$D$6:$D$49)/60 -> 6 | I21: To be confirmed
A22: 4 | B22: =TEXT(Overview!$C$10+7*(A22-1),"DD MMM")&" to "&TEXT(Overview!$C$10+7*(A22-1)+5,"DD MMM YYYY") -> 26 Oct to 31 Oct 2026 | C22: Module 2: Applied Machine Learning (4 credits). | D22: Business and data analyst craft: metric design, market basket analysis, cohort and funnel analysis, forecasting baselines | E22: Statistical foundations of business analytics 1. Design of experiments 2. Association rule mining 3. Time-to-event analysis 4. Time series foundations | F22: Statistics, data mining or time series analysis | G22: =COUNTIF(Sessions!$B$6:$B$49,A22) -> 4 | H22: =SUMIF(Sessions!$B$6:$B$49,A22,Sessions!$D$6:$D$49)/60 -> 8 | I22: To be confirmed
A23: 5 | B23: =TEXT(Overview!$C$10+7*(A23-1),"DD MMM")&" to "&TEXT(Overview!$C$10+7*(A23-1)+5,"DD MMM YYYY") -> 02 Nov to 07 Nov 2026 | C23: Module 2: Applied Machine Learning (4 credits). | D23: Machine learning core in scikit-learn: regression and classification, metrics under class imbalance, feature engineering and leakage, overfitting and regularisation, model justification | E23: Mathematical foundations of machine learning 1. Linear and logistic regression from first principles 2. Classifier evaluation 3. Multicollinearity, identifiability, and explanatory against predictive modelling 4. The bias-variance trade-off, regularisation and resampling 5. Decision trees, bagging, random forests and gradient boosting | F23: Machine learning or statistical learning | G23: =COUNTIF(Sessions!$B$6:$B$49,A23) -> 5 | H23: =SUMIF(Sessions!$B$6:$B$49,A23,Sessions!$D$6:$D$49)/60 -> 10 | I23: To be confirmed
A24: 7 | B24: =TEXT(Overview!$C$10+7*(A24-1),"DD MMM")&" to "&TEXT(Overview!$C$10+7*(A24-1)+5,"DD MMM YYYY") -> 16 Nov to 21 Nov 2026 | C24: Module 3: Deep Learning and Neural Networks (4 credits). Friday's session belongs to Module 4: Natural Language Processing. | D24: Deep learning essentials over four days (the network, learning, training diagnostics, sequence models), then tokenization on Friday | E24: Deep learning from first principles 1. Feed-forward networks 2. Backpropagation derived, and gradient-based optimisation 3. Vanishing and exploding gradients, initialisation, normalisation and regularisation in deep networks 4. Recurrent networks, LSTM and the path to attention 5. Subword tokenization and the evaluation of language models | F24: Deep learning | G24: =COUNTIF(Sessions!$B$6:$B$49,A24) -> 5 | H24: =SUMIF(Sessions!$B$6:$B$49,A24,Sessions!$D$6:$D$49)/60 -> 10 | I24: To be confirmed
A25: 8 | B25: =TEXT(Overview!$C$10+7*(A25-1),"DD MMM")&" to "&TEXT(Overview!$C$10+7*(A25-1)+5,"DD MMM YYYY") -> 23 Nov to 28 Nov 2026 | C25: Module 4: Natural Language Processing (3 credits). | D25: Transformers and LLM internals: attention and the transformer block, embeddings with BERT against GPT, decoding controls, context windows and token economics | E25: The mathematics of transformers 1. Scaled dot-product attention and the transformer block 2. Word and sentence embeddings 3. Decoding as search 4. Positional encodings, long-context attention and scaling laws | F25: Natural language processing | G25: =COUNTIF(Sessions!$B$6:$B$49,A25) -> 4 | H25: =SUMIF(Sessions!$B$6:$B$49,A25,Sessions!$D$6:$D$49)/60 -> 8 | I25: To be confirmed
A26: 10 | B26: =TEXT(Overview!$C$10+7*(A26-1),"DD MMM")&" to "&TEXT(Overview!$C$10+7*(A26-1)+5,"DD MMM YYYY") -> 07 Dec to 12 Dec 2026 | C26: Module 5: Generative AI Foundations (3 credits). | D26: Generative AI applied: prompting techniques compared, structured outputs, function calling, prompt evaluation, production cost and latency | E26: Theory of applied generative AI 1. From pretraining to instruction following 2. Constrained decoding 3. The statistics of model evaluation 4. The arithmetic of LLM inference | F26: Natural language processing or machine learning systems | G26: =COUNTIF(Sessions!$B$6:$B$49,A26) -> 4 | H26: =SUMIF(Sessions!$B$6:$B$49,A26,Sessions!$D$6:$D$49)/60 -> 8 | I26: To be confirmed
A27: 11 | B27: =TEXT(Overview!$C$10+7*(A27-1),"DD MMM")&" to "&TEXT(Overview!$C$10+7*(A27-1)+5,"DD MMM YYYY") -> 14 Dec to 19 Dec 2026 | C27: Module 6: Applied Generative AI (3 credits). | D27: Retrieval-augmented generation end to end: chunking, embedding models and vector stores, hybrid search and reranking, evaluation, grounding and citations | E27: Information retrieval 1. Classical information retrieval 2. Approximate nearest-neighbour search 3. Learning to rank, neural rerankers and rank fusion 4. Evaluating retrieval and retrieval-augmented generation 5. Long-context behaviour, grounding and hallucination in language models | F27: Information retrieval | G27: =COUNTIF(Sessions!$B$6:$B$49,A27) -> 5 | H27: =SUMIF(Sessions!$B$6:$B$49,A27,Sessions!$D$6:$D$49)/60 -> 10 | I27: To be confirmed
A28: Total | G28: =SUM(G21:G27) -> 30 | H28: =SUM(H21:H27) -> 60 | I28: Every session is tentative
A30: The programme at a glance: where the seven weeks sit in the twenty
A31: Week | B31: Dates (Mon to Sat) | C31: Module | D31: Focus of the week | E31: Assessment in the week | F31: Public holiday in the week | G31: Faculty sessions | H31: Faculty hours | I31: Taught by
A32: 0 | B32: =TEXT(Overview!$C$10+7*(A32-1),"DD MMM")&" to "&TEXT(Overview!$C$10+7*(A32-1)+5,"DD MMM YYYY") -> 28 Sep to 03 Oct 2026 | C32: Before Module 1 | D32: Orientation and baseline week: diagnostic by topic, Python and SQL refreshers, problem framing | E32: None | F32: Fri 02 Oct, Gandhi Jayanti | G32: =COUNTIF(Sessions!$B$6:$B$49,A32) -> 0 | H32: =SUMIF(Sessions!$B$6:$B$49,A32,Sessions!$D$6:$D$49)/60 -> 0 | I32: Programme team
A33: 1 | B33: =TEXT(Overview!$C$10+7*(A33-1),"DD MMM")&" to "&TEXT(Overview!$C$10+7*(A33-1)+5,"DD MMM YYYY") -> 05 Oct to 10 Oct 2026 | C33: Module 1: Foundations of AI and Data | D33: Data analysis foundations | E33: None | F33: None | G33: =COUNTIF(Sessions!$B$6:$B$49,A33) -> 0 | H33: =SUMIF(Sessions!$B$6:$B$49,A33,Sessions!$D$6:$D$49)/60 -> 0 | I33: Industry practitioner
A34: 2 | B34: =TEXT(Overview!$C$10+7*(A34-1),"DD MMM")&" to "&TEXT(Overview!$C$10+7*(A34-1)+5,"DD MMM YYYY") -> 12 Oct to 17 Oct 2026 | C34: Module 1: Foundations of AI and Data | D34: Data manipulation at depth: SQL, pandas, Excel | E34: None | F34: None | G34: =COUNTIF(Sessions!$B$6:$B$49,A34) -> 3 | H34: =SUMIF(Sessions!$B$6:$B$49,A34,Sessions!$D$6:$D$49)/60 -> 6 | I34: Industry trainer, with IIT Gandhinagar faculty on the theory
A35: 3 | B35: =TEXT(Overview!$C$10+7*(A35-1),"DD MMM")&" to "&TEXT(Overview!$C$10+7*(A35-1)+5,"DD MMM YYYY") -> 19 Oct to 24 Oct 2026 | C35: Module 1: Foundations of AI and Data | D35: Build week 1: data to insight (health-care operations data) | E35: Mini project 1, mock interview 1, business group discussion 1 | F35: Tue 20 Oct, Dussehra | G35: =COUNTIF(Sessions!$B$6:$B$49,A35) -> 0 | H35: =SUMIF(Sessions!$B$6:$B$49,A35,Sessions!$D$6:$D$49)/60 -> 0 | I35: Programme team and an industry panel; no new teaching
A36: 4 | B36: =TEXT(Overview!$C$10+7*(A36-1),"DD MMM")&" to "&TEXT(Overview!$C$10+7*(A36-1)+5,"DD MMM YYYY") -> 26 Oct to 31 Oct 2026 | C36: Module 2: Applied Machine Learning | D36: Business and data analyst craft | E36: None | F36: None | G36: =COUNTIF(Sessions!$B$6:$B$49,A36) -> 4 | H36: =SUMIF(Sessions!$B$6:$B$49,A36,Sessions!$D$6:$D$49)/60 -> 8 | I36: Industry trainer, with IIT Gandhinagar faculty on the theory
A37: 5 | B37: =TEXT(Overview!$C$10+7*(A37-1),"DD MMM")&" to "&TEXT(Overview!$C$10+7*(A37-1)+5,"DD MMM YYYY") -> 02 Nov to 07 Nov 2026 | C37: Module 2: Applied Machine Learning | D37: Machine learning core | E37: Major Exam 1 | F37: None | G37: =COUNTIF(Sessions!$B$6:$B$49,A37) -> 5 | H37: =SUMIF(Sessions!$B$6:$B$49,A37,Sessions!$D$6:$D$49)/60 -> 10 | I37: Industry trainer, with IIT Gandhinagar faculty on the theory
A38: 6 | B38: =TEXT(Overview!$C$10+7*(A38-1),"DD MMM")&" to "&TEXT(Overview!$C$10+7*(A38-1)+5,"DD MMM YYYY") -> 09 Nov to 14 Nov 2026 | C38: Module 2: Applied Machine Learning | D38: Build week 2: machine learning (lending data) | E38: Mini project 2, mock interview 2, business group discussion 2 | F38: Mon 09 Nov, the day after Diwali | G38: =COUNTIF(Sessions!$B$6:$B$49,A38) -> 0 | H38: =SUMIF(Sessions!$B$6:$B$49,A38,Sessions!$D$6:$D$49)/60 -> 0 | I38: Programme team and an industry panel; no new teaching
A39: 7 | B39: =TEXT(Overview!$C$10+7*(A39-1),"DD MMM")&" to "&TEXT(Overview!$C$10+7*(A39-1)+5,"DD MMM YYYY") -> 16 Nov to 21 Nov 2026 | C39: Module 3: Deep Learning and Neural Networks | D39: Deep learning essentials, then tokenization | E39: None | F39: None | G39: =COUNTIF(Sessions!$B$6:$B$49,A39) -> 5 | H39: =SUMIF(Sessions!$B$6:$B$49,A39,Sessions!$D$6:$D$49)/60 -> 10 | I39: Industry trainer, with IIT Gandhinagar faculty on the theory
A40: 8 | B40: =TEXT(Overview!$C$10+7*(A40-1),"DD MMM")&" to "&TEXT(Overview!$C$10+7*(A40-1)+5,"DD MMM YYYY") -> 23 Nov to 28 Nov 2026 | C40: Module 4: Natural Language Processing | D40: Transformers and LLM internals | E40: None | F40: Tue 24 Nov, Guru Nanak Jayanti | G40: =COUNTIF(Sessions!$B$6:$B$49,A40) -> 4 | H40: =SUMIF(Sessions!$B$6:$B$49,A40,Sessions!$D$6:$D$49)/60 -> 8 | I40: Industry trainer, with IIT Gandhinagar faculty on the theory
A41: 9 | B41: =TEXT(Overview!$C$10+7*(A41-1),"DD MMM")&" to "&TEXT(Overview!$C$10+7*(A41-1)+5,"DD MMM YYYY") -> 30 Nov to 05 Dec 2026 | C41: Module 3: Deep Learning and Neural Networks | D41: Build week 3: deep learning and LLMs (telecom support text) | E41: Mini project 3, mock interview 3, business group discussion 3 | F41: None | G41: =COUNTIF(Sessions!$B$6:$B$49,A41) -> 0 | H41: =SUMIF(Sessions!$B$6:$B$49,A41,Sessions!$D$6:$D$49)/60 -> 0 | I41: Programme team and an industry panel; no new teaching
A42: 10 | B42: =TEXT(Overview!$C$10+7*(A42-1),"DD MMM")&" to "&TEXT(Overview!$C$10+7*(A42-1)+5,"DD MMM YYYY") -> 07 Dec to 12 Dec 2026 | C42: Module 5: Generative AI Foundations | D42: Generative AI applied | E42: Major Exam 2 | F42: None | G42: =COUNTIF(Sessions!$B$6:$B$49,A42) -> 4 | H42: =SUMIF(Sessions!$B$6:$B$49,A42,Sessions!$D$6:$D$49)/60 -> 8 | I42: Industry trainer, with IIT Gandhinagar faculty on the theory
A43: 11 | B43: =TEXT(Overview!$C$10+7*(A43-1),"DD MMM")&" to "&TEXT(Overview!$C$10+7*(A43-1)+5,"DD MMM YYYY") -> 14 Dec to 19 Dec 2026 | C43: Module 6: Applied Generative AI | D43: Retrieval-augmented generation | E43: None | F43: None | G43: =COUNTIF(Sessions!$B$6:$B$49,A43) -> 5 | H43: =SUMIF(Sessions!$B$6:$B$49,A43,Sessions!$D$6:$D$49)/60 -> 10 | I43: Industry trainer, with IIT Gandhinagar faculty on the theory
... A52: 20 | B52: =TEXT(Overview!$C$10+7*(A52-1),"DD MMM")&" to "&TEXT(Overview!$C$10+7*(A52-1)+5,"DD MMM YYYY") -> 15 Feb to 20 Feb 2027 | C52: Module 10: Capstone Project | D52: Capstone demonstration, panel defence and closure | E52: Capstone project | F52: None | G52: =COUNTIF(Sessions!$B$6:$B$49,A52) -> 0 | H52: =SUMIF(Sessions!$B$6:$B$49,A52,Sessions!$D$6:$D$49)/60 -> 0 | I52: Mentors and an industry panel
A54: Shading: bronze tint marks the seven weeks that carry faculty sessions; grey marks build weeks, in which learners complete a graded project and no new content is taught. Blue text on yellow marks a cell to be completed or an input. The running business case used in the applied sessions, Kalpa Group, is fictional: a retailer with sister businesses in finance, logistics, health care and telecom. Any resemblance to a real company is coincidental.

Sheet Sessions
A2: IIT Gandhinagar faculty sessions · session plan · every session is tentative until confirmed
A3: One row per session, read from left to right: what the session teaches, where it sits in the programme, what learners arrive with, what is reserved for later, and what to prepare from. Reference numbers (R001 and so on) resolve to clickable links on the Reference library tab. The three yellow columns are for IIT Gandhinagar to complete. Dates follow from the start date on the Overview tab.
A4: SESSION | E4: WHAT THE SESSION TEACHES | I4: CONTEXT AND SCOPE | L4: PREPARATION | M4: TO BE COMPLETED BY IIT GANDHINAGAR
A5: Session | B5: Week | C5: Date | D5: Duration (min) | E5: Module and subject | F5: Session topic | G5: Subtopics | H5: Learning outcomes | I5: Place in the programme | J5: Prior coverage | K5: Reserved for later sessions | L5: Suggested references | M5: Faculty member | N5: Status | O5: Remarks
A6: ="WEEK 2 · "&TEXT(Overview!$C$10+7*(2-1),"DD MMM")&" to "&TEXT(Overview!$C$10+7*(2-1)+5,"DD MMM YYYY")&" · Module 1: Foundations of AI and Data · Faculty short course: Statistical inference"&" · Industry-led track this week: Data manipulation: SQL joins and window functions, pandas, Excel for analysts" -> WEEK 2 · 12 Oct to 17 Oct 2026 · Module 1: Foundations of AI and Data · Faculty short course: Statistical inference · Industry-led track this week: Data manipulation: SQL joins and window functions, pandas, Excel for analysts
A7: Learner progress before this week: One week of data analysis in Python on a retail dataset: descriptive statistics, a revenue driver tree, data profiling and cleaning with reconciliation, a permutation test with the p-value stated correctly, correlation against causation with a confounder, and a one-page note for a business stakeholder. No formula-based inference has been taught. The industry-led track this week is SQL and pandas, so these three sessions run alongside it and complete the inference that Week 1 opened.
A8: W2-1 | B8: 2 | C8: =Overview!$C$10+7*(B8-1)+0 -> 46307 | D8: =Overview!$C$11 -> 120 | E8: Module 1: Foundations of AI and Data Subject: Statistical inference | F8: Sampling distributions and the central limit theorem | G8: • Random variables, expectation and variance, as far as the session needs them • The sampling distribution of a statistic, linked to the simulated distribution learners built in Week 1 • The standard error of a mean and of a proportion • The central limit theorem: statement, conditions and a simulation • Why small samples give wide sampling distributions | H8: Learners can define a standard error, explain why sample means are approximately normal, and explain why an estimate from a very small sample is unreliable. | I8: Session 1 of 3 in the Week 2 short course. The same-day applied session (SQL foundations) is unrelated in content; the link is to Week 1, where inference was introduced through simulation only. Leads to W2-2 and W2-3, and to the statistics component of Major Exam 1 (Week 5). | J8: Week 1: descriptive statistics in Python; a permutation test run by hand and then in code with 5,000 label shuffles; the p-value stated as the share of chance-only outcomes at least as extreme as the observed one; the confidence interval named and never constructed. No formula-based inference has been taught. | K8: Confidence intervals and the t-test family (W2-2); power, sample size and multiple comparisons (W2-3). | L8: R001 · Diez, Çetinkaya-Rundel and Barr, OpenIntro Statistics, 4th ed. (Ch. 5, Foundations for inference) R002 · Poldrack, Statistical Thinking for the 21st Century (sampling and the central limit theorem) R003 · Wasserman (2004), All of Statistics (Ch. 5 and 6) R004 · MIT OpenCourseWare 18.650, Statistics for Applications (sessions 1 to 3) R005 · Seeing Theory (Brown University), interactive visualisations (Probability Distributions; Frequentist Inference) R006 · 3Blue1Brown, But what is the Central Limit Theorem? | M8: To be confirmed | N8: Tentative | O8: None yet
A9: W2-2 | B9: 2 | C9: =Overview!$C$10+7*(B9-1)+1 -> 46308 | D9: =Overview!$C$11 -> 120 | E9: Module 1: Foundations of AI and Data Subject: Statistical inference | F9: Confidence intervals and the t-test family | G9: • A confidence interval for a mean and for a proportion: construction and correct interpretation • The t distribution, and why it replaces the normal for small samples • One-sample, two-sample (Welch) and paired t-tests • The chi-square test of independence, at recognition depth • Choosing a test from the study design and the type of data • The interval and the test as two views of the same evidence | H9: Learners can construct and interpret a 95 percent confidence interval, select an appropriate test for a given comparison, and explain what an interval adds to a p-value. | I9: Session 2 of 3. The same-day applied session (SQL joins) is unrelated in content. Builds directly on W2-1. Leads to W2-3 and to experiment design in Week 4 (W4-1). | J9: W2-1: sampling distributions, the standard error and the central limit theorem. From Week 1: the permutation test and the meaning of a p-value. | K9: Power, sample size and multiple comparisons (W2-3); inference on regression coefficients (W5-1). | L9: R001 · Diez, Çetinkaya-Rundel and Barr, OpenIntro Statistics, 4th ed. (Ch. 5 to 7) R003 · Wasserman (2004), All of Statistics (Ch. 6 and 10) R004 · MIT OpenCourseWare 18.650, Statistics for Applications (sessions 7 to 10, parametric hypothesis testing) R007 · Greenland et al. (2016), Statistical tests, P values, confidence intervals, and power: a guide to misinterpretations R008 · American Statistical Association (2016), statement on statistical significance and p-values R005 · Seeing Theory (Brown University), interactive visualisations (Frequentist Inference) R009 · SciPy, scipy.stats.ttest_ind | M9: To be confirmed | N9: Tentative | O9: None yet
A10: W2-3 | B10: 2 | C10: =Overview!$C$10+7*(B10-1)+2 -> 46309 | D10: =Overview!$C$11 -> 120 | E10: Module 1: Foundations of AI and Data Subject: Statistical inference | F10: Errors, power and sample size; multiple comparisons | G10: • Type I and Type II errors; significance level and power • What determines power: effect size, variance, sample size and the significance level • Sample size for comparing two means or two proportions • Multiple comparisons: family-wise error, Bonferroni, and the false discovery rate (Benjamini-Hochberg) • Statistical significance against practical significance; effect sizes | H10: Learners can estimate the sample size a comparison needs, explain why testing many segments produces spurious findings, and distinguish a statistically significant result from a practically important one. | I10: Session 3 of 3; closes the Week 2 short course and the statistics that Major Exam 1 draws on. The same-day applied session (SQL window functions) is unrelated in content. Leads to experiment design (W4-1) and to evaluation statistics in Week 10 (W10-3). | J10: W2-1 and W2-2. From Week 1: correlation against causation, confounding and Simpson's paradox, taught on a marketing campaign dataset; a working rule that a rate computed on fewer than thirty observations is unreliable. | K10: Experiment design and A/B testing (W4-1); regression (Week 5). | L10: R010 · James, Witten, Hastie and Tibshirani (2021), An Introduction to Statistical Learning (ISLR), 2nd ed. (Ch. 13, Multiple Testing) R001 · Diez, Çetinkaya-Rundel and Barr, OpenIntro Statistics, 4th ed. (Section 7.4, power calculations) R011 · Button et al. (2013), Power failure: why small sample size undermines the reliability of neuroscience R012 · Gelman and Loken (2013), The garden of forking paths R007 · Greenland et al. (2016), Statistical tests, P values, confidence intervals, and power: a guide to misinterpretations R013 · statsmodels, statistics module: power and sample size R014 · Evan Miller, sample size calculator for A/B tests | M10: To be confirmed | N10: Tentative | O10: None yet
A11: ="WEEK 4 · "&TEXT(Overview!$C$10+7*(4-1),"DD MMM")&" to "&TEXT(Overview!$C$10+7*(4-1)+5,"DD MMM YYYY")&" · Module 2: Applied Machine Learning · Faculty short course: Statistical foundations of business analytics"&" · Industry-led track this week: Business and data analyst craft: metric design, market basket analysis, cohort and funnel analysis, forecasting baselines" -> WEEK 4 · 26 Oct to 31 Oct 2026 · Module 2: Applied Machine Learning · Faculty short course: Statistical foundations of business analytics · Industry-led track this week: Business and data analyst craft: metric design, market basket analysis, cohort and funnel analysis, forecasting baselines
A12: Learner progress before this week: Weeks 1 and 2 (Python for analysis, descriptive statistics, the permutation test, SQL joins and window functions, pandas) and a first build week on health-care operations data. The Week 2 faculty sessions covered sampling distributions, confidence intervals, the t-test family, power and multiple comparisons. Tuesday of this week is a stakeholder communication and case day and carries no faculty session.
A13: W4-1 | B13: 4 | C13: =Overview!$C$10+7*(B13-1)+0 -> 46321 | D13: =Overview!$C$11 -> 120 | E13: Module 2: Applied Machine Learning Subject: Experimentation and causal measurement | F13: Design of experiments: randomised controlled trials and A/B testing | G13: • Why randomisation identifies a causal effect; treatment and control groups • The unit of randomisation, interference between units, and novelty effects • The primary metric, guardrail metrics and the minimum detectable effect • Sample size and test duration; the problem with peeking and early stopping • Reading the result: the interval on the difference, and practical significance • Variance reduction with pre-experiment data (CUPED), at recognition depth | H13: Learners can design an A/B test for a product change, specifying the unit randomised, the primary and guardrail metrics, the sample size and the duration, and can name two ways such a test goes wrong. | I13: Session 1 of 4 in the Week 4 short course. Same-day applied session: business metric design. Builds on the Week 2 sessions on power and sample size. It also prepares a standard interview question: how would you measure the success of a new feature. | J13: Applied session: a north-star metric with guardrail metrics, leading against lagging indicators, metric definitions with numerator, denominator and window, and how a target gets gamed. Weeks 1 and 2: the permutation test, t-tests, power, sample size and confounding. | K13: Classification metrics and prediction (Week 5). Causal inference from observational data, beyond confounding, is outside the programme. | L13: R015 · Kohavi, Tang and Xu (2020), Trustworthy Online Controlled Experiments R016 · Kohavi et al. (2009), Controlled experiments on the web: survey and practical guide R017 · Kohavi et al. (2012), Trustworthy Online Controlled Experiments: Five Puzzling Outcomes Explained R018 · Deng et al. (2013), Improving the Sensitivity of Online Controlled Experiments by Utilizing Pre-Experiment Data (CUPED) R019 · Johari et al. (2015), Always Valid Inference: Bringing Sequential Analysis to A/B Testing R020 · Evan Miller, How Not To Run an A/B Test R014 · Evan Miller, sample size calculator for A/B tests R013 · statsmodels, statistics module: power and sample size (power and sample size) | M13: To be confirmed | N13: Tentative | O13: None yet
A14: W4-2 | B14: 4 | C14: =Overview!$C$10+7*(B14-1)+2 -> 46323 | D14: =Overview!$C$11 -> 120 | E14: Module 2: Applied Machine Learning Subject: Association analysis | F14: Association rule mining: probability foundations and the Apriori algorithm | G14: • Support, confidence and lift as joint and conditional probabilities • Independence, and why a lift near one signals no association • The Apriori principle (anti-monotonicity of support) and candidate pruning • Frequent itemset generation; FP-growth at recognition depth • Interest measures and their pitfalls: conviction, the phi coefficient and the chi-square view • The multiple-comparisons problem in rule mining | H14: Learners can derive lift from a contingency table, explain how frequent itemsets are found without enumerating every combination, and state why high confidence alone is misleading. | I14: Session 2 of 4. Same-day applied session: market basket analysis and cross-sell. Links back to W2-3 (multiple comparisons). | J14: Applied session: support, confidence and lift computed by counting on twelve baskets and then in code; a best-selling item with confidence 0.82 and lift 0.97, recognised as uninformative; one recommendation costed as expected incremental margin less promotion cost. | K14: Recommender systems and collaborative filtering are outside the programme. | L14: R021 · Tan, Steinbach, Karpatne and Kumar (2018), Introduction to Data Mining, 2nd ed., Ch. 5 Association Analysis (sample chapter) R022 · Leskovec, Rajaraman and Ullman, Mining of Massive Datasets, Ch. 6 Frequent Itemsets R023 · Agrawal and Srikant (1994), Fast Algorithms for Mining Association Rules R024 · Han, Pei and Yin (2000), Mining Frequent Patterns without Candidate Generation R025 · Hahsler, A Probabilistic Comparison of Commonly Used Interest Measures for Association Rules R026 · mlxtend, association rules user guide | M14: To be confirmed | N14: Tentative | O14: None yet
A15: W4-3 | B15: 4 | C15: =Overview!$C$10+7*(B15-1)+3 -> 46324 | D15: =Overview!$C$11 -> 120 | E15: Module 2: Applied Machine Learning Subject: Survival and retention analysis | F15: Time-to-event analysis: survival curves, censoring and hazard | G15: • Time-to-event data and right censoring; why ignoring censoring biases a retention estimate upward • The survival function and the hazard function • The Kaplan-Meier estimator, worked by hand on a small table • Comparing two groups: the log-rank test • The Cox proportional hazards model, at recognition depth • The link to customer retention curves and churn | H15: Learners can read a Kaplan-Meier curve, explain censoring and its effect on a retention estimate, and state when two retention curves differ by more than chance. | I15: Session 3 of 4. Same-day applied session: cohort and funnel analysis. Prepares the churn-style prediction targets of Week 5. | J15: Applied session: cohorts built by signup month; funnels read with the correct denominator at each stage; retention curves; a blended retention rate that stays flat while every cohort declines, which is a mix effect related to the Simpson's paradox example of Week 1. | K15: Predictive churn models (Week 5). Customer lifetime value modelling is outside the programme. | L15: R010 · James, Witten, Hastie and Tibshirani (2021), An Introduction to Statistical Learning (ISLR), 2nd ed. (Ch. 11, Survival Analysis and Censored Data) R029 · Kleinbaum and Klein (2012), Survival Analysis: A Self-Learning Text, 3rd ed. R027 · Rodríguez (Princeton), Lecture Notes on Generalized Linear Models, Ch. 7 Survival Models R028 · Clark et al. (2003), Survival Analysis Part I: Basic concepts and first analyses R030 · Fader and Hardie (2007), How to Project Customer Retention R031 · lifelines, Introduction to survival analysis | M15: To be confirmed | N15: Tentative | O15: None yet
A16: W4-4 | B16: 4 | C16: =Overview!$C$10+7*(B16-1)+4 -> 46325 | D16: =Overview!$C$11 -> 120 | E16: Module 2: Applied Machine Learning Subject: Time series and forecasting | F16: Time series foundations: autocorrelation, stationarity, exponential smoothing and ARIMA | G16: • Components of a series: trend, seasonality and remainder; classical decomposition • Autocorrelation and the ACF plot; white noise • Stationarity and differencing • Exponential smoothing as a weighted average of the past: simple, Holt and Holt-Winters • ARIMA at recognition depth: what p, d and q mean • Forecast evaluation: time series cross-validation, scaled errors, and why naive baselines are hard to beat | H16: Learners can read an autocorrelation plot, explain exponential smoothing as a weighted memory of the past, and state what a fitted model must beat before it is preferred to a seasonal-naive forecast. | I16: Session 4 of 4; closes the Week 4 short course. Same-day applied session: forecasting baselines. | J16: Applied session: trend and seasonality read from 24 months of revenue with an annual festival peak; last-value, seasonal-naive and drift forecasts built by hand; a six-month hold-out scored with mean absolute error; a vendor forecast that lost to the seasonal-naive baseline. | K16: Machine-learning and neural forecasting methods are outside the programme. | L16: R032 · Hyndman and Athanasopoulos (2021), Forecasting: Principles and Practice (FPP3), 3rd ed. (Ch. 2 (2.8 to 2.9), 3, 5 (5.2, 5.8, 5.10), 8 and 9) R033 · Shumway and Stoffer (2017), Time Series Analysis and Its Applications, 4th ed. (companion repository) (Ch. 1 to 3) R034 · NIST/SEMATECH e-Handbook of Statistical Methods, Section 6.4 Introduction to Time Series Analysis R035 · Nau (Duke University), Statistical forecasting: notes on regression and time series analysis (exponential smoothing and ARIMA notes) R036 · Makridakis, Spiliotis and Assimakopoulos (2018), Statistical and Machine Learning forecasting methods: Concerns and ways forward R037 · statsmodels, time series analysis (tsa) R038 · statsmodels, exponential smoothing worked example | M16: To be confirmed | N16: Tentative | O16: None yet
A17: ="WEEK 5 · "&TEXT(Overview!$C$10+7*(5-1),"DD MMM")&" to "&TEXT(Overview!$C$10+7*(5-1)+5,"DD MMM YYYY")&" · Module 2: Applied Machine Learning · Faculty short course: Mathematical foundations of machine learning"&" · Industry-led track this week: Machine learning core in scikit-learn: regression and classification, metrics under class imbalance, feature engineering and leakage, overfitting and regularisation, model justification" -> WEEK 5 · 02 Nov to 07 Nov 2026 · Module 2: Applied Machine Learning · Faculty short course: Mathematical foundations of machine learning · Industry-led track this week: Machine learning core in scikit-learn: regression and classification, metrics under class imbalance, feature engineering and leakage, overfitting and regularisation, model justification
A18: Learner progress before this week: All of the above, together with metric design, lift, cohort retention and naive forecasting baselines. A pre-work bridge course has introduced linear and logistic regression. The applied work all week uses a repeat-purchase target that is imbalanced at roughly 96 to 4. Major Exam 1 is held during this week.
A19: W5-1 | B19: 5 | C19: =Overview!$C$10+7*(B19-1)+0 -> 46328 | D19: =Overview!$C$11 -> 120 | E19: Module 2: Applied Machine Learning Subject: Supervised learning: linear models | F19: Linear and logistic regression from first principles | G19: • Least squares as projection: the normal equations and their geometry • Maximum likelihood estimation; least squares as maximum likelihood under Gaussian noise • The logistic function, log-odds, and cross-entropy loss as a likelihood • Standard errors and confidence intervals for coefficients; the t-statistic • Assumptions and diagnostics: linearity, constant variance, residual analysis • Gradient descent as the numerical route when no closed form exists | H19: Learners can explain where least-squares and logistic-regression estimates come from, interpret a coefficient together with its standard error, and state the assumptions behind the inference. | I19: Session 1 of 5 in the Week 5 short course. Same-day applied session: regression and classification in scikit-learn. Major Exam 1 is held this week. | J19: Applied session: a prediction problem framed as input, target and prediction time; train, validation and test splits; a naive baseline; linear and logistic regression fitted in scikit-learn, with coefficients interpreted in business units and residual plots examined. A pre-work bridge course introduced both models. Week 2: intervals and t-tests. | K19: Evaluation metrics (W5-2); multicollinearity (W5-3); regularisation (W5-4). | L19: R010 · James, Witten, Hastie and Tibshirani (2021), An Introduction to Statistical Learning (ISLR), 2nd ed. (Ch. 3 and 4) R039 · Hastie, Tibshirani and Friedman (2009), The Elements of Statistical Learning (ESL), 2nd ed. (Ch. 3 and 4) R041 · Bishop (2006), Pattern Recognition and Machine Learning (Ch. 3 and 4) R042 · Shalizi, Advanced Data Analysis from an Elementary Point of View R040 · Stanford CS229 lecture notes (Ma and Ng) (Part I, linear and logistic regression) R043 · Penn State STAT 501, Regression Methods (open course notes) R044 · MIT OpenCourseWare 18.06, Linear Algebra (Strang) (projections and least squares) R045 · statsmodels, linear regression | M19: To be confirmed | N19: Tentative | O19: None yet
A20: W5-2 | B20: 5 | C20: =Overview!$C$10+7*(B20-1)+1 -> 46329 | D20: =Overview!$C$11 -> 120 | E20: Module 2: Applied Machine Learning Subject: Model evaluation | F20: Classifier evaluation: ROC analysis, precision-recall and cost-sensitive decisions | G20: • The ROC curve and AUC; AUC as the probability that a positive is ranked above a negative • Precision-recall curves, and why they are more informative under class imbalance • Expected cost and the optimal decision threshold (the Bayes decision rule) • Probability calibration: reliability diagrams, Platt scaling and isotonic regression • Proper scoring rules: log loss and the Brier score | H20: Learners can read ROC and precision-recall curves, derive a decision threshold from two misclassification costs, and explain why a model that ranks well can still be poorly calibrated. | I20: Session 2 of 5. Same-day applied session: classification metrics under class imbalance. | J20: Applied session: the confusion matrix, precision, recall and F1; a classifier that is 96 percent accurate on a 96-to-4 outcome and identifies no positives; metric selection from the cost of each error type; a threshold chosen from two costs in a retail case, and again in a lending case where the costs reverse. ROC and AUC were named only. | K20: Statistical comparison of models on a shared test set (W10-3). | L20: R010 · James, Witten, Hastie and Tibshirani (2021), An Introduction to Statistical Learning (ISLR), 2nd ed. (Ch. 4, the confusion matrix and ROC curves) R046 · Fawcett (2006), An introduction to ROC analysis R047 · Saito and Rehmsmeier (2015), The Precision-Recall Plot Is More Informative than the ROC Plot When Evaluating Binary Classifiers on Imbalanced Datasets R048 · Elkan (2001), The Foundations of Cost-Sensitive Learning R049 · Niculescu-Mizil and Caruana (2005), Predicting Good Probabilities With Supervised Learning R050 · Gneiting and Raftery (2007), Strictly Proper Scoring Rules, Prediction, and Estimation R051 · Hand (2009), Measuring classifier performance: a coherent alternative to the area under the ROC curve R052 · scikit-learn user guide, Metrics and scoring (classification metrics) R053 · scikit-learn user guide, Probability calibration | M20: To be confirmed | N20: Tentative | O20: None yet
A21: W5-3 | B21: 5 | C21: =Overview!$C$10+7*(B21-1)+2 -> 46330 | D21: =Overview!$C$11 -> 120 | E21: Module 2: Applied Machine Learning Subject: Model specification and feature engineering | F21: Multicollinearity, identifiability, and explanatory against predictive modelling | G21: • Multicollinearity: its effect on coefficient variance and sign; the variance inflation factor • Identifiability, and why prediction can survive collinearity while explanation cannot • Interaction terms and non-linear transformations; categorical encodings and the dummy-variable trap • Feature scaling: where it matters (distance-based and regularised models) and where it does not • Target leakage formalised as information unavailable at prediction time • Explanatory against predictive modelling | H21: Learners can diagnose multicollinearity with a variance inflation factor, explain why a coefficient changed sign, and state when a model is fit to explain and when it is fit only to predict. | I21: Session 3 of 5. Same-day applied session: feature engineering and leakage. Motivates regularisation in W5-4. | J21: Applied session: recency, frequency and monetary features, ratios, encoding and scaling; leakage detected by asking whether a value is known at prediction time; two correlated features that reversed a coefficient's sign in the learners' own model. | K21: Regularisation as the remedy for unstable coefficients (W5-4). | L21: R010 · James, Witten, Hastie and Tibshirani (2021), An Introduction to Statistical Learning (ISLR), 2nd ed. (Section 3.3.3 and Ch. 6) R058 · Kuhn and Johnson (2019), Feature Engineering and Selection R054 · Penn State STAT 501, Lesson 12: Multicollinearity and Other Regression Pitfalls R055 · Shmueli (2010), To Explain or to Predict? R056 · Breiman (2001), Statistical Modeling: The Two Cultures R057 · Kaufman, Rosset and Perlich (2011), Leakage in Data Mining: Formulation, Detection, and Avoidance R059 · statsmodels, variance_inflation_factor | M21: To be confirmed | N21: Tentative | O21: None yet
A22: W5-4 | B22: 5 | C22: =Overview!$C$10+7*(B22-1)+3 -> 46331 | D22: =Overview!$C$11 -> 120 | E22: Module 2: Applied Machine Learning Subject: Generalisation and regularisation | F22: The bias-variance trade-off, regularisation and resampling | G22: • Decomposition of expected test error into bias, variance and irreducible noise • Model complexity, overfitting and the classical U-shaped curve; double descent noted as a current research finding • Ridge and lasso as penalised estimation; their Bayesian reading; sparsity under the L1 penalty • The regularisation path and the choice of penalty • Cross-validation: k-fold and leave-one-out, bias and variance of the estimate; nested cross-validation for model selection | H22: Learners can explain the bias-variance decomposition, state what ridge and lasso penalties do to the coefficients and why, and describe how cross-validation estimates generalisation error without touching the test set. | I22: Session 4 of 5. Same-day applied session: overfitting and regularisation. | J22: Applied session: an unrestricted decision tree scoring 100 percent on training data and 61 percent on validation data; learning curves; regularisation strength and k-fold cross-validation used in scikit-learn; trees, ensembles and clustering met at recognition depth. | K22: The internals of trees and ensembles (W5-5); regularisation in neural networks (W7-3). | L22: R039 · Hastie, Tibshirani and Friedman (2009), The Elements of Statistical Learning (ESL), 2nd ed. (Section 3.4 and Ch. 7) R010 · James, Witten, Hastie and Tibshirani (2021), An Introduction to Statistical Learning (ISLR), 2nd ed. (Ch. 5 and 6) R060 · Belkin et al. (2018), Reconciling modern machine learning practice and the bias-variance trade-off R061 · Arlot and Celisse (2010), A survey of cross-validation procedures for model selection R062 · Varma and Simon (2006), Bias in error estimation when using cross-validation for model selection R063 · Cawley and Talbot (2010), On Over-fitting in Model Selection and Subsequent Selection Bias in Performance Evaluation R065 · MLU-Explain, Bias Variance Tradeoff (interactive article) R064 · scikit-learn user guide, Cross-validation | M22: To be confirmed | N22: Tentative | O22: None yet
A23: W5-5 | B23: 5 | C23: =Overview!$C$10+7*(B23-1)+4 -> 46332 | D23: =Overview!$C$11 -> 120 | E23: Module 2: Applied Machine Learning Subject: Tree-based and ensemble methods | F23: Decision trees, bagging, random forests and gradient boosting | G23: • Recursive partitioning; split criteria (Gini impurity, entropy, variance reduction); one split computed by hand • Cost-complexity pruning • Bagging and why averaging reduces variance; out-of-bag error • Random forests: feature subsampling and the decorrelation of trees • Gradient boosting as stagewise additive modelling: fitting the negative gradient; shrinkage and early stopping • Feature importance: impurity-based against permutation importance, and their biases | H23: Learners can compute one split by hand, explain why averaging many trees lowers variance, and describe what each boosting iteration fits. | I23: Session 5 of 5; closes the Week 5 short course and the machine-learning theory that Major Exam 1 draws on. Same-day applied session: model justification. The build week that follows (Week 6) applies the week's methods to lending data. | J23: Applied session: a model justification memo in which the simpler model is recommended when performance ties, the cost of errors is stated in currency and a retraining rule is set. Decision trees, random forests and gradient boosting were used in scikit-learn on Thursday without examining their internals. | K23: Neural networks (Week 7). | L23: R039 · Hastie, Tibshirani and Friedman (2009), The Elements of Statistical Learning (ESL), 2nd ed. (Ch. 9, 10 and 15) R010 · James, Witten, Hastie and Tibshirani (2021), An Introduction to Statistical Learning (ISLR), 2nd ed. (Ch. 8) R066 · Breiman (1996), Bagging predictors R067 · Breiman (2001), Random Forests R068 · Friedman (2001), Greedy function approximation: A gradient boosting machine R069 · Chen and Guestrin (2016), XGBoost: A Scalable Tree Boosting System R070 · Ke et al. (2017), LightGBM: A Highly Efficient Gradient Boosting Decision Tree R071 · Strobl et al. (2007), Bias in random forest variable importance measures R072 · Grinsztajn et al. (2022), Why do tree-based models still outperform deep learning on tabular data? R074 · StatQuest, Gradient Boost Part 1 (of 4): Regression Main Ideas R073 · scikit-learn user guide, Ensembles | M23: To be confirmed | N23: Tentative | O23: None yet
A24: ="WEEK 7 · "&TEXT(Overview!$C$10+7*(7-1),"DD MMM")&" to "&TEXT(Overview!$C$10+7*(7-1)+5,"DD MMM YYYY")&" · Module 3: Deep Learning and Neural Networks · Faculty short course: Deep learning from first principles"&" · Industry-led track this week: Deep learning essentials over four days (the network, learning, training diagnostics, sequence models), then tokenization on Friday" -> WEEK 7 · 16 Nov to 21 Nov 2026 · Module 3: Deep Learning and Neural Networks · Faculty short course: Deep learning from first principles · Industry-led track this week: Deep learning essentials over four days (the network, learning, training diagnostics, sequence models), then tokenization on Friday
A25: Learner progress before this week: The machine learning core and a second build week on lending data with unequal misclassification costs. Learners have not yet met a neural network in class; the bridge course introduced the single neuron. Friday's topic, tokenization, opens Module 4 a day early because a public holiday falls in Week 8.
A26: W7-1 | B26: 7 | C26: =Overview!$C$10+7*(B26-1)+0 -> 46342 | D26: =Overview!$C$11 -> 120 | E26: Module 3: Deep Learning and Neural Networks Subject: Neural network fundamentals | F26: Feed-forward networks: representation, non-linearity and depth | G26: • The perceptron and its limits (XOR); the multilayer perceptron • Why non-linear activations are necessary: a stack of linear layers is linear • Activation functions compared: sigmoid, tanh, ReLU and variants; saturation • The universal approximation theorem: the statement, and what it does not promise • Depth against width: what depth buys in representational efficiency • Logistic regression as a network with no hidden layer; softmax outputs | H26: Learners can explain why a network needs non-linear activations, state the universal approximation theorem and its limits, and relate a single neuron to logistic regression. | I26: Session 1 of 5 in the Week 7 short course. Same-day applied session: the neuron, the network and activation functions. | J26: Applied session: the neuron; a forward pass traced by hand on two neurons; sigmoid, tanh and ReLU compared on one input range; the collapse of stacked layers when the activation is removed; a small network that only matches logistic regression on tabular data. Week 5: logistic regression and regularisation. | K26: Backpropagation and optimisers (W7-2); initialisation and normalisation (W7-3). Convolutional networks are outside the programme. | L26: R075 · Goodfellow, Bengio and Courville (2016), Deep Learning, Ch. 6 Deep Feedforward Networks R076 · Zhang, Lipton, Li and Smola, Dive into Deep Learning, Ch. 5 Multilayer Perceptrons R077 · Nielsen (2015), Neural Networks and Deep Learning, Ch. 4: a visual proof that neural nets can compute any function R078 · Stanford CS231n notes, Neural Networks Part 1 R079 · Cybenko (1989), Approximation by superpositions of a sigmoidal function R080 · Telgarsky (2016), Benefits of depth in neural networks R081 · Glorot, Bordes and Bengio (2011), Deep Sparse Rectifier Neural Networks R082 · 3Blue1Brown, But what is a neural network? (Deep learning, chapter 1) R083 · TensorFlow, A Neural Network Playground | M26: To be confirmed | N26: Tentative | O26: None yet
A27: W7-2 | B27: 7 | C27: =Overview!$C$10+7*(B27-1)+1 -> 46343 | D27: =Overview!$C$11 -> 120 | E27: Module 3: Deep Learning and Neural Networks Subject: Optimisation and backpropagation | F27: Backpropagation derived, and gradient-based optimisation | G27: • The chain rule on a computational graph; backpropagation derived for a two-layer network • Reverse-mode automatic differentiation: what a framework does when it computes gradients • Stochastic gradient descent and mini-batches • Momentum, RMSProp and Adam: what each corrects • The learning rate and its schedules; saddle points and conditioning of the loss surface | H27: Learners can derive the gradients of a two-layer network by hand, explain what reverse-mode automatic differentiation computes, and state what momentum and Adam each change about plain gradient descent. | I27: Session 2 of 5. Same-day applied session: loss functions, backpropagation at intuition depth, and optimisers. | J27: Applied session: loss functions for regression and classification; backpropagation explained as error attribution, with one weight updated by hand from a given gradient; SGD, momentum, RMSProp and Adam at recognition depth; the effect of the learning rate; a training run that diverged to NaN. | K27: Vanishing and exploding gradients, initialisation and normalisation (W7-3). | L27: R075 · Goodfellow, Bengio and Courville (2016), Deep Learning, Ch. 6 Deep Feedforward Networks R084 · Goodfellow, Bengio and Courville (2016), Deep Learning, Ch. 8 Optimization for Training Deep Models R085 · Nielsen (2015), Neural Networks and Deep Learning, Ch. 2: how the backpropagation algorithm works R086 · Stanford CS231n notes, Backpropagation, Intuitions R087 · Rumelhart, Hinton and Williams (1986), Learning representations by back-propagating errors R088 · Baydin et al. (2018), Automatic Differentiation in Machine Learning: a Survey R089 · Kingma and Ba (2014), Adam: A Method for Stochastic Optimization R090 · Ruder (2016), An overview of gradient descent optimization algorithms R091 · Goh (2017), Why Momentum Really Works (Distill) R092 · Karpathy, The spelled-out intro to neural networks and backpropagation: building micrograd | M27: To be confirmed | N27: Tentative | O27: None yet
A28: W7-3 | B28: 7 | C28: =Overview!$C$10+7*(B28-1)+2 -> 46344 | D28: =Overview!$C$11 -> 120 | E28: Module 3: Deep Learning and Neural Networks Subject: Training dynamics and regularisation | F28: Vanishing and exploding gradients, initialisation, normalisation and regularisation in deep networks | G28: • Why gradients vanish or explode: products of Jacobians and the role of saturating activations • Weight initialisation: the Xavier (Glorot) and He schemes, derived from variance preservation • Batch normalisation and layer normalisation: what each computes and why it helps • Residual connections and gradient flow • Dropout as approximate model averaging; weight decay against L2 regularisation (AdamW); early stopping • Gradient clipping | H28: Learners can explain why deep sigmoid networks train slowly, give the variance argument behind Xavier and He initialisation, and state what batch normalisation, dropout and weight decay each do. | I28: Session 3 of 5. Same-day applied session: training dynamics and debugging. Learners repeat that diagnostic exercise unaided in the Week 9 build week. | J28: Applied session: loss curves read as a diagnostic vocabulary; vanishing and exploding gradients at intuition depth; three faulty training runs diagnosed from their curves; regularisation, dropout, early stopping and random seeds applied as remedies. W5-4: ridge and lasso. | K28: Recurrent networks (W7-4), where the same gradient problem reappears through time. | L28: R093 · Goodfellow, Bengio and Courville (2016), Deep Learning, Ch. 7 Regularization for Deep Learning R084 · Goodfellow, Bengio and Courville (2016), Deep Learning, Ch. 8 Optimization for Training Deep Models R094 · Glorot and Bengio (2010), Understanding the difficulty of training deep feedforward neural networks R095 · He et al. (2015), Delving Deep into Rectifiers: Surpassing Human-Level Performance on ImageNet Classification R096 · Ioffe and Szegedy (2015), Batch Normalization: Accelerating Deep Network Training by Reducing Internal Covariate Shift R097 · Ba et al. (2016), Layer Normalization R098 · Santurkar et al. (2018), How Does Batch Normalization Help Optimization? R099 · He et al. (2015), Deep Residual Learning for Image Recognition R100 · Srivastava et al. (2014), Dropout: A Simple Way to Prevent Neural Networks from Overfitting R101 · Loshchilov and Hutter (2017), Decoupled Weight Decay Regularization R102 · Karpathy (2019), A Recipe for Training Neural Networks | M28: To be confirmed | N28: Tentative | O28: None yet
A29: W7-4 | B29: 7 | C29: =Overview!$C$10+7*(B29-1)+3 -> 46345 | D29: =Overview!$C$11 -> 120 | E29: Module 3: Deep Learning and Neural Networks Subject: Sequence models | F29: Recurrent networks, LSTM and the path to attention | G29: • The recurrent network and backpropagation through time • Vanishing gradients through time, and why long-range dependencies are hard to learn • The LSTM cell: gates, and the cell state as a path for gradients; the GRU in brief • Encoder-decoder (sequence-to-sequence) models and the fixed-vector bottleneck • Additive (Bahdanau) attention as the remedy, which motivates Week 8 • Language modelling as next-token prediction; teacher forcing | H29: Learners can unroll a recurrent network, explain how LSTM gating eases the vanishing-gradient problem, and state the bottleneck that attention was introduced to remove. | I29: Session 4 of 5; closes the theory of Module 3. Same-day applied session: sequence models and the bridge to language models. Leads to W8-1 (attention). | J29: Applied session: text as token ids and vectors; recurrent, LSTM (GRU named), bidirectional and encoder-decoder families placed on one map; next-token prediction and auto-regression with a small character-level model; the long-range dependency failure, and why attention replaced recurrence, at intuition depth. | K29: Self-attention and the transformer (W8-1). | L29: R103 · Goodfellow, Bengio and Courville (2016), Deep Learning, Ch. 10 Sequence Modeling R104 · Zhang, Lipton, Li and Smola, Dive into Deep Learning, Ch. 9 Recurrent Neural Networks R105 · Jurafsky and Martin, Speech and Language Processing, 3rd ed. draft (19 Aug 2026 release) (Ch. 14, RNNs and LSTMs) R106 · Hochreiter and Schmidhuber (1997), Long Short-Term Memory R107 · Pascanu, Mikolov and Bengio (2013), On the difficulty of training recurrent neural networks R108 · Cho et al. (2014), Learning Phrase Representations using RNN Encoder-Decoder for Statistical Machine Translation R109 · Sutskever et al. (2014), Sequence to Sequence Learning with Neural Networks R110 · Bahdanau et al. (2014), Neural Machine Translation by Jointly Learning to Align and Translate R111 · Olah (2015), Understanding LSTM Networks R112 · Karpathy (2015), The Unreasonable Effectiveness of Recurrent Neural Networks | M29: To be confirmed | N29: Tentative | O29: None yet
A30: W7-5 | B30: 7 | C30: =Overview!$C$10+7*(B30-1)+4 -> 46346 | D30: =Overview!$C$11 -> 120 | E30: Module 4: Natural Language Processing Subject: Tokenization and statistical language modelling | F30: Subword tokenization and the evaluation of language models | G30: • Byte-pair encoding: the merge algorithm worked by hand on a small corpus • WordPiece and the unigram language model (SentencePiece): how they differ from BPE • Byte-level tokenization and the open-vocabulary problem; vocabulary size as a design trade-off • n-gram language models and smoothing, as the historical baseline • Cross-entropy, perplexity and bits per token; why perplexities are not comparable across tokenizers • Tokenization effects on multilingual text and on numbers | H30: Learners can run byte-pair encoding merges by hand, compute perplexity from token probabilities, and explain why two models' perplexities cannot be compared when their tokenizers differ. | I30: Session 5 of 5 in Week 7, and the first session of Module 4 (Natural Language Processing), which continues through Week 8. Same-day applied session: tokenization. | J30: Applied session: why models read tokens and not words; what byte-pair encoding optimises; token counts as a cost driver, with one day of customer-support tickets costed; BPE, WordPiece and SentencePiece named; a product code that fragments into five tokens. W7-4: next-token prediction. | K30: Attention and the transformer (W8-1); embeddings (W8-2). | L30: R105 · Jurafsky and Martin, Speech and Language Processing, 3rd ed. draft (19 Aug 2026 release) (Ch. 2, Words and Tokens; Ch. 3, N-gram Language Models) R118 · Hugging Face LLM Course, Ch. 6 The Tokenizers library R113 · Sennrich, Haddow and Birch (2016), Neural Machine Translation of Rare Words with Subword Units R114 · Kudo (2018), Subword Regularization: Improving Neural Network Translation Models with Multiple Subword Candidates R115 · Kudo and Richardson (2018), SentencePiece R116 · Radford et al. (2019), Language Models are Unsupervised Multitask Learners (byte-level BPE) R117 · Petrov et al. (2023), Language Model Tokenizers Introduce Unfairness Between Languages R119 · Karpathy, Let's build the GPT Tokenizer R120 · OpenAI tiktoken, BPE tokeniser library | M30: To be confirmed | N30: Tentative | O30: None yet
A31: ="WEEK 8 · "&TEXT(Overview!$C$10+7*(8-1),"DD MMM")&" to "&TEXT(Overview!$C$10+7*(8-1)+5,"DD MMM YYYY")&" · Module 4: Natural Language Processing · Faculty short course: The mathematics of transformers"&" · Industry-led track this week: Transformers and LLM internals: attention and the transformer block, embeddings with BERT against GPT, decoding controls, context windows and token economics" -> WEEK 8 · 23 Nov to 28 Nov 2026 · Module 4: Natural Language Processing · Faculty short course: The mathematics of transformers · Industry-led track this week: Transformers and LLM internals: attention and the transformer block, embeddings with BERT against GPT, decoding controls, context windows and token economics
A32: Learner progress before this week: Feed-forward networks, backpropagation, optimisers, training diagnostics, recurrent and LSTM networks, and subword tokenization, each taught first in applied form and then in theory by the Week 7 faculty sessions. Tuesday 24 November is Guru Nanak Jayanti, so the week has four teaching days.
