Workbook

Sheet Read me
A1: Week 5 recap paper: item analysis
A2: TRAINER. Fill this after the swap-marking, one row per seat and never a name.
A3: Marks: type 1 for a tick, 0 for a cross and leave a blank for an item left empty. Yellow cells are the only inputs; everything else is computed.
A4: Items: each item's right rate, the top and bottom thirds' rates (thirds by total, once three or more seats are in), and a flag when fewer than one in five got it right or the bottom third beat the top third. Both are this programme's own working rule for a room of 39.
A5: Discussion: the items from the most missed, which is the order the solution discussion takes.
A6: Tags: the room's rate by tag and by part. Seats: each seat's rate by tag, for Monday's remediation read. Neither is a ranking, and neither is read out by name.

Sheet Marks
A1: Marks: 1 right, 0 wrong, blank left empty
A2: Part | B2: 1 | C2: 1 | D2: 1 | E2: 1 | F2: 1 | G2: 2 | H2: 2 | I2: 2 | J2: 2 | K2: 2 | L2: 2 | M2: 3 | N2: 3 | O2: 3 | P2: 3 | Q2: 3 | R2: 4 | S2: 4 | T2: 4 | U2: 4 | V2: 5 | W2: 5 | X2: 5 | Y2: 5
A3: Tag | B3: [S] | C3: [D] | D3: [F] | E3: [S] | F3: [S] | G3: [F] | H3: [S] | I3: [S] | J3: [S] | K3: [D] | L3: [S] | M3: [S] | N3: [S] | O3: [F] | P3: [F] | Q3: [S] | R3: [S] | S3: [F] | T3: [F] | U3: [D] | V3: [F] | W3: [D] | X3: [D] | Y3: [D]
A4: Seat | B4: Q1 | C4: Q2 | D4: Q3 | E4: Q4 | F4: Q5 | G4: Q6 | H4: Q7 | I4: Q8 | J4: Q9 | K4: Q10 | L4: Q11 | M4: Q12 | N4: Q13 | O4: Q14 | P4: Q15 | Q4: Q16 | R4: Q17 | S4: Q18 | T4: Q19 | U4: Q20 | V4: Q21 | W4: Q22 | X4: Q23 | Y4: Q24 | Z4: Total | AA4: Answered | AB4: Band
A5: 1 | Z5: =IF(COUNT(B5:Y5)=0,"",SUM(B5:Y5)) | AA5: =COUNT(B5:Y5) | AB5: =IF(OR(Z5="",COUNT($Z$5:$Z$43)<3),"",IF(RANK(Z5,$Z$5:$Z$43,0)<=ROUND(COUNT($Z$5:$Z$43)/3,0),"top",IF(RANK(Z5,$Z$5:$Z$43,1)<=ROUND(COUNT($Z$5:$Z$43)/3,0),"bottom","middle")))
A6: 2 | Z6: =IF(COUNT(B6:Y6)=0,"",SUM(B6:Y6)) | AA6: =COUNT(B6:Y6) | AB6: =IF(OR(Z6="",COUNT($Z$5:$Z$43)<3),"",IF(RANK(Z6,$Z$5:$Z$43,0)<=ROUND(COUNT($Z$5:$Z$43)/3,0),"top",IF(RANK(Z6,$Z$5:$Z$43,1)<=ROUND(COUNT($Z$5:$Z$43)/3,0),"bottom","middle")))
A7: 3 | Z7: =IF(COUNT(B7:Y7)=0,"",SUM(B7:Y7)) | AA7: =COUNT(B7:Y7) | AB7: =IF(OR(Z7="",COUNT($Z$5:$Z$43)<3),"",IF(RANK(Z7,$Z$5:$Z$43,0)<=ROUND(COUNT($Z$5:$Z$43)/3,0),"top",IF(RANK(Z7,$Z$5:$Z$43,1)<=ROUND(COUNT($Z$5:$Z$43)/3,0),"bottom","middle")))
A8: 4 | Z8: =IF(COUNT(B8:Y8)=0,"",SUM(B8:Y8)) | AA8: =COUNT(B8:Y8) | AB8: =IF(OR(Z8="",COUNT($Z$5:$Z$43)<3),"",IF(RANK(Z8,$Z$5:$Z$43,0)<=ROUND(COUNT($Z$5:$Z$43)/3,0),"top",IF(RANK(Z8,$Z$5:$Z$43,1)<=ROUND(COUNT($Z$5:$Z$43)/3,0),"bottom","middle")))
A9: 5 | Z9: =IF(COUNT(B9:Y9)=0,"",SUM(B9:Y9)) | AA9: =COUNT(B9:Y9) | AB9: =IF(OR(Z9="",COUNT($Z$5:$Z$43)<3),"",IF(RANK(Z9,$Z$5:$Z$43,0)<=ROUND(COUNT($Z$5:$Z$43)/3,0),"top",IF(RANK(Z9,$Z$5:$Z$43,1)<=ROUND(COUNT($Z$5:$Z$43)/3,0),"bottom","middle")))
A10: 6 | Z10: =IF(COUNT(B10:Y10)=0,"",SUM(B10:Y10)) | AA10: =COUNT(B10:Y10) | AB10: =IF(OR(Z10="",COUNT($Z$5:$Z$43)<3),"",IF(RANK(Z10,$Z$5:$Z$43,0)<=ROUND(COUNT($Z$5:$Z$43)/3,0),"top",IF(RANK(Z10,$Z$5:$Z$43,1)<=ROUND(COUNT($Z$5:$Z$43)/3,0),"bottom","middle")))
A11: 7 | Z11: =IF(COUNT(B11:Y11)=0,"",SUM(B11:Y11)) | AA11: =COUNT(B11:Y11) | AB11: =IF(OR(Z11="",COUNT($Z$5:$Z$43)<3),"",IF(RANK(Z11,$Z$5:$Z$43,0)<=ROUND(COUNT($Z$5:$Z$43)/3,0),"top",IF(RANK(Z11,$Z$5:$Z$43,1)<=ROUND(COUNT($Z$5:$Z$43)/3,0),"bottom","middle")))
A12: 8 | Z12: =IF(COUNT(B12:Y12)=0,"",SUM(B12:Y12)) | AA12: =COUNT(B12:Y12) | AB12: =IF(OR(Z12="",COUNT($Z$5:$Z$43)<3),"",IF(RANK(Z12,$Z$5:$Z$43,0)<=ROUND(COUNT($Z$5:$Z$43)/3,0),"top",IF(RANK(Z12,$Z$5:$Z$43,1)<=ROUND(COUNT($Z$5:$Z$43)/3,0),"bottom","middle")))
A13: 9 | Z13: =IF(COUNT(B13:Y13)=0,"",SUM(B13:Y13)) | AA13: =COUNT(B13:Y13) | AB13: =IF(OR(Z13="",COUNT($Z$5:$Z$43)<3),"",IF(RANK(Z13,$Z$5:$Z$43,0)<=ROUND(COUNT($Z$5:$Z$43)/3,0),"top",IF(RANK(Z13,$Z$5:$Z$43,1)<=ROUND(COUNT($Z$5:$Z$43)/3,0),"bottom","middle")))
A14: 10 | Z14: =IF(COUNT(B14:Y14)=0,"",SUM(B14:Y14)) | AA14: =COUNT(B14:Y14) | AB14: =IF(OR(Z14="",COUNT($Z$5:$Z$43)<3),"",IF(RANK(Z14,$Z$5:$Z$43,0)<=ROUND(COUNT($Z$5:$Z$43)/3,0),"top",IF(RANK(Z14,$Z$5:$Z$43,1)<=ROUND(COUNT($Z$5:$Z$43)/3,0),"bottom","middle")))
A15: 11 | Z15: =IF(COUNT(B15:Y15)=0,"",SUM(B15:Y15)) | AA15: =COUNT(B15:Y15) | AB15: =IF(OR(Z15="",COUNT($Z$5:$Z$43)<3),"",IF(RANK(Z15,$Z$5:$Z$43,0)<=ROUND(COUNT($Z$5:$Z$43)/3,0),"top",IF(RANK(Z15,$Z$5:$Z$43,1)<=ROUND(COUNT($Z$5:$Z$43)/3,0),"bottom","middle")))
A16: 12 | Z16: =IF(COUNT(B16:Y16)=0,"",SUM(B16:Y16)) | AA16: =COUNT(B16:Y16) | AB16: =IF(OR(Z16="",COUNT($Z$5:$Z$43)<3),"",IF(RANK(Z16,$Z$5:$Z$43,0)<=ROUND(COUNT($Z$5:$Z$43)/3,0),"top",IF(RANK(Z16,$Z$5:$Z$43,1)<=ROUND(COUNT($Z$5:$Z$43)/3,0),"bottom","middle")))
... A43: 39 | Z43: =IF(COUNT(B43:Y43)=0,"",SUM(B43:Y43)) | AA43: =COUNT(B43:Y43) | AB43: =IF(OR(Z43="",COUNT($Z$5:$Z$43)<3),"",IF(RANK(Z43,$Z$5:$Z$43,0)<=ROUND(COUNT($Z$5:$Z$43)/3,0),"top",IF(RANK(Z43,$Z$5:$Z$43,1)<=ROUND(COUNT($Z$5:$Z$43)/3,0),"bottom","middle")))

Sheet Items
A1: Items: the room's rate, the thirds, and what to check
A4: Q | B4: Part | C4: Type | D4: Level | E4: Tag | F4: Key | G4: Right | H4: Answered | I4: Right rate | J4: Top third rate | K4: Bottom third rate | L4: Top minus bottom | M4: Flag | N4: Order key
A5: 1 | B5: 1 | C5: One correct option | D5: Medium | E5: [S] | F5: b | G5: =COUNTIF(Marks!B$5:B$43,1) | H5: =COUNT(Marks!B$5:B$43) | I5: =IF(H5=0,"",G5/H5) | J5: =IF(SUMPRODUCT((Marks!$AB$5:$AB$43="top")*ISNUMBER(Marks!B$5:B$43))=0,"",SUMPRODUCT((Marks!$AB$5:$AB$43="top")*(Marks!B$5:B$43=1))/SUMPRODUCT((Marks!$AB$5:$AB$43="top")*ISNUMBER(Marks!B$5:B$43))) | K5: =IF(SUMPRODUCT((Marks!$AB$5:$AB$43="bottom")*ISNUMBER(Marks!B$5:B$43))=0,"",SUMPRODUCT((Marks!$AB$5:$AB$43="bottom")*(Marks!B$5:B$43=1))/SUMPRODUCT((Marks!$AB$5:$AB$43="bottom")*ISNUMBER(Marks!B$5:B$43))) | L5: =IF(OR(J5="",K5=""),"",J5-K5) | M5: =IF(H5=0,"",IF(I5<0.2,"Check the item: fewer than one in five got it right",IF(AND(L5<>"",N(L5)<0),"Check the item: the bottom third beat the top third",""))) | N5: =IF(H5=0,"",I5+ROW()/1000000)
A6: 2 | B6: 1 | C6: True or false | D6: Hard | E6: [D] | F6: a | G6: =COUNTIF(Marks!C$5:C$43,1) | H6: =COUNT(Marks!C$5:C$43) | I6: =IF(H6=0,"",G6/H6) | J6: =IF(SUMPRODUCT((Marks!$AB$5:$AB$43="top")*ISNUMBER(Marks!C$5:C$43))=0,"",SUMPRODUCT((Marks!$AB$5:$AB$43="top")*(Marks!C$5:C$43=1))/SUMPRODUCT((Marks!$AB$5:$AB$43="top")*ISNUMBER(Marks!C$5:C$43))) | K6: =IF(SUMPRODUCT((Marks!$AB$5:$AB$43="bottom")*ISNUMBER(Marks!C$5:C$43))=0,"",SUMPRODUCT((Marks!$AB$5:$AB$43="bottom")*(Marks!C$5:C$43=1))/SUMPRODUCT((Marks!$AB$5:$AB$43="bottom")*ISNUMBER(Marks!C$5:C$43))) | L6: =IF(OR(J6="",K6=""),"",J6-K6) | M6: =IF(H6=0,"",IF(I6<0.2,"Check the item: fewer than one in five got it right",IF(AND(L6<>"",N(L6)<0),"Check the item: the bottom third beat the top third",""))) | N6: =IF(H6=0,"",I6+ROW()/1000000)
A7: 3 | B7: 1 | C7: One correct option | D7: Medium | E7: [F] | F7: d | G7: =COUNTIF(Marks!D$5:D$43,1) | H7: =COUNT(Marks!D$5:D$43) | I7: =IF(H7=0,"",G7/H7) | J7: =IF(SUMPRODUCT((Marks!$AB$5:$AB$43="top")*ISNUMBER(Marks!D$5:D$43))=0,"",SUMPRODUCT((Marks!$AB$5:$AB$43="top")*(Marks!D$5:D$43=1))/SUMPRODUCT((Marks!$AB$5:$AB$43="top")*ISNUMBER(Marks!D$5:D$43))) | K7: =IF(SUMPRODUCT((Marks!$AB$5:$AB$43="bottom")*ISNUMBER(Marks!D$5:D$43))=0,"",SUMPRODUCT((Marks!$AB$5:$AB$43="bottom")*(Marks!D$5:D$43=1))/SUMPRODUCT((Marks!$AB$5:$AB$43="bottom")*ISNUMBER(Marks!D$5:D$43))) | L7: =IF(OR(J7="",K7=""),"",J7-K7) | M7: =IF(H7=0,"",IF(I7<0.2,"Check the item: fewer than one in five got it right",IF(AND(L7<>"",N(L7)<0),"Check the item: the bottom third beat the top third",""))) | N7: =IF(H7=0,"",I7+ROW()/1000000)
A8: 4 | B8: 1 | C8: More than one correct | D8: Medium | E8: [S] | F8: a, d | G8: =COUNTIF(Marks!E$5:E$43,1) | H8: =COUNT(Marks!E$5:E$43) | I8: =IF(H8=0,"",G8/H8) | J8: =IF(SUMPRODUCT((Marks!$AB$5:$AB$43="top")*ISNUMBER(Marks!E$5:E$43))=0,"",SUMPRODUCT((Marks!$AB$5:$AB$43="top")*(Marks!E$5:E$43=1))/SUMPRODUCT((Marks!$AB$5:$AB$43="top")*ISNUMBER(Marks!E$5:E$43))) | K8: =IF(SUMPRODUCT((Marks!$AB$5:$AB$43="bottom")*ISNUMBER(Marks!E$5:E$43))=0,"",SUMPRODUCT((Marks!$AB$5:$AB$43="bottom")*(Marks!E$5:E$43=1))/SUMPRODUCT((Marks!$AB$5:$AB$43="bottom")*ISNUMBER(Marks!E$5:E$43))) | L8: =IF(OR(J8="",K8=""),"",J8-K8) | M8: =IF(H8=0,"",IF(I8<0.2,"Check the item: fewer than one in five got it right",IF(AND(L8<>"",N(L8)<0),"Check the item: the bottom third beat the top third",""))) | N8: =IF(H8=0,"",I8+ROW()/1000000)
A9: 5 | B9: 1 | C9: Fill in the blank | D9: Easy | E9: [S] | F9: c | G9: =COUNTIF(Marks!F$5:F$43,1) | H9: =COUNT(Marks!F$5:F$43) | I9: =IF(H9=0,"",G9/H9) | J9: =IF(SUMPRODUCT((Marks!$AB$5:$AB$43="top")*ISNUMBER(Marks!F$5:F$43))=0,"",SUMPRODUCT((Marks!$AB$5:$AB$43="top")*(Marks!F$5:F$43=1))/SUMPRODUCT((Marks!$AB$5:$AB$43="top")*ISNUMBER(Marks!F$5:F$43))) | K9: =IF(SUMPRODUCT((Marks!$AB$5:$AB$43="bottom")*ISNUMBER(Marks!F$5:F$43))=0,"",SUMPRODUCT((Marks!$AB$5:$AB$43="bottom")*(Marks!F$5:F$43=1))/SUMPRODUCT((Marks!$AB$5:$AB$43="bottom")*ISNUMBER(Marks!F$5:F$43))) | L9: =IF(OR(J9="",K9=""),"",J9-K9) | M9: =IF(H9=0,"",IF(I9<0.2,"Check the item: fewer than one in five got it right",IF(AND(L9<>"",N(L9)<0),"Check the item: the bottom third beat the top third",""))) | N9: =IF(H9=0,"",I9+ROW()/1000000)
A10: 6 | B10: 2 | C10: True or false | D10: Medium | E10: [F] | F10: d | G10: =COUNTIF(Marks!G$5:G$43,1) | H10: =COUNT(Marks!G$5:G$43) | I10: =IF(H10=0,"",G10/H10) | J10: =IF(SUMPRODUCT((Marks!$AB$5:$AB$43="top")*ISNUMBER(Marks!G$5:G$43))=0,"",SUMPRODUCT((Marks!$AB$5:$AB$43="top")*(Marks!G$5:G$43=1))/SUMPRODUCT((Marks!$AB$5:$AB$43="top")*ISNUMBER(Marks!G$5:G$43))) | K10: =IF(SUMPRODUCT((Marks!$AB$5:$AB$43="bottom")*ISNUMBER(Marks!G$5:G$43))=0,"",SUMPRODUCT((Marks!$AB$5:$AB$43="bottom")*(Marks!G$5:G$43=1))/SUMPRODUCT((Marks!$AB$5:$AB$43="bottom")*ISNUMBER(Marks!G$5:G$43))) | L10: =IF(OR(J10="",K10=""),"",J10-K10) | M10: =IF(H10=0,"",IF(I10<0.2,"Check the item: fewer than one in five got it right",IF(AND(L10<>"",N(L10)<0),"Check the item: the bottom third beat the top third",""))) | N10: =IF(H10=0,"",I10+ROW()/1000000)
A11: 7 | B11: 2 | C11: Applied maths | D11: Medium | E11: [S] | F11: Precision 174 / 268 = 0.65; recall 174 / 928 = 0.19; F1 = 2 x 174 / (2 x 174 + 94 + 754) = 348 / 1,196 = 0.29. | G11: =COUNTIF(Marks!H$5:H$43,1) | H11: =COUNT(Marks!H$5:H$43) | I11: =IF(H11=0,"",G11/H11) | J11: =IF(SUMPRODUCT((Marks!$AB$5:$AB$43="top")*ISNUMBER(Marks!H$5:H$43))=0,"",SUMPRODUCT((Marks!$AB$5:$AB$43="top")*(Marks!H$5:H$43=1))/SUMPRODUCT((Marks!$AB$5:$AB$43="top")*ISNUMBER(Marks!H$5:H$43))) | K11: =IF(SUMPRODUCT((Marks!$AB$5:$AB$43="bottom")*ISNUMBER(Marks!H$5:H$43))=0,"",SUMPRODUCT((Marks!$AB$5:$AB$43="bottom")*(Marks!H$5:H$43=1))/SUMPRODUCT((Marks!$AB$5:$AB$43="bottom")*ISNUMBER(Marks!H$5:H$43))) | L11: =IF(OR(J11="",K11=""),"",J11-K11) | M11: =IF(H11=0,"",IF(I11<0.2,"Check the item: fewer than one in five got it right",IF(AND(L11<>"",N(L11)<0),"Check the item: the bottom third beat the top third",""))) | N11: =IF(H11=0,"",I11+ROW()/1000000)
A12: 8 | B12: 2 | C12: Applied maths | D12: Medium | E12: [S] | F12: Call when p x 1,200 > (1 - p) x 40, so p > 40 / 1,240 = 1 / 31, about 0.032 (1 in 30, 0.033, from one buyer paying for 30 calls, is accepted); the line moves down from 0.5 and recall leads. | G12: =COUNTIF(Marks!I$5:I$43,1) | H12: =COUNT(Marks!I$5:I$43) | I12: =IF(H12=0,"",G12/H12) | J12: =IF(SUMPRODUCT((Marks!$AB$5:$AB$43="top")*ISNUMBER(Marks!I$5:I$43))=0,"",SUMPRODUCT((Marks!$AB$5:$AB$43="top")*(Marks!I$5:I$43=1))/SUMPRODUCT((Marks!$AB$5:$AB$43="top")*ISNUMBER(Marks!I$5:I$43))) | K12: =IF(SUMPRODUCT((Marks!$AB$5:$AB$43="bottom")*ISNUMBER(Marks!I$5:I$43))=0,"",SUMPRODUCT((Marks!$AB$5:$AB$43="bottom")*(Marks!I$5:I$43=1))/SUMPRODUCT((Marks!$AB$5:$AB$43="bottom")*ISNUMBER(Marks!I$5:I$43))) | L12: =IF(OR(J12="",K12=""),"",J12-K12) | M12: =IF(H12=0,"",IF(I12<0.2,"Check the item: fewer than one in five got it right",IF(AND(L12<>"",N(L12)<0),"Check the item: the bottom third beat the top third",""))) | N12: =IF(H12=0,"",I12+ROW()/1000000)
A13: 9 | B13: 2 | C13: One correct option | D13: Medium | E13: [S] | F13: b | G13: =COUNTIF(Marks!J$5:J$43,1) | H13: =COUNT(Marks!J$5:J$43) | I13: =IF(H13=0,"",G13/H13) | J13: =IF(SUMPRODUCT((Marks!$AB$5:$AB$43="top")*ISNUMBER(Marks!J$5:J$43))=0,"",SUMPRODUCT((Marks!$AB$5:$AB$43="top")*(Marks!J$5:J$43=1))/SUMPRODUCT((Marks!$AB$5:$AB$43="top")*ISNUMBER(Marks!J$5:J$43))) | K13: =IF(SUMPRODUCT((Marks!$AB$5:$AB$43="bottom")*ISNUMBER(Marks!J$5:J$43))=0,"",SUMPRODUCT((Marks!$AB$5:$AB$43="bottom")*(Marks!J$5:J$43=1))/SUMPRODUCT((Marks!$AB$5:$AB$43="bottom")*ISNUMBER(Marks!J$5:J$43))) | L13: =IF(OR(J13="",K13=""),"",J13-K13) | M13: =IF(H13=0,"",IF(I13<0.2,"Check the item: fewer than one in five got it right",IF(AND(L13<>"",N(L13)<0),"Check the item: the bottom third beat the top third",""))) | N13: =IF(H13=0,"",I13+ROW()/1000000)
A14: 10 | B14: 2 | C14: One correct option | D14: Hard | E14: [D] | F14: c | G14: =COUNTIF(Marks!K$5:K$43,1) | H14: =COUNT(Marks!K$5:K$43) | I14: =IF(H14=0,"",G14/H14) | J14: =IF(SUMPRODUCT((Marks!$AB$5:$AB$43="top")*ISNUMBER(Marks!K$5:K$43))=0,"",SUMPRODUCT((Marks!$AB$5:$AB$43="top")*(Marks!K$5:K$43=1))/SUMPRODUCT((Marks!$AB$5:$AB$43="top")*ISNUMBER(Marks!K$5:K$43))) | K14: =IF(SUMPRODUCT((Marks!$AB$5:$AB$43="bottom")*ISNUMBER(Marks!K$5:K$43))=0,"",SUMPRODUCT((Marks!$AB$5:$AB$43="bottom")*(Marks!K$5:K$43=1))/SUMPRODUCT((Marks!$AB$5:$AB$43="bottom")*ISNUMBER(Marks!K$5:K$43))) | L14: =IF(OR(J14="",K14=""),"",J14-K14) | M14: =IF(H14=0,"",IF(I14<0.2,"Check the item: fewer than one in five got it right",IF(AND(L14<>"",N(L14)<0),"Check the item: the bottom third beat the top third",""))) | N14: =IF(H14=0,"",I14+ROW()/1000000)
A15: 11 | B15: 2 | C15: Fill in the blank | D15: Easy | E15: [S] | F15: b | G15: =COUNTIF(Marks!L$5:L$43,1) | H15: =COUNT(Marks!L$5:L$43) | I15: =IF(H15=0,"",G15/H15) | J15: =IF(SUMPRODUCT((Marks!$AB$5:$AB$43="top")*ISNUMBER(Marks!L$5:L$43))=0,"",SUMPRODUCT((Marks!$AB$5:$AB$43="top")*(Marks!L$5:L$43=1))/SUMPRODUCT((Marks!$AB$5:$AB$43="top")*ISNUMBER(Marks!L$5:L$43))) | K15: =IF(SUMPRODUCT((Marks!$AB$5:$AB$43="bottom")*ISNUMBER(Marks!L$5:L$43))=0,"",SUMPRODUCT((Marks!$AB$5:$AB$43="bottom")*(Marks!L$5:L$43=1))/SUMPRODUCT((Marks!$AB$5:$AB$43="bottom")*ISNUMBER(Marks!L$5:L$43))) | L15: =IF(OR(J15="",K15=""),"",J15-K15) | M15: =IF(H15=0,"",IF(I15<0.2,"Check the item: fewer than one in five got it right",IF(AND(L15<>"",N(L15)<0),"Check the item: the bottom third beat the top third",""))) | N15: =IF(H15=0,"",I15+ROW()/1000000)
A16: 12 | B16: 3 | C16: One correct option | D16: Medium | E16: [S] | F16: c | G16: =COUNTIF(Marks!M$5:M$43,1) | H16: =COUNT(Marks!M$5:M$43) | I16: =IF(H16=0,"",G16/H16) | J16: =IF(SUMPRODUCT((Marks!$AB$5:$AB$43="top")*ISNUMBER(Marks!M$5:M$43))=0,"",SUMPRODUCT((Marks!$AB$5:$AB$43="top")*(Marks!M$5:M$43=1))/SUMPRODUCT((Marks!$AB$5:$AB$43="top")*ISNUMBER(Marks!M$5:M$43))) | K16: =IF(SUMPRODUCT((Marks!$AB$5:$AB$43="bottom")*ISNUMBER(Marks!M$5:M$43))=0,"",SUMPRODUCT((Marks!$AB$5:$AB$43="bottom")*(Marks!M$5:M$43=1))/SUMPRODUCT((Marks!$AB$5:$AB$43="bottom")*ISNUMBER(Marks!M$5:M$43))) | L16: =IF(OR(J16="",K16=""),"",J16-K16) | M16: =IF(H16=0,"",IF(I16<0.2,"Check the item: fewer than one in five got it right",IF(AND(L16<>"",N(L16)<0),"Check the item: the bottom third beat the top third",""))) | N16: =IF(H16=0,"",I16+ROW()/1000000)
A17: 13 | B17: 3 | C17: More than one correct | D17: Hard | E17: [S] | F17: b, c | G17: =COUNTIF(Marks!N$5:N$43,1) | H17: =COUNT(Marks!N$5:N$43) | I17: =IF(H17=0,"",G17/H17) | J17: =IF(SUMPRODUCT((Marks!$AB$5:$AB$43="top")*ISNUMBER(Marks!N$5:N$43))=0,"",SUMPRODUCT((Marks!$AB$5:$AB$43="top")*(Marks!N$5:N$43=1))/SUMPRODUCT((Marks!$AB$5:$AB$43="top")*ISNUMBER(Marks!N$5:N$43))) | K17: =IF(SUMPRODUCT((Marks!$AB$5:$AB$43="bottom")*ISNUMBER(Marks!N$5:N$43))=0,"",SUMPRODUCT((Marks!$AB$5:$AB$43="bottom")*(Marks!N$5:N$43=1))/SUMPRODUCT((Marks!$AB$5:$AB$43="bottom")*ISNUMBER(Marks!N$5:N$43))) | L17: =IF(OR(J17="",K17=""),"",J17-K17) | M17: =IF(H17=0,"",IF(I17<0.2,"Check the item: fewer than one in five got it right",IF(AND(L17<>"",N(L17)<0),"Check the item: the bottom third beat the top third",""))) | N17: =IF(H17=0,"",I17+ROW()/1000000)
A18: 14 | B18: 3 | C18: True or false | D18: Medium | E18: [F] | F18: a | G18: =COUNTIF(Marks!O$5:O$43,1) | H18: =COUNT(Marks!O$5:O$43) | I18: =IF(H18=0,"",G18/H18) | J18: =IF(SUMPRODUCT((Marks!$AB$5:$AB$43="top")*ISNUMBER(Marks!O$5:O$43))=0,"",SUMPRODUCT((Marks!$AB$5:$AB$43="top")*(Marks!O$5:O$43=1))/SUMPRODUCT((Marks!$AB$5:$AB$43="top")*ISNUMBER(Marks!O$5:O$43))) | K18: =IF(SUMPRODUCT((Marks!$AB$5:$AB$43="bottom")*ISNUMBER(Marks!O$5:O$43))=0,"",SUMPRODUCT((Marks!$AB$5:$AB$43="bottom")*(Marks!O$5:O$43=1))/SUMPRODUCT((Marks!$AB$5:$AB$43="bottom")*ISNUMBER(Marks!O$5:O$43))) | L18: =IF(OR(J18="",K18=""),"",J18-K18) | M18: =IF(H18=0,"",IF(I18<0.2,"Check the item: fewer than one in five got it right",IF(AND(L18<>"",N(L18)<0),"Check the item: the bottom third beat the top third",""))) | N18: =IF(H18=0,"",I18+ROW()/1000000)
A19: 15 | B19: 3 | C19: One correct option | D19: Medium | E19: [F] | F19: d | G19: =COUNTIF(Marks!P$5:P$43,1) | H19: =COUNT(Marks!P$5:P$43) | I19: =IF(H19=0,"",G19/H19) | J19: =IF(SUMPRODUCT((Marks!$AB$5:$AB$43="top")*ISNUMBER(Marks!P$5:P$43))=0,"",SUMPRODUCT((Marks!$AB$5:$AB$43="top")*(Marks!P$5:P$43=1))/SUMPRODUCT((Marks!$AB$5:$AB$43="top")*ISNUMBER(Marks!P$5:P$43))) | K19: =IF(SUMPRODUCT((Marks!$AB$5:$AB$43="bottom")*ISNUMBER(Marks!P$5:P$43))=0,"",SUMPRODUCT((Marks!$AB$5:$AB$43="bottom")*(Marks!P$5:P$43=1))/SUMPRODUCT((Marks!$AB$5:$AB$43="bottom")*ISNUMBER(Marks!P$5:P$43))) | L19: =IF(OR(J19="",K19=""),"",J19-K19) | M19: =IF(H19=0,"",IF(I19<0.2,"Check the item: fewer than one in five got it right",IF(AND(L19<>"",N(L19)<0),"Check the item: the bottom third beat the top third",""))) | N19: =IF(H19=0,"",I19+ROW()/1000000)
A20: 16 | B20: 3 | C20: Fill in the blank | D20: Easy | E20: [S] | F20: c | G20: =COUNTIF(Marks!Q$5:Q$43,1) | H20: =COUNT(Marks!Q$5:Q$43) | I20: =IF(H20=0,"",G20/H20) | J20: =IF(SUMPRODUCT((Marks!$AB$5:$AB$43="top")*ISNUMBER(Marks!Q$5:Q$43))=0,"",SUMPRODUCT((Marks!$AB$5:$AB$43="top")*(Marks!Q$5:Q$43=1))/SUMPRODUCT((Marks!$AB$5:$AB$43="top")*ISNUMBER(Marks!Q$5:Q$43))) | K20: =IF(SUMPRODUCT((Marks!$AB$5:$AB$43="bottom")*ISNUMBER(Marks!Q$5:Q$43))=0,"",SUMPRODUCT((Marks!$AB$5:$AB$43="bottom")*(Marks!Q$5:Q$43=1))/SUMPRODUCT((Marks!$AB$5:$AB$43="bottom")*ISNUMBER(Marks!Q$5:Q$43))) | L20: =IF(OR(J20="",K20=""),"",J20-K20) | M20: =IF(H20=0,"",IF(I20<0.2,"Check the item: fewer than one in five got it right",IF(AND(L20<>"",N(L20)<0),"Check the item: the bottom third beat the top third",""))) | N20: =IF(H20=0,"",I20+ROW()/1000000)
A21: 17 | B21: 4 | C21: One correct option | D21: Medium | E21: [S] | F21: a | G21: =COUNTIF(Marks!R$5:R$43,1) | H21: =COUNT(Marks!R$5:R$43) | I21: =IF(H21=0,"",G21/H21) | J21: =IF(SUMPRODUCT((Marks!$AB$5:$AB$43="top")*ISNUMBER(Marks!R$5:R$43))=0,"",SUMPRODUCT((Marks!$AB$5:$AB$43="top")*(Marks!R$5:R$43=1))/SUMPRODUCT((Marks!$AB$5:$AB$43="top")*ISNUMBER(Marks!R$5:R$43))) | K21: =IF(SUMPRODUCT((Marks!$AB$5:$AB$43="bottom")*ISNUMBER(Marks!R$5:R$43))=0,"",SUMPRODUCT((Marks!$AB$5:$AB$43="bottom")*(Marks!R$5:R$43=1))/SUMPRODUCT((Marks!$AB$5:$AB$43="bottom")*ISNUMBER(Marks!R$5:R$43))) | L21: =IF(OR(J21="",K21=""),"",J21-K21) | M21: =IF(H21=0,"",IF(I21<0.2,"Check the item: fewer than one in five got it right",IF(AND(L21<>"",N(L21)<0),"Check the item: the bottom third beat the top third",""))) | N21: =IF(H21=0,"",I21+ROW()/1000000)
A22: 18 | B22: 4 | C22: More than one correct | D22: Medium | E22: [F] | F22: a, b, d | G22: =COUNTIF(Marks!S$5:S$43,1) | H22: =COUNT(Marks!S$5:S$43) | I22: =IF(H22=0,"",G22/H22) | J22: =IF(SUMPRODUCT((Marks!$AB$5:$AB$43="top")*ISNUMBER(Marks!S$5:S$43))=0,"",SUMPRODUCT((Marks!$AB$5:$AB$43="top")*(Marks!S$5:S$43=1))/SUMPRODUCT((Marks!$AB$5:$AB$43="top")*ISNUMBER(Marks!S$5:S$43))) | K22: =IF(SUMPRODUCT((Marks!$AB$5:$AB$43="bottom")*ISNUMBER(Marks!S$5:S$43))=0,"",SUMPRODUCT((Marks!$AB$5:$AB$43="bottom")*(Marks!S$5:S$43=1))/SUMPRODUCT((Marks!$AB$5:$AB$43="bottom")*ISNUMBER(Marks!S$5:S$43))) | L22: =IF(OR(J22="",K22=""),"",J22-K22) | M22: =IF(H22=0,"",IF(I22<0.2,"Check the item: fewer than one in five got it right",IF(AND(L22<>"",N(L22)<0),"Check the item: the bottom third beat the top third",""))) | N22: =IF(H22=0,"",I22+ROW()/1000000)
A23: 19 | B23: 4 | C23: One correct option | D23: Hard | E23: [F] | F23: b | G23: =COUNTIF(Marks!T$5:T$43,1) | H23: =COUNT(Marks!T$5:T$43) | I23: =IF(H23=0,"",G23/H23) | J23: =IF(SUMPRODUCT((Marks!$AB$5:$AB$43="top")*ISNUMBER(Marks!T$5:T$43))=0,"",SUMPRODUCT((Marks!$AB$5:$AB$43="top")*(Marks!T$5:T$43=1))/SUMPRODUCT((Marks!$AB$5:$AB$43="top")*ISNUMBER(Marks!T$5:T$43))) | K23: =IF(SUMPRODUCT((Marks!$AB$5:$AB$43="bottom")*ISNUMBER(Marks!T$5:T$43))=0,"",SUMPRODUCT((Marks!$AB$5:$AB$43="bottom")*(Marks!T$5:T$43=1))/SUMPRODUCT((Marks!$AB$5:$AB$43="bottom")*ISNUMBER(Marks!T$5:T$43))) | L23: =IF(OR(J23="",K23=""),"",J23-K23) | M23: =IF(H23=0,"",IF(I23<0.2,"Check the item: fewer than one in five got it right",IF(AND(L23<>"",N(L23)<0),"Check the item: the bottom third beat the top third",""))) | N23: =IF(H23=0,"",I23+ROW()/1000000)
A24: 20 | B24: 4 | C24: True or false | D24: Hard | E24: [D] | F24: b | G24: =COUNTIF(Marks!U$5:U$43,1) | H24: =COUNT(Marks!U$5:U$43) | I24: =IF(H24=0,"",G24/H24) | J24: =IF(SUMPRODUCT((Marks!$AB$5:$AB$43="top")*ISNUMBER(Marks!U$5:U$43))=0,"",SUMPRODUCT((Marks!$AB$5:$AB$43="top")*(Marks!U$5:U$43=1))/SUMPRODUCT((Marks!$AB$5:$AB$43="top")*ISNUMBER(Marks!U$5:U$43))) | K24: =IF(SUMPRODUCT((Marks!$AB$5:$AB$43="bottom")*ISNUMBER(Marks!U$5:U$43))=0,"",SUMPRODUCT((Marks!$AB$5:$AB$43="bottom")*(Marks!U$5:U$43=1))/SUMPRODUCT((Marks!$AB$5:$AB$43="bottom")*ISNUMBER(Marks!U$5:U$43))) | L24: =IF(OR(J24="",K24=""),"",J24-K24) | M24: =IF(H24=0,"",IF(I24<0.2,"Check the item: fewer than one in five got it right",IF(AND(L24<>"",N(L24)<0),"Check the item: the bottom third beat the top third",""))) | N24: =IF(H24=0,"",I24+ROW()/1000000)
A25: 21 | B25: 5 | C25: One correct option | D25: Hard | E25: [F] | F25: a | G25: =COUNTIF(Marks!V$5:V$43,1) | H25: =COUNT(Marks!V$5:V$43) | I25: =IF(H25=0,"",G25/H25) | J25: =IF(SUMPRODUCT((Marks!$AB$5:$AB$43="top")*ISNUMBER(Marks!V$5:V$43))=0,"",SUMPRODUCT((Marks!$AB$5:$AB$43="top")*(Marks!V$5:V$43=1))/SUMPRODUCT((Marks!$AB$5:$AB$43="top")*ISNUMBER(Marks!V$5:V$43))) | K25: =IF(SUMPRODUCT((Marks!$AB$5:$AB$43="bottom")*ISNUMBER(Marks!V$5:V$43))=0,"",SUMPRODUCT((Marks!$AB$5:$AB$43="bottom")*(Marks!V$5:V$43=1))/SUMPRODUCT((Marks!$AB$5:$AB$43="bottom")*ISNUMBER(Marks!V$5:V$43))) | L25: =IF(OR(J25="",K25=""),"",J25-K25) | M25: =IF(H25=0,"",IF(I25<0.2,"Check the item: fewer than one in five got it right",IF(AND(L25<>"",N(L25)<0),"Check the item: the bottom third beat the top third",""))) | N25: =IF(H25=0,"",I25+ROW()/1000000)
A26: 22 | B26: 5 | C26: More than one correct | D26: Medium | E26: [D] | F26: b, c | G26: =COUNTIF(Marks!W$5:W$43,1) | H26: =COUNT(Marks!W$5:W$43) | I26: =IF(H26=0,"",G26/H26) | J26: =IF(SUMPRODUCT((Marks!$AB$5:$AB$43="top")*ISNUMBER(Marks!W$5:W$43))=0,"",SUMPRODUCT((Marks!$AB$5:$AB$43="top")*(Marks!W$5:W$43=1))/SUMPRODUCT((Marks!$AB$5:$AB$43="top")*ISNUMBER(Marks!W$5:W$43))) | K26: =IF(SUMPRODUCT((Marks!$AB$5:$AB$43="bottom")*ISNUMBER(Marks!W$5:W$43))=0,"",SUMPRODUCT((Marks!$AB$5:$AB$43="bottom")*(Marks!W$5:W$43=1))/SUMPRODUCT((Marks!$AB$5:$AB$43="bottom")*ISNUMBER(Marks!W$5:W$43))) | L26: =IF(OR(J26="",K26=""),"",J26-K26) | M26: =IF(H26=0,"",IF(I26<0.2,"Check the item: fewer than one in five got it right",IF(AND(L26<>"",N(L26)<0),"Check the item: the bottom third beat the top third",""))) | N26: =IF(H26=0,"",I26+ROW()/1000000)
A27: 23 | B27: 5 | C27: One correct option | D27: Medium | E27: [D] | F27: c | G27: =COUNTIF(Marks!X$5:X$43,1) | H27: =COUNT(Marks!X$5:X$43) | I27: =IF(H27=0,"",G27/H27) | J27: =IF(SUMPRODUCT((Marks!$AB$5:$AB$43="top")*ISNUMBER(Marks!X$5:X$43))=0,"",SUMPRODUCT((Marks!$AB$5:$AB$43="top")*(Marks!X$5:X$43=1))/SUMPRODUCT((Marks!$AB$5:$AB$43="top")*ISNUMBER(Marks!X$5:X$43))) | K27: =IF(SUMPRODUCT((Marks!$AB$5:$AB$43="bottom")*ISNUMBER(Marks!X$5:X$43))=0,"",SUMPRODUCT((Marks!$AB$5:$AB$43="bottom")*(Marks!X$5:X$43=1))/SUMPRODUCT((Marks!$AB$5:$AB$43="bottom")*ISNUMBER(Marks!X$5:X$43))) | L27: =IF(OR(J27="",K27=""),"",J27-K27) | M27: =IF(H27=0,"",IF(I27<0.2,"Check the item: fewer than one in five got it right",IF(AND(L27<>"",N(L27)<0),"Check the item: the bottom third beat the top third",""))) | N27: =IF(H27=0,"",I27+ROW()/1000000)
A28: 24 | B28: 5 | C28: One correct option | D28: Hard | E28: [D] | F28: b | G28: =COUNTIF(Marks!Y$5:Y$43,1) | H28: =COUNT(Marks!Y$5:Y$43) | I28: =IF(H28=0,"",G28/H28) | J28: =IF(SUMPRODUCT((Marks!$AB$5:$AB$43="top")*ISNUMBER(Marks!Y$5:Y$43))=0,"",SUMPRODUCT((Marks!$AB$5:$AB$43="top")*(Marks!Y$5:Y$43=1))/SUMPRODUCT((Marks!$AB$5:$AB$43="top")*ISNUMBER(Marks!Y$5:Y$43))) | K28: =IF(SUMPRODUCT((Marks!$AB$5:$AB$43="bottom")*ISNUMBER(Marks!Y$5:Y$43))=0,"",SUMPRODUCT((Marks!$AB$5:$AB$43="bottom")*(Marks!Y$5:Y$43=1))/SUMPRODUCT((Marks!$AB$5:$AB$43="bottom")*ISNUMBER(Marks!Y$5:Y$43))) | L28: =IF(OR(J28="",K28=""),"",J28-K28) | M28: =IF(H28=0,"",IF(I28<0.2,"Check the item: fewer than one in five got it right",IF(AND(L28<>"",N(L28)<0),"Check the item: the bottom third beat the top third",""))) | N28: =IF(H28=0,"",I28+ROW()/1000000)

Sheet Discussion
A1: The solution discussion, from the most-missed item
B2: =IF(SUM(Items!H5:H28)=0,"No marks entered yet.","Most-missed first: take the items from the top.")
A4: Order | B4: Q | C4: Right rate | D4: Part | E4: Tag | F4: Flag
A5: 1 | B5: =IF(COUNT(Items!$N$5:$N$28)<A5,"",INDEX(Items!$A$5:$A$28,MATCH(SMALL(Items!$N$5:$N$28,A5),Items!$N$5:$N$28,0))) | C5: =IF(B5="","",INDEX(Items!$I$5:$I$28,MATCH(B5,Items!$A$5:$A$28,0))) | D5: =IF(B5="","",INDEX(Items!$B$5:$B$28,MATCH(B5,Items!$A$5:$A$28,0))) | E5: =IF(B5="","",INDEX(Items!$E$5:$E$28,MATCH(B5,Items!$A$5:$A$28,0))) | F5: =IF(B5="","",INDEX(Items!$M$5:$M$28,MATCH(B5,Items!$A$5:$A$28,0)))
A6: 2 | B6: =IF(COUNT(Items!$N$5:$N$28)<A6,"",INDEX(Items!$A$5:$A$28,MATCH(SMALL(Items!$N$5:$N$28,A6),Items!$N$5:$N$28,0))) | C6: =IF(B6="","",INDEX(Items!$I$5:$I$28,MATCH(B6,Items!$A$5:$A$28,0))) | D6: =IF(B6="","",INDEX(Items!$B$5:$B$28,MATCH(B6,Items!$A$5:$A$28,0))) | E6: =IF(B6="","",INDEX(Items!$E$5:$E$28,MATCH(B6,Items!$A$5:$A$28,0))) | F6: =IF(B6="","",INDEX(Items!$M$5:$M$28,MATCH(B6,Items!$A$5:$A$28,0)))
A7: 3 | B7: =IF(COUNT(Items!$N$5:$N$28)<A7,"",INDEX(Items!$A$5:$A$28,MATCH(SMALL(Items!$N$5:$N$28,A7),Items!$N$5:$N$28,0))) | C7: =IF(B7="","",INDEX(Items!$I$5:$I$28,MATCH(B7,Items!$A$5:$A$28,0))) | D7: =IF(B7="","",INDEX(Items!$B$5:$B$28,MATCH(B7,Items!$A$5:$A$28,0))) | E7: =IF(B7="","",INDEX(Items!$E$5:$E$28,MATCH(B7,Items!$A$5:$A$28,0))) | F7: =IF(B7="","",INDEX(Items!$M$5:$M$28,MATCH(B7,Items!$A$5:$A$28,0)))
A8: 4 | B8: =IF(COUNT(Items!$N$5:$N$28)<A8,"",INDEX(Items!$A$5:$A$28,MATCH(SMALL(Items!$N$5:$N$28,A8),Items!$N$5:$N$28,0))) | C8: =IF(B8="","",INDEX(Items!$I$5:$I$28,MATCH(B8,Items!$A$5:$A$28,0))) | D8: =IF(B8="","",INDEX(Items!$B$5:$B$28,MATCH(B8,Items!$A$5:$A$28,0))) | E8: =IF(B8="","",INDEX(Items!$E$5:$E$28,MATCH(B8,Items!$A$5:$A$28,0))) | F8: =IF(B8="","",INDEX(Items!$M$5:$M$28,MATCH(B8,Items!$A$5:$A$28,0)))
A9: 5 | B9: =IF(COUNT(Items!$N$5:$N$28)<A9,"",INDEX(Items!$A$5:$A$28,MATCH(SMALL(Items!$N$5:$N$28,A9),Items!$N$5:$N$28,0))) | C9: =IF(B9="","",INDEX(Items!$I$5:$I$28,MATCH(B9,Items!$A$5:$A$28,0))) | D9: =IF(B9="","",INDEX(Items!$B$5:$B$28,MATCH(B9,Items!$A$5:$A$28,0))) | E9: =IF(B9="","",INDEX(Items!$E$5:$E$28,MATCH(B9,Items!$A$5:$A$28,0))) | F9: =IF(B9="","",INDEX(Items!$M$5:$M$28,MATCH(B9,Items!$A$5:$A$28,0)))
A10: 6 | B10: =IF(COUNT(Items!$N$5:$N$28)<A10,"",INDEX(Items!$A$5:$A$28,MATCH(SMALL(Items!$N$5:$N$28,A10),Items!$N$5:$N$28,0))) | C10: =IF(B10="","",INDEX(Items!$I$5:$I$28,MATCH(B10,Items!$A$5:$A$28,0))) | D10: =IF(B10="","",INDEX(Items!$B$5:$B$28,MATCH(B10,Items!$A$5:$A$28,0))) | E10: =IF(B10="","",INDEX(Items!$E$5:$E$28,MATCH(B10,Items!$A$5:$A$28,0))) | F10: =IF(B10="","",INDEX(Items!$M$5:$M$28,MATCH(B10,Items!$A$5:$A$28,0)))
A11: 7 | B11: =IF(COUNT(Items!$N$5:$N$28)<A11,"",INDEX(Items!$A$5:$A$28,MATCH(SMALL(Items!$N$5:$N$28,A11),Items!$N$5:$N$28,0))) | C11: =IF(B11="","",INDEX(Items!$I$5:$I$28,MATCH(B11,Items!$A$5:$A$28,0))) | D11: =IF(B11="","",INDEX(Items!$B$5:$B$28,MATCH(B11,Items!$A$5:$A$28,0))) | E11: =IF(B11="","",INDEX(Items!$E$5:$E$28,MATCH(B11,Items!$A$5:$A$28,0))) | F11: =IF(B11="","",INDEX(Items!$M$5:$M$28,MATCH(B11,Items!$A$5:$A$28,0)))
A12: 8 | B12: =IF(COUNT(Items!$N$5:$N$28)<A12,"",INDEX(Items!$A$5:$A$28,MATCH(SMALL(Items!$N$5:$N$28,A12),Items!$N$5:$N$28,0))) | C12: =IF(B12="","",INDEX(Items!$I$5:$I$28,MATCH(B12,Items!$A$5:$A$28,0))) | D12: =IF(B12="","",INDEX(Items!$B$5:$B$28,MATCH(B12,Items!$A$5:$A$28,0))) | E12: =IF(B12="","",INDEX(Items!$E$5:$E$28,MATCH(B12,Items!$A$5:$A$28,0))) | F12: =IF(B12="","",INDEX(Items!$M$5:$M$28,MATCH(B12,Items!$A$5:$A$28,0)))
A13: 9 | B13: =IF(COUNT(Items!$N$5:$N$28)<A13,"",INDEX(Items!$A$5:$A$28,MATCH(SMALL(Items!$N$5:$N$28,A13),Items!$N$5:$N$28,0))) | C13: =IF(B13="","",INDEX(Items!$I$5:$I$28,MATCH(B13,Items!$A$5:$A$28,0))) | D13: =IF(B13="","",INDEX(Items!$B$5:$B$28,MATCH(B13,Items!$A$5:$A$28,0))) | E13: =IF(B13="","",INDEX(Items!$E$5:$E$28,MATCH(B13,Items!$A$5:$A$28,0))) | F13: =IF(B13="","",INDEX(Items!$M$5:$M$28,MATCH(B13,Items!$A$5:$A$28,0)))
A14: 10 | B14: =IF(COUNT(Items!$N$5:$N$28)<A14,"",INDEX(Items!$A$5:$A$28,MATCH(SMALL(Items!$N$5:$N$28,A14),Items!$N$5:$N$28,0))) | C14: =IF(B14="","",INDEX(Items!$I$5:$I$28,MATCH(B14,Items!$A$5:$A$28,0))) | D14: =IF(B14="","",INDEX(Items!$B$5:$B$28,MATCH(B14,Items!$A$5:$A$28,0))) | E14: =IF(B14="","",INDEX(Items!$E$5:$E$28,MATCH(B14,Items!$A$5:$A$28,0))) | F14: =IF(B14="","",INDEX(Items!$M$5:$M$28,MATCH(B14,Items!$A$5:$A$28,0)))
A15: 11 | B15: =IF(COUNT(Items!$N$5:$N$28)<A15,"",INDEX(Items!$A$5:$A$28,MATCH(SMALL(Items!$N$5:$N$28,A15),Items!$N$5:$N$28,0))) | C15: =IF(B15="","",INDEX(Items!$I$5:$I$28,MATCH(B15,Items!$A$5:$A$28,0))) | D15: =IF(B15="","",INDEX(Items!$B$5:$B$28,MATCH(B15,Items!$A$5:$A$28,0))) | E15: =IF(B15="","",INDEX(Items!$E$5:$E$28,MATCH(B15,Items!$A$5:$A$28,0))) | F15: =IF(B15="","",INDEX(Items!$M$5:$M$28,MATCH(B15,Items!$A$5:$A$28,0)))
A16: 12 | B16: =IF(COUNT(Items!$N$5:$N$28)<A16,"",INDEX(Items!$A$5:$A$28,MATCH(SMALL(Items!$N$5:$N$28,A16),Items!$N$5:$N$28,0))) | C16: =IF(B16="","",INDEX(Items!$I$5:$I$28,MATCH(B16,Items!$A$5:$A$28,0))) | D16: =IF(B16="","",INDEX(Items!$B$5:$B$28,MATCH(B16,Items!$A$5:$A$28,0))) | E16: =IF(B16="","",INDEX(Items!$E$5:$E$28,MATCH(B16,Items!$A$5:$A$28,0))) | F16: =IF(B16="","",INDEX(Items!$M$5:$M$28,MATCH(B16,Items!$A$5:$A$28,0)))
... A28: 24 | B28: =IF(COUNT(Items!$N$5:$N$28)<A28,"",INDEX(Items!$A$5:$A$28,MATCH(SMALL(Items!$N$5:$N$28,A28),Items!$N$5:$N$28,0))) | C28: =IF(B28="","",INDEX(Items!$I$5:$I$28,MATCH(B28,Items!$A$5:$A$28,0))) | D28: =IF(B28="","",INDEX(Items!$B$5:$B$28,MATCH(B28,Items!$A$5:$A$28,0))) | E28: =IF(B28="","",INDEX(Items!$E$5:$E$28,MATCH(B28,Items!$A$5:$A$28,0))) | F28: =IF(B28="","",INDEX(Items!$M$5:$M$28,MATCH(B28,Items!$A$5:$A$28,0)))

Sheet Tags
A1: The room's rate by tag and by part
A4: Tag or part | B4: Name | C4: Items | D4: Right rate
A5: [S] | B5: tag | C5: =COUNTIF(Items!$E$5:$E$28,A5) | D5: =IF(SUMPRODUCT((Items!$E$5:$E$28=A5)*Items!$H$5:$H$28)=0,"",SUMPRODUCT((Items!$E$5:$E$28=A5)*Items!$G$5:$G$28)/SUMPRODUCT((Items!$E$5:$E$28=A5)*Items!$H$5:$H$28))
A6: [F] | B6: tag | C6: =COUNTIF(Items!$E$5:$E$28,A6) | D6: =IF(SUMPRODUCT((Items!$E$5:$E$28=A6)*Items!$H$5:$H$28)=0,"",SUMPRODUCT((Items!$E$5:$E$28=A6)*Items!$G$5:$G$28)/SUMPRODUCT((Items!$E$5:$E$28=A6)*Items!$H$5:$H$28))
A7: [D] | B7: tag | C7: =COUNTIF(Items!$E$5:$E$28,A7) | D7: =IF(SUMPRODUCT((Items!$E$5:$E$28=A7)*Items!$H$5:$H$28)=0,"",SUMPRODUCT((Items!$E$5:$E$28=A7)*Items!$G$5:$G$28)/SUMPRODUCT((Items!$E$5:$E$28=A7)*Items!$H$5:$H$28))
A8: 1 | B8: Part 1. Should the bank build a model, and what must it beat? | C8: =COUNTIF(Items!$B$5:$B$28,A8) | D8: =IF(SUMPRODUCT((Items!$B$5:$B$28=A8)*Items!$H$5:$H$28)=0,"",SUMPRODUCT((Items!$B$5:$B$28=A8)*Items!$G$5:$G$28)/SUMPRODUCT((Items!$B$5:$B$28=A8)*Items!$H$5:$H$28))
A9: 2 | B9: Part 2. Which number tells the truth, and where does the line go? | C9: =COUNTIF(Items!$B$5:$B$28,A9) | D9: =IF(SUMPRODUCT((Items!$B$5:$B$28=A9)*Items!$H$5:$H$28)=0,"",SUMPRODUCT((Items!$B$5:$B$28=A9)*Items!$G$5:$G$28)/SUMPRODUCT((Items!$B$5:$B$28=A9)*Items!$H$5:$H$28))
A10: 3 | B10: Part 3. What was the model allowed to know? | C10: =COUNTIF(Items!$B$5:$B$28,A10) | D10: =IF(SUMPRODUCT((Items!$B$5:$B$28=A10)*Items!$H$5:$H$28)=0,"",SUMPRODUCT((Items!$B$5:$B$28=A10)*Items!$G$5:$G$28)/SUMPRODUCT((Items!$B$5:$B$28=A10)*Items!$H$5:$H$28))
A11: 4 | B11: Part 4. Is the model learning, or memorising? | C11: =COUNTIF(Items!$B$5:$B$28,A11) | D11: =IF(SUMPRODUCT((Items!$B$5:$B$28=A11)*Items!$H$5:$H$28)=0,"",SUMPRODUCT((Items!$B$5:$B$28=A11)*Items!$G$5:$G$28)/SUMPRODUCT((Items!$B$5:$B$28=A11)*Items!$H$5:$H$28))
A12: 5 | B12: Part 5. Would the committee sign, and what moves to lending? | C12: =COUNTIF(Items!$B$5:$B$28,A12) | D12: =IF(SUMPRODUCT((Items!$B$5:$B$28=A12)*Items!$H$5:$H$28)=0,"",SUMPRODUCT((Items!$B$5:$B$28=A12)*Items!$G$5:$G$28)/SUMPRODUCT((Items!$B$5:$B$28=A12)*Items!$H$5:$H$28))

Sheet Seats
A1: Each seat's rate by tag, for Monday's remediation read
A4: Seat | B4: [S] | C4: [F] | D4: [D]
A5: 1 | B5: =IF(SUMPRODUCT((Marks!$B$3:$Y$3=B$4)*ISNUMBER(Marks!$B$5:$Y$5))=0,"",SUMPRODUCT((Marks!$B$3:$Y$3=B$4)*(Marks!$B$5:$Y$5=1))/SUMPRODUCT((Marks!$B$3:$Y$3=B$4)*ISNUMBER(Marks!$B$5:$Y$5))) | C5: =IF(SUMPRODUCT((Marks!$B$3:$Y$3=C$4)*ISNUMBER(Marks!$B$5:$Y$5))=0,"",SUMPRODUCT((Marks!$B$3:$Y$3=C$4)*(Marks!$B$5:$Y$5=1))/SUMPRODUCT((Marks!$B$3:$Y$3=C$4)*ISNUMBER(Marks!$B$5:$Y$5))) | D5: =IF(SUMPRODUCT((Marks!$B$3:$Y$3=D$4)*ISNUMBER(Marks!$B$5:$Y$5))=0,"",SUMPRODUCT((Marks!$B$3:$Y$3=D$4)*(Marks!$B$5:$Y$5=1))/SUMPRODUCT((Marks!$B$3:$Y$3=D$4)*ISNUMBER(Marks!$B$5:$Y$5)))
A6: 2 | B6: =IF(SUMPRODUCT((Marks!$B$3:$Y$3=B$4)*ISNUMBER(Marks!$B$6:$Y$6))=0,"",SUMPRODUCT((Marks!$B$3:$Y$3=B$4)*(Marks!$B$6:$Y$6=1))/SUMPRODUCT((Marks!$B$3:$Y$3=B$4)*ISNUMBER(Marks!$B$6:$Y$6))) | C6: =IF(SUMPRODUCT((Marks!$B$3:$Y$3=C$4)*ISNUMBER(Marks!$B$6:$Y$6))=0,"",SUMPRODUCT((Marks!$B$3:$Y$3=C$4)*(Marks!$B$6:$Y$6=1))/SUMPRODUCT((Marks!$B$3:$Y$3=C$4)*ISNUMBER(Marks!$B$6:$Y$6))) | D6: =IF(SUMPRODUCT((Marks!$B$3:$Y$3=D$4)*ISNUMBER(Marks!$B$6:$Y$6))=0,"",SUMPRODUCT((Marks!$B$3:$Y$3=D$4)*(Marks!$B$6:$Y$6=1))/SUMPRODUCT((Marks!$B$3:$Y$3=D$4)*ISNUMBER(Marks!$B$6:$Y$6)))
A7: 3 | B7: =IF(SUMPRODUCT((Marks!$B$3:$Y$3=B$4)*ISNUMBER(Marks!$B$7:$Y$7))=0,"",SUMPRODUCT((Marks!$B$3:$Y$3=B$4)*(Marks!$B$7:$Y$7=1))/SUMPRODUCT((Marks!$B$3:$Y$3=B$4)*ISNUMBER(Marks!$B$7:$Y$7))) | C7: =IF(SUMPRODUCT((Marks!$B$3:$Y$3=C$4)*ISNUMBER(Marks!$B$7:$Y$7))=0,"",SUMPRODUCT((Marks!$B$3:$Y$3=C$4)*(Marks!$B$7:$Y$7=1))/SUMPRODUCT((Marks!$B$3:$Y$3=C$4)*ISNUMBER(Marks!$B$7:$Y$7))) | D7: =IF(SUMPRODUCT((Marks!$B$3:$Y$3=D$4)*ISNUMBER(Marks!$B$7:$Y$7))=0,"",SUMPRODUCT((Marks!$B$3:$Y$3=D$4)*(Marks!$B$7:$Y$7=1))/SUMPRODUCT((Marks!$B$3:$Y$3=D$4)*ISNUMBER(Marks!$B$7:$Y$7)))
A8: 4 | B8: =IF(SUMPRODUCT((Marks!$B$3:$Y$3=B$4)*ISNUMBER(Marks!$B$8:$Y$8))=0,"",SUMPRODUCT((Marks!$B$3:$Y$3=B$4)*(Marks!$B$8:$Y$8=1))/SUMPRODUCT((Marks!$B$3:$Y$3=B$4)*ISNUMBER(Marks!$B$8:$Y$8))) | C8: =IF(SUMPRODUCT((Marks!$B$3:$Y$3=C$4)*ISNUMBER(Marks!$B$8:$Y$8))=0,"",SUMPRODUCT((Marks!$B$3:$Y$3=C$4)*(Marks!$B$8:$Y$8=1))/SUMPRODUCT((Marks!$B$3:$Y$3=C$4)*ISNUMBER(Marks!$B$8:$Y$8))) | D8: =IF(SUMPRODUCT((Marks!$B$3:$Y$3=D$4)*ISNUMBER(Marks!$B$8:$Y$8))=0,"",SUMPRODUCT((Marks!$B$3:$Y$3=D$4)*(Marks!$B$8:$Y$8=1))/SUMPRODUCT((Marks!$B$3:$Y$3=D$4)*ISNUMBER(Marks!$B$8:$Y$8)))
A9: 5 | B9: =IF(SUMPRODUCT((Marks!$B$3:$Y$3=B$4)*ISNUMBER(Marks!$B$9:$Y$9))=0,"",SUMPRODUCT((Marks!$B$3:$Y$3=B$4)*(Marks!$B$9:$Y$9=1))/SUMPRODUCT((Marks!$B$3:$Y$3=B$4)*ISNUMBER(Marks!$B$9:$Y$9))) | C9: =IF(SUMPRODUCT((Marks!$B$3:$Y$3=C$4)*ISNUMBER(Marks!$B$9:$Y$9))=0,"",SUMPRODUCT((Marks!$B$3:$Y$3=C$4)*(Marks!$B$9:$Y$9=1))/SUMPRODUCT((Marks!$B$3:$Y$3=C$4)*ISNUMBER(Marks!$B$9:$Y$9))) | D9: =IF(SUMPRODUCT((Marks!$B$3:$Y$3=D$4)*ISNUMBER(Marks!$B$9:$Y$9))=0,"",SUMPRODUCT((Marks!$B$3:$Y$3=D$4)*(Marks!$B$9:$Y$9=1))/SUMPRODUCT((Marks!$B$3:$Y$3=D$4)*ISNUMBER(Marks!$B$9:$Y$9)))
A10: 6 | B10: =IF(SUMPRODUCT((Marks!$B$3:$Y$3=B$4)*ISNUMBER(Marks!$B$10:$Y$10))=0,"",SUMPRODUCT((Marks!$B$3:$Y$3=B$4)*(Marks!$B$10:$Y$10=1))/SUMPRODUCT((Marks!$B$3:$Y$3=B$4)*ISNUMBER(Marks!$B$10:$Y$10))) | C10: =IF(SUMPRODUCT((Marks!$B$3:$Y$3=C$4)*ISNUMBER(Marks!$B$10:$Y$10))=0,"",SUMPRODUCT((Marks!$B$3:$Y$3=C$4)*(Marks!$B$10:$Y$10=1))/SUMPRODUCT((Marks!$B$3:$Y$3=C$4)*ISNUMBER(Marks!$B$10:$Y$10))) | D10: =IF(SUMPRODUCT((Marks!$B$3:$Y$3=D$4)*ISNUMBER(Marks!$B$10:$Y$10))=0,"",SUMPRODUCT((Marks!$B$3:$Y$3=D$4)*(Marks!$B$10:$Y$10=1))/SUMPRODUCT((Marks!$B$3:$Y$3=D$4)*ISNUMBER(Marks!$B$10:$Y$10)))
A11: 7 | B11: =IF(SUMPRODUCT((Marks!$B$3:$Y$3=B$4)*ISNUMBER(Marks!$B$11:$Y$11))=0,"",SUMPRODUCT((Marks!$B$3:$Y$3=B$4)*(Marks!$B$11:$Y$11=1))/SUMPRODUCT((Marks!$B$3:$Y$3=B$4)*ISNUMBER(Marks!$B$11:$Y$11))) | C11: =IF(SUMPRODUCT((Marks!$B$3:$Y$3=C$4)*ISNUMBER(Marks!$B$11:$Y$11))=0,"",SUMPRODUCT((Marks!$B$3:$Y$3=C$4)*(Marks!$B$11:$Y$11=1))/SUMPRODUCT((Marks!$B$3:$Y$3=C$4)*ISNUMBER(Marks!$B$11:$Y$11))) | D11: =IF(SUMPRODUCT((Marks!$B$3:$Y$3=D$4)*ISNUMBER(Marks!$B$11:$Y$11))=0,"",SUMPRODUCT((Marks!$B$3:$Y$3=D$4)*(Marks!$B$11:$Y$11=1))/SUMPRODUCT((Marks!$B$3:$Y$3=D$4)*ISNUMBER(Marks!$B$11:$Y$11)))
A12: 8 | B12: =IF(SUMPRODUCT((Marks!$B$3:$Y$3=B$4)*ISNUMBER(Marks!$B$12:$Y$12))=0,"",SUMPRODUCT((Marks!$B$3:$Y$3=B$4)*(Marks!$B$12:$Y$12=1))/SUMPRODUCT((Marks!$B$3:$Y$3=B$4)*ISNUMBER(Marks!$B$12:$Y$12))) | C12: =IF(SUMPRODUCT((Marks!$B$3:$Y$3=C$4)*ISNUMBER(Marks!$B$12:$Y$12))=0,"",SUMPRODUCT((Marks!$B$3:$Y$3=C$4)*(Marks!$B$12:$Y$12=1))/SUMPRODUCT((Marks!$B$3:$Y$3=C$4)*ISNUMBER(Marks!$B$12:$Y$12))) | D12: =IF(SUMPRODUCT((Marks!$B$3:$Y$3=D$4)*ISNUMBER(Marks!$B$12:$Y$12))=0,"",SUMPRODUCT((Marks!$B$3:$Y$3=D$4)*(Marks!$B$12:$Y$12=1))/SUMPRODUCT((Marks!$B$3:$Y$3=D$4)*ISNUMBER(Marks!$B$12:$Y$12)))
A13: 9 | B13: =IF(SUMPRODUCT((Marks!$B$3:$Y$3=B$4)*ISNUMBER(Marks!$B$13:$Y$13))=0,"",SUMPRODUCT((Marks!$B$3:$Y$3=B$4)*(Marks!$B$13:$Y$13=1))/SUMPRODUCT((Marks!$B$3:$Y$3=B$4)*ISNUMBER(Marks!$B$13:$Y$13))) | C13: =IF(SUMPRODUCT((Marks!$B$3:$Y$3=C$4)*ISNUMBER(Marks!$B$13:$Y$13))=0,"",SUMPRODUCT((Marks!$B$3:$Y$3=C$4)*(Marks!$B$13:$Y$13=1))/SUMPRODUCT((Marks!$B$3:$Y$3=C$4)*ISNUMBER(Marks!$B$13:$Y$13))) | D13: =IF(SUMPRODUCT((Marks!$B$3:$Y$3=D$4)*ISNUMBER(Marks!$B$13:$Y$13))=0,"",SUMPRODUCT((Marks!$B$3:$Y$3=D$4)*(Marks!$B$13:$Y$13=1))/SUMPRODUCT((Marks!$B$3:$Y$3=D$4)*ISNUMBER(Marks!$B$13:$Y$13)))
A14: 10 | B14: =IF(SUMPRODUCT((Marks!$B$3:$Y$3=B$4)*ISNUMBER(Marks!$B$14:$Y$14))=0,"",SUMPRODUCT((Marks!$B$3:$Y$3=B$4)*(Marks!$B$14:$Y$14=1))/SUMPRODUCT((Marks!$B$3:$Y$3=B$4)*ISNUMBER(Marks!$B$14:$Y$14))) | C14: =IF(SUMPRODUCT((Marks!$B$3:$Y$3=C$4)*ISNUMBER(Marks!$B$14:$Y$14))=0,"",SUMPRODUCT((Marks!$B$3:$Y$3=C$4)*(Marks!$B$14:$Y$14=1))/SUMPRODUCT((Marks!$B$3:$Y$3=C$4)*ISNUMBER(Marks!$B$14:$Y$14))) | D14: =IF(SUMPRODUCT((Marks!$B$3:$Y$3=D$4)*ISNUMBER(Marks!$B$14:$Y$14))=0,"",SUMPRODUCT((Marks!$B$3:$Y$3=D$4)*(Marks!$B$14:$Y$14=1))/SUMPRODUCT((Marks!$B$3:$Y$3=D$4)*ISNUMBER(Marks!$B$14:$Y$14)))
A15: 11 | B15: =IF(SUMPRODUCT((Marks!$B$3:$Y$3=B$4)*ISNUMBER(Marks!$B$15:$Y$15))=0,"",SUMPRODUCT((Marks!$B$3:$Y$3=B$4)*(Marks!$B$15:$Y$15=1))/SUMPRODUCT((Marks!$B$3:$Y$3=B$4)*ISNUMBER(Marks!$B$15:$Y$15))) | C15: =IF(SUMPRODUCT((Marks!$B$3:$Y$3=C$4)*ISNUMBER(Marks!$B$15:$Y$15))=0,"",SUMPRODUCT((Marks!$B$3:$Y$3=C$4)*(Marks!$B$15:$Y$15=1))/SUMPRODUCT((Marks!$B$3:$Y$3=C$4)*ISNUMBER(Marks!$B$15:$Y$15))) | D15: =IF(SUMPRODUCT((Marks!$B$3:$Y$3=D$4)*ISNUMBER(Marks!$B$15:$Y$15))=0,"",SUMPRODUCT((Marks!$B$3:$Y$3=D$4)*(Marks!$B$15:$Y$15=1))/SUMPRODUCT((Marks!$B$3:$Y$3=D$4)*ISNUMBER(Marks!$B$15:$Y$15)))
A16: 12 | B16: =IF(SUMPRODUCT((Marks!$B$3:$Y$3=B$4)*ISNUMBER(Marks!$B$16:$Y$16))=0,"",SUMPRODUCT((Marks!$B$3:$Y$3=B$4)*(Marks!$B$16:$Y$16=1))/SUMPRODUCT((Marks!$B$3:$Y$3=B$4)*ISNUMBER(Marks!$B$16:$Y$16))) | C16: =IF(SUMPRODUCT((Marks!$B$3:$Y$3=C$4)*ISNUMBER(Marks!$B$16:$Y$16))=0,"",SUMPRODUCT((Marks!$B$3:$Y$3=C$4)*(Marks!$B$16:$Y$16=1))/SUMPRODUCT((Marks!$B$3:$Y$3=C$4)*ISNUMBER(Marks!$B$16:$Y$16))) | D16: =IF(SUMPRODUCT((Marks!$B$3:$Y$3=D$4)*ISNUMBER(Marks!$B$16:$Y$16))=0,"",SUMPRODUCT((Marks!$B$3:$Y$3=D$4)*(Marks!$B$16:$Y$16=1))/SUMPRODUCT((Marks!$B$3:$Y$3=D$4)*ISNUMBER(Marks!$B$16:$Y$16)))
A17: 13 | B17: =IF(SUMPRODUCT((Marks!$B$3:$Y$3=B$4)*ISNUMBER(Marks!$B$17:$Y$17))=0,"",SUMPRODUCT((Marks!$B$3:$Y$3=B$4)*(Marks!$B$17:$Y$17=1))/SUMPRODUCT((Marks!$B$3:$Y$3=B$4)*ISNUMBER(Marks!$B$17:$Y$17))) | C17: =IF(SUMPRODUCT((Marks!$B$3:$Y$3=C$4)*ISNUMBER(Marks!$B$17:$Y$17))=0,"",SUMPRODUCT((Marks!$B$3:$Y$3=C$4)*(Marks!$B$17:$Y$17=1))/SUMPRODUCT((Marks!$B$3:$Y$3=C$4)*ISNUMBER(Marks!$B$17:$Y$17))) | D17: =IF(SUMPRODUCT((Marks!$B$3:$Y$3=D$4)*ISNUMBER(Marks!$B$17:$Y$17))=0,"",SUMPRODUCT((Marks!$B$3:$Y$3=D$4)*(Marks!$B$17:$Y$17=1))/SUMPRODUCT((Marks!$B$3:$Y$3=D$4)*ISNUMBER(Marks!$B$17:$Y$17)))
A18: 14 | B18: =IF(SUMPRODUCT((Marks!$B$3:$Y$3=B$4)*ISNUMBER(Marks!$B$18:$Y$18))=0,"",SUMPRODUCT((Marks!$B$3:$Y$3=B$4)*(Marks!$B$18:$Y$18=1))/SUMPRODUCT((Marks!$B$3:$Y$3=B$4)*ISNUMBER(Marks!$B$18:$Y$18))) | C18: =IF(SUMPRODUCT((Marks!$B$3:$Y$3=C$4)*ISNUMBER(Marks!$B$18:$Y$18))=0,"",SUMPRODUCT((Marks!$B$3:$Y$3=C$4)*(Marks!$B$18:$Y$18=1))/SUMPRODUCT((Marks!$B$3:$Y$3=C$4)*ISNUMBER(Marks!$B$18:$Y$18))) | D18: =IF(SUMPRODUCT((Marks!$B$3:$Y$3=D$4)*ISNUMBER(Marks!$B$18:$Y$18))=0,"",SUMPRODUCT((Marks!$B$3:$Y$3=D$4)*(Marks!$B$18:$Y$18=1))/SUMPRODUCT((Marks!$B$3:$Y$3=D$4)*ISNUMBER(Marks!$B$18:$Y$18)))
A19: 15 | B19: =IF(SUMPRODUCT((Marks!$B$3:$Y$3=B$4)*ISNUMBER(Marks!$B$19:$Y$19))=0,"",SUMPRODUCT((Marks!$B$3:$Y$3=B$4)*(Marks!$B$19:$Y$19=1))/SUMPRODUCT((Marks!$B$3:$Y$3=B$4)*ISNUMBER(Marks!$B$19:$Y$19))) | C19: =IF(SUMPRODUCT((Marks!$B$3:$Y$3=C$4)*ISNUMBER(Marks!$B$19:$Y$19))=0,"",SUMPRODUCT((Marks!$B$3:$Y$3=C$4)*(Marks!$B$19:$Y$19=1))/SUMPRODUCT((Marks!$B$3:$Y$3=C$4)*ISNUMBER(Marks!$B$19:$Y$19))) | D19: =IF(SUMPRODUCT((Marks!$B$3:$Y$3=D$4)*ISNUMBER(Marks!$B$19:$Y$19))=0,"",SUMPRODUCT((Marks!$B$3:$Y$3=D$4)*(Marks!$B$19:$Y$19=1))/SUMPRODUCT((Marks!$B$3:$Y$3=D$4)*ISNUMBER(Marks!$B$19:$Y$19)))
A20: 16 | B20: =IF(SUMPRODUCT((Marks!$B$3:$Y$3=B$4)*ISNUMBER(Marks!$B$20:$Y$20))=0,"",SUMPRODUCT((Marks!$B$3:$Y$3=B$4)*(Marks!$B$20:$Y$20=1))/SUMPRODUCT((Marks!$B$3:$Y$3=B$4)*ISNUMBER(Marks!$B$20:$Y$20))) | C20: =IF(SUMPRODUCT((Marks!$B$3:$Y$3=C$4)*ISNUMBER(Marks!$B$20:$Y$20))=0,"",SUMPRODUCT((Marks!$B$3:$Y$3=C$4)*(Marks!$B$20:$Y$20=1))/SUMPRODUCT((Marks!$B$3:$Y$3=C$4)*ISNUMBER(Marks!$B$20:$Y$20))) | D20: =IF(SUMPRODUCT((Marks!$B$3:$Y$3=D$4)*ISNUMBER(Marks!$B$20:$Y$20))=0,"",SUMPRODUCT((Marks!$B$3:$Y$3=D$4)*(Marks!$B$20:$Y$20=1))/SUMPRODUCT((Marks!$B$3:$Y$3=D$4)*ISNUMBER(Marks!$B$20:$Y$20)))
A21: 17 | B21: =IF(SUMPRODUCT((Marks!$B$3:$Y$3=B$4)*ISNUMBER(Marks!$B$21:$Y$21))=0,"",SUMPRODUCT((Marks!$B$3:$Y$3=B$4)*(Marks!$B$21:$Y$21=1))/SUMPRODUCT((Marks!$B$3:$Y$3=B$4)*ISNUMBER(Marks!$B$21:$Y$21))) | C21: =IF(SUMPRODUCT((Marks!$B$3:$Y$3=C$4)*ISNUMBER(Marks!$B$21:$Y$21))=0,"",SUMPRODUCT((Marks!$B$3:$Y$3=C$4)*(Marks!$B$21:$Y$21=1))/SUMPRODUCT((Marks!$B$3:$Y$3=C$4)*ISNUMBER(Marks!$B$21:$Y$21))) | D21: =IF(SUMPRODUCT((Marks!$B$3:$Y$3=D$4)*ISNUMBER(Marks!$B$21:$Y$21))=0,"",SUMPRODUCT((Marks!$B$3:$Y$3=D$4)*(Marks!$B$21:$Y$21=1))/SUMPRODUCT((Marks!$B$3:$Y$3=D$4)*ISNUMBER(Marks!$B$21:$Y$21)))
A22: 18 | B22: =IF(SUMPRODUCT((Marks!$B$3:$Y$3=B$4)*ISNUMBER(Marks!$B$22:$Y$22))=0,"",SUMPRODUCT((Marks!$B$3:$Y$3=B$4)*(Marks!$B$22:$Y$22=1))/SUMPRODUCT((Marks!$B$3:$Y$3=B$4)*ISNUMBER(Marks!$B$22:$Y$22))) | C22: =IF(SUMPRODUCT((Marks!$B$3:$Y$3=C$4)*ISNUMBER(Marks!$B$22:$Y$22))=0,"",SUMPRODUCT((Marks!$B$3:$Y$3=C$4)*(Marks!$B$22:$Y$22=1))/SUMPRODUCT((Marks!$B$3:$Y$3=C$4)*ISNUMBER(Marks!$B$22:$Y$22))) | D22: =IF(SUMPRODUCT((Marks!$B$3:$Y$3=D$4)*ISNUMBER(Marks!$B$22:$Y$22))=0,"",SUMPRODUCT((Marks!$B$3:$Y$3=D$4)*(Marks!$B$22:$Y$22=1))/SUMPRODUCT((Marks!$B$3:$Y$3=D$4)*ISNUMBER(Marks!$B$22:$Y$22)))
A23: 19 | B23: =IF(SUMPRODUCT((Marks!$B$3:$Y$3=B$4)*ISNUMBER(Marks!$B$23:$Y$23))=0,"",SUMPRODUCT((Marks!$B$3:$Y$3=B$4)*(Marks!$B$23:$Y$23=1))/SUMPRODUCT((Marks!$B$3:$Y$3=B$4)*ISNUMBER(Marks!$B$23:$Y$23))) | C23: =IF(SUMPRODUCT((Marks!$B$3:$Y$3=C$4)*ISNUMBER(Marks!$B$23:$Y$23))=0,"",SUMPRODUCT((Marks!$B$3:$Y$3=C$4)*(Marks!$B$23:$Y$23=1))/SUMPRODUCT((Marks!$B$3:$Y$3=C$4)*ISNUMBER(Marks!$B$23:$Y$23))) | D23: =IF(SUMPRODUCT((Marks!$B$3:$Y$3=D$4)*ISNUMBER(Marks!$B$23:$Y$23))=0,"",SUMPRODUCT((Marks!$B$3:$Y$3=D$4)*(Marks!$B$23:$Y$23=1))/SUMPRODUCT((Marks!$B$3:$Y$3=D$4)*ISNUMBER(Marks!$B$23:$Y$23)))
A24: 20 | B24: =IF(SUMPRODUCT((Marks!$B$3:$Y$3=B$4)*ISNUMBER(Marks!$B$24:$Y$24))=0,"",SUMPRODUCT((Marks!$B$3:$Y$3=B$4)*(Marks!$B$24:$Y$24=1))/SUMPRODUCT((Marks!$B$3:$Y$3=B$4)*ISNUMBER(Marks!$B$24:$Y$24))) | C24: =IF(SUMPRODUCT((Marks!$B$3:$Y$3=C$4)*ISNUMBER(Marks!$B$24:$Y$24))=0,"",SUMPRODUCT((Marks!$B$3:$Y$3=C$4)*(Marks!$B$24:$Y$24=1))/SUMPRODUCT((Marks!$B$3:$Y$3=C$4)*ISNUMBER(Marks!$B$24:$Y$24))) | D24: =IF(SUMPRODUCT((Marks!$B$3:$Y$3=D$4)*ISNUMBER(Marks!$B$24:$Y$24))=0,"",SUMPRODUCT((Marks!$B$3:$Y$3=D$4)*(Marks!$B$24:$Y$24=1))/SUMPRODUCT((Marks!$B$3:$Y$3=D$4)*ISNUMBER(Marks!$B$24:$Y$24)))
A25: 21 | B25: =IF(SUMPRODUCT((Marks!$B$3:$Y$3=B$4)*ISNUMBER(Marks!$B$25:$Y$25))=0,"",SUMPRODUCT((Marks!$B$3:$Y$3=B$4)*(Marks!$B$25:$Y$25=1))/SUMPRODUCT((Marks!$B$3:$Y$3=B$4)*ISNUMBER(Marks!$B$25:$Y$25))) | C25: =IF(SUMPRODUCT((Marks!$B$3:$Y$3=C$4)*ISNUMBER(Marks!$B$25:$Y$25))=0,"",SUMPRODUCT((Marks!$B$3:$Y$3=C$4)*(Marks!$B$25:$Y$25=1))/SUMPRODUCT((Marks!$B$3:$Y$3=C$4)*ISNUMBER(Marks!$B$25:$Y$25))) | D25: =IF(SUMPRODUCT((Marks!$B$3:$Y$3=D$4)*ISNUMBER(Marks!$B$25:$Y$25))=0,"",SUMPRODUCT((Marks!$B$3:$Y$3=D$4)*(Marks!$B$25:$Y$25=1))/SUMPRODUCT((Marks!$B$3:$Y$3=D$4)*ISNUMBER(Marks!$B$25:$Y$25)))
A26: 22 | B26: =IF(SUMPRODUCT((Marks!$B$3:$Y$3=B$4)*ISNUMBER(Marks!$B$26:$Y$26))=0,"",SUMPRODUCT((Marks!$B$3:$Y$3=B$4)*(Marks!$B$26:$Y$26=1))/SUMPRODUCT((Marks!$B$3:$Y$3=B$4)*ISNUMBER(Marks!$B$26:$Y$26))) | C26: =IF(SUMPRODUCT((Marks!$B$3:$Y$3=C$4)*ISNUMBER(Marks!$B$26:$Y$26))=0,"",SUMPRODUCT((Marks!$B$3:$Y$3=C$4)*(Marks!$B$26:$Y$26=1))/SUMPRODUCT((Marks!$B$3:$Y$3=C$4)*ISNUMBER(Marks!$B$26:$Y$26))) | D26: =IF(SUMPRODUCT((Marks!$B$3:$Y$3=D$4)*ISNUMBER(Marks!$B$26:$Y$26))=0,"",SUMPRODUCT((Marks!$B$3:$Y$3=D$4)*(Marks!$B$26:$Y$26=1))/SUMPRODUCT((Marks!$B$3:$Y$3=D$4)*ISNUMBER(Marks!$B$26:$Y$26)))
A27: 23 | B27: =IF(SUMPRODUCT((Marks!$B$3:$Y$3=B$4)*ISNUMBER(Marks!$B$27:$Y$27))=0,"",SUMPRODUCT((Marks!$B$3:$Y$3=B$4)*(Marks!$B$27:$Y$27=1))/SUMPRODUCT((Marks!$B$3:$Y$3=B$4)*ISNUMBER(Marks!$B$27:$Y$27))) | C27: =IF(SUMPRODUCT((Marks!$B$3:$Y$3=C$4)*ISNUMBER(Marks!$B$27:$Y$27))=0,"",SUMPRODUCT((Marks!$B$3:$Y$3=C$4)*(Marks!$B$27:$Y$27=1))/SUMPRODUCT((Marks!$B$3:$Y$3=C$4)*ISNUMBER(Marks!$B$27:$Y$27))) | D27: =IF(SUMPRODUCT((Marks!$B$3:$Y$3=D$4)*ISNUMBER(Marks!$B$27:$Y$27))=0,"",SUMPRODUCT((Marks!$B$3:$Y$3=D$4)*(Marks!$B$27:$Y$27=1))/SUMPRODUCT((Marks!$B$3:$Y$3=D$4)*ISNUMBER(Marks!$B$27:$Y$27)))
A28: 24 | B28: =IF(SUMPRODUCT((Marks!$B$3:$Y$3=B$4)*ISNUMBER(Marks!$B$28:$Y$28))=0,"",SUMPRODUCT((Marks!$B$3:$Y$3=B$4)*(Marks!$B$28:$Y$28=1))/SUMPRODUCT((Marks!$B$3:$Y$3=B$4)*ISNUMBER(Marks!$B$28:$Y$28))) | C28: =IF(SUMPRODUCT((Marks!$B$3:$Y$3=C$4)*ISNUMBER(Marks!$B$28:$Y$28))=0,"",SUMPRODUCT((Marks!$B$3:$Y$3=C$4)*(Marks!$B$28:$Y$28=1))/SUMPRODUCT((Marks!$B$3:$Y$3=C$4)*ISNUMBER(Marks!$B$28:$Y$28))) | D28: =IF(SUMPRODUCT((Marks!$B$3:$Y$3=D$4)*ISNUMBER(Marks!$B$28:$Y$28))=0,"",SUMPRODUCT((Marks!$B$3:$Y$3=D$4)*(Marks!$B$28:$Y$28=1))/SUMPRODUCT((Marks!$B$3:$Y$3=D$4)*ISNUMBER(Marks!$B$28:$Y$28)))
A29: 25 | B29: =IF(SUMPRODUCT((Marks!$B$3:$Y$3=B$4)*ISNUMBER(Marks!$B$29:$Y$29))=0,"",SUMPRODUCT((Marks!$B$3:$Y$3=B$4)*(Marks!$B$29:$Y$29=1))/SUMPRODUCT((Marks!$B$3:$Y$3=B$4)*ISNUMBER(Marks!$B$29:$Y$29))) | C29: =IF(SUMPRODUCT((Marks!$B$3:$Y$3=C$4)*ISNUMBER(Marks!$B$29:$Y$29))=0,"",SUMPRODUCT((Marks!$B$3:$Y$3=C$4)*(Marks!$B$29:$Y$29=1))/SUMPRODUCT((Marks!$B$3:$Y$3=C$4)*ISNUMBER(Marks!$B$29:$Y$29))) | D29: =IF(SUMPRODUCT((Marks!$B$3:$Y$3=D$4)*ISNUMBER(Marks!$B$29:$Y$29))=0,"",SUMPRODUCT((Marks!$B$3:$Y$3=D$4)*(Marks!$B$29:$Y$29=1))/SUMPRODUCT((Marks!$B$3:$Y$3=D$4)*ISNUMBER(Marks!$B$29:$Y$29)))
A30: 26 | B30: =IF(SUMPRODUCT((Marks!$B$3:$Y$3=B$4)*ISNUMBER(Marks!$B$30:$Y$30))=0,"",SUMPRODUCT((Marks!$B$3:$Y$3=B$4)*(Marks!$B$30:$Y$30=1))/SUMPRODUCT((Marks!$B$3:$Y$3=B$4)*ISNUMBER(Marks!$B$30:$Y$30))) | C30: =IF(SUMPRODUCT((Marks!$B$3:$Y$3=C$4)*ISNUMBER(Marks!$B$30:$Y$30))=0,"",SUMPRODUCT((Marks!$B$3:$Y$3=C$4)*(Marks!$B$30:$Y$30=1))/SUMPRODUCT((Marks!$B$3:$Y$3=C$4)*ISNUMBER(Marks!$B$30:$Y$30))) | D30: =IF(SUMPRODUCT((Marks!$B$3:$Y$3=D$4)*ISNUMBER(Marks!$B$30:$Y$30))=0,"",SUMPRODUCT((Marks!$B$3:$Y$3=D$4)*(Marks!$B$30:$Y$30=1))/SUMPRODUCT((Marks!$B$3:$Y$3=D$4)*ISNUMBER(Marks!$B$30:$Y$30)))
A31: 27 | B31: =IF(SUMPRODUCT((Marks!$B$3:$Y$3=B$4)*ISNUMBER(Marks!$B$31:$Y$31))=0,"",SUMPRODUCT((Marks!$B$3:$Y$3=B$4)*(Marks!$B$31:$Y$31=1))/SUMPRODUCT((Marks!$B$3:$Y$3=B$4)*ISNUMBER(Marks!$B$31:$Y$31))) | C31: =IF(SUMPRODUCT((Marks!$B$3:$Y$3=C$4)*ISNUMBER(Marks!$B$31:$Y$31))=0,"",SUMPRODUCT((Marks!$B$3:$Y$3=C$4)*(Marks!$B$31:$Y$31=1))/SUMPRODUCT((Marks!$B$3:$Y$3=C$4)*ISNUMBER(Marks!$B$31:$Y$31))) | D31: =IF(SUMPRODUCT((Marks!$B$3:$Y$3=D$4)*ISNUMBER(Marks!$B$31:$Y$31))=0,"",SUMPRODUCT((Marks!$B$3:$Y$3=D$4)*(Marks!$B$31:$Y$31=1))/SUMPRODUCT((Marks!$B$3:$Y$3=D$4)*ISNUMBER(Marks!$B$31:$Y$31)))
A32: 28 | B32: =IF(SUMPRODUCT((Marks!$B$3:$Y$3=B$4)*ISNUMBER(Marks!$B$32:$Y$32))=0,"",SUMPRODUCT((Marks!$B$3:$Y$3=B$4)*(Marks!$B$32:$Y$32=1))/SUMPRODUCT((Marks!$B$3:$Y$3=B$4)*ISNUMBER(Marks!$B$32:$Y$32))) | C32: =IF(SUMPRODUCT((Marks!$B$3:$Y$3=C$4)*ISNUMBER(Marks!$B$32:$Y$32))=0,"",SUMPRODUCT((Marks!$B$3:$Y$3=C$4)*(Marks!$B$32:$Y$32=1))/SUMPRODUCT((Marks!$B$3:$Y$3=C$4)*ISNUMBER(Marks!$B$32:$Y$32))) | D32: =IF(SUMPRODUCT((Marks!$B$3:$Y$3=D$4)*ISNUMBER(Marks!$B$32:$Y$32))=0,"",SUMPRODUCT((Marks!$B$3:$Y$3=D$4)*(Marks!$B$32:$Y$32=1))/SUMPRODUCT((Marks!$B$3:$Y$3=D$4)*ISNUMBER(Marks!$B$32:$Y$32)))
A33: 29 | B33: =IF(SUMPRODUCT((Marks!$B$3:$Y$3=B$4)*ISNUMBER(Marks!$B$33:$Y$33))=0,"",SUMPRODUCT((Marks!$B$3:$Y$3=B$4)*(Marks!$B$33:$Y$33=1))/SUMPRODUCT((Marks!$B$3:$Y$3=B$4)*ISNUMBER(Marks!$B$33:$Y$33))) | C33: =IF(SUMPRODUCT((Marks!$B$3:$Y$3=C$4)*ISNUMBER(Marks!$B$33:$Y$33))=0,"",SUMPRODUCT((Marks!$B$3:$Y$3=C$4)*(Marks!$B$33:$Y$33=1))/SUMPRODUCT((Marks!$B$3:$Y$3=C$4)*ISNUMBER(Marks!$B$33:$Y$33))) | D33: =IF(SUMPRODUCT((Marks!$B$3:$Y$3=D$4)*ISNUMBER(Marks!$B$33:$Y$33))=0,"",SUMPRODUCT((Marks!$B$3:$Y$3=D$4)*(Marks!$B$33:$Y$33=1))/SUMPRODUCT((Marks!$B$3:$Y$3=D$4)*ISNUMBER(Marks!$B$33:$Y$33)))
A34: 30 | B34: =IF(SUMPRODUCT((Marks!$B$3:$Y$3=B$4)*ISNUMBER(Marks!$B$34:$Y$34))=0,"",SUMPRODUCT((Marks!$B$3:$Y$3=B$4)*(Marks!$B$34:$Y$34=1))/SUMPRODUCT((Marks!$B$3:$Y$3=B$4)*ISNUMBER(Marks!$B$34:$Y$34))) | C34: =IF(SUMPRODUCT((Marks!$B$3:$Y$3=C$4)*ISNUMBER(Marks!$B$34:$Y$34))=0,"",SUMPRODUCT((Marks!$B$3:$Y$3=C$4)*(Marks!$B$34:$Y$34=1))/SUMPRODUCT((Marks!$B$3:$Y$3=C$4)*ISNUMBER(Marks!$B$34:$Y$34))) | D34: =IF(SUMPRODUCT((Marks!$B$3:$Y$3=D$4)*ISNUMBER(Marks!$B$34:$Y$34))=0,"",SUMPRODUCT((Marks!$B$3:$Y$3=D$4)*(Marks!$B$34:$Y$34=1))/SUMPRODUCT((Marks!$B$3:$Y$3=D$4)*ISNUMBER(Marks!$B$34:$Y$34)))
A35: 31 | B35: =IF(SUMPRODUCT((Marks!$B$3:$Y$3=B$4)*ISNUMBER(Marks!$B$35:$Y$35))=0,"",SUMPRODUCT((Marks!$B$3:$Y$3=B$4)*(Marks!$B$35:$Y$35=1))/SUMPRODUCT((Marks!$B$3:$Y$3=B$4)*ISNUMBER(Marks!$B$35:$Y$35))) | C35: =IF(SUMPRODUCT((Marks!$B$3:$Y$3=C$4)*ISNUMBER(Marks!$B$35:$Y$35))=0,"",SUMPRODUCT((Marks!$B$3:$Y$3=C$4)*(Marks!$B$35:$Y$35=1))/SUMPRODUCT((Marks!$B$3:$Y$3=C$4)*ISNUMBER(Marks!$B$35:$Y$35))) | D35: =IF(SUMPRODUCT((Marks!$B$3:$Y$3=D$4)*ISNUMBER(Marks!$B$35:$Y$35))=0,"",SUMPRODUCT((Marks!$B$3:$Y$3=D$4)*(Marks!$B$35:$Y$35=1))/SUMPRODUCT((Marks!$B$3:$Y$3=D$4)*ISNUMBER(Marks!$B$35:$Y$35)))
A36: 32 | B36: =IF(SUMPRODUCT((Marks!$B$3:$Y$3=B$4)*ISNUMBER(Marks!$B$36:$Y$36))=0,"",SUMPRODUCT((Marks!$B$3:$Y$3=B$4)*(Marks!$B$36:$Y$36=1))/SUMPRODUCT((Marks!$B$3:$Y$3=B$4)*ISNUMBER(Marks!$B$36:$Y$36))) | C36: =IF(SUMPRODUCT((Marks!$B$3:$Y$3=C$4)*ISNUMBER(Marks!$B$36:$Y$36))=0,"",SUMPRODUCT((Marks!$B$3:$Y$3=C$4)*(Marks!$B$36:$Y$36=1))/SUMPRODUCT((Marks!$B$3:$Y$3=C$4)*ISNUMBER(Marks!$B$36:$Y$36))) | D36: =IF(SUMPRODUCT((Marks!$B$3:$Y$3=D$4)*ISNUMBER(Marks!$B$36:$Y$36))=0,"",SUMPRODUCT((Marks!$B$3:$Y$3=D$4)*(Marks!$B$36:$Y$36=1))/SUMPRODUCT((Marks!$B$3:$Y$3=D$4)*ISNUMBER(Marks!$B$36:$Y$36)))
A37: 33 | B37: =IF(SUMPRODUCT((Marks!$B$3:$Y$3=B$4)*ISNUMBER(Marks!$B$37:$Y$37))=0,"",SUMPRODUCT((Marks!$B$3:$Y$3=B$4)*(Marks!$B$37:$Y$37=1))/SUMPRODUCT((Marks!$B$3:$Y$3=B$4)*ISNUMBER(Marks!$B$37:$Y$37))) | C37: =IF(SUMPRODUCT((Marks!$B$3:$Y$3=C$4)*ISNUMBER(Marks!$B$37:$Y$37))=0,"",SUMPRODUCT((Marks!$B$3:$Y$3=C$4)*(Marks!$B$37:$Y$37=1))/SUMPRODUCT((Marks!$B$3:$Y$3=C$4)*ISNUMBER(Marks!$B$37:$Y$37))) | D37: =IF(SUMPRODUCT((Marks!$B$3:$Y$3=D$4)*ISNUMBER(Marks!$B$37:$Y$37))=0,"",SUMPRODUCT((Marks!$B$3:$Y$3=D$4)*(Marks!$B$37:$Y$37=1))/SUMPRODUCT((Marks!$B$3:$Y$3=D$4)*ISNUMBER(Marks!$B$37:$Y$37)))
A38: 34 | B38: =IF(SUMPRODUCT((Marks!$B$3:$Y$3=B$4)*ISNUMBER(Marks!$B$38:$Y$38))=0,"",SUMPRODUCT((Marks!$B$3:$Y$3=B$4)*(Marks!$B$38:$Y$38=1))/SUMPRODUCT((Marks!$B$3:$Y$3=B$4)*ISNUMBER(Marks!$B$38:$Y$38))) | C38: =IF(SUMPRODUCT((Marks!$B$3:$Y$3=C$4)*ISNUMBER(Marks!$B$38:$Y$38))=0,"",SUMPRODUCT((Marks!$B$3:$Y$3=C$4)*(Marks!$B$38:$Y$38=1))/SUMPRODUCT((Marks!$B$3:$Y$3=C$4)*ISNUMBER(Marks!$B$38:$Y$38))) | D38: =IF(SUMPRODUCT((Marks!$B$3:$Y$3=D$4)*ISNUMBER(Marks!$B$38:$Y$38))=0,"",SUMPRODUCT((Marks!$B$3:$Y$3=D$4)*(Marks!$B$38:$Y$38=1))/SUMPRODUCT((Marks!$B$3:$Y$3=D$4)*ISNUMBER(Marks!$B$38:$Y$38)))
A39: 35 | B39: =IF(SUMPRODUCT((Marks!$B$3:$Y$3=B$4)*ISNUMBER(Marks!$B$39:$Y$39))=0,"",SUMPRODUCT((Marks!$B$3:$Y$3=B$4)*(Marks!$B$39:$Y$39=1))/SUMPRODUCT((Marks!$B$3:$Y$3=B$4)*ISNUMBER(Marks!$B$39:$Y$39))) | C39: =IF(SUMPRODUCT((Marks!$B$3:$Y$3=C$4)*ISNUMBER(Marks!$B$39:$Y$39))=0,"",SUMPRODUCT((Marks!$B$3:$Y$3=C$4)*(Marks!$B$39:$Y$39=1))/SUMPRODUCT((Marks!$B$3:$Y$3=C$4)*ISNUMBER(Marks!$B$39:$Y$39))) | D39: =IF(SUMPRODUCT((Marks!$B$3:$Y$3=D$4)*ISNUMBER(Marks!$B$39:$Y$39))=0,"",SUMPRODUCT((Marks!$B$3:$Y$3=D$4)*(Marks!$B$39:$Y$39=1))/SUMPRODUCT((Marks!$B$3:$Y$3=D$4)*ISNUMBER(Marks!$B$39:$Y$39)))
A40: 36 | B40: =IF(SUMPRODUCT((Marks!$B$3:$Y$3=B$4)*ISNUMBER(Marks!$B$40:$Y$40))=0,"",SUMPRODUCT((Marks!$B$3:$Y$3=B$4)*(Marks!$B$40:$Y$40=1))/SUMPRODUCT((Marks!$B$3:$Y$3=B$4)*ISNUMBER(Marks!$B$40:$Y$40))) | C40: =IF(SUMPRODUCT((Marks!$B$3:$Y$3=C$4)*ISNUMBER(Marks!$B$40:$Y$40))=0,"",SUMPRODUCT((Marks!$B$3:$Y$3=C$4)*(Marks!$B$40:$Y$40=1))/SUMPRODUCT((Marks!$B$3:$Y$3=C$4)*ISNUMBER(Marks!$B$40:$Y$40))) | D40: =IF(SUMPRODUCT((Marks!$B$3:$Y$3=D$4)*ISNUMBER(Marks!$B$40:$Y$40))=0,"",SUMPRODUCT((Marks!$B$3:$Y$3=D$4)*(Marks!$B$40:$Y$40=1))/SUMPRODUCT((Marks!$B$3:$Y$3=D$4)*ISNUMBER(Marks!$B$40:$Y$40)))
A41: 37 | B41: =IF(SUMPRODUCT((Marks!$B$3:$Y$3=B$4)*ISNUMBER(Marks!$B$41:$Y$41))=0,"",SUMPRODUCT((Marks!$B$3:$Y$3=B$4)*(Marks!$B$41:$Y$41=1))/SUMPRODUCT((Marks!$B$3:$Y$3=B$4)*ISNUMBER(Marks!$B$41:$Y$41))) | C41: =IF(SUMPRODUCT((Marks!$B$3:$Y$3=C$4)*ISNUMBER(Marks!$B$41:$Y$41))=0,"",SUMPRODUCT((Marks!$B$3:$Y$3=C$4)*(Marks!$B$41:$Y$41=1))/SUMPRODUCT((Marks!$B$3:$Y$3=C$4)*ISNUMBER(Marks!$B$41:$Y$41))) | D41: =IF(SUMPRODUCT((Marks!$B$3:$Y$3=D$4)*ISNUMBER(Marks!$B$41:$Y$41))=0,"",SUMPRODUCT((Marks!$B$3:$Y$3=D$4)*(Marks!$B$41:$Y$41=1))/SUMPRODUCT((Marks!$B$3:$Y$3=D$4)*ISNUMBER(Marks!$B$41:$Y$41)))
A42: 38 | B42: =IF(SUMPRODUCT((Marks!$B$3:$Y$3=B$4)*ISNUMBER(Marks!$B$42:$Y$42))=0,"",SUMPRODUCT((Marks!$B$3:$Y$3=B$4)*(Marks!$B$42:$Y$42=1))/SUMPRODUCT((Marks!$B$3:$Y$3=B$4)*ISNUMBER(Marks!$B$42:$Y$42))) | C42: =IF(SUMPRODUCT((Marks!$B$3:$Y$3=C$4)*ISNUMBER(Marks!$B$42:$Y$42))=0,"",SUMPRODUCT((Marks!$B$3:$Y$3=C$4)*(Marks!$B$42:$Y$42=1))/SUMPRODUCT((Marks!$B$3:$Y$3=C$4)*ISNUMBER(Marks!$B$42:$Y$42))) | D42: =IF(SUMPRODUCT((Marks!$B$3:$Y$3=D$4)*ISNUMBER(Marks!$B$42:$Y$42))=0,"",SUMPRODUCT((Marks!$B$3:$Y$3=D$4)*(Marks!$B$42:$Y$42=1))/SUMPRODUCT((Marks!$B$3:$Y$3=D$4)*ISNUMBER(Marks!$B$42:$Y$42)))
...

Sheet Ratings
A1: Step one: each part's rating beside its score
A2: Type each seat's ratings, 1 to 4, from the answer sheet; the rates on the right are computed.
B3: 1 | C3: 2 | D3: 3 | E3: 4 | F3: 5 | H3: 1 | I3: 2 | J3: 3 | K3: 4 | L3: 5
A4: Seat | B4: Rating, part 1 | C4: Rating, part 2 | D4: Rating, part 3 | E4: Rating, part 4 | F4: Rating, part 5 | H4: Right rate, part 1 | I4: Right rate, part 2 | J4: Right rate, part 3 | K4: Right rate, part 4 | L4: Right rate, part 5
A5: 1 | H5: =IF(SUMPRODUCT((Marks!$B$2:$Y$2=H$3)*ISNUMBER(Marks!$B$5:$Y$5))=0,"",SUMPRODUCT((Marks!$B$2:$Y$2=H$3)*(Marks!$B$5:$Y$5=1))/SUMPRODUCT((Marks!$B$2:$Y$2=H$3)*ISNUMBER(Marks!$B$5:$Y$5))) | I5: =IF(SUMPRODUCT((Marks!$B$2:$Y$2=I$3)*ISNUMBER(Marks!$B$5:$Y$5))=0,"",SUMPRODUCT((Marks!$B$2:$Y$2=I$3)*(Marks!$B$5:$Y$5=1))/SUMPRODUCT((Marks!$B$2:$Y$2=I$3)*ISNUMBER(Marks!$B$5:$Y$5))) | J5: =IF(SUMPRODUCT((Marks!$B$2:$Y$2=J$3)*ISNUMBER(Marks!$B$5:$Y$5))=0,"",SUMPRODUCT((Marks!$B$2:$Y$2=J$3)*(Marks!$B$5:$Y$5=1))/SUMPRODUCT((Marks!$B$2:$Y$2=J$3)*ISNUMBER(Marks!$B$5:$Y$5))) | K5: =IF(SUMPRODUCT((Marks!$B$2:$Y$2=K$3)*ISNUMBER(Marks!$B$5:$Y$5))=0,"",SUMPRODUCT((Marks!$B$2:$Y$2=K$3)*(Marks!$B$5:$Y$5=1))/SUMPRODUCT((Marks!$B$2:$Y$2=K$3)*ISNUMBER(Marks!$B$5:$Y$5))) | L5: =IF(SUMPRODUCT((Marks!$B$2:$Y$2=L$3)*ISNUMBER(Marks!$B$5:$Y$5))=0,"",SUMPRODUCT((Marks!$B$2:$Y$2=L$3)*(Marks!$B$5:$Y$5=1))/SUMPRODUCT((Marks!$B$2:$Y$2=L$3)*ISNUMBER(Marks!$B$5:$Y$5)))
A6: 2 | H6: =IF(SUMPRODUCT((Marks!$B$2:$Y$2=H$3)*ISNUMBER(Marks!$B$6:$Y$6))=0,"",SUMPRODUCT((Marks!$B$2:$Y$2=H$3)*(Marks!$B$6:$Y$6=1))/SUMPRODUCT((Marks!$B$2:$Y$2=H$3)*ISNUMBER(Marks!$B$6:$Y$6))) | I6: =IF(SUMPRODUCT((Marks!$B$2:$Y$2=I$3)*ISNUMBER(Marks!$B$6:$Y$6))=0,"",SUMPRODUCT((Marks!$B$2:$Y$2=I$3)*(Marks!$B$6:$Y$6=1))/SUMPRODUCT((Marks!$B$2:$Y$2=I$3)*ISNUMBER(Marks!$B$6:$Y$6))) | J6: =IF(SUMPRODUCT((Marks!$B$2:$Y$2=J$3)*ISNUMBER(Marks!$B$6:$Y$6))=0,"",SUMPRODUCT((Marks!$B$2:$Y$2=J$3)*(Marks!$B$6:$Y$6=1))/SUMPRODUCT((Marks!$B$2:$Y$2=J$3)*ISNUMBER(Marks!$B$6:$Y$6))) | K6: =IF(SUMPRODUCT((Marks!$B$2:$Y$2=K$3)*ISNUMBER(Marks!$B$6:$Y$6))=0,"",SUMPRODUCT((Marks!$B$2:$Y$2=K$3)*(Marks!$B$6:$Y$6=1))/SUMPRODUCT((Marks!$B$2:$Y$2=K$3)*ISNUMBER(Marks!$B$6:$Y$6))) | L6: =IF(SUMPRODUCT((Marks!$B$2:$Y$2=L$3)*ISNUMBER(Marks!$B$6:$Y$6))=0,"",SUMPRODUCT((Marks!$B$2:$Y$2=L$3)*(Marks!$B$6:$Y$6=1))/SUMPRODUCT((Marks!$B$2:$Y$2=L$3)*ISNUMBER(Marks!$B$6:$Y$6)))
A7: 3 | H7: =IF(SUMPRODUCT((Marks!$B$2:$Y$2=H$3)*ISNUMBER(Marks!$B$7:$Y$7))=0,"",SUMPRODUCT((Marks!$B$2:$Y$2=H$3)*(Marks!$B$7:$Y$7=1))/SUMPRODUCT((Marks!$B$2:$Y$2=H$3)*ISNUMBER(Marks!$B$7:$Y$7))) | I7: =IF(SUMPRODUCT((Marks!$B$2:$Y$2=I$3)*ISNUMBER(Marks!$B$7:$Y$7))=0,"",SUMPRODUCT((Marks!$B$2:$Y$2=I$3)*(Marks!$B$7:$Y$7=1))/SUMPRODUCT((Marks!$B$2:$Y$2=I$3)*ISNUMBER(Marks!$B$7:$Y$7))) | J7: =IF(SUMPRODUCT((Marks!$B$2:$Y$2=J$3)*ISNUMBER(Marks!$B$7:$Y$7))=0,"",SUMPRODUCT((Marks!$B$2:$Y$2=J$3)*(Marks!$B$7:$Y$7=1))/SUMPRODUCT((Marks!$B$2:$Y$2=J$3)*ISNUMBER(Marks!$B$7:$Y$7))) | K7: =IF(SUMPRODUCT((Marks!$B$2:$Y$2=K$3)*ISNUMBER(Marks!$B$7:$Y$7))=0,"",SUMPRODUCT((Marks!$B$2:$Y$2=K$3)*(Marks!$B$7:$Y$7=1))/SUMPRODUCT((Marks!$B$2:$Y$2=K$3)*ISNUMBER(Marks!$B$7:$Y$7))) | L7: =IF(SUMPRODUCT((Marks!$B$2:$Y$2=L$3)*ISNUMBER(Marks!$B$7:$Y$7))=0,"",SUMPRODUCT((Marks!$B$2:$Y$2=L$3)*(Marks!$B$7:$Y$7=1))/SUMPRODUCT((Marks!$B$2:$Y$2=L$3)*ISNUMBER(Marks!$B$7:$Y$7)))
