Workbook

Sheet Read me
A1: Week 1 recap paper: item analysis
A2: TRAINER. Fill this after the swap-marking, one row per seat and never a name.
A3: Marks: type 1 for a tick, 0 for a cross and leave a blank for an item left empty. Yellow cells are the only inputs; everything else is computed.
A4: Items: each item's right rate, the top and bottom thirds' rates (thirds by total, once three or more seats are in), and a flag when fewer than one in five got it right or the bottom third beat the top third. Both are this programme's own working rule for a room of 35.
A5: Discussion: the items from the most missed, which is the order the solution discussion takes.
A6: Tags: the room's rate by tag and by part. Seats: each seat's rate by tag, for Monday's remediation read. Neither is a ranking, and neither is read out by name.

Sheet Marks
A1: Marks: 1 right, 0 wrong, blank left empty
A2: Part | B2: 1 | C2: 1 | D2: 1 | E2: 1 | F2: 1 | G2: 1 | H2: 1 | I2: 2 | J2: 2 | K2: 2 | L2: 2 | M2: 2 | N2: 2 | O2: 2 | P2: 2 | Q2: 3 | R2: 3 | S2: 3 | T2: 3 | U2: 3 | V2: 3 | W2: 4 | X2: 4 | Y2: 4 | Z2: 4 | AA2: 4 | AB2: 5 | AC2: 5 | AD2: 5 | AE2: 5 | AF2: 5 | AG2: 5 | AH2: 5 | AI2: 5 | AJ2: 5
A3: Tag | B3: [S] | C3: [F] | D3: [S] | E3: [S] | F3: [S] | G3: [D] | H3: [S] | I3: [F] | J3: [SV] | K3: [D] | L3: [F] | M3: [F] | N3: [F] | O3: [F] | P3: [S] | Q3: [S] | R3: [S] | S3: [S] | T3: [S] | U3: [F] | V3: [F] | W3: [S] | X3: [F] | Y3: [S] | Z3: [F] | AA3: [S] | AB3: [D] | AC3: [D] | AD3: [F] | AE3: [SV] | AF3: [S] | AG3: [S] | AH3: [S] | AI3: [S] | AJ3: [S]
A4: Seat | B4: Q1 | C4: Q2 | D4: Q3 | E4: Q4 | F4: Q5 | G4: Q6 | H4: Q7 | I4: Q8 | J4: Q9 | K4: Q10 | L4: Q11 | M4: Q12 | N4: Q13 | O4: Q14 | P4: Q15 | Q4: Q16 | R4: Q17 | S4: Q18 | T4: Q19 | U4: Q20 | V4: Q21 | W4: Q22 | X4: Q23 | Y4: Q24 | Z4: Q25 | AA4: Q26 | AB4: Q27 | AC4: Q28 | AD4: Q29 | AE4: Q30 | AF4: Q31 | AG4: Q32 | AH4: Q33 | AI4: Q34 | AJ4: Q35 | AK4: Total | AL4: Answered | AM4: Band
A5: 1 | AK5: =IF(COUNT(B5:AJ5)=0,"",SUM(B5:AJ5)) | AL5: =COUNT(B5:AJ5) | AM5: =IF(OR(AK5="",COUNT($AK$5:$AK$39)<3),"",IF(RANK(AK5,$AK$5:$AK$39,0)<=ROUND(COUNT($AK$5:$AK$39)/3,0),"top",IF(RANK(AK5,$AK$5:$AK$39,1)<=ROUND(COUNT($AK$5:$AK$39)/3,0),"bottom","middle")))
A6: 2 | AK6: =IF(COUNT(B6:AJ6)=0,"",SUM(B6:AJ6)) | AL6: =COUNT(B6:AJ6) | AM6: =IF(OR(AK6="",COUNT($AK$5:$AK$39)<3),"",IF(RANK(AK6,$AK$5:$AK$39,0)<=ROUND(COUNT($AK$5:$AK$39)/3,0),"top",IF(RANK(AK6,$AK$5:$AK$39,1)<=ROUND(COUNT($AK$5:$AK$39)/3,0),"bottom","middle")))
A7: 3 | AK7: =IF(COUNT(B7:AJ7)=0,"",SUM(B7:AJ7)) | AL7: =COUNT(B7:AJ7) | AM7: =IF(OR(AK7="",COUNT($AK$5:$AK$39)<3),"",IF(RANK(AK7,$AK$5:$AK$39,0)<=ROUND(COUNT($AK$5:$AK$39)/3,0),"top",IF(RANK(AK7,$AK$5:$AK$39,1)<=ROUND(COUNT($AK$5:$AK$39)/3,0),"bottom","middle")))
A8: 4 | AK8: =IF(COUNT(B8:AJ8)=0,"",SUM(B8:AJ8)) | AL8: =COUNT(B8:AJ8) | AM8: =IF(OR(AK8="",COUNT($AK$5:$AK$39)<3),"",IF(RANK(AK8,$AK$5:$AK$39,0)<=ROUND(COUNT($AK$5:$AK$39)/3,0),"top",IF(RANK(AK8,$AK$5:$AK$39,1)<=ROUND(COUNT($AK$5:$AK$39)/3,0),"bottom","middle")))
A9: 5 | AK9: =IF(COUNT(B9:AJ9)=0,"",SUM(B9:AJ9)) | AL9: =COUNT(B9:AJ9) | AM9: =IF(OR(AK9="",COUNT($AK$5:$AK$39)<3),"",IF(RANK(AK9,$AK$5:$AK$39,0)<=ROUND(COUNT($AK$5:$AK$39)/3,0),"top",IF(RANK(AK9,$AK$5:$AK$39,1)<=ROUND(COUNT($AK$5:$AK$39)/3,0),"bottom","middle")))
A10: 6 | AK10: =IF(COUNT(B10:AJ10)=0,"",SUM(B10:AJ10)) | AL10: =COUNT(B10:AJ10) | AM10: =IF(OR(AK10="",COUNT($AK$5:$AK$39)<3),"",IF(RANK(AK10,$AK$5:$AK$39,0)<=ROUND(COUNT($AK$5:$AK$39)/3,0),"top",IF(RANK(AK10,$AK$5:$AK$39,1)<=ROUND(COUNT($AK$5:$AK$39)/3,0),"bottom","middle")))
A11: 7 | AK11: =IF(COUNT(B11:AJ11)=0,"",SUM(B11:AJ11)) | AL11: =COUNT(B11:AJ11) | AM11: =IF(OR(AK11="",COUNT($AK$5:$AK$39)<3),"",IF(RANK(AK11,$AK$5:$AK$39,0)<=ROUND(COUNT($AK$5:$AK$39)/3,0),"top",IF(RANK(AK11,$AK$5:$AK$39,1)<=ROUND(COUNT($AK$5:$AK$39)/3,0),"bottom","middle")))
A12: 8 | AK12: =IF(COUNT(B12:AJ12)=0,"",SUM(B12:AJ12)) | AL12: =COUNT(B12:AJ12) | AM12: =IF(OR(AK12="",COUNT($AK$5:$AK$39)<3),"",IF(RANK(AK12,$AK$5:$AK$39,0)<=ROUND(COUNT($AK$5:$AK$39)/3,0),"top",IF(RANK(AK12,$AK$5:$AK$39,1)<=ROUND(COUNT($AK$5:$AK$39)/3,0),"bottom","middle")))
A13: 9 | AK13: =IF(COUNT(B13:AJ13)=0,"",SUM(B13:AJ13)) | AL13: =COUNT(B13:AJ13) | AM13: =IF(OR(AK13="",COUNT($AK$5:$AK$39)<3),"",IF(RANK(AK13,$AK$5:$AK$39,0)<=ROUND(COUNT($AK$5:$AK$39)/3,0),"top",IF(RANK(AK13,$AK$5:$AK$39,1)<=ROUND(COUNT($AK$5:$AK$39)/3,0),"bottom","middle")))
A14: 10 | AK14: =IF(COUNT(B14:AJ14)=0,"",SUM(B14:AJ14)) | AL14: =COUNT(B14:AJ14) | AM14: =IF(OR(AK14="",COUNT($AK$5:$AK$39)<3),"",IF(RANK(AK14,$AK$5:$AK$39,0)<=ROUND(COUNT($AK$5:$AK$39)/3,0),"top",IF(RANK(AK14,$AK$5:$AK$39,1)<=ROUND(COUNT($AK$5:$AK$39)/3,0),"bottom","middle")))
A15: 11 | AK15: =IF(COUNT(B15:AJ15)=0,"",SUM(B15:AJ15)) | AL15: =COUNT(B15:AJ15) | AM15: =IF(OR(AK15="",COUNT($AK$5:$AK$39)<3),"",IF(RANK(AK15,$AK$5:$AK$39,0)<=ROUND(COUNT($AK$5:$AK$39)/3,0),"top",IF(RANK(AK15,$AK$5:$AK$39,1)<=ROUND(COUNT($AK$5:$AK$39)/3,0),"bottom","middle")))
A16: 12 | AK16: =IF(COUNT(B16:AJ16)=0,"",SUM(B16:AJ16)) | AL16: =COUNT(B16:AJ16) | AM16: =IF(OR(AK16="",COUNT($AK$5:$AK$39)<3),"",IF(RANK(AK16,$AK$5:$AK$39,0)<=ROUND(COUNT($AK$5:$AK$39)/3,0),"top",IF(RANK(AK16,$AK$5:$AK$39,1)<=ROUND(COUNT($AK$5:$AK$39)/3,0),"bottom","middle")))
... A39: 35 | AK39: =IF(COUNT(B39:AJ39)=0,"",SUM(B39:AJ39)) | AL39: =COUNT(B39:AJ39) | AM39: =IF(OR(AK39="",COUNT($AK$5:$AK$39)<3),"",IF(RANK(AK39,$AK$5:$AK$39,0)<=ROUND(COUNT($AK$5:$AK$39)/3,0),"top",IF(RANK(AK39,$AK$5:$AK$39,1)<=ROUND(COUNT($AK$5:$AK$39)/3,0),"bottom","middle")))

Sheet Items
A1: Items: the room's rate, the thirds, and what to check
A4: Q | B4: Part | C4: Type | D4: Level | E4: Tag | F4: Key | G4: Right | H4: Answered | I4: Right rate | J4: Top third rate | K4: Bottom third rate | L4: Top minus bottom | M4: Flag | N4: Order key
A5: 1 | B5: 1 | C5: Applied maths | D5: Medium | E5: [S] | F5: Rs 11 crore (Rs 12 crore before discounts). | G5: =COUNTIF(Marks!B$5:B$39,1) | H5: =COUNT(Marks!B$5:B$39) | I5: =IF(H5=0,"",G5/H5) | J5: =IF(SUMPRODUCT((Marks!$AM$5:$AM$39="top")*ISNUMBER(Marks!B$5:B$39))=0,"",SUMPRODUCT((Marks!$AM$5:$AM$39="top")*(Marks!B$5:B$39=1))/SUMPRODUCT((Marks!$AM$5:$AM$39="top")*ISNUMBER(Marks!B$5:B$39))) | K5: =IF(SUMPRODUCT((Marks!$AM$5:$AM$39="bottom")*ISNUMBER(Marks!B$5:B$39))=0,"",SUMPRODUCT((Marks!$AM$5:$AM$39="bottom")*(Marks!B$5:B$39=1))/SUMPRODUCT((Marks!$AM$5:$AM$39="bottom")*ISNUMBER(Marks!B$5:B$39))) | L5: =IF(OR(J5="",K5=""),"",J5-K5) | M5: =IF(H5=0,"",IF(I5<0.2,"Check the item: fewer than one in five got it right",IF(AND(L5<>"",N(L5)<0),"Check the item: the bottom third beat the top third",""))) | N5: =IF(H5=0,"",I5+ROW()/1000000)
A6: 2 | B6: 1 | C6: One correct option | D6: Hard | E6: [F] | F6: c | G6: =COUNTIF(Marks!C$5:C$39,1) | H6: =COUNT(Marks!C$5:C$39) | I6: =IF(H6=0,"",G6/H6) | J6: =IF(SUMPRODUCT((Marks!$AM$5:$AM$39="top")*ISNUMBER(Marks!C$5:C$39))=0,"",SUMPRODUCT((Marks!$AM$5:$AM$39="top")*(Marks!C$5:C$39=1))/SUMPRODUCT((Marks!$AM$5:$AM$39="top")*ISNUMBER(Marks!C$5:C$39))) | K6: =IF(SUMPRODUCT((Marks!$AM$5:$AM$39="bottom")*ISNUMBER(Marks!C$5:C$39))=0,"",SUMPRODUCT((Marks!$AM$5:$AM$39="bottom")*(Marks!C$5:C$39=1))/SUMPRODUCT((Marks!$AM$5:$AM$39="bottom")*ISNUMBER(Marks!C$5:C$39))) | L6: =IF(OR(J6="",K6=""),"",J6-K6) | M6: =IF(H6=0,"",IF(I6<0.2,"Check the item: fewer than one in five got it right",IF(AND(L6<>"",N(L6)<0),"Check the item: the bottom third beat the top third",""))) | N6: =IF(H6=0,"",I6+ROW()/1000000)
A7: 3 | B7: 1 | C7: Applied maths | D7: Hard | E7: [S] | F7: Rs 2,060. | G7: =COUNTIF(Marks!D$5:D$39,1) | H7: =COUNT(Marks!D$5:D$39) | I7: =IF(H7=0,"",G7/H7) | J7: =IF(SUMPRODUCT((Marks!$AM$5:$AM$39="top")*ISNUMBER(Marks!D$5:D$39))=0,"",SUMPRODUCT((Marks!$AM$5:$AM$39="top")*(Marks!D$5:D$39=1))/SUMPRODUCT((Marks!$AM$5:$AM$39="top")*ISNUMBER(Marks!D$5:D$39))) | K7: =IF(SUMPRODUCT((Marks!$AM$5:$AM$39="bottom")*ISNUMBER(Marks!D$5:D$39))=0,"",SUMPRODUCT((Marks!$AM$5:$AM$39="bottom")*(Marks!D$5:D$39=1))/SUMPRODUCT((Marks!$AM$5:$AM$39="bottom")*ISNUMBER(Marks!D$5:D$39))) | L7: =IF(OR(J7="",K7=""),"",J7-K7) | M7: =IF(H7=0,"",IF(I7<0.2,"Check the item: fewer than one in five got it right",IF(AND(L7<>"",N(L7)<0),"Check the item: the bottom third beat the top third",""))) | N7: =IF(H7=0,"",I7+ROW()/1000000)
A8: 4 | B8: 1 | C8: One correct option | D8: Medium | E8: [S] | F8: d | G8: =COUNTIF(Marks!E$5:E$39,1) | H8: =COUNT(Marks!E$5:E$39) | I8: =IF(H8=0,"",G8/H8) | J8: =IF(SUMPRODUCT((Marks!$AM$5:$AM$39="top")*ISNUMBER(Marks!E$5:E$39))=0,"",SUMPRODUCT((Marks!$AM$5:$AM$39="top")*(Marks!E$5:E$39=1))/SUMPRODUCT((Marks!$AM$5:$AM$39="top")*ISNUMBER(Marks!E$5:E$39))) | K8: =IF(SUMPRODUCT((Marks!$AM$5:$AM$39="bottom")*ISNUMBER(Marks!E$5:E$39))=0,"",SUMPRODUCT((Marks!$AM$5:$AM$39="bottom")*(Marks!E$5:E$39=1))/SUMPRODUCT((Marks!$AM$5:$AM$39="bottom")*ISNUMBER(Marks!E$5:E$39))) | L8: =IF(OR(J8="",K8=""),"",J8-K8) | M8: =IF(H8=0,"",IF(I8<0.2,"Check the item: fewer than one in five got it right",IF(AND(L8<>"",N(L8)<0),"Check the item: the bottom third beat the top third",""))) | N8: =IF(H8=0,"",I8+ROW()/1000000)
A9: 5 | B9: 1 | C9: One correct option | D9: Easy | E9: [S] | F9: a | G9: =COUNTIF(Marks!F$5:F$39,1) | H9: =COUNT(Marks!F$5:F$39) | I9: =IF(H9=0,"",G9/H9) | J9: =IF(SUMPRODUCT((Marks!$AM$5:$AM$39="top")*ISNUMBER(Marks!F$5:F$39))=0,"",SUMPRODUCT((Marks!$AM$5:$AM$39="top")*(Marks!F$5:F$39=1))/SUMPRODUCT((Marks!$AM$5:$AM$39="top")*ISNUMBER(Marks!F$5:F$39))) | K9: =IF(SUMPRODUCT((Marks!$AM$5:$AM$39="bottom")*ISNUMBER(Marks!F$5:F$39))=0,"",SUMPRODUCT((Marks!$AM$5:$AM$39="bottom")*(Marks!F$5:F$39=1))/SUMPRODUCT((Marks!$AM$5:$AM$39="bottom")*ISNUMBER(Marks!F$5:F$39))) | L9: =IF(OR(J9="",K9=""),"",J9-K9) | M9: =IF(H9=0,"",IF(I9<0.2,"Check the item: fewer than one in five got it right",IF(AND(L9<>"",N(L9)<0),"Check the item: the bottom third beat the top third",""))) | N9: =IF(H9=0,"",I9+ROW()/1000000)
A10: 6 | B10: 1 | C10: One correct option | D10: Hard | E10: [D] | F10: c | G10: =COUNTIF(Marks!G$5:G$39,1) | H10: =COUNT(Marks!G$5:G$39) | I10: =IF(H10=0,"",G10/H10) | J10: =IF(SUMPRODUCT((Marks!$AM$5:$AM$39="top")*ISNUMBER(Marks!G$5:G$39))=0,"",SUMPRODUCT((Marks!$AM$5:$AM$39="top")*(Marks!G$5:G$39=1))/SUMPRODUCT((Marks!$AM$5:$AM$39="top")*ISNUMBER(Marks!G$5:G$39))) | K10: =IF(SUMPRODUCT((Marks!$AM$5:$AM$39="bottom")*ISNUMBER(Marks!G$5:G$39))=0,"",SUMPRODUCT((Marks!$AM$5:$AM$39="bottom")*(Marks!G$5:G$39=1))/SUMPRODUCT((Marks!$AM$5:$AM$39="bottom")*ISNUMBER(Marks!G$5:G$39))) | L10: =IF(OR(J10="",K10=""),"",J10-K10) | M10: =IF(H10=0,"",IF(I10<0.2,"Check the item: fewer than one in five got it right",IF(AND(L10<>"",N(L10)<0),"Check the item: the bottom third beat the top third",""))) | N10: =IF(H10=0,"",I10+ROW()/1000000)
A11: 7 | B11: 1 | C11: Order the steps | D11: Medium | E11: [S] | F11: b, d, e, a, c | G11: =COUNTIF(Marks!H$5:H$39,1) | H11: =COUNT(Marks!H$5:H$39) | I11: =IF(H11=0,"",G11/H11) | J11: =IF(SUMPRODUCT((Marks!$AM$5:$AM$39="top")*ISNUMBER(Marks!H$5:H$39))=0,"",SUMPRODUCT((Marks!$AM$5:$AM$39="top")*(Marks!H$5:H$39=1))/SUMPRODUCT((Marks!$AM$5:$AM$39="top")*ISNUMBER(Marks!H$5:H$39))) | K11: =IF(SUMPRODUCT((Marks!$AM$5:$AM$39="bottom")*ISNUMBER(Marks!H$5:H$39))=0,"",SUMPRODUCT((Marks!$AM$5:$AM$39="bottom")*(Marks!H$5:H$39=1))/SUMPRODUCT((Marks!$AM$5:$AM$39="bottom")*ISNUMBER(Marks!H$5:H$39))) | L11: =IF(OR(J11="",K11=""),"",J11-K11) | M11: =IF(H11=0,"",IF(I11<0.2,"Check the item: fewer than one in five got it right",IF(AND(L11<>"",N(L11)<0),"Check the item: the bottom third beat the top third",""))) | N11: =IF(H11=0,"",I11+ROW()/1000000)
A12: 8 | B12: 2 | C12: One correct option | D12: Hard | E12: [F] | F12: c | G12: =COUNTIF(Marks!I$5:I$39,1) | H12: =COUNT(Marks!I$5:I$39) | I12: =IF(H12=0,"",G12/H12) | J12: =IF(SUMPRODUCT((Marks!$AM$5:$AM$39="top")*ISNUMBER(Marks!I$5:I$39))=0,"",SUMPRODUCT((Marks!$AM$5:$AM$39="top")*(Marks!I$5:I$39=1))/SUMPRODUCT((Marks!$AM$5:$AM$39="top")*ISNUMBER(Marks!I$5:I$39))) | K12: =IF(SUMPRODUCT((Marks!$AM$5:$AM$39="bottom")*ISNUMBER(Marks!I$5:I$39))=0,"",SUMPRODUCT((Marks!$AM$5:$AM$39="bottom")*(Marks!I$5:I$39=1))/SUMPRODUCT((Marks!$AM$5:$AM$39="bottom")*ISNUMBER(Marks!I$5:I$39))) | L12: =IF(OR(J12="",K12=""),"",J12-K12) | M12: =IF(H12=0,"",IF(I12<0.2,"Check the item: fewer than one in five got it right",IF(AND(L12<>"",N(L12)<0),"Check the item: the bottom third beat the top third",""))) | N12: =IF(H12=0,"",I12+ROW()/1000000)
A13: 9 | B13: 2 | C13: True or false | D13: Medium | E13: [SV] | F13: d | G13: =COUNTIF(Marks!J$5:J$39,1) | H13: =COUNT(Marks!J$5:J$39) | I13: =IF(H13=0,"",G13/H13) | J13: =IF(SUMPRODUCT((Marks!$AM$5:$AM$39="top")*ISNUMBER(Marks!J$5:J$39))=0,"",SUMPRODUCT((Marks!$AM$5:$AM$39="top")*(Marks!J$5:J$39=1))/SUMPRODUCT((Marks!$AM$5:$AM$39="top")*ISNUMBER(Marks!J$5:J$39))) | K13: =IF(SUMPRODUCT((Marks!$AM$5:$AM$39="bottom")*ISNUMBER(Marks!J$5:J$39))=0,"",SUMPRODUCT((Marks!$AM$5:$AM$39="bottom")*(Marks!J$5:J$39=1))/SUMPRODUCT((Marks!$AM$5:$AM$39="bottom")*ISNUMBER(Marks!J$5:J$39))) | L13: =IF(OR(J13="",K13=""),"",J13-K13) | M13: =IF(H13=0,"",IF(I13<0.2,"Check the item: fewer than one in five got it right",IF(AND(L13<>"",N(L13)<0),"Check the item: the bottom third beat the top third",""))) | N13: =IF(H13=0,"",I13+ROW()/1000000)
A14: 10 | B14: 2 | C14: One correct option | D14: Hard | E14: [D] | F14: a | G14: =COUNTIF(Marks!K$5:K$39,1) | H14: =COUNT(Marks!K$5:K$39) | I14: =IF(H14=0,"",G14/H14) | J14: =IF(SUMPRODUCT((Marks!$AM$5:$AM$39="top")*ISNUMBER(Marks!K$5:K$39))=0,"",SUMPRODUCT((Marks!$AM$5:$AM$39="top")*(Marks!K$5:K$39=1))/SUMPRODUCT((Marks!$AM$5:$AM$39="top")*ISNUMBER(Marks!K$5:K$39))) | K14: =IF(SUMPRODUCT((Marks!$AM$5:$AM$39="bottom")*ISNUMBER(Marks!K$5:K$39))=0,"",SUMPRODUCT((Marks!$AM$5:$AM$39="bottom")*(Marks!K$5:K$39=1))/SUMPRODUCT((Marks!$AM$5:$AM$39="bottom")*ISNUMBER(Marks!K$5:K$39))) | L14: =IF(OR(J14="",K14=""),"",J14-K14) | M14: =IF(H14=0,"",IF(I14<0.2,"Check the item: fewer than one in five got it right",IF(AND(L14<>"",N(L14)<0),"Check the item: the bottom third beat the top third",""))) | N14: =IF(H14=0,"",I14+ROW()/1000000)
A15: 11 | B15: 2 | C15: More than one correct | D15: Hard | E15: [F] | F15: b, d | G15: =COUNTIF(Marks!L$5:L$39,1) | H15: =COUNT(Marks!L$5:L$39) | I15: =IF(H15=0,"",G15/H15) | J15: =IF(SUMPRODUCT((Marks!$AM$5:$AM$39="top")*ISNUMBER(Marks!L$5:L$39))=0,"",SUMPRODUCT((Marks!$AM$5:$AM$39="top")*(Marks!L$5:L$39=1))/SUMPRODUCT((Marks!$AM$5:$AM$39="top")*ISNUMBER(Marks!L$5:L$39))) | K15: =IF(SUMPRODUCT((Marks!$AM$5:$AM$39="bottom")*ISNUMBER(Marks!L$5:L$39))=0,"",SUMPRODUCT((Marks!$AM$5:$AM$39="bottom")*(Marks!L$5:L$39=1))/SUMPRODUCT((Marks!$AM$5:$AM$39="bottom")*ISNUMBER(Marks!L$5:L$39))) | L15: =IF(OR(J15="",K15=""),"",J15-K15) | M15: =IF(H15=0,"",IF(I15<0.2,"Check the item: fewer than one in five got it right",IF(AND(L15<>"",N(L15)<0),"Check the item: the bottom third beat the top third",""))) | N15: =IF(H15=0,"",I15+ROW()/1000000)
A16: 12 | B16: 2 | C16: Applied maths | D16: Hard | E16: [F] | F16: Q1 Rs 4,680 and Q2 Rs 7,410. | G16: =COUNTIF(Marks!M$5:M$39,1) | H16: =COUNT(Marks!M$5:M$39) | I16: =IF(H16=0,"",G16/H16) | J16: =IF(SUMPRODUCT((Marks!$AM$5:$AM$39="top")*ISNUMBER(Marks!M$5:M$39))=0,"",SUMPRODUCT((Marks!$AM$5:$AM$39="top")*(Marks!M$5:M$39=1))/SUMPRODUCT((Marks!$AM$5:$AM$39="top")*ISNUMBER(Marks!M$5:M$39))) | K16: =IF(SUMPRODUCT((Marks!$AM$5:$AM$39="bottom")*ISNUMBER(Marks!M$5:M$39))=0,"",SUMPRODUCT((Marks!$AM$5:$AM$39="bottom")*(Marks!M$5:M$39=1))/SUMPRODUCT((Marks!$AM$5:$AM$39="bottom")*ISNUMBER(Marks!M$5:M$39))) | L16: =IF(OR(J16="",K16=""),"",J16-K16) | M16: =IF(H16=0,"",IF(I16<0.2,"Check the item: fewer than one in five got it right",IF(AND(L16<>"",N(L16)<0),"Check the item: the bottom third beat the top third",""))) | N16: =IF(H16=0,"",I16+ROW()/1000000)
A17: 13 | B17: 2 | C17: Order the steps | D17: Medium | E17: [F] | F17: b, d, a, c | G17: =COUNTIF(Marks!N$5:N$39,1) | H17: =COUNT(Marks!N$5:N$39) | I17: =IF(H17=0,"",G17/H17) | J17: =IF(SUMPRODUCT((Marks!$AM$5:$AM$39="top")*ISNUMBER(Marks!N$5:N$39))=0,"",SUMPRODUCT((Marks!$AM$5:$AM$39="top")*(Marks!N$5:N$39=1))/SUMPRODUCT((Marks!$AM$5:$AM$39="top")*ISNUMBER(Marks!N$5:N$39))) | K17: =IF(SUMPRODUCT((Marks!$AM$5:$AM$39="bottom")*ISNUMBER(Marks!N$5:N$39))=0,"",SUMPRODUCT((Marks!$AM$5:$AM$39="bottom")*(Marks!N$5:N$39=1))/SUMPRODUCT((Marks!$AM$5:$AM$39="bottom")*ISNUMBER(Marks!N$5:N$39))) | L17: =IF(OR(J17="",K17=""),"",J17-K17) | M17: =IF(H17=0,"",IF(I17<0.2,"Check the item: fewer than one in five got it right",IF(AND(L17<>"",N(L17)<0),"Check the item: the bottom third beat the top third",""))) | N17: =IF(H17=0,"",I17+ROW()/1000000)
A18: 14 | B18: 2 | C18: Scenario set | D18: Hard | E18: [F] | F18: A fall of 1.6 percent (down 1.6, or -1.6). | G18: =COUNTIF(Marks!O$5:O$39,1) | H18: =COUNT(Marks!O$5:O$39) | I18: =IF(H18=0,"",G18/H18) | J18: =IF(SUMPRODUCT((Marks!$AM$5:$AM$39="top")*ISNUMBER(Marks!O$5:O$39))=0,"",SUMPRODUCT((Marks!$AM$5:$AM$39="top")*(Marks!O$5:O$39=1))/SUMPRODUCT((Marks!$AM$5:$AM$39="top")*ISNUMBER(Marks!O$5:O$39))) | K18: =IF(SUMPRODUCT((Marks!$AM$5:$AM$39="bottom")*ISNUMBER(Marks!O$5:O$39))=0,"",SUMPRODUCT((Marks!$AM$5:$AM$39="bottom")*(Marks!O$5:O$39=1))/SUMPRODUCT((Marks!$AM$5:$AM$39="bottom")*ISNUMBER(Marks!O$5:O$39))) | L18: =IF(OR(J18="",K18=""),"",J18-K18) | M18: =IF(H18=0,"",IF(I18<0.2,"Check the item: fewer than one in five got it right",IF(AND(L18<>"",N(L18)<0),"Check the item: the bottom third beat the top third",""))) | N18: =IF(H18=0,"",I18+ROW()/1000000)
A19: 15 | B19: 2 | C19: Scenario set | D19: Hard | E19: [S] | F19: a | G19: =COUNTIF(Marks!P$5:P$39,1) | H19: =COUNT(Marks!P$5:P$39) | I19: =IF(H19=0,"",G19/H19) | J19: =IF(SUMPRODUCT((Marks!$AM$5:$AM$39="top")*ISNUMBER(Marks!P$5:P$39))=0,"",SUMPRODUCT((Marks!$AM$5:$AM$39="top")*(Marks!P$5:P$39=1))/SUMPRODUCT((Marks!$AM$5:$AM$39="top")*ISNUMBER(Marks!P$5:P$39))) | K19: =IF(SUMPRODUCT((Marks!$AM$5:$AM$39="bottom")*ISNUMBER(Marks!P$5:P$39))=0,"",SUMPRODUCT((Marks!$AM$5:$AM$39="bottom")*(Marks!P$5:P$39=1))/SUMPRODUCT((Marks!$AM$5:$AM$39="bottom")*ISNUMBER(Marks!P$5:P$39))) | L19: =IF(OR(J19="",K19=""),"",J19-K19) | M19: =IF(H19=0,"",IF(I19<0.2,"Check the item: fewer than one in five got it right",IF(AND(L19<>"",N(L19)<0),"Check the item: the bottom third beat the top third",""))) | N19: =IF(H19=0,"",I19+ROW()/1000000)
A20: 16 | B20: 3 | C20: One correct option | D20: Hard | E20: [S] | F20: c | G20: =COUNTIF(Marks!Q$5:Q$39,1) | H20: =COUNT(Marks!Q$5:Q$39) | I20: =IF(H20=0,"",G20/H20) | J20: =IF(SUMPRODUCT((Marks!$AM$5:$AM$39="top")*ISNUMBER(Marks!Q$5:Q$39))=0,"",SUMPRODUCT((Marks!$AM$5:$AM$39="top")*(Marks!Q$5:Q$39=1))/SUMPRODUCT((Marks!$AM$5:$AM$39="top")*ISNUMBER(Marks!Q$5:Q$39))) | K20: =IF(SUMPRODUCT((Marks!$AM$5:$AM$39="bottom")*ISNUMBER(Marks!Q$5:Q$39))=0,"",SUMPRODUCT((Marks!$AM$5:$AM$39="bottom")*(Marks!Q$5:Q$39=1))/SUMPRODUCT((Marks!$AM$5:$AM$39="bottom")*ISNUMBER(Marks!Q$5:Q$39))) | L20: =IF(OR(J20="",K20=""),"",J20-K20) | M20: =IF(H20=0,"",IF(I20<0.2,"Check the item: fewer than one in five got it right",IF(AND(L20<>"",N(L20)<0),"Check the item: the bottom third beat the top third",""))) | N20: =IF(H20=0,"",I20+ROW()/1000000)
A21: 17 | B21: 3 | C21: True or false | D21: Hard | E21: [S] | F21: a | G21: =COUNTIF(Marks!R$5:R$39,1) | H21: =COUNT(Marks!R$5:R$39) | I21: =IF(H21=0,"",G21/H21) | J21: =IF(SUMPRODUCT((Marks!$AM$5:$AM$39="top")*ISNUMBER(Marks!R$5:R$39))=0,"",SUMPRODUCT((Marks!$AM$5:$AM$39="top")*(Marks!R$5:R$39=1))/SUMPRODUCT((Marks!$AM$5:$AM$39="top")*ISNUMBER(Marks!R$5:R$39))) | K21: =IF(SUMPRODUCT((Marks!$AM$5:$AM$39="bottom")*ISNUMBER(Marks!R$5:R$39))=0,"",SUMPRODUCT((Marks!$AM$5:$AM$39="bottom")*(Marks!R$5:R$39=1))/SUMPRODUCT((Marks!$AM$5:$AM$39="bottom")*ISNUMBER(Marks!R$5:R$39))) | L21: =IF(OR(J21="",K21=""),"",J21-K21) | M21: =IF(H21=0,"",IF(I21<0.2,"Check the item: fewer than one in five got it right",IF(AND(L21<>"",N(L21)<0),"Check the item: the bottom third beat the top third",""))) | N21: =IF(H21=0,"",I21+ROW()/1000000)
A22: 18 | B22: 3 | C22: More than one correct | D22: Medium | E22: [S] | F22: a, c, d | G22: =COUNTIF(Marks!S$5:S$39,1) | H22: =COUNT(Marks!S$5:S$39) | I22: =IF(H22=0,"",G22/H22) | J22: =IF(SUMPRODUCT((Marks!$AM$5:$AM$39="top")*ISNUMBER(Marks!S$5:S$39))=0,"",SUMPRODUCT((Marks!$AM$5:$AM$39="top")*(Marks!S$5:S$39=1))/SUMPRODUCT((Marks!$AM$5:$AM$39="top")*ISNUMBER(Marks!S$5:S$39))) | K22: =IF(SUMPRODUCT((Marks!$AM$5:$AM$39="bottom")*ISNUMBER(Marks!S$5:S$39))=0,"",SUMPRODUCT((Marks!$AM$5:$AM$39="bottom")*(Marks!S$5:S$39=1))/SUMPRODUCT((Marks!$AM$5:$AM$39="bottom")*ISNUMBER(Marks!S$5:S$39))) | L22: =IF(OR(J22="",K22=""),"",J22-K22) | M22: =IF(H22=0,"",IF(I22<0.2,"Check the item: fewer than one in five got it right",IF(AND(L22<>"",N(L22)<0),"Check the item: the bottom third beat the top third",""))) | N22: =IF(H22=0,"",I22+ROW()/1000000)
A23: 19 | B23: 3 | C23: One correct option | D23: Hard | E23: [S] | F23: d | G23: =COUNTIF(Marks!T$5:T$39,1) | H23: =COUNT(Marks!T$5:T$39) | I23: =IF(H23=0,"",G23/H23) | J23: =IF(SUMPRODUCT((Marks!$AM$5:$AM$39="top")*ISNUMBER(Marks!T$5:T$39))=0,"",SUMPRODUCT((Marks!$AM$5:$AM$39="top")*(Marks!T$5:T$39=1))/SUMPRODUCT((Marks!$AM$5:$AM$39="top")*ISNUMBER(Marks!T$5:T$39))) | K23: =IF(SUMPRODUCT((Marks!$AM$5:$AM$39="bottom")*ISNUMBER(Marks!T$5:T$39))=0,"",SUMPRODUCT((Marks!$AM$5:$AM$39="bottom")*(Marks!T$5:T$39=1))/SUMPRODUCT((Marks!$AM$5:$AM$39="bottom")*ISNUMBER(Marks!T$5:T$39))) | L23: =IF(OR(J23="",K23=""),"",J23-K23) | M23: =IF(H23=0,"",IF(I23<0.2,"Check the item: fewer than one in five got it right",IF(AND(L23<>"",N(L23)<0),"Check the item: the bottom third beat the top third",""))) | N23: =IF(H23=0,"",I23+ROW()/1000000)
A24: 20 | B24: 3 | C24: One correct option | D24: Hard | E24: [F] | F24: b | G24: =COUNTIF(Marks!U$5:U$39,1) | H24: =COUNT(Marks!U$5:U$39) | I24: =IF(H24=0,"",G24/H24) | J24: =IF(SUMPRODUCT((Marks!$AM$5:$AM$39="top")*ISNUMBER(Marks!U$5:U$39))=0,"",SUMPRODUCT((Marks!$AM$5:$AM$39="top")*(Marks!U$5:U$39=1))/SUMPRODUCT((Marks!$AM$5:$AM$39="top")*ISNUMBER(Marks!U$5:U$39))) | K24: =IF(SUMPRODUCT((Marks!$AM$5:$AM$39="bottom")*ISNUMBER(Marks!U$5:U$39))=0,"",SUMPRODUCT((Marks!$AM$5:$AM$39="bottom")*(Marks!U$5:U$39=1))/SUMPRODUCT((Marks!$AM$5:$AM$39="bottom")*ISNUMBER(Marks!U$5:U$39))) | L24: =IF(OR(J24="",K24=""),"",J24-K24) | M24: =IF(H24=0,"",IF(I24<0.2,"Check the item: fewer than one in five got it right",IF(AND(L24<>"",N(L24)<0),"Check the item: the bottom third beat the top third",""))) | N24: =IF(H24=0,"",I24+ROW()/1000000)
A25: 21 | B25: 3 | C25: One correct option | D25: Hard | E25: [F] | F25: c | G25: =COUNTIF(Marks!V$5:V$39,1) | H25: =COUNT(Marks!V$5:V$39) | I25: =IF(H25=0,"",G25/H25) | J25: =IF(SUMPRODUCT((Marks!$AM$5:$AM$39="top")*ISNUMBER(Marks!V$5:V$39))=0,"",SUMPRODUCT((Marks!$AM$5:$AM$39="top")*(Marks!V$5:V$39=1))/SUMPRODUCT((Marks!$AM$5:$AM$39="top")*ISNUMBER(Marks!V$5:V$39))) | K25: =IF(SUMPRODUCT((Marks!$AM$5:$AM$39="bottom")*ISNUMBER(Marks!V$5:V$39))=0,"",SUMPRODUCT((Marks!$AM$5:$AM$39="bottom")*(Marks!V$5:V$39=1))/SUMPRODUCT((Marks!$AM$5:$AM$39="bottom")*ISNUMBER(Marks!V$5:V$39))) | L25: =IF(OR(J25="",K25=""),"",J25-K25) | M25: =IF(H25=0,"",IF(I25<0.2,"Check the item: fewer than one in five got it right",IF(AND(L25<>"",N(L25)<0),"Check the item: the bottom third beat the top third",""))) | N25: =IF(H25=0,"",I25+ROW()/1000000)
A26: 22 | B26: 4 | C26: Scenario set | D26: Hard | E26: [S] | F26: d | G26: =COUNTIF(Marks!W$5:W$39,1) | H26: =COUNT(Marks!W$5:W$39) | I26: =IF(H26=0,"",G26/H26) | J26: =IF(SUMPRODUCT((Marks!$AM$5:$AM$39="top")*ISNUMBER(Marks!W$5:W$39))=0,"",SUMPRODUCT((Marks!$AM$5:$AM$39="top")*(Marks!W$5:W$39=1))/SUMPRODUCT((Marks!$AM$5:$AM$39="top")*ISNUMBER(Marks!W$5:W$39))) | K26: =IF(SUMPRODUCT((Marks!$AM$5:$AM$39="bottom")*ISNUMBER(Marks!W$5:W$39))=0,"",SUMPRODUCT((Marks!$AM$5:$AM$39="bottom")*(Marks!W$5:W$39=1))/SUMPRODUCT((Marks!$AM$5:$AM$39="bottom")*ISNUMBER(Marks!W$5:W$39))) | L26: =IF(OR(J26="",K26=""),"",J26-K26) | M26: =IF(H26=0,"",IF(I26<0.2,"Check the item: fewer than one in five got it right",IF(AND(L26<>"",N(L26)<0),"Check the item: the bottom third beat the top third",""))) | N26: =IF(H26=0,"",I26+ROW()/1000000)
A27: 23 | B27: 4 | C27: Scenario set | D27: Medium | E27: [F] | F27: d | G27: =COUNTIF(Marks!X$5:X$39,1) | H27: =COUNT(Marks!X$5:X$39) | I27: =IF(H27=0,"",G27/H27) | J27: =IF(SUMPRODUCT((Marks!$AM$5:$AM$39="top")*ISNUMBER(Marks!X$5:X$39))=0,"",SUMPRODUCT((Marks!$AM$5:$AM$39="top")*(Marks!X$5:X$39=1))/SUMPRODUCT((Marks!$AM$5:$AM$39="top")*ISNUMBER(Marks!X$5:X$39))) | K27: =IF(SUMPRODUCT((Marks!$AM$5:$AM$39="bottom")*ISNUMBER(Marks!X$5:X$39))=0,"",SUMPRODUCT((Marks!$AM$5:$AM$39="bottom")*(Marks!X$5:X$39=1))/SUMPRODUCT((Marks!$AM$5:$AM$39="bottom")*ISNUMBER(Marks!X$5:X$39))) | L27: =IF(OR(J27="",K27=""),"",J27-K27) | M27: =IF(H27=0,"",IF(I27<0.2,"Check the item: fewer than one in five got it right",IF(AND(L27<>"",N(L27)<0),"Check the item: the bottom third beat the top third",""))) | N27: =IF(H27=0,"",I27+ROW()/1000000)
A28: 24 | B28: 4 | C28: One correct option | D28: Medium | E28: [S] | F28: b | G28: =COUNTIF(Marks!Y$5:Y$39,1) | H28: =COUNT(Marks!Y$5:Y$39) | I28: =IF(H28=0,"",G28/H28) | J28: =IF(SUMPRODUCT((Marks!$AM$5:$AM$39="top")*ISNUMBER(Marks!Y$5:Y$39))=0,"",SUMPRODUCT((Marks!$AM$5:$AM$39="top")*(Marks!Y$5:Y$39=1))/SUMPRODUCT((Marks!$AM$5:$AM$39="top")*ISNUMBER(Marks!Y$5:Y$39))) | K28: =IF(SUMPRODUCT((Marks!$AM$5:$AM$39="bottom")*ISNUMBER(Marks!Y$5:Y$39))=0,"",SUMPRODUCT((Marks!$AM$5:$AM$39="bottom")*(Marks!Y$5:Y$39=1))/SUMPRODUCT((Marks!$AM$5:$AM$39="bottom")*ISNUMBER(Marks!Y$5:Y$39))) | L28: =IF(OR(J28="",K28=""),"",J28-K28) | M28: =IF(H28=0,"",IF(I28<0.2,"Check the item: fewer than one in five got it right",IF(AND(L28<>"",N(L28)<0),"Check the item: the bottom third beat the top third",""))) | N28: =IF(H28=0,"",I28+ROW()/1000000)
A29: 25 | B29: 4 | C29: More than one correct | D29: Medium | E29: [F] | F29: b, e | G29: =COUNTIF(Marks!Z$5:Z$39,1) | H29: =COUNT(Marks!Z$5:Z$39) | I29: =IF(H29=0,"",G29/H29) | J29: =IF(SUMPRODUCT((Marks!$AM$5:$AM$39="top")*ISNUMBER(Marks!Z$5:Z$39))=0,"",SUMPRODUCT((Marks!$AM$5:$AM$39="top")*(Marks!Z$5:Z$39=1))/SUMPRODUCT((Marks!$AM$5:$AM$39="top")*ISNUMBER(Marks!Z$5:Z$39))) | K29: =IF(SUMPRODUCT((Marks!$AM$5:$AM$39="bottom")*ISNUMBER(Marks!Z$5:Z$39))=0,"",SUMPRODUCT((Marks!$AM$5:$AM$39="bottom")*(Marks!Z$5:Z$39=1))/SUMPRODUCT((Marks!$AM$5:$AM$39="bottom")*ISNUMBER(Marks!Z$5:Z$39))) | L29: =IF(OR(J29="",K29=""),"",J29-K29) | M29: =IF(H29=0,"",IF(I29<0.2,"Check the item: fewer than one in five got it right",IF(AND(L29<>"",N(L29)<0),"Check the item: the bottom third beat the top third",""))) | N29: =IF(H29=0,"",I29+ROW()/1000000)
A30: 26 | B30: 4 | C30: One correct option | D30: Medium | E30: [S] | F30: b | G30: =COUNTIF(Marks!AA$5:AA$39,1) | H30: =COUNT(Marks!AA$5:AA$39) | I30: =IF(H30=0,"",G30/H30) | J30: =IF(SUMPRODUCT((Marks!$AM$5:$AM$39="top")*ISNUMBER(Marks!AA$5:AA$39))=0,"",SUMPRODUCT((Marks!$AM$5:$AM$39="top")*(Marks!AA$5:AA$39=1))/SUMPRODUCT((Marks!$AM$5:$AM$39="top")*ISNUMBER(Marks!AA$5:AA$39))) | K30: =IF(SUMPRODUCT((Marks!$AM$5:$AM$39="bottom")*ISNUMBER(Marks!AA$5:AA$39))=0,"",SUMPRODUCT((Marks!$AM$5:$AM$39="bottom")*(Marks!AA$5:AA$39=1))/SUMPRODUCT((Marks!$AM$5:$AM$39="bottom")*ISNUMBER(Marks!AA$5:AA$39))) | L30: =IF(OR(J30="",K30=""),"",J30-K30) | M30: =IF(H30=0,"",IF(I30<0.2,"Check the item: fewer than one in five got it right",IF(AND(L30<>"",N(L30)<0),"Check the item: the bottom third beat the top third",""))) | N30: =IF(H30=0,"",I30+ROW()/1000000)
A31: 27 | B31: 5 | C31: Scenario set | D31: Hard | E31: [D] | F31: A fall of Rs 12,500. | G31: =COUNTIF(Marks!AB$5:AB$39,1) | H31: =COUNT(Marks!AB$5:AB$39) | I31: =IF(H31=0,"",G31/H31) | J31: =IF(SUMPRODUCT((Marks!$AM$5:$AM$39="top")*ISNUMBER(Marks!AB$5:AB$39))=0,"",SUMPRODUCT((Marks!$AM$5:$AM$39="top")*(Marks!AB$5:AB$39=1))/SUMPRODUCT((Marks!$AM$5:$AM$39="top")*ISNUMBER(Marks!AB$5:AB$39))) | K31: =IF(SUMPRODUCT((Marks!$AM$5:$AM$39="bottom")*ISNUMBER(Marks!AB$5:AB$39))=0,"",SUMPRODUCT((Marks!$AM$5:$AM$39="bottom")*(Marks!AB$5:AB$39=1))/SUMPRODUCT((Marks!$AM$5:$AM$39="bottom")*ISNUMBER(Marks!AB$5:AB$39))) | L31: =IF(OR(J31="",K31=""),"",J31-K31) | M31: =IF(H31=0,"",IF(I31<0.2,"Check the item: fewer than one in five got it right",IF(AND(L31<>"",N(L31)<0),"Check the item: the bottom third beat the top third",""))) | N31: =IF(H31=0,"",I31+ROW()/1000000)
A32: 28 | B32: 5 | C32: Scenario set | D32: Hard | E32: [D] | F32: b | G32: =COUNTIF(Marks!AC$5:AC$39,1) | H32: =COUNT(Marks!AC$5:AC$39) | I32: =IF(H32=0,"",G32/H32) | J32: =IF(SUMPRODUCT((Marks!$AM$5:$AM$39="top")*ISNUMBER(Marks!AC$5:AC$39))=0,"",SUMPRODUCT((Marks!$AM$5:$AM$39="top")*(Marks!AC$5:AC$39=1))/SUMPRODUCT((Marks!$AM$5:$AM$39="top")*ISNUMBER(Marks!AC$5:AC$39))) | K32: =IF(SUMPRODUCT((Marks!$AM$5:$AM$39="bottom")*ISNUMBER(Marks!AC$5:AC$39))=0,"",SUMPRODUCT((Marks!$AM$5:$AM$39="bottom")*(Marks!AC$5:AC$39=1))/SUMPRODUCT((Marks!$AM$5:$AM$39="bottom")*ISNUMBER(Marks!AC$5:AC$39))) | L32: =IF(OR(J32="",K32=""),"",J32-K32) | M32: =IF(H32=0,"",IF(I32<0.2,"Check the item: fewer than one in five got it right",IF(AND(L32<>"",N(L32)<0),"Check the item: the bottom third beat the top third",""))) | N32: =IF(H32=0,"",I32+ROW()/1000000)
A33: 29 | B33: 5 | C33: One correct option | D33: Hard | E33: [F] | F33: c | G33: =COUNTIF(Marks!AD$5:AD$39,1) | H33: =COUNT(Marks!AD$5:AD$39) | I33: =IF(H33=0,"",G33/H33) | J33: =IF(SUMPRODUCT((Marks!$AM$5:$AM$39="top")*ISNUMBER(Marks!AD$5:AD$39))=0,"",SUMPRODUCT((Marks!$AM$5:$AM$39="top")*(Marks!AD$5:AD$39=1))/SUMPRODUCT((Marks!$AM$5:$AM$39="top")*ISNUMBER(Marks!AD$5:AD$39))) | K33: =IF(SUMPRODUCT((Marks!$AM$5:$AM$39="bottom")*ISNUMBER(Marks!AD$5:AD$39))=0,"",SUMPRODUCT((Marks!$AM$5:$AM$39="bottom")*(Marks!AD$5:AD$39=1))/SUMPRODUCT((Marks!$AM$5:$AM$39="bottom")*ISNUMBER(Marks!AD$5:AD$39))) | L33: =IF(OR(J33="",K33=""),"",J33-K33) | M33: =IF(H33=0,"",IF(I33<0.2,"Check the item: fewer than one in five got it right",IF(AND(L33<>"",N(L33)<0),"Check the item: the bottom third beat the top third",""))) | N33: =IF(H33=0,"",I33+ROW()/1000000)
A34: 30 | B34: 5 | C34: One correct option | D34: Hard | E34: [SV] | F34: a | G34: =COUNTIF(Marks!AE$5:AE$39,1) | H34: =COUNT(Marks!AE$5:AE$39) | I34: =IF(H34=0,"",G34/H34) | J34: =IF(SUMPRODUCT((Marks!$AM$5:$AM$39="top")*ISNUMBER(Marks!AE$5:AE$39))=0,"",SUMPRODUCT((Marks!$AM$5:$AM$39="top")*(Marks!AE$5:AE$39=1))/SUMPRODUCT((Marks!$AM$5:$AM$39="top")*ISNUMBER(Marks!AE$5:AE$39))) | K34: =IF(SUMPRODUCT((Marks!$AM$5:$AM$39="bottom")*ISNUMBER(Marks!AE$5:AE$39))=0,"",SUMPRODUCT((Marks!$AM$5:$AM$39="bottom")*(Marks!AE$5:AE$39=1))/SUMPRODUCT((Marks!$AM$5:$AM$39="bottom")*ISNUMBER(Marks!AE$5:AE$39))) | L34: =IF(OR(J34="",K34=""),"",J34-K34) | M34: =IF(H34=0,"",IF(I34<0.2,"Check the item: fewer than one in five got it right",IF(AND(L34<>"",N(L34)<0),"Check the item: the bottom third beat the top third",""))) | N34: =IF(H34=0,"",I34+ROW()/1000000)
A35: 31 | B35: 5 | C35: One correct option | D35: Hard | E35: [S] | F35: b | G35: =COUNTIF(Marks!AF$5:AF$39,1) | H35: =COUNT(Marks!AF$5:AF$39) | I35: =IF(H35=0,"",G35/H35) | J35: =IF(SUMPRODUCT((Marks!$AM$5:$AM$39="top")*ISNUMBER(Marks!AF$5:AF$39))=0,"",SUMPRODUCT((Marks!$AM$5:$AM$39="top")*(Marks!AF$5:AF$39=1))/SUMPRODUCT((Marks!$AM$5:$AM$39="top")*ISNUMBER(Marks!AF$5:AF$39))) | K35: =IF(SUMPRODUCT((Marks!$AM$5:$AM$39="bottom")*ISNUMBER(Marks!AF$5:AF$39))=0,"",SUMPRODUCT((Marks!$AM$5:$AM$39="bottom")*(Marks!AF$5:AF$39=1))/SUMPRODUCT((Marks!$AM$5:$AM$39="bottom")*ISNUMBER(Marks!AF$5:AF$39))) | L35: =IF(OR(J35="",K35=""),"",J35-K35) | M35: =IF(H35=0,"",IF(I35<0.2,"Check the item: fewer than one in five got it right",IF(AND(L35<>"",N(L35)<0),"Check the item: the bottom third beat the top third",""))) | N35: =IF(H35=0,"",I35+ROW()/1000000)
A36: 32 | B36: 5 | C36: One correct option | D36: Hard | E36: [S] | F36: a | G36: =COUNTIF(Marks!AG$5:AG$39,1) | H36: =COUNT(Marks!AG$5:AG$39) | I36: =IF(H36=0,"",G36/H36) | J36: =IF(SUMPRODUCT((Marks!$AM$5:$AM$39="top")*ISNUMBER(Marks!AG$5:AG$39))=0,"",SUMPRODUCT((Marks!$AM$5:$AM$39="top")*(Marks!AG$5:AG$39=1))/SUMPRODUCT((Marks!$AM$5:$AM$39="top")*ISNUMBER(Marks!AG$5:AG$39))) | K36: =IF(SUMPRODUCT((Marks!$AM$5:$AM$39="bottom")*ISNUMBER(Marks!AG$5:AG$39))=0,"",SUMPRODUCT((Marks!$AM$5:$AM$39="bottom")*(Marks!AG$5:AG$39=1))/SUMPRODUCT((Marks!$AM$5:$AM$39="bottom")*ISNUMBER(Marks!AG$5:AG$39))) | L36: =IF(OR(J36="",K36=""),"",J36-K36) | M36: =IF(H36=0,"",IF(I36<0.2,"Check the item: fewer than one in five got it right",IF(AND(L36<>"",N(L36)<0),"Check the item: the bottom third beat the top third",""))) | N36: =IF(H36=0,"",I36+ROW()/1000000)
A37: 33 | B37: 5 | C37: Match the following | D37: Medium | E37: [S] | F37: c | G37: =COUNTIF(Marks!AH$5:AH$39,1) | H37: =COUNT(Marks!AH$5:AH$39) | I37: =IF(H37=0,"",G37/H37) | J37: =IF(SUMPRODUCT((Marks!$AM$5:$AM$39="top")*ISNUMBER(Marks!AH$5:AH$39))=0,"",SUMPRODUCT((Marks!$AM$5:$AM$39="top")*(Marks!AH$5:AH$39=1))/SUMPRODUCT((Marks!$AM$5:$AM$39="top")*ISNUMBER(Marks!AH$5:AH$39))) | K37: =IF(SUMPRODUCT((Marks!$AM$5:$AM$39="bottom")*ISNUMBER(Marks!AH$5:AH$39))=0,"",SUMPRODUCT((Marks!$AM$5:$AM$39="bottom")*(Marks!AH$5:AH$39=1))/SUMPRODUCT((Marks!$AM$5:$AM$39="bottom")*ISNUMBER(Marks!AH$5:AH$39))) | L37: =IF(OR(J37="",K37=""),"",J37-K37) | M37: =IF(H37=0,"",IF(I37<0.2,"Check the item: fewer than one in five got it right",IF(AND(L37<>"",N(L37)<0),"Check the item: the bottom third beat the top third",""))) | N37: =IF(H37=0,"",I37+ROW()/1000000)
A38: 34 | B38: 5 | C38: Match the following | D38: Medium | E38: [S] | F38: f | G38: =COUNTIF(Marks!AI$5:AI$39,1) | H38: =COUNT(Marks!AI$5:AI$39) | I38: =IF(H38=0,"",G38/H38) | J38: =IF(SUMPRODUCT((Marks!$AM$5:$AM$39="top")*ISNUMBER(Marks!AI$5:AI$39))=0,"",SUMPRODUCT((Marks!$AM$5:$AM$39="top")*(Marks!AI$5:AI$39=1))/SUMPRODUCT((Marks!$AM$5:$AM$39="top")*ISNUMBER(Marks!AI$5:AI$39))) | K38: =IF(SUMPRODUCT((Marks!$AM$5:$AM$39="bottom")*ISNUMBER(Marks!AI$5:AI$39))=0,"",SUMPRODUCT((Marks!$AM$5:$AM$39="bottom")*(Marks!AI$5:AI$39=1))/SUMPRODUCT((Marks!$AM$5:$AM$39="bottom")*ISNUMBER(Marks!AI$5:AI$39))) | L38: =IF(OR(J38="",K38=""),"",J38-K38) | M38: =IF(H38=0,"",IF(I38<0.2,"Check the item: fewer than one in five got it right",IF(AND(L38<>"",N(L38)<0),"Check the item: the bottom third beat the top third",""))) | N38: =IF(H38=0,"",I38+ROW()/1000000)
A39: 35 | B39: 5 | C39: Match the following | D39: Medium | E39: [S] | F39: a | G39: =COUNTIF(Marks!AJ$5:AJ$39,1) | H39: =COUNT(Marks!AJ$5:AJ$39) | I39: =IF(H39=0,"",G39/H39) | J39: =IF(SUMPRODUCT((Marks!$AM$5:$AM$39="top")*ISNUMBER(Marks!AJ$5:AJ$39))=0,"",SUMPRODUCT((Marks!$AM$5:$AM$39="top")*(Marks!AJ$5:AJ$39=1))/SUMPRODUCT((Marks!$AM$5:$AM$39="top")*ISNUMBER(Marks!AJ$5:AJ$39))) | K39: =IF(SUMPRODUCT((Marks!$AM$5:$AM$39="bottom")*ISNUMBER(Marks!AJ$5:AJ$39))=0,"",SUMPRODUCT((Marks!$AM$5:$AM$39="bottom")*(Marks!AJ$5:AJ$39=1))/SUMPRODUCT((Marks!$AM$5:$AM$39="bottom")*ISNUMBER(Marks!AJ$5:AJ$39))) | L39: =IF(OR(J39="",K39=""),"",J39-K39) | M39: =IF(H39=0,"",IF(I39<0.2,"Check the item: fewer than one in five got it right",IF(AND(L39<>"",N(L39)<0),"Check the item: the bottom third beat the top third",""))) | N39: =IF(H39=0,"",I39+ROW()/1000000)

Sheet Discussion
A1: The solution discussion, from the most-missed item
B2: =IF(SUM(Items!H5:H39)=0,"No marks entered yet.","Most-missed first: take the items from the top.")
A4: Order | B4: Q | C4: Right rate | D4: Part | E4: Tag | F4: Flag
A5: 1 | B5: =IF(COUNT(Items!$N$5:$N$39)<A5,"",INDEX(Items!$A$5:$A$39,MATCH(SMALL(Items!$N$5:$N$39,A5),Items!$N$5:$N$39,0))) | C5: =IF(B5="","",INDEX(Items!$I$5:$I$39,MATCH(B5,Items!$A$5:$A$39,0))) | D5: =IF(B5="","",INDEX(Items!$B$5:$B$39,MATCH(B5,Items!$A$5:$A$39,0))) | E5: =IF(B5="","",INDEX(Items!$E$5:$E$39,MATCH(B5,Items!$A$5:$A$39,0))) | F5: =IF(B5="","",INDEX(Items!$M$5:$M$39,MATCH(B5,Items!$A$5:$A$39,0)))
A6: 2 | B6: =IF(COUNT(Items!$N$5:$N$39)<A6,"",INDEX(Items!$A$5:$A$39,MATCH(SMALL(Items!$N$5:$N$39,A6),Items!$N$5:$N$39,0))) | C6: =IF(B6="","",INDEX(Items!$I$5:$I$39,MATCH(B6,Items!$A$5:$A$39,0))) | D6: =IF(B6="","",INDEX(Items!$B$5:$B$39,MATCH(B6,Items!$A$5:$A$39,0))) | E6: =IF(B6="","",INDEX(Items!$E$5:$E$39,MATCH(B6,Items!$A$5:$A$39,0))) | F6: =IF(B6="","",INDEX(Items!$M$5:$M$39,MATCH(B6,Items!$A$5:$A$39,0)))
A7: 3 | B7: =IF(COUNT(Items!$N$5:$N$39)<A7,"",INDEX(Items!$A$5:$A$39,MATCH(SMALL(Items!$N$5:$N$39,A7),Items!$N$5:$N$39,0))) | C7: =IF(B7="","",INDEX(Items!$I$5:$I$39,MATCH(B7,Items!$A$5:$A$39,0))) | D7: =IF(B7="","",INDEX(Items!$B$5:$B$39,MATCH(B7,Items!$A$5:$A$39,0))) | E7: =IF(B7="","",INDEX(Items!$E$5:$E$39,MATCH(B7,Items!$A$5:$A$39,0))) | F7: =IF(B7="","",INDEX(Items!$M$5:$M$39,MATCH(B7,Items!$A$5:$A$39,0)))
A8: 4 | B8: =IF(COUNT(Items!$N$5:$N$39)<A8,"",INDEX(Items!$A$5:$A$39,MATCH(SMALL(Items!$N$5:$N$39,A8),Items!$N$5:$N$39,0))) | C8: =IF(B8="","",INDEX(Items!$I$5:$I$39,MATCH(B8,Items!$A$5:$A$39,0))) | D8: =IF(B8="","",INDEX(Items!$B$5:$B$39,MATCH(B8,Items!$A$5:$A$39,0))) | E8: =IF(B8="","",INDEX(Items!$E$5:$E$39,MATCH(B8,Items!$A$5:$A$39,0))) | F8: =IF(B8="","",INDEX(Items!$M$5:$M$39,MATCH(B8,Items!$A$5:$A$39,0)))
A9: 5 | B9: =IF(COUNT(Items!$N$5:$N$39)<A9,"",INDEX(Items!$A$5:$A$39,MATCH(SMALL(Items!$N$5:$N$39,A9),Items!$N$5:$N$39,0))) | C9: =IF(B9="","",INDEX(Items!$I$5:$I$39,MATCH(B9,Items!$A$5:$A$39,0))) | D9: =IF(B9="","",INDEX(Items!$B$5:$B$39,MATCH(B9,Items!$A$5:$A$39,0))) | E9: =IF(B9="","",INDEX(Items!$E$5:$E$39,MATCH(B9,Items!$A$5:$A$39,0))) | F9: =IF(B9="","",INDEX(Items!$M$5:$M$39,MATCH(B9,Items!$A$5:$A$39,0)))
A10: 6 | B10: =IF(COUNT(Items!$N$5:$N$39)<A10,"",INDEX(Items!$A$5:$A$39,MATCH(SMALL(Items!$N$5:$N$39,A10),Items!$N$5:$N$39,0))) | C10: =IF(B10="","",INDEX(Items!$I$5:$I$39,MATCH(B10,Items!$A$5:$A$39,0))) | D10: =IF(B10="","",INDEX(Items!$B$5:$B$39,MATCH(B10,Items!$A$5:$A$39,0))) | E10: =IF(B10="","",INDEX(Items!$E$5:$E$39,MATCH(B10,Items!$A$5:$A$39,0))) | F10: =IF(B10="","",INDEX(Items!$M$5:$M$39,MATCH(B10,Items!$A$5:$A$39,0)))
A11: 7 | B11: =IF(COUNT(Items!$N$5:$N$39)<A11,"",INDEX(Items!$A$5:$A$39,MATCH(SMALL(Items!$N$5:$N$39,A11),Items!$N$5:$N$39,0))) | C11: =IF(B11="","",INDEX(Items!$I$5:$I$39,MATCH(B11,Items!$A$5:$A$39,0))) | D11: =IF(B11="","",INDEX(Items!$B$5:$B$39,MATCH(B11,Items!$A$5:$A$39,0))) | E11: =IF(B11="","",INDEX(Items!$E$5:$E$39,MATCH(B11,Items!$A$5:$A$39,0))) | F11: =IF(B11="","",INDEX(Items!$M$5:$M$39,MATCH(B11,Items!$A$5:$A$39,0)))
A12: 8 | B12: =IF(COUNT(Items!$N$5:$N$39)<A12,"",INDEX(Items!$A$5:$A$39,MATCH(SMALL(Items!$N$5:$N$39,A12),Items!$N$5:$N$39,0))) | C12: =IF(B12="","",INDEX(Items!$I$5:$I$39,MATCH(B12,Items!$A$5:$A$39,0))) | D12: =IF(B12="","",INDEX(Items!$B$5:$B$39,MATCH(B12,Items!$A$5:$A$39,0))) | E12: =IF(B12="","",INDEX(Items!$E$5:$E$39,MATCH(B12,Items!$A$5:$A$39,0))) | F12: =IF(B12="","",INDEX(Items!$M$5:$M$39,MATCH(B12,Items!$A$5:$A$39,0)))
A13: 9 | B13: =IF(COUNT(Items!$N$5:$N$39)<A13,"",INDEX(Items!$A$5:$A$39,MATCH(SMALL(Items!$N$5:$N$39,A13),Items!$N$5:$N$39,0))) | C13: =IF(B13="","",INDEX(Items!$I$5:$I$39,MATCH(B13,Items!$A$5:$A$39,0))) | D13: =IF(B13="","",INDEX(Items!$B$5:$B$39,MATCH(B13,Items!$A$5:$A$39,0))) | E13: =IF(B13="","",INDEX(Items!$E$5:$E$39,MATCH(B13,Items!$A$5:$A$39,0))) | F13: =IF(B13="","",INDEX(Items!$M$5:$M$39,MATCH(B13,Items!$A$5:$A$39,0)))
A14: 10 | B14: =IF(COUNT(Items!$N$5:$N$39)<A14,"",INDEX(Items!$A$5:$A$39,MATCH(SMALL(Items!$N$5:$N$39,A14),Items!$N$5:$N$39,0))) | C14: =IF(B14="","",INDEX(Items!$I$5:$I$39,MATCH(B14,Items!$A$5:$A$39,0))) | D14: =IF(B14="","",INDEX(Items!$B$5:$B$39,MATCH(B14,Items!$A$5:$A$39,0))) | E14: =IF(B14="","",INDEX(Items!$E$5:$E$39,MATCH(B14,Items!$A$5:$A$39,0))) | F14: =IF(B14="","",INDEX(Items!$M$5:$M$39,MATCH(B14,Items!$A$5:$A$39,0)))
A15: 11 | B15: =IF(COUNT(Items!$N$5:$N$39)<A15,"",INDEX(Items!$A$5:$A$39,MATCH(SMALL(Items!$N$5:$N$39,A15),Items!$N$5:$N$39,0))) | C15: =IF(B15="","",INDEX(Items!$I$5:$I$39,MATCH(B15,Items!$A$5:$A$39,0))) | D15: =IF(B15="","",INDEX(Items!$B$5:$B$39,MATCH(B15,Items!$A$5:$A$39,0))) | E15: =IF(B15="","",INDEX(Items!$E$5:$E$39,MATCH(B15,Items!$A$5:$A$39,0))) | F15: =IF(B15="","",INDEX(Items!$M$5:$M$39,MATCH(B15,Items!$A$5:$A$39,0)))
A16: 12 | B16: =IF(COUNT(Items!$N$5:$N$39)<A16,"",INDEX(Items!$A$5:$A$39,MATCH(SMALL(Items!$N$5:$N$39,A16),Items!$N$5:$N$39,0))) | C16: =IF(B16="","",INDEX(Items!$I$5:$I$39,MATCH(B16,Items!$A$5:$A$39,0))) | D16: =IF(B16="","",INDEX(Items!$B$5:$B$39,MATCH(B16,Items!$A$5:$A$39,0))) | E16: =IF(B16="","",INDEX(Items!$E$5:$E$39,MATCH(B16,Items!$A$5:$A$39,0))) | F16: =IF(B16="","",INDEX(Items!$M$5:$M$39,MATCH(B16,Items!$A$5:$A$39,0)))
... A39: 35 | B39: =IF(COUNT(Items!$N$5:$N$39)<A39,"",INDEX(Items!$A$5:$A$39,MATCH(SMALL(Items!$N$5:$N$39,A39),Items!$N$5:$N$39,0))) | C39: =IF(B39="","",INDEX(Items!$I$5:$I$39,MATCH(B39,Items!$A$5:$A$39,0))) | D39: =IF(B39="","",INDEX(Items!$B$5:$B$39,MATCH(B39,Items!$A$5:$A$39,0))) | E39: =IF(B39="","",INDEX(Items!$E$5:$E$39,MATCH(B39,Items!$A$5:$A$39,0))) | F39: =IF(B39="","",INDEX(Items!$M$5:$M$39,MATCH(B39,Items!$A$5:$A$39,0)))

Sheet Tags
A1: The room's rate by tag and by part
A4: Tag or part | B4: Name | C4: Items | D4: Right rate
A5: [S] | B5: tag | C5: =COUNTIF(Items!$E$5:$E$39,A5) | D5: =IF(SUMPRODUCT((Items!$E$5:$E$39=A5)*Items!$H$5:$H$39)=0,"",SUMPRODUCT((Items!$E$5:$E$39=A5)*Items!$G$5:$G$39)/SUMPRODUCT((Items!$E$5:$E$39=A5)*Items!$H$5:$H$39))
A6: [F] | B6: tag | C6: =COUNTIF(Items!$E$5:$E$39,A6) | D6: =IF(SUMPRODUCT((Items!$E$5:$E$39=A6)*Items!$H$5:$H$39)=0,"",SUMPRODUCT((Items!$E$5:$E$39=A6)*Items!$G$5:$G$39)/SUMPRODUCT((Items!$E$5:$E$39=A6)*Items!$H$5:$H$39))
A7: [SV] | B7: tag | C7: =COUNTIF(Items!$E$5:$E$39,A7) | D7: =IF(SUMPRODUCT((Items!$E$5:$E$39=A7)*Items!$H$5:$H$39)=0,"",SUMPRODUCT((Items!$E$5:$E$39=A7)*Items!$G$5:$G$39)/SUMPRODUCT((Items!$E$5:$E$39=A7)*Items!$H$5:$H$39))
A8: [D] | B8: tag | C8: =COUNTIF(Items!$E$5:$E$39,A8) | D8: =IF(SUMPRODUCT((Items!$E$5:$E$39=A8)*Items!$H$5:$H$39)=0,"",SUMPRODUCT((Items!$E$5:$E$39=A8)*Items!$G$5:$G$39)/SUMPRODUCT((Items!$E$5:$E$39=A8)*Items!$H$5:$H$39))
A9: 1 | B9: Part 1. Where did Kalpa's revenue go between the first quarter and the second? | C9: =COUNTIF(Items!$B$5:$B$39,A9) | D9: =IF(SUMPRODUCT((Items!$B$5:$B$39=A9)*Items!$H$5:$H$39)=0,"",SUMPRODUCT((Items!$B$5:$B$39=A9)*Items!$G$5:$G$39)/SUMPRODUCT((Items!$B$5:$B$39=A9)*Items!$H$5:$H$39))
A10: 2 | B10: Part 2. Did Kalpa book Rs 2.1 crore in the first quarter, or Rs 1.9 crore? | C10: =COUNTIF(Items!$B$5:$B$39,A10) | D10: =IF(SUMPRODUCT((Items!$B$5:$B$39=A10)*Items!$H$5:$H$39)=0,"",SUMPRODUCT((Items!$B$5:$B$39=A10)*Items!$G$5:$G$39)/SUMPRODUCT((Items!$B$5:$B$39=A10)*Items!$H$5:$H$39))
A11: 3 | B11: Part 3. Is the Retail-Plus fall more than chance, and what should Meera's note say? | C11: =COUNTIF(Items!$B$5:$B$39,A11) | D11: =IF(SUMPRODUCT((Items!$B$5:$B$39=A11)*Items!$H$5:$H$39)=0,"",SUMPRODUCT((Items!$B$5:$B$39=A11)*Items!$G$5:$G$39)/SUMPRODUCT((Items!$B$5:$B$39=A11)*Items!$H$5:$H$39))
A12: 4 | B12: Part 4. Which check would have caught the misleading number in five public cases? | C12: =COUNTIF(Items!$B$5:$B$39,A12) | D12: =IF(SUMPRODUCT((Items!$B$5:$B$39=A12)*Items!$H$5:$H$39)=0,"",SUMPRODUCT((Items!$B$5:$B$39=A12)*Items!$G$5:$G$39)/SUMPRODUCT((Items!$B$5:$B$39=A12)*Items!$H$5:$H$39))
A13: 5 | B13: Part 5. Did a delivery company's offer raise spending, and are its AI agent's numbers right? | C13: =COUNTIF(Items!$B$5:$B$39,A13) | D13: =IF(SUMPRODUCT((Items!$B$5:$B$39=A13)*Items!$H$5:$H$39)=0,"",SUMPRODUCT((Items!$B$5:$B$39=A13)*Items!$G$5:$G$39)/SUMPRODUCT((Items!$B$5:$B$39=A13)*Items!$H$5:$H$39))

Sheet Seats
A1: Each seat's rate by tag, for Monday's remediation read
A4: Seat | B4: [S] | C4: [F] | D4: [SV] | E4: [D]
A5: 1 | B5: =IF(SUMPRODUCT((Marks!$B$3:$AJ$3=B$4)*ISNUMBER(Marks!$B$5:$AJ$5))=0,"",SUMPRODUCT((Marks!$B$3:$AJ$3=B$4)*(Marks!$B$5:$AJ$5=1))/SUMPRODUCT((Marks!$B$3:$AJ$3=B$4)*ISNUMBER(Marks!$B$5:$AJ$5))) | C5: =IF(SUMPRODUCT((Marks!$B$3:$AJ$3=C$4)*ISNUMBER(Marks!$B$5:$AJ$5))=0,"",SUMPRODUCT((Marks!$B$3:$AJ$3=C$4)*(Marks!$B$5:$AJ$5=1))/SUMPRODUCT((Marks!$B$3:$AJ$3=C$4)*ISNUMBER(Marks!$B$5:$AJ$5))) | D5: =IF(SUMPRODUCT((Marks!$B$3:$AJ$3=D$4)*ISNUMBER(Marks!$B$5:$AJ$5))=0,"",SUMPRODUCT((Marks!$B$3:$AJ$3=D$4)*(Marks!$B$5:$AJ$5=1))/SUMPRODUCT((Marks!$B$3:$AJ$3=D$4)*ISNUMBER(Marks!$B$5:$AJ$5))) | E5: =IF(SUMPRODUCT((Marks!$B$3:$AJ$3=E$4)*ISNUMBER(Marks!$B$5:$AJ$5))=0,"",SUMPRODUCT((Marks!$B$3:$AJ$3=E$4)*(Marks!$B$5:$AJ$5=1))/SUMPRODUCT((Marks!$B$3:$AJ$3=E$4)*ISNUMBER(Marks!$B$5:$AJ$5)))
A6: 2 | B6: =IF(SUMPRODUCT((Marks!$B$3:$AJ$3=B$4)*ISNUMBER(Marks!$B$6:$AJ$6))=0,"",SUMPRODUCT((Marks!$B$3:$AJ$3=B$4)*(Marks!$B$6:$AJ$6=1))/SUMPRODUCT((Marks!$B$3:$AJ$3=B$4)*ISNUMBER(Marks!$B$6:$AJ$6))) | C6: =IF(SUMPRODUCT((Marks!$B$3:$AJ$3=C$4)*ISNUMBER(Marks!$B$6:$AJ$6))=0,"",SUMPRODUCT((Marks!$B$3:$AJ$3=C$4)*(Marks!$B$6:$AJ$6=1))/SUMPRODUCT((Marks!$B$3:$AJ$3=C$4)*ISNUMBER(Marks!$B$6:$AJ$6))) | D6: =IF(SUMPRODUCT((Marks!$B$3:$AJ$3=D$4)*ISNUMBER(Marks!$B$6:$AJ$6))=0,"",SUMPRODUCT((Marks!$B$3:$AJ$3=D$4)*(Marks!$B$6:$AJ$6=1))/SUMPRODUCT((Marks!$B$3:$AJ$3=D$4)*ISNUMBER(Marks!$B$6:$AJ$6))) | E6: =IF(SUMPRODUCT((Marks!$B$3:$AJ$3=E$4)*ISNUMBER(Marks!$B$6:$AJ$6))=0,"",SUMPRODUCT((Marks!$B$3:$AJ$3=E$4)*(Marks!$B$6:$AJ$6=1))/SUMPRODUCT((Marks!$B$3:$AJ$3=E$4)*ISNUMBER(Marks!$B$6:$AJ$6)))
A7: 3 | B7: =IF(SUMPRODUCT((Marks!$B$3:$AJ$3=B$4)*ISNUMBER(Marks!$B$7:$AJ$7))=0,"",SUMPRODUCT((Marks!$B$3:$AJ$3=B$4)*(Marks!$B$7:$AJ$7=1))/SUMPRODUCT((Marks!$B$3:$AJ$3=B$4)*ISNUMBER(Marks!$B$7:$AJ$7))) | C7: =IF(SUMPRODUCT((Marks!$B$3:$AJ$3=C$4)*ISNUMBER(Marks!$B$7:$AJ$7))=0,"",SUMPRODUCT((Marks!$B$3:$AJ$3=C$4)*(Marks!$B$7:$AJ$7=1))/SUMPRODUCT((Marks!$B$3:$AJ$3=C$4)*ISNUMBER(Marks!$B$7:$AJ$7))) | D7: =IF(SUMPRODUCT((Marks!$B$3:$AJ$3=D$4)*ISNUMBER(Marks!$B$7:$AJ$7))=0,"",SUMPRODUCT((Marks!$B$3:$AJ$3=D$4)*(Marks!$B$7:$AJ$7=1))/SUMPRODUCT((Marks!$B$3:$AJ$3=D$4)*ISNUMBER(Marks!$B$7:$AJ$7))) | E7: =IF(SUMPRODUCT((Marks!$B$3:$AJ$3=E$4)*ISNUMBER(Marks!$B$7:$AJ$7))=0,"",SUMPRODUCT((Marks!$B$3:$AJ$3=E$4)*(Marks!$B$7:$AJ$7=1))/SUMPRODUCT((Marks!$B$3:$AJ$3=E$4)*ISNUMBER(Marks!$B$7:$AJ$7)))
A8: 4 | B8: =IF(SUMPRODUCT((Marks!$B$3:$AJ$3=B$4)*ISNUMBER(Marks!$B$8:$AJ$8))=0,"",SUMPRODUCT((Marks!$B$3:$AJ$3=B$4)*(Marks!$B$8:$AJ$8=1))/SUMPRODUCT((Marks!$B$3:$AJ$3=B$4)*ISNUMBER(Marks!$B$8:$AJ$8))) | C8: =IF(SUMPRODUCT((Marks!$B$3:$AJ$3=C$4)*ISNUMBER(Marks!$B$8:$AJ$8))=0,"",SUMPRODUCT((Marks!$B$3:$AJ$3=C$4)*(Marks!$B$8:$AJ$8=1))/SUMPRODUCT((Marks!$B$3:$AJ$3=C$4)*ISNUMBER(Marks!$B$8:$AJ$8))) | D8: =IF(SUMPRODUCT((Marks!$B$3:$AJ$3=D$4)*ISNUMBER(Marks!$B$8:$AJ$8))=0,"",SUMPRODUCT((Marks!$B$3:$AJ$3=D$4)*(Marks!$B$8:$AJ$8=1))/SUMPRODUCT((Marks!$B$3:$AJ$3=D$4)*ISNUMBER(Marks!$B$8:$AJ$8))) | E8: =IF(SUMPRODUCT((Marks!$B$3:$AJ$3=E$4)*ISNUMBER(Marks!$B$8:$AJ$8))=0,"",SUMPRODUCT((Marks!$B$3:$AJ$3=E$4)*(Marks!$B$8:$AJ$8=1))/SUMPRODUCT((Marks!$B$3:$AJ$3=E$4)*ISNUMBER(Marks!$B$8:$AJ$8)))
A9: 5 | B9: =IF(SUMPRODUCT((Marks!$B$3:$AJ$3=B$4)*ISNUMBER(Marks!$B$9:$AJ$9))=0,"",SUMPRODUCT((Marks!$B$3:$AJ$3=B$4)*(Marks!$B$9:$AJ$9=1))/SUMPRODUCT((Marks!$B$3:$AJ$3=B$4)*ISNUMBER(Marks!$B$9:$AJ$9))) | C9: =IF(SUMPRODUCT((Marks!$B$3:$AJ$3=C$4)*ISNUMBER(Marks!$B$9:$AJ$9))=0,"",SUMPRODUCT((Marks!$B$3:$AJ$3=C$4)*(Marks!$B$9:$AJ$9=1))/SUMPRODUCT((Marks!$B$3:$AJ$3=C$4)*ISNUMBER(Marks!$B$9:$AJ$9))) | D9: =IF(SUMPRODUCT((Marks!$B$3:$AJ$3=D$4)*ISNUMBER(Marks!$B$9:$AJ$9))=0,"",SUMPRODUCT((Marks!$B$3:$AJ$3=D$4)*(Marks!$B$9:$AJ$9=1))/SUMPRODUCT((Marks!$B$3:$AJ$3=D$4)*ISNUMBER(Marks!$B$9:$AJ$9))) | E9: =IF(SUMPRODUCT((Marks!$B$3:$AJ$3=E$4)*ISNUMBER(Marks!$B$9:$AJ$9))=0,"",SUMPRODUCT((Marks!$B$3:$AJ$3=E$4)*(Marks!$B$9:$AJ$9=1))/SUMPRODUCT((Marks!$B$3:$AJ$3=E$4)*ISNUMBER(Marks!$B$9:$AJ$9)))
A10: 6 | B10: =IF(SUMPRODUCT((Marks!$B$3:$AJ$3=B$4)*ISNUMBER(Marks!$B$10:$AJ$10))=0,"",SUMPRODUCT((Marks!$B$3:$AJ$3=B$4)*(Marks!$B$10:$AJ$10=1))/SUMPRODUCT((Marks!$B$3:$AJ$3=B$4)*ISNUMBER(Marks!$B$10:$AJ$10))) | C10: =IF(SUMPRODUCT((Marks!$B$3:$AJ$3=C$4)*ISNUMBER(Marks!$B$10:$AJ$10))=0,"",SUMPRODUCT((Marks!$B$3:$AJ$3=C$4)*(Marks!$B$10:$AJ$10=1))/SUMPRODUCT((Marks!$B$3:$AJ$3=C$4)*ISNUMBER(Marks!$B$10:$AJ$10))) | D10: =IF(SUMPRODUCT((Marks!$B$3:$AJ$3=D$4)*ISNUMBER(Marks!$B$10:$AJ$10))=0,"",SUMPRODUCT((Marks!$B$3:$AJ$3=D$4)*(Marks!$B$10:$AJ$10=1))/SUMPRODUCT((Marks!$B$3:$AJ$3=D$4)*ISNUMBER(Marks!$B$10:$AJ$10))) | E10: =IF(SUMPRODUCT((Marks!$B$3:$AJ$3=E$4)*ISNUMBER(Marks!$B$10:$AJ$10))=0,"",SUMPRODUCT((Marks!$B$3:$AJ$3=E$4)*(Marks!$B$10:$AJ$10=1))/SUMPRODUCT((Marks!$B$3:$AJ$3=E$4)*ISNUMBER(Marks!$B$10:$AJ$10)))
A11: 7 | B11: =IF(SUMPRODUCT((Marks!$B$3:$AJ$3=B$4)*ISNUMBER(Marks!$B$11:$AJ$11))=0,"",SUMPRODUCT((Marks!$B$3:$AJ$3=B$4)*(Marks!$B$11:$AJ$11=1))/SUMPRODUCT((Marks!$B$3:$AJ$3=B$4)*ISNUMBER(Marks!$B$11:$AJ$11))) | C11: =IF(SUMPRODUCT((Marks!$B$3:$AJ$3=C$4)*ISNUMBER(Marks!$B$11:$AJ$11))=0,"",SUMPRODUCT((Marks!$B$3:$AJ$3=C$4)*(Marks!$B$11:$AJ$11=1))/SUMPRODUCT((Marks!$B$3:$AJ$3=C$4)*ISNUMBER(Marks!$B$11:$AJ$11))) | D11: =IF(SUMPRODUCT((Marks!$B$3:$AJ$3=D$4)*ISNUMBER(Marks!$B$11:$AJ$11))=0,"",SUMPRODUCT((Marks!$B$3:$AJ$3=D$4)*(Marks!$B$11:$AJ$11=1))/SUMPRODUCT((Marks!$B$3:$AJ$3=D$4)*ISNUMBER(Marks!$B$11:$AJ$11))) | E11: =IF(SUMPRODUCT((Marks!$B$3:$AJ$3=E$4)*ISNUMBER(Marks!$B$11:$AJ$11))=0,"",SUMPRODUCT((Marks!$B$3:$AJ$3=E$4)*(Marks!$B$11:$AJ$11=1))/SUMPRODUCT((Marks!$B$3:$AJ$3=E$4)*ISNUMBER(Marks!$B$11:$AJ$11)))
A12: 8 | B12: =IF(SUMPRODUCT((Marks!$B$3:$AJ$3=B$4)*ISNUMBER(Marks!$B$12:$AJ$12))=0,"",SUMPRODUCT((Marks!$B$3:$AJ$3=B$4)*(Marks!$B$12:$AJ$12=1))/SUMPRODUCT((Marks!$B$3:$AJ$3=B$4)*ISNUMBER(Marks!$B$12:$AJ$12))) | C12: =IF(SUMPRODUCT((Marks!$B$3:$AJ$3=C$4)*ISNUMBER(Marks!$B$12:$AJ$12))=0,"",SUMPRODUCT((Marks!$B$3:$AJ$3=C$4)*(Marks!$B$12:$AJ$12=1))/SUMPRODUCT((Marks!$B$3:$AJ$3=C$4)*ISNUMBER(Marks!$B$12:$AJ$12))) | D12: =IF(SUMPRODUCT((Marks!$B$3:$AJ$3=D$4)*ISNUMBER(Marks!$B$12:$AJ$12))=0,"",SUMPRODUCT((Marks!$B$3:$AJ$3=D$4)*(Marks!$B$12:$AJ$12=1))/SUMPRODUCT((Marks!$B$3:$AJ$3=D$4)*ISNUMBER(Marks!$B$12:$AJ$12))) | E12: =IF(SUMPRODUCT((Marks!$B$3:$AJ$3=E$4)*ISNUMBER(Marks!$B$12:$AJ$12))=0,"",SUMPRODUCT((Marks!$B$3:$AJ$3=E$4)*(Marks!$B$12:$AJ$12=1))/SUMPRODUCT((Marks!$B$3:$AJ$3=E$4)*ISNUMBER(Marks!$B$12:$AJ$12)))
A13: 9 | B13: =IF(SUMPRODUCT((Marks!$B$3:$AJ$3=B$4)*ISNUMBER(Marks!$B$13:$AJ$13))=0,"",SUMPRODUCT((Marks!$B$3:$AJ$3=B$4)*(Marks!$B$13:$AJ$13=1))/SUMPRODUCT((Marks!$B$3:$AJ$3=B$4)*ISNUMBER(Marks!$B$13:$AJ$13))) | C13: =IF(SUMPRODUCT((Marks!$B$3:$AJ$3=C$4)*ISNUMBER(Marks!$B$13:$AJ$13))=0,"",SUMPRODUCT((Marks!$B$3:$AJ$3=C$4)*(Marks!$B$13:$AJ$13=1))/SUMPRODUCT((Marks!$B$3:$AJ$3=C$4)*ISNUMBER(Marks!$B$13:$AJ$13))) | D13: =IF(SUMPRODUCT((Marks!$B$3:$AJ$3=D$4)*ISNUMBER(Marks!$B$13:$AJ$13))=0,"",SUMPRODUCT((Marks!$B$3:$AJ$3=D$4)*(Marks!$B$13:$AJ$13=1))/SUMPRODUCT((Marks!$B$3:$AJ$3=D$4)*ISNUMBER(Marks!$B$13:$AJ$13))) | E13: =IF(SUMPRODUCT((Marks!$B$3:$AJ$3=E$4)*ISNUMBER(Marks!$B$13:$AJ$13))=0,"",SUMPRODUCT((Marks!$B$3:$AJ$3=E$4)*(Marks!$B$13:$AJ$13=1))/SUMPRODUCT((Marks!$B$3:$AJ$3=E$4)*ISNUMBER(Marks!$B$13:$AJ$13)))
A14: 10 | B14: =IF(SUMPRODUCT((Marks!$B$3:$AJ$3=B$4)*ISNUMBER(Marks!$B$14:$AJ$14))=0,"",SUMPRODUCT((Marks!$B$3:$AJ$3=B$4)*(Marks!$B$14:$AJ$14=1))/SUMPRODUCT((Marks!$B$3:$AJ$3=B$4)*ISNUMBER(Marks!$B$14:$AJ$14))) | C14: =IF(SUMPRODUCT((Marks!$B$3:$AJ$3=C$4)*ISNUMBER(Marks!$B$14:$AJ$14))=0,"",SUMPRODUCT((Marks!$B$3:$AJ$3=C$4)*(Marks!$B$14:$AJ$14=1))/SUMPRODUCT((Marks!$B$3:$AJ$3=C$4)*ISNUMBER(Marks!$B$14:$AJ$14))) | D14: =IF(SUMPRODUCT((Marks!$B$3:$AJ$3=D$4)*ISNUMBER(Marks!$B$14:$AJ$14))=0,"",SUMPRODUCT((Marks!$B$3:$AJ$3=D$4)*(Marks!$B$14:$AJ$14=1))/SUMPRODUCT((Marks!$B$3:$AJ$3=D$4)*ISNUMBER(Marks!$B$14:$AJ$14))) | E14: =IF(SUMPRODUCT((Marks!$B$3:$AJ$3=E$4)*ISNUMBER(Marks!$B$14:$AJ$14))=0,"",SUMPRODUCT((Marks!$B$3:$AJ$3=E$4)*(Marks!$B$14:$AJ$14=1))/SUMPRODUCT((Marks!$B$3:$AJ$3=E$4)*ISNUMBER(Marks!$B$14:$AJ$14)))
A15: 11 | B15: =IF(SUMPRODUCT((Marks!$B$3:$AJ$3=B$4)*ISNUMBER(Marks!$B$15:$AJ$15))=0,"",SUMPRODUCT((Marks!$B$3:$AJ$3=B$4)*(Marks!$B$15:$AJ$15=1))/SUMPRODUCT((Marks!$B$3:$AJ$3=B$4)*ISNUMBER(Marks!$B$15:$AJ$15))) | C15: =IF(SUMPRODUCT((Marks!$B$3:$AJ$3=C$4)*ISNUMBER(Marks!$B$15:$AJ$15))=0,"",SUMPRODUCT((Marks!$B$3:$AJ$3=C$4)*(Marks!$B$15:$AJ$15=1))/SUMPRODUCT((Marks!$B$3:$AJ$3=C$4)*ISNUMBER(Marks!$B$15:$AJ$15))) | D15: =IF(SUMPRODUCT((Marks!$B$3:$AJ$3=D$4)*ISNUMBER(Marks!$B$15:$AJ$15))=0,"",SUMPRODUCT((Marks!$B$3:$AJ$3=D$4)*(Marks!$B$15:$AJ$15=1))/SUMPRODUCT((Marks!$B$3:$AJ$3=D$4)*ISNUMBER(Marks!$B$15:$AJ$15))) | E15: =IF(SUMPRODUCT((Marks!$B$3:$AJ$3=E$4)*ISNUMBER(Marks!$B$15:$AJ$15))=0,"",SUMPRODUCT((Marks!$B$3:$AJ$3=E$4)*(Marks!$B$15:$AJ$15=1))/SUMPRODUCT((Marks!$B$3:$AJ$3=E$4)*ISNUMBER(Marks!$B$15:$AJ$15)))
A16: 12 | B16: =IF(SUMPRODUCT((Marks!$B$3:$AJ$3=B$4)*ISNUMBER(Marks!$B$16:$AJ$16))=0,"",SUMPRODUCT((Marks!$B$3:$AJ$3=B$4)*(Marks!$B$16:$AJ$16=1))/SUMPRODUCT((Marks!$B$3:$AJ$3=B$4)*ISNUMBER(Marks!$B$16:$AJ$16))) | C16: =IF(SUMPRODUCT((Marks!$B$3:$AJ$3=C$4)*ISNUMBER(Marks!$B$16:$AJ$16))=0,"",SUMPRODUCT((Marks!$B$3:$AJ$3=C$4)*(Marks!$B$16:$AJ$16=1))/SUMPRODUCT((Marks!$B$3:$AJ$3=C$4)*ISNUMBER(Marks!$B$16:$AJ$16))) | D16: =IF(SUMPRODUCT((Marks!$B$3:$AJ$3=D$4)*ISNUMBER(Marks!$B$16:$AJ$16))=0,"",SUMPRODUCT((Marks!$B$3:$AJ$3=D$4)*(Marks!$B$16:$AJ$16=1))/SUMPRODUCT((Marks!$B$3:$AJ$3=D$4)*ISNUMBER(Marks!$B$16:$AJ$16))) | E16: =IF(SUMPRODUCT((Marks!$B$3:$AJ$3=E$4)*ISNUMBER(Marks!$B$16:$AJ$16))=0,"",SUMPRODUCT((Marks!$B$3:$AJ$3=E$4)*(Marks!$B$16:$AJ$16=1))/SUMPRODUCT((Marks!$B$3:$AJ$3=E$4)*ISNUMBER(Marks!$B$16:$AJ$16)))
A17: 13 | B17: =IF(SUMPRODUCT((Marks!$B$3:$AJ$3=B$4)*ISNUMBER(Marks!$B$17:$AJ$17))=0,"",SUMPRODUCT((Marks!$B$3:$AJ$3=B$4)*(Marks!$B$17:$AJ$17=1))/SUMPRODUCT((Marks!$B$3:$AJ$3=B$4)*ISNUMBER(Marks!$B$17:$AJ$17))) | C17: =IF(SUMPRODUCT((Marks!$B$3:$AJ$3=C$4)*ISNUMBER(Marks!$B$17:$AJ$17))=0,"",SUMPRODUCT((Marks!$B$3:$AJ$3=C$4)*(Marks!$B$17:$AJ$17=1))/SUMPRODUCT((Marks!$B$3:$AJ$3=C$4)*ISNUMBER(Marks!$B$17:$AJ$17))) | D17: =IF(SUMPRODUCT((Marks!$B$3:$AJ$3=D$4)*ISNUMBER(Marks!$B$17:$AJ$17))=0,"",SUMPRODUCT((Marks!$B$3:$AJ$3=D$4)*(Marks!$B$17:$AJ$17=1))/SUMPRODUCT((Marks!$B$3:$AJ$3=D$4)*ISNUMBER(Marks!$B$17:$AJ$17))) | E17: =IF(SUMPRODUCT((Marks!$B$3:$AJ$3=E$4)*ISNUMBER(Marks!$B$17:$AJ$17))=0,"",SUMPRODUCT((Marks!$B$3:$AJ$3=E$4)*(Marks!$B$17:$AJ$17=1))/SUMPRODUCT((Marks!$B$3:$AJ$3=E$4)*ISNUMBER(Marks!$B$17:$AJ$17)))
A18: 14 | B18: =IF(SUMPRODUCT((Marks!$B$3:$AJ$3=B$4)*ISNUMBER(Marks!$B$18:$AJ$18))=0,"",SUMPRODUCT((Marks!$B$3:$AJ$3=B$4)*(Marks!$B$18:$AJ$18=1))/SUMPRODUCT((Marks!$B$3:$AJ$3=B$4)*ISNUMBER(Marks!$B$18:$AJ$18))) | C18: =IF(SUMPRODUCT((Marks!$B$3:$AJ$3=C$4)*ISNUMBER(Marks!$B$18:$AJ$18))=0,"",SUMPRODUCT((Marks!$B$3:$AJ$3=C$4)*(Marks!$B$18:$AJ$18=1))/SUMPRODUCT((Marks!$B$3:$AJ$3=C$4)*ISNUMBER(Marks!$B$18:$AJ$18))) | D18: =IF(SUMPRODUCT((Marks!$B$3:$AJ$3=D$4)*ISNUMBER(Marks!$B$18:$AJ$18))=0,"",SUMPRODUCT((Marks!$B$3:$AJ$3=D$4)*(Marks!$B$18:$AJ$18=1))/SUMPRODUCT((Marks!$B$3:$AJ$3=D$4)*ISNUMBER(Marks!$B$18:$AJ$18))) | E18: =IF(SUMPRODUCT((Marks!$B$3:$AJ$3=E$4)*ISNUMBER(Marks!$B$18:$AJ$18))=0,"",SUMPRODUCT((Marks!$B$3:$AJ$3=E$4)*(Marks!$B$18:$AJ$18=1))/SUMPRODUCT((Marks!$B$3:$AJ$3=E$4)*ISNUMBER(Marks!$B$18:$AJ$18)))
A19: 15 | B19: =IF(SUMPRODUCT((Marks!$B$3:$AJ$3=B$4)*ISNUMBER(Marks!$B$19:$AJ$19))=0,"",SUMPRODUCT((Marks!$B$3:$AJ$3=B$4)*(Marks!$B$19:$AJ$19=1))/SUMPRODUCT((Marks!$B$3:$AJ$3=B$4)*ISNUMBER(Marks!$B$19:$AJ$19))) | C19: =IF(SUMPRODUCT((Marks!$B$3:$AJ$3=C$4)*ISNUMBER(Marks!$B$19:$AJ$19))=0,"",SUMPRODUCT((Marks!$B$3:$AJ$3=C$4)*(Marks!$B$19:$AJ$19=1))/SUMPRODUCT((Marks!$B$3:$AJ$3=C$4)*ISNUMBER(Marks!$B$19:$AJ$19))) | D19: =IF(SUMPRODUCT((Marks!$B$3:$AJ$3=D$4)*ISNUMBER(Marks!$B$19:$AJ$19))=0,"",SUMPRODUCT((Marks!$B$3:$AJ$3=D$4)*(Marks!$B$19:$AJ$19=1))/SUMPRODUCT((Marks!$B$3:$AJ$3=D$4)*ISNUMBER(Marks!$B$19:$AJ$19))) | E19: =IF(SUMPRODUCT((Marks!$B$3:$AJ$3=E$4)*ISNUMBER(Marks!$B$19:$AJ$19))=0,"",SUMPRODUCT((Marks!$B$3:$AJ$3=E$4)*(Marks!$B$19:$AJ$19=1))/SUMPRODUCT((Marks!$B$3:$AJ$3=E$4)*ISNUMBER(Marks!$B$19:$AJ$19)))
A20: 16 | B20: =IF(SUMPRODUCT((Marks!$B$3:$AJ$3=B$4)*ISNUMBER(Marks!$B$20:$AJ$20))=0,"",SUMPRODUCT((Marks!$B$3:$AJ$3=B$4)*(Marks!$B$20:$AJ$20=1))/SUMPRODUCT((Marks!$B$3:$AJ$3=B$4)*ISNUMBER(Marks!$B$20:$AJ$20))) | C20: =IF(SUMPRODUCT((Marks!$B$3:$AJ$3=C$4)*ISNUMBER(Marks!$B$20:$AJ$20))=0,"",SUMPRODUCT((Marks!$B$3:$AJ$3=C$4)*(Marks!$B$20:$AJ$20=1))/SUMPRODUCT((Marks!$B$3:$AJ$3=C$4)*ISNUMBER(Marks!$B$20:$AJ$20))) | D20: =IF(SUMPRODUCT((Marks!$B$3:$AJ$3=D$4)*ISNUMBER(Marks!$B$20:$AJ$20))=0,"",SUMPRODUCT((Marks!$B$3:$AJ$3=D$4)*(Marks!$B$20:$AJ$20=1))/SUMPRODUCT((Marks!$B$3:$AJ$3=D$4)*ISNUMBER(Marks!$B$20:$AJ$20))) | E20: =IF(SUMPRODUCT((Marks!$B$3:$AJ$3=E$4)*ISNUMBER(Marks!$B$20:$AJ$20))=0,"",SUMPRODUCT((Marks!$B$3:$AJ$3=E$4)*(Marks!$B$20:$AJ$20=1))/SUMPRODUCT((Marks!$B$3:$AJ$3=E$4)*ISNUMBER(Marks!$B$20:$AJ$20)))
A21: 17 | B21: =IF(SUMPRODUCT((Marks!$B$3:$AJ$3=B$4)*ISNUMBER(Marks!$B$21:$AJ$21))=0,"",SUMPRODUCT((Marks!$B$3:$AJ$3=B$4)*(Marks!$B$21:$AJ$21=1))/SUMPRODUCT((Marks!$B$3:$AJ$3=B$4)*ISNUMBER(Marks!$B$21:$AJ$21))) | C21: =IF(SUMPRODUCT((Marks!$B$3:$AJ$3=C$4)*ISNUMBER(Marks!$B$21:$AJ$21))=0,"",SUMPRODUCT((Marks!$B$3:$AJ$3=C$4)*(Marks!$B$21:$AJ$21=1))/SUMPRODUCT((Marks!$B$3:$AJ$3=C$4)*ISNUMBER(Marks!$B$21:$AJ$21))) | D21: =IF(SUMPRODUCT((Marks!$B$3:$AJ$3=D$4)*ISNUMBER(Marks!$B$21:$AJ$21))=0,"",SUMPRODUCT((Marks!$B$3:$AJ$3=D$4)*(Marks!$B$21:$AJ$21=1))/SUMPRODUCT((Marks!$B$3:$AJ$3=D$4)*ISNUMBER(Marks!$B$21:$AJ$21))) | E21: =IF(SUMPRODUCT((Marks!$B$3:$AJ$3=E$4)*ISNUMBER(Marks!$B$21:$AJ$21))=0,"",SUMPRODUCT((Marks!$B$3:$AJ$3=E$4)*(Marks!$B$21:$AJ$21=1))/SUMPRODUCT((Marks!$B$3:$AJ$3=E$4)*ISNUMBER(Marks!$B$21:$AJ$21)))
A22: 18 | B22: =IF(SUMPRODUCT((Marks!$B$3:$AJ$3=B$4)*ISNUMBER(Marks!$B$22:$AJ$22))=0,"",SUMPRODUCT((Marks!$B$3:$AJ$3=B$4)*(Marks!$B$22:$AJ$22=1))/SUMPRODUCT((Marks!$B$3:$AJ$3=B$4)*ISNUMBER(Marks!$B$22:$AJ$22))) | C22: =IF(SUMPRODUCT((Marks!$B$3:$AJ$3=C$4)*ISNUMBER(Marks!$B$22:$AJ$22))=0,"",SUMPRODUCT((Marks!$B$3:$AJ$3=C$4)*(Marks!$B$22:$AJ$22=1))/SUMPRODUCT((Marks!$B$3:$AJ$3=C$4)*ISNUMBER(Marks!$B$22:$AJ$22))) | D22: =IF(SUMPRODUCT((Marks!$B$3:$AJ$3=D$4)*ISNUMBER(Marks!$B$22:$AJ$22))=0,"",SUMPRODUCT((Marks!$B$3:$AJ$3=D$4)*(Marks!$B$22:$AJ$22=1))/SUMPRODUCT((Marks!$B$3:$AJ$3=D$4)*ISNUMBER(Marks!$B$22:$AJ$22))) | E22: =IF(SUMPRODUCT((Marks!$B$3:$AJ$3=E$4)*ISNUMBER(Marks!$B$22:$AJ$22))=0,"",SUMPRODUCT((Marks!$B$3:$AJ$3=E$4)*(Marks!$B$22:$AJ$22=1))/SUMPRODUCT((Marks!$B$3:$AJ$3=E$4)*ISNUMBER(Marks!$B$22:$AJ$22)))
A23: 19 | B23: =IF(SUMPRODUCT((Marks!$B$3:$AJ$3=B$4)*ISNUMBER(Marks!$B$23:$AJ$23))=0,"",SUMPRODUCT((Marks!$B$3:$AJ$3=B$4)*(Marks!$B$23:$AJ$23=1))/SUMPRODUCT((Marks!$B$3:$AJ$3=B$4)*ISNUMBER(Marks!$B$23:$AJ$23))) | C23: =IF(SUMPRODUCT((Marks!$B$3:$AJ$3=C$4)*ISNUMBER(Marks!$B$23:$AJ$23))=0,"",SUMPRODUCT((Marks!$B$3:$AJ$3=C$4)*(Marks!$B$23:$AJ$23=1))/SUMPRODUCT((Marks!$B$3:$AJ$3=C$4)*ISNUMBER(Marks!$B$23:$AJ$23))) | D23: =IF(SUMPRODUCT((Marks!$B$3:$AJ$3=D$4)*ISNUMBER(Marks!$B$23:$AJ$23))=0,"",SUMPRODUCT((Marks!$B$3:$AJ$3=D$4)*(Marks!$B$23:$AJ$23=1))/SUMPRODUCT((Marks!$B$3:$AJ$3=D$4)*ISNUMBER(Marks!$B$23:$AJ$23))) | E23: =IF(SUMPRODUCT((Marks!$B$3:$AJ$3=E$4)*ISNUMBER(Marks!$B$23:$AJ$23))=0,"",SUMPRODUCT((Marks!$B$3:$AJ$3=E$4)*(Marks!$B$23:$AJ$23=1))/SUMPRODUCT((Marks!$B$3:$AJ$3=E$4)*ISNUMBER(Marks!$B$23:$AJ$23)))
A24: 20 | B24: =IF(SUMPRODUCT((Marks!$B$3:$AJ$3=B$4)*ISNUMBER(Marks!$B$24:$AJ$24))=0,"",SUMPRODUCT((Marks!$B$3:$AJ$3=B$4)*(Marks!$B$24:$AJ$24=1))/SUMPRODUCT((Marks!$B$3:$AJ$3=B$4)*ISNUMBER(Marks!$B$24:$AJ$24))) | C24: =IF(SUMPRODUCT((Marks!$B$3:$AJ$3=C$4)*ISNUMBER(Marks!$B$24:$AJ$24))=0,"",SUMPRODUCT((Marks!$B$3:$AJ$3=C$4)*(Marks!$B$24:$AJ$24=1))/SUMPRODUCT((Marks!$B$3:$AJ$3=C$4)*ISNUMBER(Marks!$B$24:$AJ$24))) | D24: =IF(SUMPRODUCT((Marks!$B$3:$AJ$3=D$4)*ISNUMBER(Marks!$B$24:$AJ$24))=0,"",SUMPRODUCT((Marks!$B$3:$AJ$3=D$4)*(Marks!$B$24:$AJ$24=1))/SUMPRODUCT((Marks!$B$3:$AJ$3=D$4)*ISNUMBER(Marks!$B$24:$AJ$24))) | E24: =IF(SUMPRODUCT((Marks!$B$3:$AJ$3=E$4)*ISNUMBER(Marks!$B$24:$AJ$24))=0,"",SUMPRODUCT((Marks!$B$3:$AJ$3=E$4)*(Marks!$B$24:$AJ$24=1))/SUMPRODUCT((Marks!$B$3:$AJ$3=E$4)*ISNUMBER(Marks!$B$24:$AJ$24)))
