Workbook

Sheet Read me
A1: Week 0 diagnostic: the score workbook
A2: TRAINER ONLY. For the Academic TA and the Support TA, who mark the four papers tonight.
A4: Keep the filled copy on the programme's own drive and never in the repository: the repository is public, and a learner's name beside a score is personal data.
A6: 1. On Scores, type each learner's name, yes or no for sitting the paper, and Monday's self-rating letter for each topic.
A7: 2. Mark against answer-key/C2_W00_D02_diagnostic_key_TRAINER.md and type 1 or 0 in each tick column. A blank item is 0.
A8: 3. The ticks per paper, Wednesday's Python track and the line for the baseline card fill in themselves. Grey is the example row, which no count includes.
A9: 4. Room gives Wednesday's two track sizes, the make-up count and the most-missed ticks, which are where the brush-up starts.
A11: Yellow cells are typed in. The one blue cell, Settings B9, is the track rule, and it is the only decision in the workbook.
A12: A learner sees their own ticks only: never the track line, never a level label and never another learner's count.

Sheet Scores
A1: Week 0 diagnostic: ticks per learner
A2: Yellow cells are typed in: sat the paper (yes or no), Monday's self-rating (A to D) and one tick per column, 1 or 0, from the key. Everything to the right recalculates.
G3: Python | T3: SQL | AA3: Statistics | AI3: Stating a problem
A4: Learner | B4: Sat the paper | C4: Said on Monday: Python | D4: Said on Monday: SQL | E4: Said on Monday: Statistics | F4: Said on Monday: Stating a problem | G4: 1 | H4: 2 | I4: 3 | J4: 4 | K4: 5 | L4: 6 | M4: 7 | N4: 8 | O4: 9 | P4: 10 | Q4: 11a | R4: 11b | S4: 11c | T4: 12 | U4: 13 | V4: 14 | W4: 15 | X4: 16 | Y4: 17 | Z4: 18 | AA4: 19 | AB4: 20 | AC4: 21 | AD4: 22 | AE4: 23 | AF4: 24 | AG4: 25 | AH4: 26 | AI4: 27a | AJ4: 27b | AK4: 27c | AL4: 27d | AM4: 27e | AN4: 28a | AO4: 28b | AP4: 28c | AQ4: Python ticks | AR4: SQL ticks | AS4: Statistics ticks | AT4: Stating a problem ticks | AU4: Wednesday's Python track | AV4: For the baseline card
A5: Example, not counted | B5: yes | C5: B | D5: C | E5: B | F5: C | G5: 1 | H5: 1 | I5: 1 | J5: 1 | K5: 1 | L5: 0 | M5: 0 | N5: 0 | O5: 0 | P5: 0 | Q5: 1 | R5: 0 | S5: 0 | T5: 1 | U5: 1 | V5: 0 | W5: 0 | X5: 1 | Y5: 0 | Z5: 0 | AA5: 1 | AB5: 1 | AC5: 1 | AD5: 0 | AE5: 0 | AF5: 1 | AG5: 1 | AH5: 1 | AI5: 1 | AJ5: 1 | AK5: 1 | AL5: 0 | AM5: 0 | AN5: 1 | AO5: 0 | AP5: 0 | AQ5: =IF(COUNT(G5:S5)=0,"",SUM(G5:S5)) | AR5: =IF(COUNT(T5:Z5)=0,"",SUM(T5:Z5)) | AS5: =IF(COUNT(AA5:AH5)=0,"",SUM(AA5:AH5)) | AT5: =IF(COUNT(AI5:AP5)=0,"",SUM(AI5:AP5)) | AU5: =IF($B5="no","no paper yet",IF(AQ5="","",IF(AQ5<Settings!$B$10,"taught","practice"))) | AV5: =IF(COUNT(AQ5:AT5)<4,"","Python "&AQ5&" of "&Settings!$B$4&"; "&"SQL "&AR5&" of "&Settings!$B$5&"; "&"Statistics "&AS5&" of "&Settings!$B$6&"; "&"Stating a problem "&AT5&" of "&Settings!$B$7)
AQ6: =IF(COUNT(G6:S6)=0,"",SUM(G6:S6)) | AR6: =IF(COUNT(T6:Z6)=0,"",SUM(T6:Z6)) | AS6: =IF(COUNT(AA6:AH6)=0,"",SUM(AA6:AH6)) | AT6: =IF(COUNT(AI6:AP6)=0,"",SUM(AI6:AP6)) | AU6: =IF($B6="no","no paper yet",IF(AQ6="","",IF(AQ6<Settings!$B$10,"taught","practice"))) | AV6: =IF(COUNT(AQ6:AT6)<4,"","Python "&AQ6&" of "&Settings!$B$4&"; "&"SQL "&AR6&" of "&Settings!$B$5&"; "&"Statistics "&AS6&" of "&Settings!$B$6&"; "&"Stating a problem "&AT6&" of "&Settings!$B$7)
AQ7: =IF(COUNT(G7:S7)=0,"",SUM(G7:S7)) | AR7: =IF(COUNT(T7:Z7)=0,"",SUM(T7:Z7)) | AS7: =IF(COUNT(AA7:AH7)=0,"",SUM(AA7:AH7)) | AT7: =IF(COUNT(AI7:AP7)=0,"",SUM(AI7:AP7)) | AU7: =IF($B7="no","no paper yet",IF(AQ7="","",IF(AQ7<Settings!$B$10,"taught","practice"))) | AV7: =IF(COUNT(AQ7:AT7)<4,"","Python "&AQ7&" of "&Settings!$B$4&"; "&"SQL "&AR7&" of "&Settings!$B$5&"; "&"Statistics "&AS7&" of "&Settings!$B$6&"; "&"Stating a problem "&AT7&" of "&Settings!$B$7)
AQ8: =IF(COUNT(G8:S8)=0,"",SUM(G8:S8)) | AR8: =IF(COUNT(T8:Z8)=0,"",SUM(T8:Z8)) | AS8: =IF(COUNT(AA8:AH8)=0,"",SUM(AA8:AH8)) | AT8: =IF(COUNT(AI8:AP8)=0,"",SUM(AI8:AP8)) | AU8: =IF($B8="no","no paper yet",IF(AQ8="","",IF(AQ8<Settings!$B$10,"taught","practice"))) | AV8: =IF(COUNT(AQ8:AT8)<4,"","Python "&AQ8&" of "&Settings!$B$4&"; "&"SQL "&AR8&" of "&Settings!$B$5&"; "&"Statistics "&AS8&" of "&Settings!$B$6&"; "&"Stating a problem "&AT8&" of "&Settings!$B$7)
AQ9: =IF(COUNT(G9:S9)=0,"",SUM(G9:S9)) | AR9: =IF(COUNT(T9:Z9)=0,"",SUM(T9:Z9)) | AS9: =IF(COUNT(AA9:AH9)=0,"",SUM(AA9:AH9)) | AT9: =IF(COUNT(AI9:AP9)=0,"",SUM(AI9:AP9)) | AU9: =IF($B9="no","no paper yet",IF(AQ9="","",IF(AQ9<Settings!$B$10,"taught","practice"))) | AV9: =IF(COUNT(AQ9:AT9)<4,"","Python "&AQ9&" of "&Settings!$B$4&"; "&"SQL "&AR9&" of "&Settings!$B$5&"; "&"Statistics "&AS9&" of "&Settings!$B$6&"; "&"Stating a problem "&AT9&" of "&Settings!$B$7)
AQ10: =IF(COUNT(G10:S10)=0,"",SUM(G10:S10)) | AR10: =IF(COUNT(T10:Z10)=0,"",SUM(T10:Z10)) | AS10: =IF(COUNT(AA10:AH10)=0,"",SUM(AA10:AH10)) | AT10: =IF(COUNT(AI10:AP10)=0,"",SUM(AI10:AP10)) | AU10: =IF($B10="no","no paper yet",IF(AQ10="","",IF(AQ10<Settings!$B$10,"taught","practice"))) | AV10: =IF(COUNT(AQ10:AT10)<4,"","Python "&AQ10&" of "&Settings!$B$4&"; "&"SQL "&AR10&" of "&Settings!$B$5&"; "&"Statistics "&AS10&" of "&Settings!$B$6&"; "&"Stating a problem "&AT10&" of "&Settings!$B$7)
AQ11: =IF(COUNT(G11:S11)=0,"",SUM(G11:S11)) | AR11: =IF(COUNT(T11:Z11)=0,"",SUM(T11:Z11)) | AS11: =IF(COUNT(AA11:AH11)=0,"",SUM(AA11:AH11)) | AT11: =IF(COUNT(AI11:AP11)=0,"",SUM(AI11:AP11)) | AU11: =IF($B11="no","no paper yet",IF(AQ11="","",IF(AQ11<Settings!$B$10,"taught","practice"))) | AV11: =IF(COUNT(AQ11:AT11)<4,"","Python "&AQ11&" of "&Settings!$B$4&"; "&"SQL "&AR11&" of "&Settings!$B$5&"; "&"Statistics "&AS11&" of "&Settings!$B$6&"; "&"Stating a problem "&AT11&" of "&Settings!$B$7)
AQ12: =IF(COUNT(G12:S12)=0,"",SUM(G12:S12)) | AR12: =IF(COUNT(T12:Z12)=0,"",SUM(T12:Z12)) | AS12: =IF(COUNT(AA12:AH12)=0,"",SUM(AA12:AH12)) | AT12: =IF(COUNT(AI12:AP12)=0,"",SUM(AI12:AP12)) | AU12: =IF($B12="no","no paper yet",IF(AQ12="","",IF(AQ12<Settings!$B$10,"taught","practice"))) | AV12: =IF(COUNT(AQ12:AT12)<4,"","Python "&AQ12&" of "&Settings!$B$4&"; "&"SQL "&AR12&" of "&Settings!$B$5&"; "&"Statistics "&AS12&" of "&Settings!$B$6&"; "&"Stating a problem "&AT12&" of "&Settings!$B$7)
AQ13: =IF(COUNT(G13:S13)=0,"",SUM(G13:S13)) | AR13: =IF(COUNT(T13:Z13)=0,"",SUM(T13:Z13)) | AS13: =IF(COUNT(AA13:AH13)=0,"",SUM(AA13:AH13)) | AT13: =IF(COUNT(AI13:AP13)=0,"",SUM(AI13:AP13)) | AU13: =IF($B13="no","no paper yet",IF(AQ13="","",IF(AQ13<Settings!$B$10,"taught","practice"))) | AV13: =IF(COUNT(AQ13:AT13)<4,"","Python "&AQ13&" of "&Settings!$B$4&"; "&"SQL "&AR13&" of "&Settings!$B$5&"; "&"Statistics "&AS13&" of "&Settings!$B$6&"; "&"Stating a problem "&AT13&" of "&Settings!$B$7)
AQ14: =IF(COUNT(G14:S14)=0,"",SUM(G14:S14)) | AR14: =IF(COUNT(T14:Z14)=0,"",SUM(T14:Z14)) | AS14: =IF(COUNT(AA14:AH14)=0,"",SUM(AA14:AH14)) | AT14: =IF(COUNT(AI14:AP14)=0,"",SUM(AI14:AP14)) | AU14: =IF($B14="no","no paper yet",IF(AQ14="","",IF(AQ14<Settings!$B$10,"taught","practice"))) | AV14: =IF(COUNT(AQ14:AT14)<4,"","Python "&AQ14&" of "&Settings!$B$4&"; "&"SQL "&AR14&" of "&Settings!$B$5&"; "&"Statistics "&AS14&" of "&Settings!$B$6&"; "&"Stating a problem "&AT14&" of "&Settings!$B$7)
AQ15: =IF(COUNT(G15:S15)=0,"",SUM(G15:S15)) | AR15: =IF(COUNT(T15:Z15)=0,"",SUM(T15:Z15)) | AS15: =IF(COUNT(AA15:AH15)=0,"",SUM(AA15:AH15)) | AT15: =IF(COUNT(AI15:AP15)=0,"",SUM(AI15:AP15)) | AU15: =IF($B15="no","no paper yet",IF(AQ15="","",IF(AQ15<Settings!$B$10,"taught","practice"))) | AV15: =IF(COUNT(AQ15:AT15)<4,"","Python "&AQ15&" of "&Settings!$B$4&"; "&"SQL "&AR15&" of "&Settings!$B$5&"; "&"Statistics "&AS15&" of "&Settings!$B$6&"; "&"Stating a problem "&AT15&" of "&Settings!$B$7)
AQ16: =IF(COUNT(G16:S16)=0,"",SUM(G16:S16)) | AR16: =IF(COUNT(T16:Z16)=0,"",SUM(T16:Z16)) | AS16: =IF(COUNT(AA16:AH16)=0,"",SUM(AA16:AH16)) | AT16: =IF(COUNT(AI16:AP16)=0,"",SUM(AI16:AP16)) | AU16: =IF($B16="no","no paper yet",IF(AQ16="","",IF(AQ16<Settings!$B$10,"taught","practice"))) | AV16: =IF(COUNT(AQ16:AT16)<4,"","Python "&AQ16&" of "&Settings!$B$4&"; "&"SQL "&AR16&" of "&Settings!$B$5&"; "&"Statistics "&AS16&" of "&Settings!$B$6&"; "&"Stating a problem "&AT16&" of "&Settings!$B$7)
AQ17: =IF(COUNT(G17:S17)=0,"",SUM(G17:S17)) | AR17: =IF(COUNT(T17:Z17)=0,"",SUM(T17:Z17)) | AS17: =IF(COUNT(AA17:AH17)=0,"",SUM(AA17:AH17)) | AT17: =IF(COUNT(AI17:AP17)=0,"",SUM(AI17:AP17)) | AU17: =IF($B17="no","no paper yet",IF(AQ17="","",IF(AQ17<Settings!$B$10,"taught","practice"))) | AV17: =IF(COUNT(AQ17:AT17)<4,"","Python "&AQ17&" of "&Settings!$B$4&"; "&"SQL "&AR17&" of "&Settings!$B$5&"; "&"Statistics "&AS17&" of "&Settings!$B$6&"; "&"Stating a problem "&AT17&" of "&Settings!$B$7)
... AQ45: =IF(COUNT(G45:S45)=0,"",SUM(G45:S45)) | AR45: =IF(COUNT(T45:Z45)=0,"",SUM(T45:Z45)) | AS45: =IF(COUNT(AA45:AH45)=0,"",SUM(AA45:AH45)) | AT45: =IF(COUNT(AI45:AP45)=0,"",SUM(AI45:AP45)) | AU45: =IF($B45="no","no paper yet",IF(AQ45="","",IF(AQ45<Settings!$B$10,"taught","practice"))) | AV45: =IF(COUNT(AQ45:AT45)<4,"","Python "&AQ45&" of "&Settings!$B$4&"; "&"SQL "&AR45&" of "&Settings!$B$5&"; "&"Statistics "&AS45&" of "&Settings!$B$6&"; "&"Stating a problem "&AT45&" of "&Settings!$B$7)

Sheet Settings
A1: Settings
A2: Only B9 is an input. The counts come from the grid's own columns.
A3: Ticks on each paper
A4: Python | B4: =COLUMNS(Scores!G4:S4)
A5: SQL | B5: =COLUMNS(Scores!T4:Z4)
A6: Statistics | B6: =COLUMNS(Scores!AA4:AH4)
A7: Stating a problem | B7: =COLUMNS(Scores!AI4:AP4)
A9: Taught track below this share of the Python ticks | B9: 0.5
A10: The line, in Python ticks | B10: =B4*B9
A11: The rule as it reads | B11: ="A learner with "&(ROUNDUP(B10,0)-1)&" or fewer of the "&B4&" Python ticks joins the taught track; everyone else joins the practice track."

Sheet Room
A1: The room, for Wednesday morning
A2: Counts leave out the example row. Share right is among the learners who sat the paper.
A4: Sat the paper | B4: =COUNTIF(Scores!$B$6:$B$45,"yes")
A5: Missed it, so sit the make-up | B5: =COUNTIF(Scores!$B$6:$B$45,"no")
A6: Taught track | B6: =COUNTIFS(Scores!$B$6:$B$45,"yes",Scores!$AU$6:$AU$45,"taught")
A7: Practice track | B7: =COUNTIFS(Scores!$B$6:$B$45,"yes",Scores!$AU$6:$AU$45,"practice")
A9: Paper | B9: Share of its ticks earned
A10: Python | B10: =IF($B$4=0,"",SUMIFS(Scores!AQ$6:AQ$45,Scores!$B$6:$B$45,"yes")/($B$4*Settings!$B$4))
A11: SQL | B11: =IF($B$4=0,"",SUMIFS(Scores!AR$6:AR$45,Scores!$B$6:$B$45,"yes")/($B$4*Settings!$B$5))
A12: Statistics | B12: =IF($B$4=0,"",SUMIFS(Scores!AS$6:AS$45,Scores!$B$6:$B$45,"yes")/($B$4*Settings!$B$6))
A13: Stating a problem | B13: =IF($B$4=0,"",SUMIFS(Scores!AT$6:AT$45,Scores!$B$6:$B$45,"yes")/($B$4*Settings!$B$7))
A15: Tick | B15: Paper | C15: Earned | D15: Share right | E15: Most missed first
A16: 1 | B16: Python | C16: =COUNTIFS(Scores!$B$6:$B$45,"yes",Scores!G$6:G$45,1) | D16: =IF($B$4=0,"",C16/$B$4) | E16: =IF(D16="","",RANK(D16,$D$16:$D$51,1))
A17: 2 | B17: Python | C17: =COUNTIFS(Scores!$B$6:$B$45,"yes",Scores!H$6:H$45,1) | D17: =IF($B$4=0,"",C17/$B$4) | E17: =IF(D17="","",RANK(D17,$D$16:$D$51,1))
A18: 3 | B18: Python | C18: =COUNTIFS(Scores!$B$6:$B$45,"yes",Scores!I$6:I$45,1) | D18: =IF($B$4=0,"",C18/$B$4) | E18: =IF(D18="","",RANK(D18,$D$16:$D$51,1))
A19: 4 | B19: Python | C19: =COUNTIFS(Scores!$B$6:$B$45,"yes",Scores!J$6:J$45,1) | D19: =IF($B$4=0,"",C19/$B$4) | E19: =IF(D19="","",RANK(D19,$D$16:$D$51,1))
A20: 5 | B20: Python | C20: =COUNTIFS(Scores!$B$6:$B$45,"yes",Scores!K$6:K$45,1) | D20: =IF($B$4=0,"",C20/$B$4) | E20: =IF(D20="","",RANK(D20,$D$16:$D$51,1))
A21: 6 | B21: Python | C21: =COUNTIFS(Scores!$B$6:$B$45,"yes",Scores!L$6:L$45,1) | D21: =IF($B$4=0,"",C21/$B$4) | E21: =IF(D21="","",RANK(D21,$D$16:$D$51,1))
A22: 7 | B22: Python | C22: =COUNTIFS(Scores!$B$6:$B$45,"yes",Scores!M$6:M$45,1) | D22: =IF($B$4=0,"",C22/$B$4) | E22: =IF(D22="","",RANK(D22,$D$16:$D$51,1))
A23: 8 | B23: Python | C23: =COUNTIFS(Scores!$B$6:$B$45,"yes",Scores!N$6:N$45,1) | D23: =IF($B$4=0,"",C23/$B$4) | E23: =IF(D23="","",RANK(D23,$D$16:$D$51,1))
A24: 9 | B24: Python | C24: =COUNTIFS(Scores!$B$6:$B$45,"yes",Scores!O$6:O$45,1) | D24: =IF($B$4=0,"",C24/$B$4) | E24: =IF(D24="","",RANK(D24,$D$16:$D$51,1))
A25: 10 | B25: Python | C25: =COUNTIFS(Scores!$B$6:$B$45,"yes",Scores!P$6:P$45,1) | D25: =IF($B$4=0,"",C25/$B$4) | E25: =IF(D25="","",RANK(D25,$D$16:$D$51,1))
A26: 11a | B26: Python | C26: =COUNTIFS(Scores!$B$6:$B$45,"yes",Scores!Q$6:Q$45,1) | D26: =IF($B$4=0,"",C26/$B$4) | E26: =IF(D26="","",RANK(D26,$D$16:$D$51,1))
A27: 11b | B27: Python | C27: =COUNTIFS(Scores!$B$6:$B$45,"yes",Scores!R$6:R$45,1) | D27: =IF($B$4=0,"",C27/$B$4) | E27: =IF(D27="","",RANK(D27,$D$16:$D$51,1))
A28: 11c | B28: Python | C28: =COUNTIFS(Scores!$B$6:$B$45,"yes",Scores!S$6:S$45,1) | D28: =IF($B$4=0,"",C28/$B$4) | E28: =IF(D28="","",RANK(D28,$D$16:$D$51,1))
A29: 12 | B29: SQL | C29: =COUNTIFS(Scores!$B$6:$B$45,"yes",Scores!T$6:T$45,1) | D29: =IF($B$4=0,"",C29/$B$4) | E29: =IF(D29="","",RANK(D29,$D$16:$D$51,1))
A30: 13 | B30: SQL | C30: =COUNTIFS(Scores!$B$6:$B$45,"yes",Scores!U$6:U$45,1) | D30: =IF($B$4=0,"",C30/$B$4) | E30: =IF(D30="","",RANK(D30,$D$16:$D$51,1))
A31: 14 | B31: SQL | C31: =COUNTIFS(Scores!$B$6:$B$45,"yes",Scores!V$6:V$45,1) | D31: =IF($B$4=0,"",C31/$B$4) | E31: =IF(D31="","",RANK(D31,$D$16:$D$51,1))
A32: 15 | B32: SQL | C32: =COUNTIFS(Scores!$B$6:$B$45,"yes",Scores!W$6:W$45,1) | D32: =IF($B$4=0,"",C32/$B$4) | E32: =IF(D32="","",RANK(D32,$D$16:$D$51,1))
A33: 16 | B33: SQL | C33: =COUNTIFS(Scores!$B$6:$B$45,"yes",Scores!X$6:X$45,1) | D33: =IF($B$4=0,"",C33/$B$4) | E33: =IF(D33="","",RANK(D33,$D$16:$D$51,1))
A34: 17 | B34: SQL | C34: =COUNTIFS(Scores!$B$6:$B$45,"yes",Scores!Y$6:Y$45,1) | D34: =IF($B$4=0,"",C34/$B$4) | E34: =IF(D34="","",RANK(D34,$D$16:$D$51,1))
A35: 18 | B35: SQL | C35: =COUNTIFS(Scores!$B$6:$B$45,"yes",Scores!Z$6:Z$45,1) | D35: =IF($B$4=0,"",C35/$B$4) | E35: =IF(D35="","",RANK(D35,$D$16:$D$51,1))
A36: 19 | B36: Statistics | C36: =COUNTIFS(Scores!$B$6:$B$45,"yes",Scores!AA$6:AA$45,1) | D36: =IF($B$4=0,"",C36/$B$4) | E36: =IF(D36="","",RANK(D36,$D$16:$D$51,1))
A37: 20 | B37: Statistics | C37: =COUNTIFS(Scores!$B$6:$B$45,"yes",Scores!AB$6:AB$45,1) | D37: =IF($B$4=0,"",C37/$B$4) | E37: =IF(D37="","",RANK(D37,$D$16:$D$51,1))
A38: 21 | B38: Statistics | C38: =COUNTIFS(Scores!$B$6:$B$45,"yes",Scores!AC$6:AC$45,1) | D38: =IF($B$4=0,"",C38/$B$4) | E38: =IF(D38="","",RANK(D38,$D$16:$D$51,1))
A39: 22 | B39: Statistics | C39: =COUNTIFS(Scores!$B$6:$B$45,"yes",Scores!AD$6:AD$45,1) | D39: =IF($B$4=0,"",C39/$B$4) | E39: =IF(D39="","",RANK(D39,$D$16:$D$51,1))
A40: 23 | B40: Statistics | C40: =COUNTIFS(Scores!$B$6:$B$45,"yes",Scores!AE$6:AE$45,1) | D40: =IF($B$4=0,"",C40/$B$4) | E40: =IF(D40="","",RANK(D40,$D$16:$D$51,1))
A41: 24 | B41: Statistics | C41: =COUNTIFS(Scores!$B$6:$B$45,"yes",Scores!AF$6:AF$45,1) | D41: =IF($B$4=0,"",C41/$B$4) | E41: =IF(D41="","",RANK(D41,$D$16:$D$51,1))
A42: 25 | B42: Statistics | C42: =COUNTIFS(Scores!$B$6:$B$45,"yes",Scores!AG$6:AG$45,1) | D42: =IF($B$4=0,"",C42/$B$4) | E42: =IF(D42="","",RANK(D42,$D$16:$D$51,1))
A43: 26 | B43: Statistics | C43: =COUNTIFS(Scores!$B$6:$B$45,"yes",Scores!AH$6:AH$45,1) | D43: =IF($B$4=0,"",C43/$B$4) | E43: =IF(D43="","",RANK(D43,$D$16:$D$51,1))
...
