Workbook

Sheet Start
A1: Monday's growth review: the deck pack
A3: Kalpa Retail, Week 2, Friday. Three things Meera's chief of staff opens on a laptop without a login.
A4: Tree: the revenue tree by segment for Q1 and Q2. Protect: the top-fifty protect list and a lookup by member id. FrontPage: one number with its period, its comparison, its denominator and its monthly trend.
A5: Checks: whether all three may go into the deck. It holds anything that does not reconcile to the warehouse.
A6: Yellow cells are the assumptions a director may change in the room. Every other cell is a live formula over the Raw and Customers tabs, which hold the two exports exactly as they arrived.
A7: The Tree tab is a pivot written as SUMIFS, so it recalculates the moment a yellow cell changes. A PivotTable needs a refresh after its source changes.
A8: The XLOOKUP cell on the Protect tab is computed in Excel and not proved here: LibreOffice 24.2 returns #NAME? for it, so every other lookup uses INDEX and MATCH.
A9: The warehouse owns these numbers. Change an assumption here; never type over a computed cell.

Sheet Checks
A1: What may go into Monday's deck
A2: Each deliverable goes in only when its numbers reconcile to the warehouse. A held item says why.
A4: Check | B4: Passes | C4: What it found
A5: The tree reconciles to the warehouse | B5: =IF(ABS(Tree!C15)<1,1,0) | C5: =Tree!C18
A6: The customer table reconciles to the warehouse | B6: =IF(ABS(SUM(Customers!$E$2:$E$301)-Tree!C5)<1,1,0) | C6: =IF(B6=1,"The customer table sums to the warehouse total.","The customer table is "&IF(ABS((Tree!C5-SUM(Customers!$E$2:$E$301)))>=10000000,"Rs "&TEXT((Tree!C5-SUM(Customers!$E$2:$E$301))/10000000,"0.00")&" crore",IF(ABS((Tree!C5-SUM(Customers!$E$2:$E$301)))>=100000,"Rs "&TEXT((Tree!C5-SUM(Customers!$E$2:$E$301))/100000,"0.00")&" lakh","Rs "&IF(ROUND((Tree!C5-SUM(Customers!$E$2:$E$301)),0)>=100000,INT(ROUND((Tree!C5-SUM(Customers!$E$2:$E$301)),0)/100000)&","&TEXT(INT(MOD(ROUND((Tree!C5-SUM(Customers!$E$2:$E$301)),0),100000)/1000),"00")&","&TEXT(MOD(ROUND((Tree!C5-SUM(Customers!$E$2:$E$301)),0),1000),"000"),IF(ROUND((Tree!C5-SUM(Customers!$E$2:$E$301)),0)>=1000,INT(ROUND((Tree!C5-SUM(Customers!$E$2:$E$301)),0)/1000)&","&TEXT(MOD(ROUND((Tree!C5-SUM(Customers!$E$2:$E$301)),0),1000),"000"),ROUND((Tree!C5-SUM(Customers!$E$2:$E$301)),0)&""))))&" and "&(Tree!C17-SUM(Customers!$D$2:$D$301))&" orders short of the warehouse, so the protect list may be missing a member.")
A7: The lookup answers with the member asked for | B7: =IF(OR(Protect!F4="not found",Protect!F4=Protect!C6),1,0) | C7: =Protect!F7
A8: The front page reconciles to the warehouse | B8: =IF(ABS(FrontPage!H11+FrontPage!I11-Tree!C5)<1,1,0) | C8: =FrontPage!B18
A10: Release | C10: =IF(SUM(B5:B8)=4,"Ready for Monday's deck: the tree, the protect list and the front page.",IF(B5=0,"Do not send anything: the tree counts an order more than once, and the card inherits it.",IF(B6=0,"Send the tree and the front page. Hold the protect list until the customer table reconciles to the warehouse.","Hold what fails above and send the rest.")))

Sheet Raw
A1: order_id | B1: customer_id | C1: segment | D1: channel | E1: order_date | F1: order_amount | G1: paid_amount | H1: paid_date | I1: quarter | J1: month | K1: first row of this order | L1: first order of this customer in the quarter | M1: amount counted | N1: orders counted | O1: customers counted
A2: KR-00001 | B2: C-0316 | C2: Student | D2: web | E2: 46132 | F2: 520 | G2: 520 | H2: 2026-04-22 | I2: =IF(MONTH(E2)<=6,"Q1","Q2") | J2: =YEAR(E2)*100+MONTH(E2) | K2: =IF(COUNTIF($A$2:A2,A2)=1,1,0) | L2: =IF(K2=1,IF(COUNTIFS($B$2:B2,B2,$I$2:I2,I2,$K$2:K2,1)=1,1,0),0) | M2: =IF(Tree!$C$4="once per order",F2*K2,F2) | N2: =IF(Tree!$C$4="once per order",K2,1) | O2: =IF(Tree!$C$4="once per order",L2,1)
A3: KR-00001 | B3: C-0316 | C3: Student | D3: web | E3: 46132 | F3: 520 | G3: 520 | H3: 2026-04-22 | I3: =IF(MONTH(E3)<=6,"Q1","Q2") | J3: =YEAR(E3)*100+MONTH(E3) | K3: =IF(COUNTIF($A$2:A3,A3)=1,1,0) | L3: =IF(K3=1,IF(COUNTIFS($B$2:B3,B3,$I$2:I3,I3,$K$2:K3,1)=1,1,0),0) | M3: =IF(Tree!$C$4="once per order",F3*K3,F3) | N3: =IF(Tree!$C$4="once per order",K3,1) | O3: =IF(Tree!$C$4="once per order",L3,1)
A4: KR-00002 | B4: C-0323 | C4: Student | D4: app | E4: 46161 | F4: 800 | G4: 800 | H4: 2026-05-21 | I4: =IF(MONTH(E4)<=6,"Q1","Q2") | J4: =YEAR(E4)*100+MONTH(E4) | K4: =IF(COUNTIF($A$2:A4,A4)=1,1,0) | L4: =IF(K4=1,IF(COUNTIFS($B$2:B4,B4,$I$2:I4,I4,$K$2:K4,1)=1,1,0),0) | M4: =IF(Tree!$C$4="once per order",F4*K4,F4) | N4: =IF(Tree!$C$4="once per order",K4,1) | O4: =IF(Tree!$C$4="once per order",L4,1)
A5: KR-00002 | B5: C-0323 | C5: Student | D5: app | E5: 46161 | F5: 800 | G5: 800 | H5: 2026-05-21 | I5: =IF(MONTH(E5)<=6,"Q1","Q2") | J5: =YEAR(E5)*100+MONTH(E5) | K5: =IF(COUNTIF($A$2:A5,A5)=1,1,0) | L5: =IF(K5=1,IF(COUNTIFS($B$2:B5,B5,$I$2:I5,I5,$K$2:K5,1)=1,1,0),0) | M5: =IF(Tree!$C$4="once per order",F5*K5,F5) | N5: =IF(Tree!$C$4="once per order",K5,1) | O5: =IF(Tree!$C$4="once per order",L5,1)
A6: KR-00003 | B6: C-0322 | C6: Student | D6: store | E6: 46181 | F6: 800 | G6: 800 | H6: 2026-06-10 | I6: =IF(MONTH(E6)<=6,"Q1","Q2") | J6: =YEAR(E6)*100+MONTH(E6) | K6: =IF(COUNTIF($A$2:A6,A6)=1,1,0) | L6: =IF(K6=1,IF(COUNTIFS($B$2:B6,B6,$I$2:I6,I6,$K$2:K6,1)=1,1,0),0) | M6: =IF(Tree!$C$4="once per order",F6*K6,F6) | N6: =IF(Tree!$C$4="once per order",K6,1) | O6: =IF(Tree!$C$4="once per order",L6,1)
A7: KR-00003 | B7: C-0322 | C7: Student | D7: store | E7: 46181 | F7: 800 | G7: 800 | H7: 2026-06-10 | I7: =IF(MONTH(E7)<=6,"Q1","Q2") | J7: =YEAR(E7)*100+MONTH(E7) | K7: =IF(COUNTIF($A$2:A7,A7)=1,1,0) | L7: =IF(K7=1,IF(COUNTIFS($B$2:B7,B7,$I$2:I7,I7,$K$2:K7,1)=1,1,0),0) | M7: =IF(Tree!$C$4="once per order",F7*K7,F7) | N7: =IF(Tree!$C$4="once per order",K7,1) | O7: =IF(Tree!$C$4="once per order",L7,1)
A8: KR-00004 | B8: C-0325 | C8: Student | D8: app | E8: 46136 | F8: 1310 | G8: 1310 | H8: 2026-04-26 | I8: =IF(MONTH(E8)<=6,"Q1","Q2") | J8: =YEAR(E8)*100+MONTH(E8) | K8: =IF(COUNTIF($A$2:A8,A8)=1,1,0) | L8: =IF(K8=1,IF(COUNTIFS($B$2:B8,B8,$I$2:I8,I8,$K$2:K8,1)=1,1,0),0) | M8: =IF(Tree!$C$4="once per order",F8*K8,F8) | N8: =IF(Tree!$C$4="once per order",K8,1) | O8: =IF(Tree!$C$4="once per order",L8,1)
A9: KR-00005 | B9: C-0333 | C9: Student | D9: app | E9: 46169 | F9: 1380 | G9: 1380 | H9: 2026-05-28 | I9: =IF(MONTH(E9)<=6,"Q1","Q2") | J9: =YEAR(E9)*100+MONTH(E9) | K9: =IF(COUNTIF($A$2:A9,A9)=1,1,0) | L9: =IF(K9=1,IF(COUNTIFS($B$2:B9,B9,$I$2:I9,I9,$K$2:K9,1)=1,1,0),0) | M9: =IF(Tree!$C$4="once per order",F9*K9,F9) | N9: =IF(Tree!$C$4="once per order",K9,1) | O9: =IF(Tree!$C$4="once per order",L9,1)
A10: KR-00006 | B10: C-0323 | C10: Student | D10: app | E10: 46198 | F10: 970 | G10: 970 | H10: 2026-06-27 | I10: =IF(MONTH(E10)<=6,"Q1","Q2") | J10: =YEAR(E10)*100+MONTH(E10) | K10: =IF(COUNTIF($A$2:A10,A10)=1,1,0) | L10: =IF(K10=1,IF(COUNTIFS($B$2:B10,B10,$I$2:I10,I10,$K$2:K10,1)=1,1,0),0) | M10: =IF(Tree!$C$4="once per order",F10*K10,F10) | N10: =IF(Tree!$C$4="once per order",K10,1) | O10: =IF(Tree!$C$4="once per order",L10,1)
A11: KR-00007 | B11: C-0315 | C11: Student | D11: store | E11: 46115 | F11: 1310 | G11: 1310 | H11: 2026-04-05 | I11: =IF(MONTH(E11)<=6,"Q1","Q2") | J11: =YEAR(E11)*100+MONTH(E11) | K11: =IF(COUNTIF($A$2:A11,A11)=1,1,0) | L11: =IF(K11=1,IF(COUNTIFS($B$2:B11,B11,$I$2:I11,I11,$K$2:K11,1)=1,1,0),0) | M11: =IF(Tree!$C$4="once per order",F11*K11,F11) | N11: =IF(Tree!$C$4="once per order",K11,1) | O11: =IF(Tree!$C$4="once per order",L11,1)
A12: KR-00008 | B12: C-0331 | C12: Student | D12: app | E12: 46160 | F12: 1070 | G12: 1070 | H12: 2026-05-20 | I12: =IF(MONTH(E12)<=6,"Q1","Q2") | J12: =YEAR(E12)*100+MONTH(E12) | K12: =IF(COUNTIF($A$2:A12,A12)=1,1,0) | L12: =IF(K12=1,IF(COUNTIFS($B$2:B12,B12,$I$2:I12,I12,$K$2:K12,1)=1,1,0),0) | M12: =IF(Tree!$C$4="once per order",F12*K12,F12) | N12: =IF(Tree!$C$4="once per order",K12,1) | O12: =IF(Tree!$C$4="once per order",L12,1)
A13: KR-00009 | B13: C-0335 | C13: Student | D13: app | E13: 46193 | F13: 900 | G13: 900 | H13: 2026-06-22 | I13: =IF(MONTH(E13)<=6,"Q1","Q2") | J13: =YEAR(E13)*100+MONTH(E13) | K13: =IF(COUNTIF($A$2:A13,A13)=1,1,0) | L13: =IF(K13=1,IF(COUNTIFS($B$2:B13,B13,$I$2:I13,I13,$K$2:K13,1)=1,1,0),0) | M13: =IF(Tree!$C$4="once per order",F13*K13,F13) | N13: =IF(Tree!$C$4="once per order",K13,1) | O13: =IF(Tree!$C$4="once per order",L13,1)
... A829: KR-00576 | B829: C-0337 | C829: Student | D829: store | E829: 46238 | F829: 1390 | G829: 1390 | H829: 2026-08-06 | I829: =IF(MONTH(E829)<=6,"Q1","Q2") | J829: =YEAR(E829)*100+MONTH(E829) | K829: =IF(COUNTIF($A$2:A829,A829)=1,1,0) | L829: =IF(K829=1,IF(COUNTIFS($B$2:B829,B829,$I$2:I829,I829,$K$2:K829,1)=1,1,0),0) | M829: =IF(Tree!$C$4="once per order",F829*K829,F829) | N829: =IF(Tree!$C$4="once per order",K829,1) | O829: =IF(Tree!$C$4="once per order",L829,1)
A830: KR-00577 | B830: C-0278 | C830: Business | D830: store | E830: 46224 | F830: 927000 | G830: 0 | I830: =IF(MONTH(E830)<=6,"Q1","Q2") | J830: =YEAR(E830)*100+MONTH(E830) | K830: =IF(COUNTIF($A$2:A830,A830)=1,1,0) | L830: =IF(K830=1,IF(COUNTIFS($B$2:B830,B830,$I$2:I830,I830,$K$2:K830,1)=1,1,0),0) | M830: =IF(Tree!$C$4="once per order",F830*K830,F830) | N830: =IF(Tree!$C$4="once per order",K830,1) | O830: =IF(Tree!$C$4="once per order",L830,1)
A831: KR-00578 | B831: C-0273 | C831: Business | D831: app | E831: 46254 | F831: 950000 | G831: 570000 | H831: 2026-08-22 | I831: =IF(MONTH(E831)<=6,"Q1","Q2") | J831: =YEAR(E831)*100+MONTH(E831) | K831: =IF(COUNTIF($A$2:A831,A831)=1,1,0) | L831: =IF(K831=1,IF(COUNTIFS($B$2:B831,B831,$I$2:I831,I831,$K$2:K831,1)=1,1,0),0) | M831: =IF(Tree!$C$4="once per order",F831*K831,F831) | N831: =IF(Tree!$C$4="once per order",K831,1) | O831: =IF(Tree!$C$4="once per order",L831,1)
A832: KR-00578 | B832: C-0273 | C832: Business | D832: app | E832: 46254 | F832: 950000 | G832: 380000 | H832: 2026-08-22 | I832: =IF(MONTH(E832)<=6,"Q1","Q2") | J832: =YEAR(E832)*100+MONTH(E832) | K832: =IF(COUNTIF($A$2:A832,A832)=1,1,0) | L832: =IF(K832=1,IF(COUNTIFS($B$2:B832,B832,$I$2:I832,I832,$K$2:K832,1)=1,1,0),0) | M832: =IF(Tree!$C$4="once per order",F832*K832,F832) | N832: =IF(Tree!$C$4="once per order",K832,1) | O832: =IF(Tree!$C$4="once per order",L832,1)
A833: KR-00579 | B833: C-0310 | C833: Business | D833: app | E833: 46278 | F833: 750000 | G833: 450000 | H833: 2026-09-15 | I833: =IF(MONTH(E833)<=6,"Q1","Q2") | J833: =YEAR(E833)*100+MONTH(E833) | K833: =IF(COUNTIF($A$2:A833,A833)=1,1,0) | L833: =IF(K833=1,IF(COUNTIFS($B$2:B833,B833,$I$2:I833,I833,$K$2:K833,1)=1,1,0),0) | M833: =IF(Tree!$C$4="once per order",F833*K833,F833) | N833: =IF(Tree!$C$4="once per order",K833,1) | O833: =IF(Tree!$C$4="once per order",L833,1)
A834: KR-00579 | B834: C-0310 | C834: Business | D834: app | E834: 46278 | F834: 750000 | G834: 300000 | H834: 2026-09-15 | I834: =IF(MONTH(E834)<=6,"Q1","Q2") | J834: =YEAR(E834)*100+MONTH(E834) | K834: =IF(COUNTIF($A$2:A834,A834)=1,1,0) | L834: =IF(K834=1,IF(COUNTIFS($B$2:B834,B834,$I$2:I834,I834,$K$2:K834,1)=1,1,0),0) | M834: =IF(Tree!$C$4="once per order",F834*K834,F834) | N834: =IF(Tree!$C$4="once per order",K834,1) | O834: =IF(Tree!$C$4="once per order",L834,1)
A835: KR-00580 | B835: C-0274 | C835: Business | D835: store | E835: 46225 | F835: 855000 | G835: 513000 | H835: 2026-07-24 | I835: =IF(MONTH(E835)<=6,"Q1","Q2") | J835: =YEAR(E835)*100+MONTH(E835) | K835: =IF(COUNTIF($A$2:A835,A835)=1,1,0) | L835: =IF(K835=1,IF(COUNTIFS($B$2:B835,B835,$I$2:I835,I835,$K$2:K835,1)=1,1,0),0) | M835: =IF(Tree!$C$4="once per order",F835*K835,F835) | N835: =IF(Tree!$C$4="once per order",K835,1) | O835: =IF(Tree!$C$4="once per order",L835,1)
A836: KR-00580 | B836: C-0274 | C836: Business | D836: store | E836: 46225 | F836: 855000 | G836: 342000 | H836: 2026-07-24 | I836: =IF(MONTH(E836)<=6,"Q1","Q2") | J836: =YEAR(E836)*100+MONTH(E836) | K836: =IF(COUNTIF($A$2:A836,A836)=1,1,0) | L836: =IF(K836=1,IF(COUNTIFS($B$2:B836,B836,$I$2:I836,I836,$K$2:K836,1)=1,1,0),0) | M836: =IF(Tree!$C$4="once per order",F836*K836,F836) | N836: =IF(Tree!$C$4="once per order",K836,1) | O836: =IF(Tree!$C$4="once per order",L836,1)
A837: KR-00581 | B837: C-0276 | C837: Business | D837: store | E837: 46254 | F837: 1170000 | G837: 702000 | H837: 2026-08-22 | I837: =IF(MONTH(E837)<=6,"Q1","Q2") | J837: =YEAR(E837)*100+MONTH(E837) | K837: =IF(COUNTIF($A$2:A837,A837)=1,1,0) | L837: =IF(K837=1,IF(COUNTIFS($B$2:B837,B837,$I$2:I837,I837,$K$2:K837,1)=1,1,0),0) | M837: =IF(Tree!$C$4="once per order",F837*K837,F837) | N837: =IF(Tree!$C$4="once per order",K837,1) | O837: =IF(Tree!$C$4="once per order",L837,1)
A838: KR-00581 | B838: C-0276 | C838: Business | D838: store | E838: 46254 | F838: 1170000 | G838: 468000 | H838: 2026-08-22 | I838: =IF(MONTH(E838)<=6,"Q1","Q2") | J838: =YEAR(E838)*100+MONTH(E838) | K838: =IF(COUNTIF($A$2:A838,A838)=1,1,0) | L838: =IF(K838=1,IF(COUNTIFS($B$2:B838,B838,$I$2:I838,I838,$K$2:K838,1)=1,1,0),0) | M838: =IF(Tree!$C$4="once per order",F838*K838,F838) | N838: =IF(Tree!$C$4="once per order",K838,1) | O838: =IF(Tree!$C$4="once per order",L838,1)
A839: KR-00582 | B839: C-0289 | C839: Business | D839: web | E839: 46286 | F839: 770000 | G839: 0 | I839: =IF(MONTH(E839)<=6,"Q1","Q2") | J839: =YEAR(E839)*100+MONTH(E839) | K839: =IF(COUNTIF($A$2:A839,A839)=1,1,0) | L839: =IF(K839=1,IF(COUNTIFS($B$2:B839,B839,$I$2:I839,I839,$K$2:K839,1)=1,1,0),0) | M839: =IF(Tree!$C$4="once per order",F839*K839,F839) | N839: =IF(Tree!$C$4="once per order",K839,1) | O839: =IF(Tree!$C$4="once per order",L839,1)
A840: KR-00583 | B840: C-0280 | C840: Business | D840: store | E840: 46219 | F840: 376000 | G840: 225600 | H840: 2026-07-18 | I840: =IF(MONTH(E840)<=6,"Q1","Q2") | J840: =YEAR(E840)*100+MONTH(E840) | K840: =IF(COUNTIF($A$2:A840,A840)=1,1,0) | L840: =IF(K840=1,IF(COUNTIFS($B$2:B840,B840,$I$2:I840,I840,$K$2:K840,1)=1,1,0),0) | M840: =IF(Tree!$C$4="once per order",F840*K840,F840) | N840: =IF(Tree!$C$4="once per order",K840,1) | O840: =IF(Tree!$C$4="once per order",L840,1)
A841: KR-00583 | B841: C-0280 | C841: Business | D841: store | E841: 46219 | F841: 376000 | G841: 150400 | H841: 2026-07-18 | I841: =IF(MONTH(E841)<=6,"Q1","Q2") | J841: =YEAR(E841)*100+MONTH(E841) | K841: =IF(COUNTIF($A$2:A841,A841)=1,1,0) | L841: =IF(K841=1,IF(COUNTIFS($B$2:B841,B841,$I$2:I841,I841,$K$2:K841,1)=1,1,0),0) | M841: =IF(Tree!$C$4="once per order",F841*K841,F841) | N841: =IF(Tree!$C$4="once per order",K841,1) | O841: =IF(Tree!$C$4="once per order",L841,1)
A842: KR-00584 | B842: C-0310 | C842: Business | D842: app | E842: 46262 | F842: 792000 | G842: 475200 | H842: 2026-08-28 | I842: =IF(MONTH(E842)<=6,"Q1","Q2") | J842: =YEAR(E842)*100+MONTH(E842) | K842: =IF(COUNTIF($A$2:A842,A842)=1,1,0) | L842: =IF(K842=1,IF(COUNTIFS($B$2:B842,B842,$I$2:I842,I842,$K$2:K842,1)=1,1,0),0) | M842: =IF(Tree!$C$4="once per order",F842*K842,F842) | N842: =IF(Tree!$C$4="once per order",K842,1) | O842: =IF(Tree!$C$4="once per order",L842,1)
A843: KR-00584 | B843: C-0310 | C843: Business | D843: app | E843: 46262 | F843: 792000 | G843: 316800 | H843: 2026-08-28 | I843: =IF(MONTH(E843)<=6,"Q1","Q2") | J843: =YEAR(E843)*100+MONTH(E843) | K843: =IF(COUNTIF($A$2:A843,A843)=1,1,0) | L843: =IF(K843=1,IF(COUNTIFS($B$2:B843,B843,$I$2:I843,I843,$K$2:K843,1)=1,1,0),0) | M843: =IF(Tree!$C$4="once per order",F843*K843,F843) | N843: =IF(Tree!$C$4="once per order",K843,1) | O843: =IF(Tree!$C$4="once per order",L843,1)
A844: KR-00585 | B844: C-0289 | C844: Business | D844: app | E844: 46280 | F844: 1228000 | G844: 736800 | H844: 2026-09-17 | I844: =IF(MONTH(E844)<=6,"Q1","Q2") | J844: =YEAR(E844)*100+MONTH(E844) | K844: =IF(COUNTIF($A$2:A844,A844)=1,1,0) | L844: =IF(K844=1,IF(COUNTIFS($B$2:B844,B844,$I$2:I844,I844,$K$2:K844,1)=1,1,0),0) | M844: =IF(Tree!$C$4="once per order",F844*K844,F844) | N844: =IF(Tree!$C$4="once per order",K844,1) | O844: =IF(Tree!$C$4="once per order",L844,1)
A845: KR-00585 | B845: C-0289 | C845: Business | D845: app | E845: 46280 | F845: 1228000 | G845: 491200 | H845: 2026-09-17 | I845: =IF(MONTH(E845)<=6,"Q1","Q2") | J845: =YEAR(E845)*100+MONTH(E845) | K845: =IF(COUNTIF($A$2:A845,A845)=1,1,0) | L845: =IF(K845=1,IF(COUNTIFS($B$2:B845,B845,$I$2:I845,I845,$K$2:K845,1)=1,1,0),0) | M845: =IF(Tree!$C$4="once per order",F845*K845,F845) | N845: =IF(Tree!$C$4="once per order",K845,1) | O845: =IF(Tree!$C$4="once per order",L845,1)
A846: KR-00586 | B846: C-0293 | C846: Business | D846: app | E846: 46228 | F846: 604000 | G846: 362400 | H846: 2026-07-27 | I846: =IF(MONTH(E846)<=6,"Q1","Q2") | J846: =YEAR(E846)*100+MONTH(E846) | K846: =IF(COUNTIF($A$2:A846,A846)=1,1,0) | L846: =IF(K846=1,IF(COUNTIFS($B$2:B846,B846,$I$2:I846,I846,$K$2:K846,1)=1,1,0),0) | M846: =IF(Tree!$C$4="once per order",F846*K846,F846) | N846: =IF(Tree!$C$4="once per order",K846,1) | O846: =IF(Tree!$C$4="once per order",L846,1)
A847: KR-00586 | B847: C-0293 | C847: Business | D847: app | E847: 46228 | F847: 604000 | G847: 241600 | H847: 2026-07-27 | I847: =IF(MONTH(E847)<=6,"Q1","Q2") | J847: =YEAR(E847)*100+MONTH(E847) | K847: =IF(COUNTIF($A$2:A847,A847)=1,1,0) | L847: =IF(K847=1,IF(COUNTIFS($B$2:B847,B847,$I$2:I847,I847,$K$2:K847,1)=1,1,0),0) | M847: =IF(Tree!$C$4="once per order",F847*K847,F847) | N847: =IF(Tree!$C$4="once per order",K847,1) | O847: =IF(Tree!$C$4="once per order",L847,1)
A848: KR-00587 | B848: C-0271 | C848: Business | D848: store | E848: 46259 | F848: 1310000 | G848: 786000 | H848: 2026-08-27 | I848: =IF(MONTH(E848)<=6,"Q1","Q2") | J848: =YEAR(E848)*100+MONTH(E848) | K848: =IF(COUNTIF($A$2:A848,A848)=1,1,0) | L848: =IF(K848=1,IF(COUNTIFS($B$2:B848,B848,$I$2:I848,I848,$K$2:K848,1)=1,1,0),0) | M848: =IF(Tree!$C$4="once per order",F848*K848,F848) | N848: =IF(Tree!$C$4="once per order",K848,1) | O848: =IF(Tree!$C$4="once per order",L848,1)
A849: KR-00587 | B849: C-0271 | C849: Business | D849: store | E849: 46259 | F849: 1310000 | G849: 524000 | H849: 2026-08-27 | I849: =IF(MONTH(E849)<=6,"Q1","Q2") | J849: =YEAR(E849)*100+MONTH(E849) | K849: =IF(COUNTIF($A$2:A849,A849)=1,1,0) | L849: =IF(K849=1,IF(COUNTIFS($B$2:B849,B849,$I$2:I849,I849,$K$2:K849,1)=1,1,0),0) | M849: =IF(Tree!$C$4="once per order",F849*K849,F849) | N849: =IF(Tree!$C$4="once per order",K849,1) | O849: =IF(Tree!$C$4="once per order",L849,1)
A850: KR-00588 | B850: C-0284 | C850: Business | D850: store | E850: 46276 | F850: 831000 | G850: 498600 | H850: 2026-09-13 | I850: =IF(MONTH(E850)<=6,"Q1","Q2") | J850: =YEAR(E850)*100+MONTH(E850) | K850: =IF(COUNTIF($A$2:A850,A850)=1,1,0) | L850: =IF(K850=1,IF(COUNTIFS($B$2:B850,B850,$I$2:I850,I850,$K$2:K850,1)=1,1,0),0) | M850: =IF(Tree!$C$4="once per order",F850*K850,F850) | N850: =IF(Tree!$C$4="once per order",K850,1) | O850: =IF(Tree!$C$4="once per order",L850,1)
A851: KR-00588 | B851: C-0284 | C851: Business | D851: store | E851: 46276 | F851: 831000 | G851: 332400 | H851: 2026-09-13 | I851: =IF(MONTH(E851)<=6,"Q1","Q2") | J851: =YEAR(E851)*100+MONTH(E851) | K851: =IF(COUNTIF($A$2:A851,A851)=1,1,0) | L851: =IF(K851=1,IF(COUNTIFS($B$2:B851,B851,$I$2:I851,I851,$K$2:K851,1)=1,1,0),0) | M851: =IF(Tree!$C$4="once per order",F851*K851,F851) | N851: =IF(Tree!$C$4="once per order",K851,1) | O851: =IF(Tree!$C$4="once per order",L851,1)
... A1413: KR-00963 | B1413: C-0070 | C1413: Retail-Core | D1413: store | E1413: 46290 | F1413: 1260 | G1413: 1260 | H1413: 2026-09-27 | I1413: =IF(MONTH(E1413)<=6,"Q1","Q2") | J1413: =YEAR(E1413)*100+MONTH(E1413) | K1413: =IF(COUNTIF($A$2:A1413,A1413)=1,1,0) | L1413: =IF(K1413=1,IF(COUNTIFS($B$2:B1413,B1413,$I$2:I1413,I1413,$K$2:K1413,1)=1,1,0),0) | M1413: =IF(Tree!$C$4="once per order",F1413*K1413,F1413) | N1413: =IF(Tree!$C$4="once per order",K1413,1) | O1413: =IF(Tree!$C$4="once per order",L1413,1)
A1414: KR-00964 | B1414: C-0011 | C1414: Retail-Core | D1414: store | E1414: 46221 | F1414: 1220 | G1414: 0 | I1414: =IF(MONTH(E1414)<=6,"Q1","Q2") | J1414: =YEAR(E1414)*100+MONTH(E1414) | K1414: =IF(COUNTIF($A$2:A1414,A1414)=1,1,0) | L1414: =IF(K1414=1,IF(COUNTIFS($B$2:B1414,B1414,$I$2:I1414,I1414,$K$2:K1414,1)=1,1,0),0) | M1414: =IF(Tree!$C$4="once per order",F1414*K1414,F1414) | N1414: =IF(Tree!$C$4="once per order",K1414,1) | O1414: =IF(Tree!$C$4="once per order",L1414,1)
A1415: KR-00965 | B1415: C-0033 | C1415: Retail-Core | D1415: store | E1415: 46244 | F1415: 1280 | G1415: 1280 | H1415: 2026-08-12 | I1415: =IF(MONTH(E1415)<=6,"Q1","Q2") | J1415: =YEAR(E1415)*100+MONTH(E1415) | K1415: =IF(COUNTIF($A$2:A1415,A1415)=1,1,0) | L1415: =IF(K1415=1,IF(COUNTIFS($B$2:B1415,B1415,$I$2:I1415,I1415,$K$2:K1415,1)=1,1,0),0) | M1415: =IF(Tree!$C$4="once per order",F1415*K1415,F1415) | N1415: =IF(Tree!$C$4="once per order",K1415,1) | O1415: =IF(Tree!$C$4="once per order",L1415,1)
A1416: KR-00966 | B1416: C-0041 | C1416: Retail-Core | D1416: web | E1416: 46288 | F1416: 2250 | G1416: 2250 | H1416: 2026-09-25 | I1416: =IF(MONTH(E1416)<=6,"Q1","Q2") | J1416: =YEAR(E1416)*100+MONTH(E1416) | K1416: =IF(COUNTIF($A$2:A1416,A1416)=1,1,0) | L1416: =IF(K1416=1,IF(COUNTIFS($B$2:B1416,B1416,$I$2:I1416,I1416,$K$2:K1416,1)=1,1,0),0) | M1416: =IF(Tree!$C$4="once per order",F1416*K1416,F1416) | N1416: =IF(Tree!$C$4="once per order",K1416,1) | O1416: =IF(Tree!$C$4="once per order",L1416,1)
...

Sheet Customers
A1: customer_id | B1: segment | C1: city | D1: orders | E1: revenue | F1: last_order_date | G1: rank in the list's segment
A2: C-0001 | B2: Retail-Core | C2: Delhi | D2: 2 | E2: 2840 | F2: 46240 | G2: =IF(B2=Protect!$C$4,COUNTIFS($B$2:$B$301,B2,$E$2:$E$301,">"&E2)+COUNTIFS($B$2:B2,B2,$E$2:E2,E2),"")
A3: C-0002 | B3: Retail-Core | C3: Chennai | D3: 4 | E3: 6700 | F3: 46208 | G3: =IF(B3=Protect!$C$4,COUNTIFS($B$2:$B$301,B3,$E$2:$E$301,">"&E3)+COUNTIFS($B$2:B3,B3,$E$2:E3,E3),"")
A4: C-0003 | B4: Retail-Core | C4: Delhi | D4: 6 | E4: 9710 | F4: 46249 | G4: =IF(B4=Protect!$C$4,COUNTIFS($B$2:$B$301,B4,$E$2:$E$301,">"&E4)+COUNTIFS($B$2:B4,B4,$E$2:E4,E4),"")
A5: C-0004 | B5: Retail-Core | C5: Bengaluru | D5: 2 | E5: 3120 | F5: 46245 | G5: =IF(B5=Protect!$C$4,COUNTIFS($B$2:$B$301,B5,$E$2:$E$301,">"&E5)+COUNTIFS($B$2:B5,B5,$E$2:E5,E5),"")
A6: C-0005 | B6: Retail-Core | C6: Bengaluru | D6: 3 | E6: 4970 | F6: 46284 | G6: =IF(B6=Protect!$C$4,COUNTIFS($B$2:$B$301,B6,$E$2:$E$301,">"&E6)+COUNTIFS($B$2:B6,B6,$E$2:E6,E6),"")
A7: C-0006 | B7: Retail-Core | C7: Hyderabad | D7: 4 | E7: 9630 | F7: 46276 | G7: =IF(B7=Protect!$C$4,COUNTIFS($B$2:$B$301,B7,$E$2:$E$301,">"&E7)+COUNTIFS($B$2:B7,B7,$E$2:E7,E7),"")
A8: C-0007 | B8: Retail-Core | C8: Bengaluru | D8: 5 | E8: 8250 | F8: 46267 | G8: =IF(B8=Protect!$C$4,COUNTIFS($B$2:$B$301,B8,$E$2:$E$301,">"&E8)+COUNTIFS($B$2:B8,B8,$E$2:E8,E8),"")
A9: C-0008 | B9: Retail-Core | C9: Chennai | D9: 3 | E9: 6550 | F9: 46159 | G9: =IF(B9=Protect!$C$4,COUNTIFS($B$2:$B$301,B9,$E$2:$E$301,">"&E9)+COUNTIFS($B$2:B9,B9,$E$2:E9,E9),"")
A10: C-0009 | B10: Retail-Core | C10: Pune | D10: 3 | E10: 8670 | F10: 46174 | G10: =IF(B10=Protect!$C$4,COUNTIFS($B$2:$B$301,B10,$E$2:$E$301,">"&E10)+COUNTIFS($B$2:B10,B10,$E$2:E10,E10),"")
A11: C-0010 | B11: Retail-Core | C11: Hyderabad | D11: 10 | E11: 19680 | F11: 46289 | G11: =IF(B11=Protect!$C$4,COUNTIFS($B$2:$B$301,B11,$E$2:$E$301,">"&E11)+COUNTIFS($B$2:B11,B11,$E$2:E11,E11),"")
A12: C-0011 | B12: Retail-Core | C12: Bengaluru | D12: 7 | E12: 13970 | F12: 46292 | G12: =IF(B12=Protect!$C$4,COUNTIFS($B$2:$B$301,B12,$E$2:$E$301,">"&E12)+COUNTIFS($B$2:B12,B12,$E$2:E12,E12),"")
A13: C-0012 | B13: Retail-Core | C13: Delhi | D13: 3 | E13: 5180 | F13: 46177 | G13: =IF(B13=Protect!$C$4,COUNTIFS($B$2:$B$301,B13,$E$2:$E$301,">"&E13)+COUNTIFS($B$2:B13,B13,$E$2:E13,E13),"")
... A301: C-0340 | B301: Student | C301: Mumbai | D301: 2 | E301: 1620 | F301: 46267 | G301: =IF(B301=Protect!$C$4,COUNTIFS($B$2:$B$301,B301,$E$2:$E$301,">"&E301)+COUNTIFS($B$2:B301,B301,$E$2:E301,E301),"")

Sheet Tree
A1: The revenue tree by segment, Q1 against Q2
A2: Customers times orders per customer times revenue per order, per segment and quarter, counted from the raw export. It must reconcile to the warehouse before any number leaves the team.
A4: Count each order | C4: once per order
A5: Warehouse total, both quarters (Rs) | C5: 198400000
A7: Segment | B7: Q1 customers | C7: Q1 orders | D7: Q1 orders per customer | E7: Q1 revenue per order | F7: Q1 revenue (Rs) | G7: Q2 customers | H7: Q2 orders | I7: Q2 orders per customer | J7: Q2 revenue per order | K7: Q2 revenue (Rs) | L7: Revenue change
A8: Business | B8: =SUMIFS(Raw!$O$2:$O$1451,Raw!$C$2:$C$1451,$A8,Raw!$I$2:$I$1451,"Q1") | C8: =SUMIFS(Raw!$N$2:$N$1451,Raw!$C$2:$C$1451,$A8,Raw!$I$2:$I$1451,"Q1") | D8: =IF(B8=0,0,C8/B8) | E8: =IF(C8=0,0,F8/C8) | F8: =SUMIFS(Raw!$M$2:$M$1451,Raw!$C$2:$C$1451,$A8,Raw!$I$2:$I$1451,"Q1") | G8: =SUMIFS(Raw!$O$2:$O$1451,Raw!$C$2:$C$1451,$A8,Raw!$I$2:$I$1451,"Q2") | H8: =SUMIFS(Raw!$N$2:$N$1451,Raw!$C$2:$C$1451,$A8,Raw!$I$2:$I$1451,"Q2") | I8: =IF(G8=0,0,H8/G8) | J8: =IF(H8=0,0,K8/H8) | K8: =SUMIFS(Raw!$M$2:$M$1451,Raw!$C$2:$C$1451,$A8,Raw!$I$2:$I$1451,"Q2") | L8: =IF(F8=0,0,(K8-F8)/F8)
A9: Retail-Core | B9: =SUMIFS(Raw!$O$2:$O$1451,Raw!$C$2:$C$1451,$A9,Raw!$I$2:$I$1451,"Q1") | C9: =SUMIFS(Raw!$N$2:$N$1451,Raw!$C$2:$C$1451,$A9,Raw!$I$2:$I$1451,"Q1") | D9: =IF(B9=0,0,C9/B9) | E9: =IF(C9=0,0,F9/C9) | F9: =SUMIFS(Raw!$M$2:$M$1451,Raw!$C$2:$C$1451,$A9,Raw!$I$2:$I$1451,"Q1") | G9: =SUMIFS(Raw!$O$2:$O$1451,Raw!$C$2:$C$1451,$A9,Raw!$I$2:$I$1451,"Q2") | H9: =SUMIFS(Raw!$N$2:$N$1451,Raw!$C$2:$C$1451,$A9,Raw!$I$2:$I$1451,"Q2") | I9: =IF(G9=0,0,H9/G9) | J9: =IF(H9=0,0,K9/H9) | K9: =SUMIFS(Raw!$M$2:$M$1451,Raw!$C$2:$C$1451,$A9,Raw!$I$2:$I$1451,"Q2") | L9: =IF(F9=0,0,(K9-F9)/F9)
A10: Retail-Plus | B10: =SUMIFS(Raw!$O$2:$O$1451,Raw!$C$2:$C$1451,$A10,Raw!$I$2:$I$1451,"Q1") | C10: =SUMIFS(Raw!$N$2:$N$1451,Raw!$C$2:$C$1451,$A10,Raw!$I$2:$I$1451,"Q1") | D10: =IF(B10=0,0,C10/B10) | E10: =IF(C10=0,0,F10/C10) | F10: =SUMIFS(Raw!$M$2:$M$1451,Raw!$C$2:$C$1451,$A10,Raw!$I$2:$I$1451,"Q1") | G10: =SUMIFS(Raw!$O$2:$O$1451,Raw!$C$2:$C$1451,$A10,Raw!$I$2:$I$1451,"Q2") | H10: =SUMIFS(Raw!$N$2:$N$1451,Raw!$C$2:$C$1451,$A10,Raw!$I$2:$I$1451,"Q2") | I10: =IF(G10=0,0,H10/G10) | J10: =IF(H10=0,0,K10/H10) | K10: =SUMIFS(Raw!$M$2:$M$1451,Raw!$C$2:$C$1451,$A10,Raw!$I$2:$I$1451,"Q2") | L10: =IF(F10=0,0,(K10-F10)/F10)
A11: Student | B11: =SUMIFS(Raw!$O$2:$O$1451,Raw!$C$2:$C$1451,$A11,Raw!$I$2:$I$1451,"Q1") | C11: =SUMIFS(Raw!$N$2:$N$1451,Raw!$C$2:$C$1451,$A11,Raw!$I$2:$I$1451,"Q1") | D11: =IF(B11=0,0,C11/B11) | E11: =IF(C11=0,0,F11/C11) | F11: =SUMIFS(Raw!$M$2:$M$1451,Raw!$C$2:$C$1451,$A11,Raw!$I$2:$I$1451,"Q1") | G11: =SUMIFS(Raw!$O$2:$O$1451,Raw!$C$2:$C$1451,$A11,Raw!$I$2:$I$1451,"Q2") | H11: =SUMIFS(Raw!$N$2:$N$1451,Raw!$C$2:$C$1451,$A11,Raw!$I$2:$I$1451,"Q2") | I11: =IF(G11=0,0,H11/G11) | J11: =IF(H11=0,0,K11/H11) | K11: =SUMIFS(Raw!$M$2:$M$1451,Raw!$C$2:$C$1451,$A11,Raw!$I$2:$I$1451,"Q2") | L11: =IF(F11=0,0,(K11-F11)/F11)
A12: All segments | B12: =SUM(B8:B11) | C12: =SUM(C8:C11) | D12: =IF(B12=0,0,C12/B12) | E12: =IF(C12=0,0,F12/C12) | F12: =SUM(F8:F11) | G12: =SUM(G8:G11) | H12: =SUM(H8:H11) | I12: =IF(G12=0,0,H12/G12) | J12: =IF(H12=0,0,K12/H12) | K12: =SUM(K8:K11) | L12: =IF(F12=0,0,(K12-F12)/F12)
A14: Tree total, both quarters (Rs) | C14: =F12+K12
A15: Tree total less the warehouse (Rs) | C15: =C14-C5
A16: Rows in the export | C16: =COUNTA(Raw!$A$2:$A$1451)
A17: Distinct orders in the export | C17: =SUM(Raw!$K$2:$K$1451)
A18: The check | C18: =IF(ABS(C15)<1,"The tree reconciles to the warehouse to the rupee.","The tree is "&IF(ABS((C15))>=10000000,"Rs "&TEXT((C15)/10000000,"0.00")&" crore",IF(ABS((C15))>=100000,"Rs "&TEXT((C15)/100000,"0.00")&" lakh","Rs "&IF(ROUND((C15),0)>=100000,INT(ROUND((C15),0)/100000)&","&TEXT(INT(MOD(ROUND((C15),0),100000)/1000),"00")&","&TEXT(MOD(ROUND((C15),0),1000),"000"),IF(ROUND((C15),0)>=1000,INT(ROUND((C15),0)/1000)&","&TEXT(MOD(ROUND((C15),0),1000),"000"),ROUND((C15),0)&""))))&" over the warehouse: "&C16&" rows carry "&C17&" orders, so some orders are counted more than once.")
A20: Verdict | C20: =IF(ABS(C15)>=1,"Do not send: the tree counts an order once per payment row. Count each order once.","Send: Q2 revenue "&IF(ABS((K12))>=10000000,"Rs "&TEXT((K12)/10000000,"0.00")&" crore",IF(ABS((K12))>=100000,"Rs "&TEXT((K12)/100000,"0.00")&" lakh","Rs "&IF(ROUND((K12),0)>=100000,INT(ROUND((K12),0)/100000)&","&TEXT(INT(MOD(ROUND((K12),0),100000)/1000),"00")&","&TEXT(MOD(ROUND((K12),0),1000),"000"),IF(ROUND((K12),0)>=1000,INT(ROUND((K12),0)/1000)&","&TEXT(MOD(ROUND((K12),0),1000),"000"),ROUND((K12),0)&""))))&", "&IF(L12<0,"down ","up ")&TEXT(ABS(L12)*100,"0.0")&" percent on Q1; Retail-Plus orders per customer "&TEXT(D10,"0.00")&" to "&TEXT(I10,"0.00")&", customers "&B10&" to "&G10&".")

Sheet Protect
A1: The protect list, and a lookup by member id
A2: The top members of one segment by revenue across both quarters, from the clean customer table. The lookup must say so when an id is missing.
A4: Segment of the list | C4: Retail-Plus | E4: Row returned | F4: =IF(C7="exact",IFERROR(INDEX(Customers!$A$2:$A$301,MATCH(C6,Customers!$A$2:$A$301,0)),"not found"),IFERROR(INDEX(Customers!$A$2:$A$301,MATCH(C6,Customers!$A$2:$A$301,1)),"not found"))
A5: List size | C5: 50 | E5: Revenue (Rs) | F5: =IF(F4="not found","",INDEX(Customers!$E$2:$E$301,MATCH(F4,Customers!$A$2:$A$301,0)))
A6: Member id to find | C6: C-0152 | E6: Place on the list | F6: =IF(F4="not found","",IFERROR(IF(INDEX(Customers!$G$2:$G$301,MATCH(F4,Customers!$A$2:$A$301,0))<=C5,"rank "&INDEX(Customers!$G$2:$G$301,MATCH(F4,Customers!$A$2:$A$301,0))&" of "&C5&" on the "&C4&" list","outside the top "&C5),"not in the "&C4&" segment"))
A7: Match type | C7: exact | E7: The check | F7: =IF(F4="not found",C6&" is not in the customer table.",IF(F4=C6,"The row returned is the member asked for.","The lookup returned "&F4&" for "&C6&": an approximate match answered with a neighbour."))
E8: XLOOKUP, in Excel | F8: =_xlfn.XLOOKUP(C6,Customers!$A$2:$A$301,Customers!$E$2:$E$301,"not in the table",0) | G8: Computed in Excel, not proved here: LibreOffice 24.2 returns #NAME? for XLOOKUP.
E9: Verdict | F9: =IF(F4="not found",C6&" is not in the customer table: say so, and check the export before anyone answers.",IF(F4<>C6,"Do not answer: the lookup returned "&F4&"'s row for "&C6&". Switch the match to exact.",C6&": "&"Rs "&IF(ROUND(F5,0)>=100000,INT(ROUND(F5,0)/100000)&","&TEXT(INT(MOD(ROUND(F5,0),100000)/1000),"00")&","&TEXT(MOD(ROUND(F5,0),1000),"000"),IF(ROUND(F5,0)>=1000,INT(ROUND(F5,0)/1000)&","&TEXT(MOD(ROUND(F5,0),1000),"000"),ROUND(F5,0)&""))&" across both quarters, "&F6&"."))
A11: Rank | B11: Member id | C11: City | D11: Orders | E11: Revenue (Rs) | F11: Last order
A12: 1 | B12: =IF($A12<=$C$5,IFERROR(INDEX(Customers!$A$2:$A$301,MATCH($A12,Customers!$G$2:$G$301,0)),""),"") | C12: =IF($B12="","",INDEX(Customers!$C$2:$C$301,MATCH($B12,Customers!$A$2:$A$301,0))) | D12: =IF($B12="","",INDEX(Customers!$D$2:$D$301,MATCH($B12,Customers!$A$2:$A$301,0))) | E12: =IF($B12="","",INDEX(Customers!$E$2:$E$301,MATCH($B12,Customers!$A$2:$A$301,0))) | F12: =IF($B12="","",INDEX(Customers!$F$2:$F$301,MATCH($B12,Customers!$A$2:$A$301,0)))
A13: 2 | B13: =IF($A13<=$C$5,IFERROR(INDEX(Customers!$A$2:$A$301,MATCH($A13,Customers!$G$2:$G$301,0)),""),"") | C13: =IF($B13="","",INDEX(Customers!$C$2:$C$301,MATCH($B13,Customers!$A$2:$A$301,0))) | D13: =IF($B13="","",INDEX(Customers!$D$2:$D$301,MATCH($B13,Customers!$A$2:$A$301,0))) | E13: =IF($B13="","",INDEX(Customers!$E$2:$E$301,MATCH($B13,Customers!$A$2:$A$301,0))) | F13: =IF($B13="","",INDEX(Customers!$F$2:$F$301,MATCH($B13,Customers!$A$2:$A$301,0)))
A14: 3 | B14: =IF($A14<=$C$5,IFERROR(INDEX(Customers!$A$2:$A$301,MATCH($A14,Customers!$G$2:$G$301,0)),""),"") | C14: =IF($B14="","",INDEX(Customers!$C$2:$C$301,MATCH($B14,Customers!$A$2:$A$301,0))) | D14: =IF($B14="","",INDEX(Customers!$D$2:$D$301,MATCH($B14,Customers!$A$2:$A$301,0))) | E14: =IF($B14="","",INDEX(Customers!$E$2:$E$301,MATCH($B14,Customers!$A$2:$A$301,0))) | F14: =IF($B14="","",INDEX(Customers!$F$2:$F$301,MATCH($B14,Customers!$A$2:$A$301,0)))
A15: 4 | B15: =IF($A15<=$C$5,IFERROR(INDEX(Customers!$A$2:$A$301,MATCH($A15,Customers!$G$2:$G$301,0)),""),"") | C15: =IF($B15="","",INDEX(Customers!$C$2:$C$301,MATCH($B15,Customers!$A$2:$A$301,0))) | D15: =IF($B15="","",INDEX(Customers!$D$2:$D$301,MATCH($B15,Customers!$A$2:$A$301,0))) | E15: =IF($B15="","",INDEX(Customers!$E$2:$E$301,MATCH($B15,Customers!$A$2:$A$301,0))) | F15: =IF($B15="","",INDEX(Customers!$F$2:$F$301,MATCH($B15,Customers!$A$2:$A$301,0)))
A16: 5 | B16: =IF($A16<=$C$5,IFERROR(INDEX(Customers!$A$2:$A$301,MATCH($A16,Customers!$G$2:$G$301,0)),""),"") | C16: =IF($B16="","",INDEX(Customers!$C$2:$C$301,MATCH($B16,Customers!$A$2:$A$301,0))) | D16: =IF($B16="","",INDEX(Customers!$D$2:$D$301,MATCH($B16,Customers!$A$2:$A$301,0))) | E16: =IF($B16="","",INDEX(Customers!$E$2:$E$301,MATCH($B16,Customers!$A$2:$A$301,0))) | F16: =IF($B16="","",INDEX(Customers!$F$2:$F$301,MATCH($B16,Customers!$A$2:$A$301,0)))
A17: 6 | B17: =IF($A17<=$C$5,IFERROR(INDEX(Customers!$A$2:$A$301,MATCH($A17,Customers!$G$2:$G$301,0)),""),"") | C17: =IF($B17="","",INDEX(Customers!$C$2:$C$301,MATCH($B17,Customers!$A$2:$A$301,0))) | D17: =IF($B17="","",INDEX(Customers!$D$2:$D$301,MATCH($B17,Customers!$A$2:$A$301,0))) | E17: =IF($B17="","",INDEX(Customers!$E$2:$E$301,MATCH($B17,Customers!$A$2:$A$301,0))) | F17: =IF($B17="","",INDEX(Customers!$F$2:$F$301,MATCH($B17,Customers!$A$2:$A$301,0)))
A18: 7 | B18: =IF($A18<=$C$5,IFERROR(INDEX(Customers!$A$2:$A$301,MATCH($A18,Customers!$G$2:$G$301,0)),""),"") | C18: =IF($B18="","",INDEX(Customers!$C$2:$C$301,MATCH($B18,Customers!$A$2:$A$301,0))) | D18: =IF($B18="","",INDEX(Customers!$D$2:$D$301,MATCH($B18,Customers!$A$2:$A$301,0))) | E18: =IF($B18="","",INDEX(Customers!$E$2:$E$301,MATCH($B18,Customers!$A$2:$A$301,0))) | F18: =IF($B18="","",INDEX(Customers!$F$2:$F$301,MATCH($B18,Customers!$A$2:$A$301,0)))
A19: 8 | B19: =IF($A19<=$C$5,IFERROR(INDEX(Customers!$A$2:$A$301,MATCH($A19,Customers!$G$2:$G$301,0)),""),"") | C19: =IF($B19="","",INDEX(Customers!$C$2:$C$301,MATCH($B19,Customers!$A$2:$A$301,0))) | D19: =IF($B19="","",INDEX(Customers!$D$2:$D$301,MATCH($B19,Customers!$A$2:$A$301,0))) | E19: =IF($B19="","",INDEX(Customers!$E$2:$E$301,MATCH($B19,Customers!$A$2:$A$301,0))) | F19: =IF($B19="","",INDEX(Customers!$F$2:$F$301,MATCH($B19,Customers!$A$2:$A$301,0)))
A20: 9 | B20: =IF($A20<=$C$5,IFERROR(INDEX(Customers!$A$2:$A$301,MATCH($A20,Customers!$G$2:$G$301,0)),""),"") | C20: =IF($B20="","",INDEX(Customers!$C$2:$C$301,MATCH($B20,Customers!$A$2:$A$301,0))) | D20: =IF($B20="","",INDEX(Customers!$D$2:$D$301,MATCH($B20,Customers!$A$2:$A$301,0))) | E20: =IF($B20="","",INDEX(Customers!$E$2:$E$301,MATCH($B20,Customers!$A$2:$A$301,0))) | F20: =IF($B20="","",INDEX(Customers!$F$2:$F$301,MATCH($B20,Customers!$A$2:$A$301,0)))
A21: 10 | B21: =IF($A21<=$C$5,IFERROR(INDEX(Customers!$A$2:$A$301,MATCH($A21,Customers!$G$2:$G$301,0)),""),"") | C21: =IF($B21="","",INDEX(Customers!$C$2:$C$301,MATCH($B21,Customers!$A$2:$A$301,0))) | D21: =IF($B21="","",INDEX(Customers!$D$2:$D$301,MATCH($B21,Customers!$A$2:$A$301,0))) | E21: =IF($B21="","",INDEX(Customers!$E$2:$E$301,MATCH($B21,Customers!$A$2:$A$301,0))) | F21: =IF($B21="","",INDEX(Customers!$F$2:$F$301,MATCH($B21,Customers!$A$2:$A$301,0)))
A22: 11 | B22: =IF($A22<=$C$5,IFERROR(INDEX(Customers!$A$2:$A$301,MATCH($A22,Customers!$G$2:$G$301,0)),""),"") | C22: =IF($B22="","",INDEX(Customers!$C$2:$C$301,MATCH($B22,Customers!$A$2:$A$301,0))) | D22: =IF($B22="","",INDEX(Customers!$D$2:$D$301,MATCH($B22,Customers!$A$2:$A$301,0))) | E22: =IF($B22="","",INDEX(Customers!$E$2:$E$301,MATCH($B22,Customers!$A$2:$A$301,0))) | F22: =IF($B22="","",INDEX(Customers!$F$2:$F$301,MATCH($B22,Customers!$A$2:$A$301,0)))
A23: 12 | B23: =IF($A23<=$C$5,IFERROR(INDEX(Customers!$A$2:$A$301,MATCH($A23,Customers!$G$2:$G$301,0)),""),"") | C23: =IF($B23="","",INDEX(Customers!$C$2:$C$301,MATCH($B23,Customers!$A$2:$A$301,0))) | D23: =IF($B23="","",INDEX(Customers!$D$2:$D$301,MATCH($B23,Customers!$A$2:$A$301,0))) | E23: =IF($B23="","",INDEX(Customers!$E$2:$E$301,MATCH($B23,Customers!$A$2:$A$301,0))) | F23: =IF($B23="","",INDEX(Customers!$F$2:$F$301,MATCH($B23,Customers!$A$2:$A$301,0)))
... A71: 60 | B71: =IF($A71<=$C$5,IFERROR(INDEX(Customers!$A$2:$A$301,MATCH($A71,Customers!$G$2:$G$301,0)),""),"") | C71: =IF($B71="","",INDEX(Customers!$C$2:$C$301,MATCH($B71,Customers!$A$2:$A$301,0))) | D71: =IF($B71="","",INDEX(Customers!$D$2:$D$301,MATCH($B71,Customers!$A$2:$A$301,0))) | E71: =IF($B71="","",INDEX(Customers!$E$2:$E$301,MATCH($B71,Customers!$A$2:$A$301,0))) | F71: =IF($B71="","",INDEX(Customers!$F$2:$F$301,MATCH($B71,Customers!$A$2:$A$301,0)))
A73: Members you can see | E73: =SUBTOTAL(102,E12:E71)
A74: Total of the rows you can see (Rs) | E74: =SUBTOTAL(109,E12:E71)
A75: Total of the whole list (Rs) | E75: =SUM(E12:E71)
A76: List verdict | B76: =IF(E73<COUNT(E12:E71),"Filtered: the foot totals the "&E73&" members you can see, "&"Rs "&IF(ROUND(E74,0)>=100000,INT(ROUND(E74,0)/100000)&","&TEXT(INT(MOD(ROUND(E74,0),100000)/1000),"00")&","&TEXT(MOD(ROUND(E74,0),1000),"000"),IF(ROUND(E74,0)>=1000,INT(ROUND(E74,0)/1000)&","&TEXT(MOD(ROUND(E74,0),1000),"000"),ROUND(E74,0)&""))&"; the whole list is "&IF(ABS((E75))>=10000000,"Rs "&TEXT((E75)/10000000,"0.00")&" crore",IF(ABS((E75))>=100000,"Rs "&TEXT((E75)/100000,"0.00")&" lakh","Rs "&IF(ROUND((E75),0)>=100000,INT(ROUND((E75),0)/100000)&","&TEXT(INT(MOD(ROUND((E75),0),100000)/1000),"00")&","&TEXT(MOD(ROUND((E75),0),1000),"000"),IF(ROUND((E75),0)>=1000,INT(ROUND((E75),0)/1000)&","&TEXT(MOD(ROUND((E75),0),1000),"000"),ROUND((E75),0)&""))))&".","The top "&E73&" "&C4&" members spent "&IF(ABS((E74))>=10000000,"Rs "&TEXT((E74)/10000000,"0.00")&" crore",IF(ABS((E74))>=100000,"Rs "&TEXT((E74)/100000,"0.00")&" lakh","Rs "&IF(ROUND((E74),0)>=100000,INT(ROUND((E74),0)/100000)&","&TEXT(INT(MOD(ROUND((E74),0),100000)/1000),"00")&","&TEXT(MOD(ROUND((E74),0),1000),"000"),IF(ROUND((E74),0)>=1000,INT(ROUND((E74),0)/1000)&","&TEXT(MOD(ROUND((E74),0),1000),"000"),ROUND((E74),0)&""))))&" across both quarters.")

Sheet FrontPage
A1: One number, with its period, comparison, denominator and trend
A2: The card a director reads in two minutes. Change the scope and the number, the sentence and the trend move together.
A4: What the card covers | B4: All segments
A6: Revenue by month (Rs) | B6: Apr | C6: May | D6: Jun | E6: Jul | F6: Aug | G6: Sep | H6: Q1 total | I6: Q2 total
A7: Business | B7: =SUMIFS(Raw!$M$2:$M$1451,Raw!$C$2:$C$1451,$A7,Raw!$J$2:$J$1451,202604) | C7: =SUMIFS(Raw!$M$2:$M$1451,Raw!$C$2:$C$1451,$A7,Raw!$J$2:$J$1451,202605) | D7: =SUMIFS(Raw!$M$2:$M$1451,Raw!$C$2:$C$1451,$A7,Raw!$J$2:$J$1451,202606) | E7: =SUMIFS(Raw!$M$2:$M$1451,Raw!$C$2:$C$1451,$A7,Raw!$J$2:$J$1451,202607) | F7: =SUMIFS(Raw!$M$2:$M$1451,Raw!$C$2:$C$1451,$A7,Raw!$J$2:$J$1451,202608) | G7: =SUMIFS(Raw!$M$2:$M$1451,Raw!$C$2:$C$1451,$A7,Raw!$J$2:$J$1451,202609) | H7: =SUM(B7:D7) | I7: =SUM(E7:G7)
A8: Retail-Core | B8: =SUMIFS(Raw!$M$2:$M$1451,Raw!$C$2:$C$1451,$A8,Raw!$J$2:$J$1451,202604) | C8: =SUMIFS(Raw!$M$2:$M$1451,Raw!$C$2:$C$1451,$A8,Raw!$J$2:$J$1451,202605) | D8: =SUMIFS(Raw!$M$2:$M$1451,Raw!$C$2:$C$1451,$A8,Raw!$J$2:$J$1451,202606) | E8: =SUMIFS(Raw!$M$2:$M$1451,Raw!$C$2:$C$1451,$A8,Raw!$J$2:$J$1451,202607) | F8: =SUMIFS(Raw!$M$2:$M$1451,Raw!$C$2:$C$1451,$A8,Raw!$J$2:$J$1451,202608) | G8: =SUMIFS(Raw!$M$2:$M$1451,Raw!$C$2:$C$1451,$A8,Raw!$J$2:$J$1451,202609) | H8: =SUM(B8:D8) | I8: =SUM(E8:G8)
A9: Retail-Plus | B9: =SUMIFS(Raw!$M$2:$M$1451,Raw!$C$2:$C$1451,$A9,Raw!$J$2:$J$1451,202604) | C9: =SUMIFS(Raw!$M$2:$M$1451,Raw!$C$2:$C$1451,$A9,Raw!$J$2:$J$1451,202605) | D9: =SUMIFS(Raw!$M$2:$M$1451,Raw!$C$2:$C$1451,$A9,Raw!$J$2:$J$1451,202606) | E9: =SUMIFS(Raw!$M$2:$M$1451,Raw!$C$2:$C$1451,$A9,Raw!$J$2:$J$1451,202607) | F9: =SUMIFS(Raw!$M$2:$M$1451,Raw!$C$2:$C$1451,$A9,Raw!$J$2:$J$1451,202608) | G9: =SUMIFS(Raw!$M$2:$M$1451,Raw!$C$2:$C$1451,$A9,Raw!$J$2:$J$1451,202609) | H9: =SUM(B9:D9) | I9: =SUM(E9:G9)
A10: Student | B10: =SUMIFS(Raw!$M$2:$M$1451,Raw!$C$2:$C$1451,$A10,Raw!$J$2:$J$1451,202604) | C10: =SUMIFS(Raw!$M$2:$M$1451,Raw!$C$2:$C$1451,$A10,Raw!$J$2:$J$1451,202605) | D10: =SUMIFS(Raw!$M$2:$M$1451,Raw!$C$2:$C$1451,$A10,Raw!$J$2:$J$1451,202606) | E10: =SUMIFS(Raw!$M$2:$M$1451,Raw!$C$2:$C$1451,$A10,Raw!$J$2:$J$1451,202607) | F10: =SUMIFS(Raw!$M$2:$M$1451,Raw!$C$2:$C$1451,$A10,Raw!$J$2:$J$1451,202608) | G10: =SUMIFS(Raw!$M$2:$M$1451,Raw!$C$2:$C$1451,$A10,Raw!$J$2:$J$1451,202609) | H10: =SUM(B10:D10) | I10: =SUM(E10:G10)
A11: All segments | B11: =SUM(B7:B10) | C11: =SUM(C7:C10) | D11: =SUM(D7:D10) | E11: =SUM(E7:E10) | F11: =SUM(F7:F10) | G11: =SUM(G7:G10) | H11: =SUM(B11:D11) | I11: =SUM(E11:G11)
A12: The card's scope | B12: =IF($B$4="All segments",B11,IF($B$4="All except Business",B11-B7,INDEX(B7:B10,MATCH($B$4,$A$7:$A$10,0)))) | C12: =IF($B$4="All segments",C11,IF($B$4="All except Business",C11-C7,INDEX(C7:C10,MATCH($B$4,$A$7:$A$10,0)))) | D12: =IF($B$4="All segments",D11,IF($B$4="All except Business",D11-D7,INDEX(D7:D10,MATCH($B$4,$A$7:$A$10,0)))) | E12: =IF($B$4="All segments",E11,IF($B$4="All except Business",E11-E7,INDEX(E7:E10,MATCH($B$4,$A$7:$A$10,0)))) | F12: =IF($B$4="All segments",F11,IF($B$4="All except Business",F11-F7,INDEX(F7:F10,MATCH($B$4,$A$7:$A$10,0)))) | G12: =IF($B$4="All segments",G11,IF($B$4="All except Business",G11-G7,INDEX(G7:G10,MATCH($B$4,$A$7:$A$10,0)))) | H12: =SUM(B12:D12) | I12: =SUM(E12:G12)
A14: The number | B14: =IF(ABS((I12))>=10000000,"Rs "&TEXT((I12)/10000000,"0.00")&" crore",IF(ABS((I12))>=100000,"Rs "&TEXT((I12)/100000,"0.00")&" lakh","Rs "&IF(ROUND((I12),0)>=100000,INT(ROUND((I12),0)/100000)&","&TEXT(INT(MOD(ROUND((I12),0),100000)/1000),"00")&","&TEXT(MOD(ROUND((I12),0),1000),"000"),IF(ROUND((I12),0)>=1000,INT(ROUND((I12),0)/1000)&","&TEXT(MOD(ROUND((I12),0),1000),"000"),ROUND((I12),0)&""))))
A15: The period | B15: Q2, July to September 2026
A16: The comparison | B16: =IF(H12=0,"no Q1 figure to compare",IF(I12<H12,"down ","up ")&TEXT(ABS(I12-H12)/H12*100,"0.0")&" percent on Q1, April to June 2026 ("&IF(ABS((H12))>=10000000,"Rs "&TEXT((H12)/10000000,"0.00")&" crore",IF(ABS((H12))>=100000,"Rs "&TEXT((H12)/100000,"0.00")&" lakh","Rs "&IF(ROUND((H12),0)>=100000,INT(ROUND((H12),0)/100000)&","&TEXT(INT(MOD(ROUND((H12),0),100000)/1000),"00")&","&TEXT(MOD(ROUND((H12),0),1000),"000"),IF(ROUND((H12),0)>=1000,INT(ROUND((H12),0)/1000)&","&TEXT(MOD(ROUND((H12),0),1000),"000"),ROUND((H12),0)&""))))&")")
A17: The denominator | B17: =TEXT(I12/I11*100,"0.0")&" percent of company revenue in Q2"
A18: The check | B18: =IF(ABS(H11+I11-Tree!C5)<1,"The card reconciles to the warehouse.","The card does not reconcile: its two quarters sum to "&IF(ABS((H11+I11))>=10000000,"Rs "&TEXT((H11+I11)/10000000,"0.00")&" crore",IF(ABS((H11+I11))>=100000,"Rs "&TEXT((H11+I11)/100000,"0.00")&" lakh","Rs "&IF(ROUND((H11+I11),0)>=100000,INT(ROUND((H11+I11),0)/100000)&","&TEXT(INT(MOD(ROUND((H11+I11),0),100000)/1000),"00")&","&TEXT(MOD(ROUND((H11+I11),0),1000),"000"),IF(ROUND((H11+I11),0)>=1000,INT(ROUND((H11+I11),0)/1000)&","&TEXT(MOD(ROUND((H11+I11),0),1000),"000"),ROUND((H11+I11),0)&""))))&" against the warehouse's "&IF(ABS((Tree!C5))>=10000000,"Rs "&TEXT((Tree!C5)/10000000,"0.00")&" crore",IF(ABS((Tree!C5))>=100000,"Rs "&TEXT((Tree!C5)/100000,"0.00")&" lakh","Rs "&IF(ROUND((Tree!C5),0)>=100000,INT(ROUND((Tree!C5),0)/100000)&","&TEXT(INT(MOD(ROUND((Tree!C5),0),100000)/1000),"00")&","&TEXT(MOD(ROUND((Tree!C5),0),1000),"000"),IF(ROUND((Tree!C5),0)>=1000,INT(ROUND((Tree!C5),0)/1000)&","&TEXT(MOD(ROUND((Tree!C5),0),1000),"000"),ROUND((Tree!C5),0)&""))))&".")
A20: The card | B20: =IF(ABS(H11+I11-Tree!C5)>=1,"Hold the card: it is built on a count that does not reconcile to the warehouse.",B4&", "&B15&": "&B14&", "&B16&"; "&B17&".")
